Workbook

Sheet Payroll Mr Shin
A1: CÔNG TY TNHH SHINSUNG VINA
A2: Lô CN04, khu công nghiệp Cẩm Khê, TT.Cẩm Khê, H.Cẩm Khê, T.Phú Thọ
A3: PAYROLL AUGUST 2024
A4: From 1st -31th August 2024
A6: Tỷ giá Vietinbank: 31/08/2024 | C6: 24520 | D6: 25020
A8: STT (No) | B8: Họ và tên (First and last name) | C8: Vị trí (Location) | D8: Giờ công cơ bản thực tế (The actual basic hourly) | E8: Giờ công làm thêm (Hours of overtime) | I8: Lương cơ bản (Basic salary) USD | J8: Lương cơ bản (Basic salary) | K8: Các khoản phụ cấp (Allowances) | Q8: Tổng các khoản phụ cấp (Total allowances) | R8: Lương đóng bảo hiểm | S8: Lương giờ công | T8: Tổng lương giờ công cơ bản | U8: Lương giờ công làm thêm | Z8: Tổng lương | AA8: BH tính vào chi phí / Isuarance payable by company | AF8: BH khấu trừ lương / Isuarance deductions from salary | AJ8: Thuế TNCN /Personal income tax | AQ8: Thực nhận | AS8: Số tài khoản | AT8: Ký nhận
E9: Tăng ca ngày | F9: Tăng ca đêm | G9: Tăng ca CN 200% | H9: Tăng ca ngày lễ 300% | K9: Phụ cấp trách nhiệm | L9: Phụ cấp điện thoại | M9: Phụ cấp xăng xe | N9: Phụ cấp nhà ở | O9: Phụ cấp đi lại | P9: Chuyên cần (Diligence) | U9: Tăng ca ngày 150% | V9: Tăng ca đêm | W9: Tăng ca CN 200% | X9: Tăng ca ngày lễ 300% | Y9: Tổng lương làm thêm | AA9: Lương đóng bảo hiểm/Salary base for insurance | AB9: BHXH / Social Insurance 17.5% | AC9: BHYT / Health Insurance 3%건강보험 (회사분) | AD9: BHTN / Unemployment Insurance 1% | AE9: Cộng /Amount Isurance | AF9: BHXH / Social Insurance 8% | AG9: BHYT / Health Insurance 1,5% 건강보험 (개인분) | AH9: BHTN / Unemployment Insurance 1% | AI9: Cộng 10.5%/Amount Isurance | AJ9: Giảm trừ bản thân (기본공제금 ) (VND) | AK9: Số người phụ thuộc /Number Deduction family | AL9: Giảm trừ người phụ thuộc /deduction-family 4400000/1person | AM9: Tax excemption | AN9: Thu nhập chịu thuế | AO9: Thu nhập tính thuế (과세 대상 금액) (VND) | AP9: Thuế TNCN (개인소득세) ( VND) | AQ9: VND | AR9: USD (Quy đổi)
A10: -1 | B10: -2 | C10: -3 | D10: -4 | E10: -5 | F10: (5a) | G10: -6 | H10: -7 | J10: -8 | K10: -9 | L10: -10 | M10: -11 | N10: (11 a) | O10: (11b) | P10: -12 | Q10: (13)=10+11+11a+11b+ 12 | R10: (14)=(8)+(9) | S10: (15)=(14)/4 | T10: (16)=(15)*(4) | U10: (17)=(5)* (15)*150% | V10: (17a) | W10: (18)=(6)* (15)*200% | X10: (19)=(7)* (15)*300% | Y10: (20)= (17)+(18)+(19) | Z10: (21)=(13)+(16)+ (20) | AA10: (22)=(8)+ (10) | AB10: (23)=(22)x17% | AC10: (24)=(22)x3% | AD10: 25 | AE10: (26)=(23)+(24) | AF10: 27 | AG10: (28)=(22)x1.5% | AH10: 29 | AI10: (30)=(27)+(28)+(29) | AJ10: -31 | AK10: (31a) | AL10: (32)= (31a)x4400000 | AM10: -33 | AN10: (34)=(21)-(33) | AO10: (35)=(21)-(31)-(32)-(33) | AP10: -36 | AQ10: -37 | AR10: -38 | AS10: -39 | AT10: -40
A11: 1 | B11: Shin Chun Ki | C11: TGĐ | D11: 208 | J11: =2500*D6 -> 62550000 | Q11: =SUM(L11:P11) -> 0 | R11: =J11+K11 -> 62550000 | S11: =R11/D11 -> 300721.15 | T11: =S11*D11 -> 62550000 | U11: =S11*E11*150% -> 0 | W11: =S11*G11*200% -> 0 | X11: =S11*H11*300% -> 0 | Y11: =SUM(U11:X11) -> 0 | Z11: =Q11+T11+Y11 -> 62550000 | AA11: 29800000 | AB11: =AA11*5% -> 1490000 | AC11: =AA11*3% -> 894000 | AE11: =AB11+AC11+AD11 -> 2384000 | AG11: =AA11*1.5% -> 447000 | AI11: =AF11+AG11+AH11 -> 447000 | AJ11: 11000000 | AK11: 3 | AL11: =AK11*4400000 -> 13200000 | AM11: =L11 -> 0 | AN11: =Z11-AM11 -> 62550000 | AO11: =(Z11-AJ11-AL11-AM11-AI11) -> 37903000 | AP11: =ROUND(IF(AO11<=5000000,AO11*5%,IF(AND(AO11>5000000,AO11<=10000000),AO11*10%-250000,IF(AND(AO11>10000000,AO11<=18000000),AO11*15%-750000,IF(AND(AO11>18000000,AO11<=32000000),AO11*20%-1650000,IF(AND(AO11>32000000,AO11<=52000000),AO11*25%-3250000,IF(AND(AO11>52000000,AO11<80000000),AO11*30%-5850000,IF(AO11>80000000,AO11*35%-9850000))))))),0) -> 6225750 | AQ11: =Z11-AI11-AP11 -> 55877250 | AR11: =+AQ11/D6 -> 2233.3034
A12: 1 | B12: Shin Chun Ki | C12: Nhà quản lý | D12: 216 | I12: =6000*0.85 -> 5100 | J12: =I12*D6 -> 127602000 | Q12: =SUM(L12:P12) -> 0 | R12: =J12+K12 -> 127602000 | S12: =R12/D12 -> 590750 | T12: =S12*D12 -> 127602000 | U12: =S12*E12*150% -> 0 | W12: =S12*G12*200% -> 0 | X12: =S12*H12*300% -> 0 | Y12: =SUM(U12:X12) -> 0 | Z12: =Q12+T12+Y12 -> 127602000 | AA12: 46800000 | AB12: =AA12*17.5% -> 8190000 | AC12: =+AA12*3% -> 1404000 | AE12: =AB12+AC12+AD12 -> 9594000 | AF12: =AA12*8% -> 3744000 | AG12: =+AA12*1.5% -> 702000 | AI12: =AF12+AG12+AH12 -> 4446000 | AJ12: 11000000 | AK12: 3 | AL12: =+AK12*4400000 -> 13200000 | AN12: =Z12-AM12 -> 127602000 | AO12: =(AN12-AJ12-AL12-AI12) -> 98956000 | AP12: =ROUND(IF(AO12<=5000000,AO12*5%,IF(AND(AO12>5000000,AO12<=10000000),AO12*10%-250000,IF(AND(AO12>10000000,AO12<=18000000),AO12*15%-750000,IF(AND(AO12>18000000,AO12<=32000000),AO12*20%-1650000,IF(AND(AO12>32000000,AO12<=52000000),AO12*25%-3250000,IF(AND(AO12>52000000,AO12<80000000),AO12*30%-5850000,IF(AO12>80000000,AO12*35%-9850000))))))),0) -> 24784600 | AQ12: =Z12-AI12-AP12 -> 98371400 | AR12: =AQ12/D6 -> 3931.7106 | AS12: 109871163330
B14: Scheduling | V14: Manager | AG14: Manager | AS14: Director- general
AQ19: =AP12+'Mr. Lim'!AS11+Mr.Moon!AS11+'Mr. Yang'!AS11+'Mr. Choi'!AS11+'Mr. Hwang'!AS11+'Payroll Office'!BM23+'Payroll of factory (SOI) '!BN27 -> 67940860 | AS19: =AR12+'Mr. Lim'!AV11+'Mr. Yang'!AV11 -> 7759.2389
AQ20: =AP12+'Mr. Lim'!AS11+Mr.Moon!AS11+'Mr. Yang'!AS11+'Mr. Choi'!AS11+'Mr. Hwang'!AS11+'Payroll Office'!BM23+'Payroll of factory (SOI) '!BN27+'Payroll of factory '!BM22 -> 67940860
AL23: =AE12+'Mr. Lim'!AE11+'Mr. Yang'!AE11+'Mr. Hwang'!AE11+'Payroll Office'!BB23+'Payroll of factory '!BB22+'Payroll of factory (SOI) '!BC27+'Payroll of factory (DET).1'!BD40 -> 116191080

Sheet Mr. Lim
A1: CÔNG TY TNHH SHINSUNG VINA
A2: Lô CN04, khu công nghiệp Cẩm Khê, TT.Cẩm Khê, H.Cẩm Khê, T.Phú Thọ
A3: PAYROLL AUGUST 2024
A4: From 1st -31th August 2024
A6: ='Payroll Mr Shin'!A6 -> Tỷ giá Vietinbank: 31/08/2024 | C6: ='Payroll Mr Shin'!C6 -> 24520 | D6: ='Payroll Mr Shin'!D6 -> 25020
A8: STT (No) | B8: Họ và tên (First and last name) | C8: Vị trí (Location) | D8: Giờ công cơ bản thực tế (The actual basic hourly) | E8: Giờ công làm thêm (Hours of overtime) | I8: Lương cơ bản (Basic salary) USD | J8: Lương cơ bản (Basic salary) | K8: Các khoản phụ cấp (Allowances) | Q8: Tổng các khoản phụ cấp (Total allowances) | R8: Lương đóng bảo hiểm | S8: Lương giờ công | T8: Tổng lương giờ công cơ bản | U8: Lương giờ công làm thêm | Z8: Tổng lương | AA8: BH tính vào chi phí / Isuarance payable by company | AF8: BH khấu trừ lương / Isuarance deductions from salary | AJ8: Thuế TNCN /Personal income tax | AT8: Khấu trừ Thuế TNCN | AU8: Thực nhận | AW8: Số tài khoản | AX8: Ký nhận
E9: Tăng ca ngày | F9: Tăng ca đêm | G9: Tăng ca CN 200% | H9: Tăng ca ngày lễ 300% | K9: Phụ cấp trách nhiệm | L9: Phụ cấp điện thoại | M9: Phụ cấp xăng xe | N9: Phụ cấp nhà ở | O9: Phụ cấp đi lại | P9: Chuyên cần (Diligence) | U9: Tăng ca ngày 150% | V9: Tăng ca đêm | W9: Tăng ca CN 200% | X9: Tăng ca ngày lễ 300% | Y9: Tổng lương làm thêm | AA9: Lương đóng bảo hiểm/Salary base for insurance | AB9: BHXH / Social Insurance 17% | AC9: BHYT / Health Insurance 3%건강보험 (회사분) | AD9: BHTN / Unemployment Insurance 1% | AE9: Cộng /Amount Isurance | AF9: BHXH / Social Insurance 8% | AG9: BHYT / Health Insurance 1,5% 건강보험 (개인분) | AH9: BHTN / Unemployment Insurance 1% | AI9: Cộng 10.5%/Amount Isurance | AJ9: Giảm trừ bản thân (기본공제금 ) (VND) | AK9: Số người phụ thuộc /Number Deduction family | AL9: Giảm trừ người phụ thuộc /deduction-family 4400000/1person | AM9: Tax excemption | AN9: Thu nhập chịu thuế | AO9: 15% TNCN | AP9: Tiền thuê nhà thực tế | AQ9: Thu nhập chịu thuế bao gồm tiền thuê nhà | AR9: Thu nhập tính thuế (과세 대상 금액) VND | AS9: Thuế TNCN (개인소득세) ( VND) | AU9: VND | AV9: USD (Quy đổi)
A10: -1 | B10: -2 | C10: -3 | D10: -4 | E10: -5 | F10: (5a) | G10: -6 | H10: -7 | J10: -8 | K10: -9 | L10: -10 | M10: -11 | N10: (11 a) | O10: (11b) | P10: -12 | Q10: (13)=10+11+11a+11b+ 12 | R10: (14)=(8)+(9) | S10: (15)=(14)/4 | T10: (16)=(15)*(4) | U10: (17)=(5)* (15)*150% | V10: (17a) | W10: (18)=(6)* (15)*200% | X10: (19)=(7)* (15)*300% | Y10: (20)= (17)+(18)+(19) | Z10: (21)=(13)+(16)+ (20) | AA10: (22)=(8)+ (10) | AB10: (23)=(22)x17.5% | AC10: (24)=(22)x3% | AD10: 25 | AE10: (26)=(23)+(24) | AF10: (27)=(22)x8% | AG10: (28)=(22)x1.5% | AH10: 29 | AI10: (30)=(27)+(28)+(29) | AJ10: -31 | AK10: (31a) | AL10: (32)= (31a)x4400000 | AM10: -33 | AN10: (34)=(21)-(33) | AO10: -32 | AP10: (34)=(21)-(33) | AQ10: -31 | AR10: (35)=(21)-(31)-(32)-(33) | AS10: -36 | AT10: -36 | AU10: -37 | AV10: -38 | AW10: -39 | AX10: -40
A11: 1 | B11: Lim Heungsub | C11: CG | D11: 216 | I11: =3500*0.85 -> 2975 | J11: =I11*D6 -> 74434500 | Q11: =SUM(L11:P11) -> 0 | S11: =J11/D11 -> 344604.17 | T11: =S11*D11 -> 74434500 | U11: =S11*E11*150% -> 0 | W11: =S11*G11*200% -> 0 | X11: =S11*H11*300% -> 0 | Y11: =SUM(U11:X11) -> 0 | Z11: =Q11+T11+Y11 -> 74434500 | AA11: 46800000 | AB11: =AA11*17.5% -> 8190000 | AC11: =+AA11*3% -> 1404000 | AE11: =AB11+AC11+AD11 -> 9594000 | AF11: =AA11*0.08 -> 3744000 | AG11: =+AA11*1.5% -> 702000 | AI11: =AF11+AG11+AH11 -> 4446000 | AJ11: 11000000 | AK11: 1 | AL11: =+AK11*4400000 -> 4400000 | AN11: =Z11-AM11 -> 74434500 | AO11: =AN11*15% -> 11165175 | AP11: =2000000/5 -> 400000 | AQ11: =AN11+AP11 -> 74834500 | AR11: =(AQ11-AJ11-AL11-AI11) -> 54988500 | AS11: =ROUND(IF(AR11<=5000000,AR11*5%,IF(AND(AR11>5000000,AR11<=10000000),AR11*10%-250000,IF(AND(AR11>10000000,AR11<=18000000),AR11*15%-750000,IF(AND(AR11>18000000,AR11<=32000000),AR11*20%-1650000,IF(AND(AR11>32000000,AR11<=52000000),AR11*25%-3250000,IF(AND(AR11>52000000,AR11<80000000),AR11*30%-5850000,IF(AR11>80000000,AR11*35%-9850000))))))),0) -> 10646550 | AT11: 0 | AU11: =Z11-AI11-AS11-AT11 -> 59341950 | AV11: =AU11/D6 -> 2371.7806 | AW11: 103873550905
B13: Scheduling | AI13: Manager | AW13: Director- general

Sheet Mr.Moon
A1: CÔNG TY TNHH SHINSUNG VINA
A2: Lô CN04, khu công nghiệp Cẩm Khê, TT.Cẩm Khê, H.Cẩm Khê, T.Phú Thọ
A3: PAYROLL AUGUST 2024
A4: From 1st -31th August 2024
A6: ='Payroll Mr Shin'!A6 -> Tỷ giá Vietinbank: 31/08/2024 | C6: ='Payroll Mr Shin'!C6 -> 24520 | D6: ='Payroll Mr Shin'!D6 -> 25020
A8: STT (No) | B8: Họ và tên (First and last name) | C8: Vị trí (Location) | D8: Giờ công cơ bản thực tế (The actual basic hourly) | E8: Giờ công làm thêm (Hours of overtime) | I8: Lương cơ bản (Basic salary) USD | J8: Lương cơ bản (Basic salary) | K8: Các khoản phụ cấp (Allowances) | Q8: Tổng các khoản phụ cấp (Total allowances) | R8: Lương đóng bảo hiểm | S8: Lương giờ công | T8: Tổng lương giờ công cơ bản | U8: Lương giờ công làm thêm | Z8: Tổng lương | AA8: BH tính vào chi phí / Isuarance payable by company | AF8: BH khấu trừ lương / Isuarance deductions from salary | AJ8: Thuế TNCN /Personal income tax | AT8: Khấu trừ Thuế TNCN | AU8: Thực nhận | AW8: Số tài khoản | AX8: Ký nhận
E9: Tăng ca ngày | F9: Tăng ca đêm | G9: Tăng ca CN 200% | H9: Tăng ca ngày lễ 300% | K9: Phụ cấp trách nhiệm | L9: Phụ cấp điện thoại | M9: Phụ cấp xăng xe | N9: Phụ cấp nhà ở | O9: Phụ cấp đi lại | P9: Chuyên cần (Diligence) | U9: Tăng ca ngày 150% | V9: Tăng ca đêm | W9: Tăng ca CN 200% | X9: Tăng ca ngày lễ 300% | Y9: Tổng lương làm thêm | AA9: Lương đóng bảo hiểm/Salary base for insurance | AB9: BHXH / Social Insurance 17% | AC9: BHYT / Health Insurance 3%건강보험 (회사분) | AD9: BHTN / Unemployment Insurance 1% | AE9: Cộng /Amount Isurance | AF9: BHXH / Social Insurance 8% | AG9: BHYT / Health Insurance 1,5% 건강보험 (개인분) | AH9: BHTN / Unemployment Insurance 1% | AI9: Cộng 10.5%/Amount Isurance | AJ9: Giảm trừ bản thân (기본공제금 ) (VND) | AK9: Số người phụ thuộc /Number Deduction family | AL9: Giảm trừ người phụ thuộc /deduction-family 4400000/1person | AM9: Tax excemption | AN9: Thu nhập chịu thuế | AO9: 15% TNCN | AP9: Tiền thuê nhà thực tế | AQ9: Thu nhập chịu thuế bao gồm tiền thuê nhà | AR9: Thu nhập tính thuế (과세 대상 금액) VND | AS9: Thuế TNCN (개인소득세) ( VND) | AU9: VND | AV9: USD (Quy đổi)
A10: -1 | B10: -2 | C10: -3 | D10: -4 | E10: -5 | F10: (5a) | G10: -6 | H10: -7 | J10: -8 | K10: -9 | L10: -10 | M10: -11 | N10: (11 a) | O10: (11b) | P10: -12 | Q10: (13)=10+11+11a+11b+ 12 | R10: (14)=(8)+(9) | S10: (15)=(14)/4 | T10: (16)=(15)*(4) | U10: (17)=(5)* (15)*150% | V10: (17a) | W10: (18)=(6)* (15)*200% | X10: (19)=(7)* (15)*300% | Y10: (20)= (17)+(18)+(19) | Z10: (21)=(13)+(16)+ (20) | AA10: (22)=(8)+ (10) | AB10: (23)=(22)x17.5% | AC10: (24)=(22)x3% | AD10: 25 | AE10: (26)=(23)+(24) | AF10: (27)=(22)x8% | AG10: (28)=(22)x1.5% | AH10: 29 | AI10: (30)=(27)+(28)+(29) | AJ10: -31 | AK10: (31a) | AL10: (32)= (31a)x4400000 | AM10: -33 | AN10: (34)=(21)-(33) | AO10: -32 | AP10: (34)=(21)-(33) | AQ10: -31 | AR10: (35)=(21)-(31)-(32)-(33) | AS10: -36 | AT10: -36 | AU10: -37 | AV10: -38 | AW10: -39 | AX10: -40
A11: 1 | B11: Moon Han Soo | C11: GĐĐH | D11: 216 | I11: =3500*0.85 -> 2975 | J11: =I11*D6 -> 74434500 | Q11: =SUM(L11:P11) -> 0 | S11: =J11/D11 -> 344604.17 | T11: =S11*D11 -> 74434500 | U11: =S11*E11*150% -> 0 | W11: =S11*G11*200% -> 0 | X11: =S11*H11*300% -> 0 | Y11: =SUM(U11:X11) -> 0 | Z11: =Q11+T11+Y11 -> 74434500 | AA11: 0 | AB11: =AA11*17.5% -> 0 | AC11: =+AA11*3% -> 0 | AE11: =AB11+AC11+AD11 -> 0 | AF11: =AA11*0.08 -> 0 | AG11: =+AA11*1.5% -> 0 | AI11: =AF11+AG11+AH11 -> 0 | AJ11: 11000000 | AK11: 0 | AL11: =+AK11*4400000 -> 0 | AN11: =Z11-AM11 -> 74434500 | AO11: =AN11*15% -> 11165175 | AP11: =2000000/5 -> 400000 | AQ11: =AN11+AP11 -> 74834500 | AR11: =(AQ11-AJ11-AL11-AI11) -> 63834500 | AS11: =ROUND(IF(AR11<=5000000,AR11*5%,IF(AND(AR11>5000000,AR11<=10000000),AR11*10%-250000,IF(AND(AR11>10000000,AR11<=18000000),AR11*15%-750000,IF(AND(AR11>18000000,AR11<=32000000),AR11*20%-1650000,IF(AND(AR11>32000000,AR11<=52000000),AR11*25%-3250000,IF(AND(AR11>52000000,AR11<80000000),AR11*30%-5850000,IF(AR11>80000000,AR11*35%-9850000))))))),0) -> 13300350 | AT11: 0 | AU11: =Z11-AI11-AS11-AT11 -> 61134150 | AV11: =AU11/D6 -> 2443.4113 | AW11: 103873550905
B13: Scheduling | V13: Manager | AH13: Manager | AW13: Director- general

Sheet Mr. Yang
A1: CÔNG TY TNHH SHINSUNG VINA
A2: Lô CN04, khu công nghiệp Cẩm Khê, TT.Cẩm Khê, H.Cẩm Khê, T.Phú Thọ
A3: PAYROLL AUGUST 2024
A4: From 1st -31th August 2024
A6: ='Payroll Mr Shin'!A6 -> Tỷ giá Vietinbank: 31/08/2024 | C6: ='Payroll Mr Shin'!C6 -> 24520 | D6: ='Payroll Mr Shin'!D6 -> 25020
A8: STT (No) | B8: Họ và tên (First and last name) | C8: Vị trí (Location) | D8: Giờ công cơ bản thực tế (The actual basic hourly) | E8: Giờ công làm thêm (Hours of overtime) | I8: Lương cơ bản (Basic salary) USD | J8: Lương cơ bản (Basic salary) | K8: Các khoản phụ cấp (Allowances) | Q8: Tổng các khoản phụ cấp (Total allowances) | R8: Lương đóng bảo hiểm | S8: Lương giờ công | T8: Tổng lương giờ công cơ bản | U8: Lương giờ công làm thêm | Z8: Tổng lương | AA8: BH tính vào chi phí / Isuarance payable by company | AF8: BH khấu trừ lương / Isuarance deductions from salary | AJ8: Thuế TNCN /Personal income tax | AT8: Khấu trừ Thuế TNCN | AU8: Thực nhận | AW8: Số tài khoản | AX8: Ký nhận
E9: Tăng ca ngày | F9: Tăng ca đêm | G9: Tăng ca CN 200% | H9: Tăng ca ngày lễ 300% | K9: Phụ cấp trách nhiệm | L9: Phụ cấp điện thoại | M9: Phụ cấp xăng xe | N9: Phụ cấp nhà ở | O9: Phụ cấp đi lại | P9: Chuyên cần (Diligence) | U9: Tăng ca ngày 150% | V9: Tăng ca đêm | W9: Tăng ca CN 200% | X9: Tăng ca ngày lễ 300% | Y9: Tổng lương làm thêm | AA9: Lương đóng bảo hiểm/Salary base for insurance | AB9: BHXH / Social Insurance 17% | AC9: BHYT / Health Insurance 3%건강보험 (회사분) | AD9: BHTN / Unemployment Insurance 1% | AE9: Cộng /Amount Isurance | AF9: BHXH / Social Insurance 8% | AG9: BHYT / Health Insurance 1,5% 건강보험 (개인분) | AH9: BHTN / Unemployment Insurance 1% | AI9: Cộng 10.5%/Amount Isurance | AJ9: Giảm trừ bản thân (기본공제금 ) (VND) | AK9: Số người phụ thuộc /Number Deduction family | AL9: Giảm trừ người phụ thuộc /deduction-family 4400000/1person | AM9: Tax excemption | AN9: Thu nhập chịu thuế | AO9: 15% TNCN | AP9: Tiền thuê nhà thực tế | AQ9: Thu nhập chịu thuế bao gồm tiền thuê nhà | AR9: Thu nhập tính thuế (과세 대상 금액) VND | AS9: Thuế TNCN (개인소득세) ( VND) | AU9: VND | AV9: USD (Quy đổi)
A10: -1 | B10: -2 | C10: -3 | D10: -4 | E10: -5 | F10: (5a) | G10: -6 | H10: -7 | J10: -8 | K10: -9 | L10: -10 | M10: -11 | N10: (11 a) | O10: (11b) | P10: -12 | Q10: (13)=10+11+11a+11b+ 12 | R10: (14)=(8)+(9) | S10: (15)=(14)/4 | T10: (16)=(15)*(4) | U10: (17)=(5)* (15)*150% | V10: (17a) | W10: (18)=(6)* (15)*200% | X10: (19)=(7)* (15)*300% | Y10: (20)= (17)+(18)+(19) | Z10: (21)=(13)+(16)+ (20) | AA10: (22)=(8)+ (10) | AB10: (23)=(22)x17.5% | AC10: (24)=(22)x3% | AD10: 25 | AE10: (26)=(23)+(24) | AF10: (27)=(22)x8% | AG10: (28)=(22)x1.5% | AH10: 29 | AI10: (30)=(27)+(28)+(29) | AJ10: -31 | AK10: (31a) | AL10: (32)= (31a)x4400000 | AM10: -33 | AN10: (34)=(21)-(33) | AO10: -32 | AP10: (34)=(21)-(33) | AQ10: -31 | AR10: (35)=(21)-(31)-(32)-(33) | AS10: -36 | AT10: -36 | AU10: -37 | AV10: -38 | AW10: -39 | AX10: -40
A11: 1 | B11: Yang Dao Jun | C11: LĐKT | D11: 216 | I11: =2000*0.85 -> 1700 | J11: =I11*D6 -> 42534000 | Q11: =SUM(L11:P11) -> 0 | S11: =J11/D11 -> 196916.67 | T11: =S11*D11 -> 42534000 | U11: =S11*E11*150% -> 0 | W11: =S11*G11*200% -> 0 | X11: =S11*H11*300% -> 0 | Y11: =SUM(U11:X11) -> 0 | Z11: =Q11+T11+Y11 -> 42534000 | AA11: 41242000 | AB11: =AA11*17.5% -> 7217350 | AC11: =+AA11*3% -> 1237260 | AE11: =AB11+AC11+AD11 -> 8454610 | AF11: =AA11*0.08 -> 3299360 | AG11: =+AA11*1.5% -> 618630 | AI11: =AF11+AG11+AH11 -> 3917990 | AJ11: 11000000 | AK11: 2 | AL11: =+AK11*4400000 -> 8800000 | AN11: =Z11-AM11 -> 42534000 | AO11: =AN11*15% -> 6380100 | AP11: =2000000/5 -> 400000 | AQ11: =AN11+AP11 -> 42934000 | AR11: =(AQ11-AJ11-AL11-AI11) -> 19216010 | AS11: =ROUND(IF(AR11<=5000000,AR11*5%,IF(AND(AR11>5000000,AR11<=10000000),AR11*10%-250000,IF(AND(AR11>10000000,AR11<=18000000),AR11*15%-750000,IF(AND(AR11>18000000,AR11<=32000000),AR11*20%-1650000,IF(AND(AR11>32000000,AR11<=52000000),AR11*25%-3250000,IF(AND(AR11>52000000,AR11<80000000),AR11*30%-5850000,IF(AR11>80000000,AR11*35%-9850000))))))),0) -> 2193202 | AT11: 0 | AU11: =Z11-AI11-AS11-AT11 -> 36422808 | AV11: =AU11/D6 -> 1455.7477 | AW11: 103873550905
B13: Scheduling | V13: Manager | AI13: Manager | AW13: Director- general

Sheet Mr. Choi
A1: CÔNG TY TNHH SHINSUNG VINA
A2: Lô CN04, khu công nghiệp Cẩm Khê, TT.Cẩm Khê, H.Cẩm Khê, T.Phú Thọ
A3: PAYROLL AUGUST 2024
A4: From 1st -31th August 2024
A6: ='Payroll Mr Shin'!A6 -> Tỷ giá Vietinbank: 31/08/2024 | C6: ='Payroll Mr Shin'!C6 -> 24520 | D6: ='Payroll Mr Shin'!D6 -> 25020
A8: STT (No) | B8: Họ và tên (First and last name) | C8: Vị trí (Location) | D8: Giờ công cơ bản thực tế (The actual basic hourly) | E8: Giờ công làm thêm (Hours of overtime) | I8: Lương cơ bản (Basic salary) USD | J8: Lương cơ bản (Basic salary) | K8: Các khoản phụ cấp (Allowances) | Q8: Tổng các khoản phụ cấp (Total allowances) | R8: Lương đóng bảo hiểm | S8: Lương giờ công | T8: Tổng lương giờ công cơ bản | U8: Lương giờ công làm thêm | Z8: Tổng lương | AA8: BH tính vào chi phí / Isuarance payable by company | AF8: BH khấu trừ lương / Isuarance deductions from salary | AJ8: Thuế TNCN /Personal income tax | AT8: Khấu trừ Thuế TNCN | AU8: Thực nhận | AW8: Số tài khoản | AX8: Ký nhận
E9: Tăng ca ngày | F9: Tăng ca đêm | G9: Tăng ca CN 200% | H9: Tăng ca ngày lễ 300% | K9: Phụ cấp trách nhiệm | L9: Phụ cấp điện thoại | M9: Phụ cấp xăng xe | N9: Phụ cấp nhà ở | O9: Phụ cấp đi lại | P9: Chuyên cần (Diligence) | U9: Tăng ca ngày 150% | V9: Tăng ca đêm | W9: Tăng ca CN 200% | X9: Tăng ca ngày lễ 300% | Y9: Tổng lương làm thêm | AA9: Lương đóng bảo hiểm/Salary base for insurance | AB9: BHXH / Social Insurance 17% | AC9: BHYT / Health Insurance 3%건강보험 (회사분) | AD9: BHTN / Unemployment Insurance 1% | AE9: Cộng /Amount Isurance | AF9: BHXH / Social Insurance 8% | AG9: BHYT / Health Insurance 1,5% 건강보험 (개인분) | AH9: BHTN / Unemployment Insurance 1% | AI9: Cộng 10.5%/Amount Isurance | AJ9: Giảm trừ bản thân (기본공제금 ) (VND) | AK9: Số người phụ thuộc /Number Deduction family | AL9: Giảm trừ người phụ thuộc /deduction-family 4400000/1person | AM9: Tax excemption | AN9: Thu nhập chịu thuế | AO9: 15% TNCN | AP9: Tiền thuê nhà thực tế | AQ9: Thu nhập chịu thuế bao gồm tiền thuê nhà | AR9: Thu nhập tính thuế (과세 대상 금액) VND | AS9: Thuế TNCN (개인소득세) ( VND) | AU9: VND | AV9: USD (Quy đổi)
A10: -1 | B10: -2 | C10: -3 | D10: -4 | E10: -5 | F10: (5a) | G10: -6 | H10: -7 | J10: -8 | K10: -9 | L10: -10 | M10: -11 | N10: (11 a) | O10: (11b) | P10: -12 | Q10: (13)=10+11+11a+11b+ 12 | R10: (14)=(8)+(9) | S10: (15)=(14)/4 | T10: (16)=(15)*(4) | U10: (17)=(5)* (15)*150% | V10: (17a) | W10: (18)=(6)* (15)*200% | X10: (19)=(7)* (15)*300% | Y10: (20)= (17)+(18)+(19) | Z10: (21)=(13)+(16)+ (20) | AA10: (22)=(8)+ (10) | AB10: (23)=(22)x17.5% | AC10: (24)=(22)x3% | AD10: 25 | AE10: (26)=(23)+(24) | AF10: (27)=(22)x8% | AG10: (28)=(22)x1.5% | AH10: 29 | AI10: (30)=(27)+(28)+(29) | AJ10: -31 | AK10: (31a) | AL10: (32)= (31a)x4400000 | AM10: -33 | AN10: (34)=(21)-(33) | AO10: -32 | AP10: (34)=(21)-(33) | AQ10: -31 | AR10: (35)=(21)-(31)-(32)-(33) | AS10: -36 | AT10: -36 | AU10: -37 | AV10: -38 | AW10: -39 | AX10: -40
A11: 1 | B11: Choi Jin Sun | C11: LĐKT | D11: 216 | I11: =3500*0.85 -> 2975 | J11: =I11*D6 -> 74434500 | Q11: =SUM(L11:P11) -> 0 | S11: =J11/D11 -> 344604.17 | T11: =S11*D11 -> 74434500 | U11: =S11*E11*150% -> 0 | W11: =S11*G11*200% -> 0 | X11: =S11*H11*300% -> 0 | Y11: =SUM(U11:X11) -> 0 | Z11: =Q11+T11+Y11 -> 74434500 | AA11: 0 | AB11: =AA11*17.5% -> 0 | AC11: =+AA11*3% -> 0 | AE11: =AB11+AC11+AD11 -> 0 | AF11: =AA11*0.08 -> 0 | AG11: =+AA11*1.5% -> 0 | AI11: =AF11+AG11+AH11 -> 0 | AJ11: 11000000 | AK11: 1 | AL11: =+AK11*4400000 -> 4400000 | AN11: =Z11-AM11 -> 74434500 | AO11: =AN11*15% -> 11165175 | AP11: =2000000/5 -> 400000 | AQ11: =AN11+AP11 -> 74834500 | AR11: =(AQ11-AJ11-AL11-AI11) -> 59434500 | AS11: =ROUND(IF(AR11<=5000000,AR11*5%,IF(AND(AR11>5000000,AR11<=10000000),AR11*10%-250000,IF(AND(AR11>10000000,AR11<=18000000),AR11*15%-750000,IF(AND(AR11>18000000,AR11<=32000000),AR11*20%-1650000,IF(AND(AR11>32000000,AR11<=52000000),AR11*25%-3250000,IF(AND(AR11>52000000,AR11<80000000),AR11*30%-5850000,IF(AR11>80000000,AR11*35%-9850000))))))),0) -> 11980350 | AT11: 0 | AU11: =Z11-AI11-AS11-AT11 -> 62454150 | AV11: =AU11/D6 -> 2496.1691 | AW11: 103873550905 | AX11: =AV11+Mr.Moon!AV11 -> 4939.5803
B13: Scheduling | AI13: Manager | AW13: Director- general
AV18: =AV11+Mr.Moon!AV11 -> 4939.5803
AV21: =AV11+Mr.Moon!AV11 -> 4939.5803

Sheet Mr. Hwang
A1: CÔNG TY TNHH SHINSUNG VINA
A2: Lô CN04, khu công nghiệp Cẩm Khê, TT.Cẩm Khê, H.Cẩm Khê, T.Phú Thọ
A3: PAYROLL AUGUST 2024
A4: From 1st -31th August 2024
A6: ='Payroll Mr Shin'!A6 -> Tỷ giá Vietinbank: 31/08/2024 | C6: ='Payroll Mr Shin'!C6 -> 24520 | D6: ='Payroll Mr Shin'!D6 -> 25020
A8: STT (No) | B8: Họ và tên (First and last name) | C8: Vị trí (Location) | D8: Giờ công cơ bản thực tế (The actual basic hourly) | E8: Giờ công làm thêm (Hours of overtime) | I8: Lương cơ bản (Basic salary) USD | J8: Lương cơ bản (Basic salary) | K8: Các khoản phụ cấp (Allowances) | Q8: Tổng các khoản phụ cấp (Total allowances) | R8: Lương đóng bảo hiểm | S8: Lương giờ công | T8: Tổng lương giờ công cơ bản | U8: Lương giờ công làm thêm | Z8: Tổng lương | AA8: BH tính vào chi phí / Isuarance payable by company | AF8: BH khấu trừ lương / Isuarance deductions from salary | AJ8: Thuế TNCN /Personal income tax | AT8: Khấu trừ Thuế TNCN | AU8: Thực nhận (VND) | AV8: Thực nhận quy đổi ( USD) | AW8: Số tài khoản | AX8: Ký nhận
E9: Tăng ca ngày | F9: Tăng ca đêm | G9: Tăng ca CN 200% | H9: Tăng ca ngày lễ 300% | K9: Phụ cấp trách nhiệm | L9: Phụ cấp điện thoại | M9: Phụ cấp xăng xe | N9: Phụ cấp nhà ở | O9: Phụ cấp đi lại | P9: Chuyên cần (Diligence) | U9: Tăng ca ngày 150% | V9: Tăng ca đêm | W9: Tăng ca CN 200% | X9: Tăng ca ngày lễ 300% | Y9: Tổng lương làm thêm | AA9: Lương đóng bảo hiểm/Salary base for insurance | AB9: BHXH / Social Insurance 17% | AC9: BHYT / Health Insurance 3%건강보험 (회사분) | AD9: BHTN / Unemployment Insurance 1% | AE9: Cộng /Amount Isurance | AF9: BHXH / Social Insurance 8% | AG9: BHYT / Health Insurance 1,5% 건강보험 (개인분) | AH9: BHTN / Unemployment Insurance 1% | AI9: Cộng 10.5%/Amount Isurance | AJ9: Giảm trừ bản thân (기본공제금 ) (VND) | AK9: Số người phụ thuộc /Number Deduction family | AL9: Giảm trừ người phụ thuộc /deduction-family 4400000/1person | AM9: Tax excemption | AN9: Thu nhập chịu thuế | AO9: 15% TNCN | AP9: Tiền thuê nhà thực tế | AQ9: Thu nhập chịu thuế bao gồm tiền thuê nhà | AR9: Thu nhập tính thuế (과세 대상 금액) VND | AS9: Thuế TNCN (개인소득세) ( VND)
A10: -1 | B10: -2 | C10: -3 | D10: -4 | E10: -5 | F10: (5a) | G10: -6 | H10: -7 | J10: -8 | K10: -9 | L10: -10 | M10: -11 | N10: (11 a) | O10: (11b) | P10: -12 | Q10: (13)=10+11+11a+11b+ 12 | R10: (14)=(8)+(9) | S10: (15)=(14)/4 | T10: (16)=(15)*(4) | U10: (17)=(5)* (15)*150% | V10: (17a) | W10: (18)=(6)* (15)*200% | X10: (19)=(7)* (15)*300% | Y10: (20)= (17)+(18)+(19) | Z10: (21)=(13)+(16)+ (20) | AA10: (22)=(8)+ (10) | AB10: (23)=(22)x17.5% | AC10: (24)=(22)x3% | AD10: 25 | AE10: (26)=(23)+(24) | AF10: (27)=(22)x8% | AG10: (28)=(22)x1.5% | AH10: 29 | AI10: (30)=(27)+(28)+(29) | AJ10: -31 | AK10: (31a) | AL10: (32)= (31a)x4400000 | AM10: -33 | AN10: (34)=(21)-(33) | AO10: -32 | AP10: (34)=(21)-(33) | AQ10: -31 | AR10: (35)=(21)-(31)-(32)-(33) | AS10: -36 | AT10: -36 | AU10: -37 | AV10: -37.333333 | AW10: -37.833333 | AX10: -39
A11: 1 | B11: Hwang Seungyun | C11: LĐKT | D11: 216 | J11: =50000000*0.85 -> 42500000 | Q11: =SUM(L11:P11) -> 0 | S11: =J11/D11 -> 196759.26 | T11: =S11*D11 -> 42500000 | U11: =S11*E11*150% -> 0 | W11: =S11*G11*200% -> 0 | X11: =S11*H11*300% -> 0 | Y11: =SUM(U11:X11) -> 0 | Z11: =Q11+T11+Y11 -> 42500000 | AA11: 0 | AB11: =AA11*17.5% -> 0 | AC11: =+AA11*3% -> 0 | AE11: =AB11+AC11+AD11 -> 0 | AF11: =AA11*0.08 -> 0 | AG11: =+AA11*1.5% -> 0 | AI11: =AF11+AG11+AH11 -> 0 | AJ11: 11000000 | AK11: 0 | AL11: 0 | AN11: =Z11-AM11 -> 42500000 | AO11: =AN11*15% -> 6375000 | AP11: =2000000/5 -> 400000 | AQ11: =AN11+AP11 -> 42900000 | AR11: =(AQ11-AJ11-AL11-AI11) -> 31900000 | AS11: =ROUND(IF(AR11<=5000000,AR11*5%,IF(AND(AR11>5000000,AR11<=10000000),AR11*10%-250000,IF(AND(AR11>10000000,AR11<=18000000),AR11*15%-750000,IF(AND(AR11>18000000,AR11<=32000000),AR11*20%-1650000,IF(AND(AR11>32000000,AR11<=52000000),AR11*25%-3250000,IF(AND(AR11>52000000,AR11<80000000),AR11*30%-5850000,IF(AR11>80000000,AR11*35%-9850000))))))),0) -> 4730000 | AT11: 0 | AU11: =Z11-AI11-AS11-AT11 -> 37770000 | AV11: =AU11/D6 -> 1509.5923 | AW11: 103873550905
B13: Scheduling | V13: Manager | AH13: Manager | AW13: Director- general
AV16: =AU11+#REF! -> #REF!

Sheet Payroll Office
A1: CÔNG TY TNHH SHINSUNG VINA
A2: Lô CN04, khu công nghiệp Cẩm Khê, TT.Cẩm Khê, H.Cẩm Khê, T.Phú Thọ
A3: PAYROLL AUGUST 2024
A4: From 1st -31th August 2024
BO6: VND
A7: STT (No) | B7: Họ và tên (First and last name) | C7: Vị trí (Location) | D7: Tổng số giờ công chuẩn | E7: Giờ công cơ bản thực tế (The actual basic hourly) | G7: Số bữa phụ | H7: Giờ công làm thêm (Hours of overtime) | Q7: Lương đóng bảo hiểm | U7: Các khoản phụ cấp (Allowances) | AF7: Thưởng Tết Âm lịch 20% (Ngày lễ 02/09) | AG7: HT làm thêm ngày lễ 01/05 | AH7: Tổng phụ cấp không đóng BH được nhận (Total allowances) | AI7: Lương đóng bảo hiểm | AJ7: Lương giờ công | AK7: Tổng lương giờ công cơ bản | AL7: Lương giờ công làm thêm | AV7: Tổng lương | AW7: BH tính vào chi phí / Isuarance payable by company | BC7: BH khấu trừ lương / Isuarance deductions from salary | BG7: Thuế TNCN | BO7: Thực nhận | BP7: Số tài khoản | BQ7: Ký nhận
E8: Ca ngày | F8: Ca đêm | H8: Tăng ca 150% | I8: Tăng ca đêm 195% | J8: CN ngày 200% | K8: CN đêm 260% | L8: Tăng ca ngày CN 300% | M8: Tăng ca đêm CN 390% | N8: Ngày lễ ngày 300% | O8: Ngày lễ đêm 390% | P8: TC lễ (450%) | Q8: Lương cơ bản (Basic salary) | R8: Phụ cấp trách nhiệm/ Responsibility allowance | S8: PC ngoại ngữ/ Foreign language support | T8: Phụ cấp thâm niên/ Seniority allowances | U8: HT điện thoại /Phone charges/ 26 Công | V8: HT điện thoại /Phone charges | W8: HT xăng xe /Fuel costs for vehicles/ 26 Công | X8: HT xăng xe /Fuel costs for vehicles | Y8: HT nhà ở /Housing support/ 26 Công | Z8: HT nhà ở /Housing support | AA8: HT đi lại/ Mobility assistance | AB8: HT con nhỏ/ Support workers with small children | AC8: Thưởng Chuyên cần / Attendance Bonus | AD8: Trợ cấp bữa phụ /Snack allowance | AE8: Thưởng sinh nhật tháng 08 /Birthday in August | AL8: Tăng ca ngày | AM8: Tăng ca đêm | AN8: CN ngày | AO8: CN đêm | AP8: Tăng ca ngày CN | AQ8: Tăng ca đêm CN | AR8: Ngày lễ ngày | AS8: Ngày lễ đêm | AT8: TC lễ | AU8: Tổng lương làm thêm | AW8: Lương đóng bảo hiểm/Salary base for insurance | AX8: BHXH / Social Insurance 17.5% | AY8: BHYT / Health Insurance 3%건강보험 (회사분) | AZ8: BHTN / Unemployment Insurance 1% | BA8: KPCĐ 2% | BB8: Cộng /Amount Isurance | BC8: BHXH / Social Insurance 8% | BD8: BHYT / Health Insurance 1,5% 건강보험 (개인분) | BE8: BHTN / Unemployment Insurance 1% | BF8: Cộng 10.5%/Amount Isurance | BG8: Giảm trừ bản thân (기본공제금 ) (VND) | BH8: Số người phụ thuộc /Number Deduction family | BI8: Giảm trừ người phụ thuộc /deduction-family 4400000/1person | BJ8: Tax excemption | BK8: Thu nhập chịu thuế | BL8: Thu nhập tính thuế (과세 대상 금액) VND | BM8: Thuế TNCN (개인소득세) ( VND) | BN8: Đoàn phí
A9: -1 | B9: -2 | C9: -3 | E9: -4 | F9: -5 | H9: -5 | J9: (5a) | K9: -6 | N9: -7 | Q9: -8 | R9: -9 | S9: (9a) | V9: -10 | X9: -11 | Z9: (11 a) | AA9: (11b) | AB9: (11c) | AC9: -12 | AH9: (13)=10+11+11a+11b+ 12 | AI9: (14)=(8)+ (9)+(9a) | AJ9: (15)=(14)/4 | AK9: (16)=(15)*(4) | AL9: (17)=(5)* (15)*150% | AN9: (17a) | AO9: (18)=(6)* (15)*200% | AR9: (19)=(7)* (15)*300% | AU9: (20)= (17)+(18)+(19) | AV9: (21)=(13)+(16)+ (20) | AW9: (22)=(8)+ (10) | AX9: (23)=(22)x17% | AY9: (24)=(22)x3% | AZ9: (25)=(22)x1% | BB9: (26)=(23)+(24)+ (25) | BC9: (27)=(22)x8% | BD9: (28)=(22)x1.5% | BE9: (29)=(22)x1% | BF9: (30)=(27)+(28)+(29) | BG9: -31 | BH9: (31a) | BI9: (32)= (31a)x4400000 | BJ9: -33 | BK9: (34)=(21)-(33) | BL9: (35)=(34)-(30)-(31)-(32) | BM9: -36 | BO9: -37
A10: 1 | B10: Nguyễn Minh Đức | C10: Tổng quản lý | D10: 216 | E10: 216 | Q10: 21550000 | T10: =1500000 -> 1500000 | U10: 2000000 | V10: =3000000 -> 3000000 | Z10: =2000000 -> 2000000 | AD10: =G10*13000 -> 0 | AH10: =V10+X10+Z10+AA10+AB10+AC10+AD10+AE10 -> 5000000 | AI10: =Q10+R10+S10+T10 -> 23050000 | AJ10: =AI10/D10 -> 106712.96 | AK10: =AJ10*E10 -> 23050000 | AM10: =AJ10*I10*150%*130% -> 0 | AN10: =J10*200%*AJ10 -> 0 | AP10: =L10*AJ10*300% -> 0 | AU10: =SUM(AL10:AT10) -> 0 | AV10: =AH10+AK10+AU10+AG10+AF10 -> 28050000 | BA10: =AW10*2% -> 0 | BF10: =BC10+BD10+BE10 -> 0 | BG10: 11000000 | BH10: 2 | BI10: =BH10*4400000 -> 8800000 | BJ10: =V10+AA10 -> 3000000 | BK10: =AV10-BJ10-AJ10*H10*0.5-AJ10*I10*0.95-AJ10*J10-AJ10*K10*1.6-AJ10*L10*2-AJ10*M10*2.9-AJ10*N10*2-AJ10*O10*2.9-P10*3.5 -> 25050000 | BL10: =IF(BK10-BI10-BG10-BF10<0,0,BK10-BI10-BG10-BF10) -> 5250000 | BM10: =ROUND(IF(BL10<=5000000,BL10*5%,IF(AND(BL10>5000000,BL10<=10000000),BL10*10%-250000,IF(AND(BL10>10000000,BL10<=18000000),BL10*15%-750000,IF(AND(BL10>18000000,BL10<=32000000),BL10*20%-1650000,IF(AND(BL10>32000000,BL10<=52000000),BL10*25%-3250000,IF(AND(BL10>52000000,BL10<80000000),BL10*30%-585000,IF(BL10>80000000,BL10*35%-9850000))))))),0) -> 275000 | BN10: 35000 | BO10: =AV10-BF10-BM10-BN10 -> 27740000 | BP10: 101883483888
A11: =A10+1 -> 2 | B11: Nguyễn Thị Thu | C11: Kế toán | D11: 208 | E11: 184 | Q11: 5450000 | R11: 5000000 | T11: 300000 | U11: 1200000 | V11: =IF((E11+F11)>=160,U11, U11/D11*(E11+F11)) -> 1200000 | W11: 1400000 | X11: =IF((E11+F11)>=160,W11, W11/208*(E11+F11)) -> 1400000 | Y11: 1400000 | Z11: =IF((E11+F11)>=160,Y11, Y11/208*(E11+F11)) -> 1400000 | AB11: 20000 | AC11: 500000 | AD11: =G11*13000 -> 0 | AE11: 100000 | AH11: =V11+X11+Z11+AA11+AB11+AC11+AD11+AE11 -> 4620000 | AI11: =Q11+R11+S11+T11 -> 10750000 | AJ11: =AI11/D11 -> 51682.692 | AK11: =AJ11*E11 -> 9509615.4 | AL11: =AJ11*H11*150% -> 0 | AM11: =AJ11*I11*150%*130% -> 0 | AN11: =J11*200%*AJ11 -> 0 | AO11: =AJ11*K11*200% -> 0 | AP11: =L11*AJ11*300% -> 0 | AR11: =AJ11*N11*300% -> 0 | AU11: =SUM(AL11:AT11) -> 0 | AV11: =AH11+AK11+AU11+AG11+AF11 -> 14129615 | AW11: =Q11+R11+S11+T11 -> 10750000 | AX11: =AW11*17.5% -> 1881250 | AY11: =AW11*3% -> 322500 | AZ11: =AW11*1% -> 107500 | BA11: =AW11*2% -> 215000 | BB11: =AX11+AY11+AZ11+BA11 -> 2526250 | BC11: =AW11*8% -> 860000 | BD11: =AW11*1.5% -> 161250 | BE11: =AW11*1% -> 107500 | BF11: =BC11+BD11+BE11 -> 1128750 | BG11: 11000000 | BH11: 2 | BI11: =BH11*4400000 -> 8800000 | BJ11: =V11 -> 1200000 | BK11: =AV11-BJ11-AJ11*H11*0.5-AJ11*I11*0.95-AJ11*J11-AJ11*K11*1.6-AJ11*L11*2-AJ11*M11*2.9-AJ11*N11*2-AJ11*O11*2.9-P11*3.5 -> 12929615 | BL11: =IF(BK11-BI11-BG11-BF11<0,0,BK11-BI11-BG11-BF11) -> 0 | BM11: =ROUND(IF(BL11<=5000000,BL11*5%,IF(AND(BL11>5000000,BL11<=10000000),BL11*10%-250000,IF(AND(BL11>10000000,BL11<=18000000),BL11*15%-750000,IF(AND(BL11>18000000,BL11<=32000000),BL11*20%-1650000,IF(AND(BL11>32000000,BL11<=52000000),BL11*25%-3250000,IF(AND(BL11>52000000,BL11<80000000),BL11*30%-585000,IF(BL11>80000000,BL11*35%-9850000))))))),0) -> 0 | BN11: 35000 | BO11: =AV11-BF11-BM11-BN11 -> 12965865 | BP11: 107876999632
A12: =A11+1 -> 3 | B12: Nguyễn Thị Kim Liên | C12: Kế toán | D12: 208 | E12: 184 | Q12: 5450000 | R12: 2000000 | T12: 600000 | U12: 800000 | V12: =IF((E12+F12)>=160,U12, U12/D12*(E12+F12)) -> 800000 | W12: 700000 | X12: =IF((E12+F12)>=160,W12, W12/208*(E12+F12)) -> 700000 | Y12: 700000 | Z12: =IF((E12+F12)>=160,Y12, Y12/208*(E12+F12)) -> 700000 | AC12: 500000 | AD12: =G12*13000 -> 0 | AH12: =V12+X12+Z12+AA12+AB12+AC12+AD12+AE12 -> 2700000 | AI12: =Q12+R12+S12+T12 -> 8050000 | AJ12: =AI12/D12 -> 38701.923 | AK12: =AJ12*E12 -> 7121153.8 | AL12: =AJ12*H12*150% -> 0 | AM12: =AJ12*I12*150%*130% -> 0 | AN12: =J12*200%*AJ12 -> 0 | AO12: =AJ12*K12*200% -> 0 | AP12: =L12*AJ12*300% -> 0 | AR12: =AJ12*N12*300% -> 0 | AU12: =SUM(AL12:AT12) -> 0 | AV12: =AH12+AK12+AU12+AG12+AF12 -> 9821153.8 | AW12: =Q12+R12+S12+T12 -> 8050000 | AX12: =AW12*17.5% -> 1408750 | AY12: =AW12*3% -> 241500 | AZ12: =AW12*1% -> 80500 | BA12: =AW12*2% -> 161000 | BB12: =AX12+AY12+AZ12+BA12 -> 1891750 | BC12: =AW12*8% -> 644000 | BD12: =AW12*1.5% -> 120750 | BE12: =AW12*1% -> 80500 | BF12: =BC12+BD12+BE12 -> 845250 | BG12: 11000000 | BH12: 0 | BI12: =BH12*4400000 -> 0 | BJ12: =V12 -> 800000 | BK12: 10724760 | BL12: =IF(BK12-BI12-BG12-BF12<0,0,BK12-BI12-BG12-BF12) -> 0 | BM12: =ROUND(IF(BL12<=5000000,BL12*5%,IF(AND(BL12>5000000,BL12<=10000000),BL12*10%-250000,IF(AND(BL12>10000000,BL12<=18000000),BL12*15%-750000,IF(AND(BL12>18000000,BL12<=32000000),BL12*20%-1650000,IF(AND(BL12>32000000,BL12<=52000000),BL12*25%-3250000,IF(AND(BL12>52000000,BL12<80000000),BL12*30%-585000,IF(BL12>80000000,BL12*35%-9850000))))))),0) -> 0 | BN12: 35000 | BO12: =AV12-BF12-BM12-BN12 -> 8940903.8 | BP12: 103875891817
A13: =A12+1 -> 4 | B13: Dương Thị Vân | C13: Kế toán | D13: 208 | E13: 184 | Q13: 5190000 | R13: 500000 | U13: 700000 | V13: =IF((E13+F13)>=160,U13, U13/D13*(E13+F13)) -> 700000 | W13: 700000 | X13: =IF((E13+F13)>=160,W13, W13/208*(E13+F13)) -> 700000 | Y13: 700000 | Z13: =IF((E13+F13)>=160,Y13, Y13/208*(E13+F13)) -> 700000 | AC13: 500000 | AD13: =G13*13000 -> 0 | AH13: =V13+X13+Z13+AA13+AB13+AC13+AD13+AE13 -> 2600000 | AI13: =Q13+R13+S13+T13 -> 5690000 | AJ13: =AI13/D13 -> 27355.769 | AK13: =AJ13*E13 -> 5033461.5 | AL13: =AJ13*H13*150% -> 0 | AM13: =AJ13*I13*150%*130% -> 0 | AN13: =J13*200%*AJ13 -> 0 | AP13: =L13*AJ13*300% -> 0 | AR13: =AJ13*N13*300% -> 0 | AU13: =SUM(AL13:AT13) -> 0 | AV13: =AH13+AK13+AU13+AG13+AF13 -> 7633461.5 | AW13: =Q13+R13+S13+T13 -> 5690000 | AX13: =AW13*17.5% -> 995750 | AY13: =AW13*3% -> 170700 | AZ13: =AW13*1% -> 56900 | BA13: =AW13*2% -> 113800 | BB13: =AX13+AY13+AZ13+BA13 -> 1337150 | BC13: =AW13*8% -> 455200 | BD13: =AW13*1.5% -> 85350 | BE13: =AW13*1% -> 56900 | BF13: =BC13+BD13+BE13 -> 597450 | BG13: 11000000 | BH13: 0 | BI13: =BH13*4400000 -> 0 | BJ13: =V13 -> 700000 | BK13: =AV13-BJ13-AJ13*H13*0.5-AJ13*I13*0.95-AJ13*J13-AJ13*K13*1.6-AJ13*L13*2-AJ13*M13*2.9-AJ13*N13*2-AJ13*O13*2.9-P13*3.5 -> 6933461.5 | BL13: =IF(BK13-BI13-BG13-BF13<0,0,BK13-BI13-BG13-BF13) -> 0 | BM13: =ROUND(IF(BL13<=5000000,BL13*5%,IF(AND(BL13>5000000,BL13<=10000000),BL13*10%-250000,IF(AND(BL13>10000000,BL13<=18000000),BL13*15%-750000,IF(AND(BL13>18000000,BL13<=32000000),BL13*20%-1650000,IF(AND(BL13>32000000,BL13<=52000000),BL13*25%-3250000,IF(AND(BL13>52000000,BL13<80000000),BL13*30%-585000,IF(BL13>80000000,BL13*35%-9850000))))))),0) -> 0 | BN13: 35000 | BO13: =AV13-BF13-BM13-BN13 -> 7001011.5 | BP13: 104873387926
A14: =A13+1 -> 5 | B14: Nguyễn Thị Lý (Từ 01-24/08) | C14: HCNS | D14: 208 | E14: 152 | Q14: 4000000 | U14: 700000 | W14: 1000000 | Y14: 1000000 | AD14: =G14*13000 -> 0 | AH14: =V14+X14+Z14+AA14+AB14+AC14+AD14+AE14 -> 0 | AI14: =Q14+R14+S14+T14 -> 4000000 | AJ14: =AI14/D14 -> 19230.769 | AK14: =AJ14*E14 -> 2923076.9 | AL14: =AJ14*H14*150% -> 0 | AM14: =AJ14*I14*150%*130% -> 0 | AN14: =J14*200%*AJ14 -> 0 | AP14: =L14*AJ14*300% -> 0 | AR14: =AJ14*N14*300% -> 0 | AU14: =SUM(AL14:AT14) -> 0 | AV14: =AH14+AK14+AU14+AG14+AF14 -> 2923076.9 | AW14: 0 | AX14: =AW14*17.5% -> 0 | AY14: =AW14*3% -> 0 | AZ14: =AW14*1% -> 0 | BA14: =AW14*2% -> 0 | BB14: =AX14+AY14+AZ14+BA14 -> 0 | BC14: =AW14*8% -> 0 | BD14: =AW14*1.5% -> 0 | BE14: =AW14*1% -> 0 | BF14: =BC14+BD14+BE14 -> 0 | BG14: 11000000 | BH14: 0 | BI14: =BH14*4400000 -> 0 | BJ14: =V14 -> 0 | BK14: =AV14-BJ14-AJ14*H14*0.5-AJ14*I14*0.95-AJ14*J14-AJ14*K14*1.6-AJ14*L14*2-AJ14*M14*2.9-AJ14*N14*2-AJ14*O14*2.9-P14*3.5 -> 2923076.9 | BL14: =IF(BK14-BI14-BG14-BF14<0,0,BK14-BI14-BG14-BF14) -> 0 | BM14: =ROUND(IF(BL14<=5000000,BL14*5%,IF(AND(BL14>5000000,BL14<=10000000),BL14*10%-250000,IF(AND(BL14>10000000,BL14<=18000000),BL14*15%-750000,IF(AND(BL14>18000000,BL14<=32000000),BL14*20%-1650000,IF(AND(BL14>32000000,BL14<=52000000),BL14*25%-3250000,IF(AND(BL14>52000000,BL14<80000000),BL14*30%-585000,IF(BL14>80000000,BL14*35%-9850000))))))),0) -> 0 | BO14: =AV14-BF14-BM14-BN14 -> 2923076.9 | BP14: 104873387926 | BQ14: =BO14+BO15 -> 6580139.2
A15: =A14+1 -> 6 | B15: Nguyễn Thị Lý (Từ 25-31/08) | C15: HCNS | D15: 208 | E15: 40 | Q15: 4706000 | R15: 300000 | U15: 700000 | V15: 700000 | W15: 1000000 | X15: 1000000 | Y15: 1000000 | Z15: 1000000 | AB15: 20000 | AC15: 500000 | AD15: =G15*13000 -> 0 | AH15: =V15+X15+Z15+AA15+AB15+AC15+AD15+AE15 -> 3220000 | AI15: =Q15+R15+S15+T15 -> 5006000 | AJ15: =AI15/D15 -> 24067.308 | AK15: =AJ15*E15 -> 962692.31 | AL15: =AJ15*H15*150% -> 0 | AM15: =AJ15*I15*150%*130% -> 0 | AN15: =J15*200%*AJ15 -> 0 | AP15: =L15*AJ15*300% -> 0 | AR15: =AJ15*N15*300% -> 0 | AU15: =SUM(AL15:AT15) -> 0 | AV15: =AH15+AK15+AU15+AG15+AF15 -> 4182692.3 | AW15: =Q15+R15+S15+T15 -> 5006000 | AX15: =AW15*17.5% -> 876050 | AY15: =AW15*3% -> 150180 | AZ15: =AW15*1% -> 50060 | BA15: =AW15*2% -> 100120 | BB15: =AX15+AY15+AZ15+BA15 -> 1176410 | BC15: =AW15*8% -> 400480 | BD15: =AW15*1.5% -> 75090 | BE15: =AW15*1% -> 50060 | BF15: =BC15+BD15+BE15 -> 525630 | BG15: 11000000 | BH15: 0 | BI15: =BH15*4400000 -> 0 | BJ15: =V15 -> 700000 | BK15: =AV15-BJ15-AJ15*H15*0.5-AJ15*I15*0.95-AJ15*J15-AJ15*K15*1.6-AJ15*L15*2-AJ15*M15*2.9-AJ15*N15*2-AJ15*O15*2.9-P15*3.5 -> 3482692.3 | BL15: =IF(BK15-BI15-BG15-BF15<0,0,BK15-BI15-BG15-BF15) -> 0 | BM15: =ROUND(IF(BL15<=5000000,BL15*5%,IF(AND(BL15>5000000,BL15<=10000000),BL15*10%-250000,IF(AND(BL15>10000000,BL15<=18000000),BL15*15%-750000,IF(AND(BL15>18000000,BL15<=32000000),BL15*20%-1650000,IF(AND(BL15>32000000,BL15<=52000000),BL15*25%-3250000,IF(AND(BL15>52000000,BL15<80000000),BL15*30%-585000,IF(BL15>80000000,BL15*35%-9850000))))))),0) -> 0 | BO15: =AV15-BF15-BM15-BN15 -> 3657062.3 | BP15: 104873387926 | BQ15: =AV14+AV15 -> 7105769.2
A16: =A15+1 -> 7 | B16: Phạm Thị Chín | C16: Tạp vụ | D16: 208 | E16: 216 | H16: 0.5 | Q16: 4064000 | R16: 1000000 | T16: 900000 | U16: 600000 | V16: =IF((E16+F16)>=160,U16, U16/D16*(E16+F16)) -> 600000 | W16: 600000 | X16: =IF((E16+F16)>=160,W16, W16/208*(E16+F16)) -> 600000 | Y16: 600000 | Z16: =IF((E16+F16)>=160,Y16, Y16/208*(E16+F16)) -> 600000 | AC16: 500000 | AD16: =G16*13000 -> 0 | AH16: =V16+X16+Z16+AA16+AB16+AC16+AD16+AE16 -> 2300000 | AI16: =Q16+R16+S16+T16 -> 5964000 | AJ16: =AI16/D16 -> 28673.077 | AK16: =AJ16*E16 -> 6193384.6 | AL16: =AJ16*H16*150% -> 21504.808 | AM16: =AJ16*I16*150%*130% -> 0 | AN16: =J16*200%*AJ16 -> 0 | AO16: =AJ16*K16*200% -> 0 | AP16: =L16*AJ16*300% -> 0 | AR16: 0 | AU16: =SUM(AL16:AT16) -> 21504.808 | AV16: =AH16+AK16+AU16+AG16+AF16 -> 8514889.4 | AW16: =Q16+R16+S16+T16 -> 5964000 | AX16: =AW16*17.5% -> 1043700 | AY16: =AW16*3% -> 178920 | AZ16: =AW16*1% -> 59640 | BA16: =AW16*2% -> 119280 | BB16: =AX16+AY16+AZ16+BA16 -> 1401540 | BC16: =AW16*8% -> 477120 | BD16: =AW16*1.5% -> 89460 | BE16: =AW16*1% -> 59640 | BF16: =BC16+BD16+BE16 -> 626220 | BG16: 11000000 | BI16: =BH16*4400000 -> 0 | BJ16: =V16 -> 600000 | BK16: =AV16-BJ16-AJ16*H16*0.5-AJ16*I16*0.95-AJ16*J16-AJ16*K16*1.6-AJ16*L16*2-AJ16*M16*2.9-AJ16*N16*2-AJ16*O16*2.9-P16*3.5 -> 7907721.2 | BL16: =IF(BK16-BI16-BG16-BF16<0,0,BK16-BI16-BG16-BF16) -> 0 | BM16: =ROUND(IF(BL16<=5000000,BL16*5%,IF(AND(BL16>5000000,BL16<=10000000),BL16*10%-250000,IF(AND(BL16>10000000,BL16<=18000000),BL16*15%-750000,IF(AND(BL16>18000000,BL16<=32000000),BL16*20%-1650000,IF(AND(BL16>32000000,BL16<=52000000),BL16*25%-3250000,IF(AND(BL16>52000000,BL16<80000000),BL16*30%-585000,IF(BL16>80000000,BL16*35%-9850000))))))),0) -> 0 | BN16: 35000 | BO16: =AV16-BF16-BM16-BN16 -> 7853669.4 | BP16: 104871827327
A17: =A16+1 -> 8 | B17: Nguyễn Khắc Linh | C17: Nấu ăn | D17: 208 | E17: 216 | Q17: 4706000 | R17: 1200000 | T17: 900000 | U17: 400000 | V17: =IF((E17+F17)>=160,U17, U17/D17*(E17+F17)) -> 400000 | W17: 400000 | X17: =IF((E17+F17)>=160,W17, W17/208*(E17+F17)) -> 400000 | Y17: 400000 | Z17: =IF((E17+F17)>=160,Y17, Y17/208*(E17+F17)) -> 400000 | AB17: 20000 | AC17: 500000 | AD17: =G17*13000 -> 0 | AH17: =V17+X17+Z17+AA17+AB17+AC17+AD17+AE17 -> 1720000 | AI17: =Q17+R17+S17+T17 -> 6806000 | AJ17: =AI17/D17 -> 32721.154 | AK17: =AJ17*E17 -> 7067769.2 | AL17: =AJ17*H17*150% -> 0 | AM17: =AJ17*I17*150%*130% -> 0 | AN17: =J17*200%*AJ17 -> 0 | AO17: =AJ17*K17*200% -> 0 | AP17: =L17*AJ17*300% -> 0 | AR17: 0 | AU17: =SUM(AL17:AT17) -> 0 | AV17: =AH17+AK17+AU17+AG17+AF17 -> 8787769.2 | AW17: =Q17+R17+S17+T17 -> 6806000 | AX17: =AW17*17.5% -> 1191050 | AY17: =AW17*3% -> 204180 | AZ17: =AW17*1% -> 68060 | BA17: =AW17*2% -> 136120 | BB17: =AX17+AY17+AZ17+BA17 -> 1599410 | BC17: =AW17*8% -> 544480 | BD17: =AW17*1.5% -> 102090 | BE17: =AW17*1% -> 68060 | BF17: =BC17+BD17+BE17 -> 714630 | BG17: 11000000 | BH17: 0 | BI17: =BH17*4400000 -> 0 | BJ17: =V17 -> 400000 | BK17: =AV17-BJ17-AJ17*H17*0.5-AJ17*I17*0.95-AJ17*J17-AJ17*K17*1.6-AJ17*L17*2-AJ17*M17*2.9-AJ17*N17*2-AJ17*O17*2.9-P17*3.5 -> 8387769.2 | BL17: =IF(BK17-BI17-BG17-BF17<0,0,BK17-BI17-BG17-BF17) -> 0 | BM17: =ROUND(IF(BL17<=5000000,BL17*5%,IF(AND(BL17>5000000,BL17<=10000000),BL17*10%-250000,IF(AND(BL17>10000000,BL17<=18000000),BL17*15%-750000,IF(AND(BL17>18000000,BL17<=32000000),BL17*20%-1650000,IF(AND(BL17>32000000,BL17<=52000000),BL17*25%-3250000,IF(AND(BL17>52000000,BL17<80000000),BL17*30%-585000,IF(BL17>80000000,BL17*35%-9850000))))))),0) -> 0 | BN17: 35000 | BO17: =AV17-BF17-BM17-BN17 -> 8038139.2 | BP17: 104872539680
A18: =A17+1 -> 9 | B18: Hoàng Việt Dũng | C18: Lái xe | D18: 208 | E18: 183 | H18: 31 | I18: 1.5 | J18: 1.5 | K18: 2.5 | Q18: 4480000 | R18: 1200000 | S18: 400000 | T18: 600000 | U18: 300000 | V18: =IF((E18+F18)>=160,U18, U18/D18*(E18+F18)) -> 300000 | W18: 600000 | X18: =IF((E18+F18)>=160,W18, W18/208*(E18+F18)) -> 600000 | Y18: 600000 | Z18: =IF((E18+F18)>=160,Y18, Y18/208*(E18+F18)) -> 600000 | AB18: 20000 | AC18: 500000 | AD18: =G18*13000 -> 0 | AH18: =V18+X18+Z18+AA18+AB18+AC18+AD18+AE18 -> 2020000 | AI18: =Q18+R18+S18+T18 -> 6680000 | AJ18: =AI18/D18 -> 32115.385 | AK18: =AJ18*E18 -> 5877115.4 | AL18: =AJ18*H18*150% -> 1493365.4 | AM18: =AJ18*I18*150%*130% -> 93937.5 | AN18: =J18*200%*AJ18 -> 96346.154 | AO18: =AJ18*K18*200% -> 160576.92 | AP18: =L18*AJ18*300% -> 0 | AR18: =AJ18*N18*300% -> 0 | AS18: =AJ18*O18*390% -> 0 | AU18: =SUM(AL18:AT18) -> 1844226 | AV18: =AH18+AK18+AU18+AG18+AF18 -> 9741341.3 | AW18: =Q18+R18+S18+T18 -> 6680000 | AX18: =AW18*17.5% -> 1169000 | AY18: =AW18*3% -> 200400 | AZ18: =AW18*1% -> 66800 | BA18: =AW18*2% -> 133600 | BB18: =AX18+AY18+AZ18+BA18 -> 1569800 | BC18: =AW18*8% -> 534400 | BD18: =AW18*1.5% -> 100200 | BE18: =AW18*1% -> 66800 | BF18: =BC18+BD18+BE18 -> 701400 | BG18: 11000000 | BH18: 0 | BI18: =BH18*4400000 -> 0 | BJ18: =V18 -> 300000 | BK18: =AV18-BJ18-AJ18*H18*0.5-AJ18*I18*0.95-AJ18*J18-AJ18*K18*1.6-AJ18*L18*2-AJ18*M18*2.9-AJ18*N18*2-AJ18*O18*2.9-P18*3.5 -> 8721153.8 | BL18: =IF(BK18-BI18-BG18-BF18<0,0,BK18-BI18-BG18-BF18) -> 0 | BM18: =ROUND(IF(BL18<=5000000,BL18*5%,IF(AND(BL18>5000000,BL18<=10000000),BL18*10%-250000,IF(AND(BL18>10000000,BL18<=18000000),BL18*15%-750000,IF(AND(BL18>18000000,BL18<=32000000),BL18*20%-1650000,IF(AND(BL18>32000000,BL18<=52000000),BL18*25%-3250000,IF(AND(BL18>52000000,BL18<80000000),BL18*30%-585000,IF(BL18>80000000,BL18*35%-9850000))))))),0) -> 0 | BN18: 35000 | BO18: =AV18-BF18-BM18-BN18 -> 9004941.3 | BP18: 104872402810
A19: =A18+1 -> 10 | B19: Đào Thị Thu Hằng | C19: TPKD | D19: 208 | E19: 184 | Q19: 10600000 | R19: 4000000 | S19: 2000000 | T19: 600000 | U19: 3000000 | V19: =IF((E19+F19)>=160,U19, U19/D19*(E19+F19)) -> 3000000 | W19: 1600000 | X19: =IF((E19+F19)>=160,W19, W19/208*(E19+F19)) -> 1600000 | Y19: 3000000 | Z19: =IF((E19+F19)>=160,Y19, Y19/208*(E19+F19)) -> 3000000 | AB19: 20000 | AC19: 500000 | AD19: =G19*13000 -> 0 | AH19: =V19+X19+Z19+AA19+AB19+AC19+AD19+AE19 -> 8120000 | AI19: =Q19+R19+S19+T19 -> 17200000 | AJ19: =AI19/D19 -> 82692.308 | AK19: =AJ19*E19 -> 15215385 | AL19: =AJ19*H19*150% -> 0 | AM19: =AJ19*I19*150%*130% -> 0 | AN19: =J19*200%*AJ19 -> 0 | AO19: =AJ19*K19*200% -> 0 | AP19: =L19*AJ19*300% -> 0 | AR19: =AJ19*N19*300% -> 0 | AU19: =SUM(AL19:AT19) -> 0 | AV19: =AH19+AK19+AU19+AG19+AF19 -> 23335385 | AW19: =Q19+R19+S19+T19 -> 17200000 | AX19: =AW19*17.5% -> 3010000 | AY19: =AW19*3% -> 516000 | AZ19: =AW19*1% -> 172000 | BA19: =AW19*2% -> 344000 | BB19: =AX19+AY19+AZ19+BA19 -> 4042000 | BC19: =AW19*8% -> 1376000 | BD19: =AW19*1.5% -> 258000 | BE19: =AW19*1% -> 172000 | BF19: =BC19+BD19+BE19 -> 1806000 | BG19: 11000000 | BH19: 2 | BI19: =BH19*4400000 -> 8800000 | BJ19: =V19 -> 3000000 | BK19: 22222163 | BL19: =IF(BK19-BI19-BG19-BF19<0,0,BK19-BI19-BG19-BF19) -> 616163 | BM19: =ROUND(IF(BL19<=5000000,BL19*5%,IF(AND(BL19>5000000,BL19<=10000000),BL19*10%-250000,IF(AND(BL19>10000000,BL19<=18000000),BL19*15%-750000,IF(AND(BL19>18000000,BL19<=32000000),BL19*20%-1650000,IF(AND(BL19>32000000,BL19<=52000000),BL19*25%-3250000,IF(AND(BL19>52000000,BL19<80000000),BL19*30%-585000,IF(BL19>80000000,BL19*35%-9850000))))))),0) -> 30808 | BN19: 35000 | BO19: =AV19-BF19-BM19-BN19 -> 21463577 | BP19: 100875693796
A20: =A19+1 -> 11 | B20: Vũ Thị Khánh Linh | C20: XNK | D20: 208 | E20: 184 | Q20: 5190000 | U20: 300000 | V20: =IF((E20+F20)>=160,U20, U20/D20*(E20+F20)) -> 300000 | W20: 1000000 | X20: =IF((E20+F20)>=160,W20, W20/208*(E20+F20)) -> 1000000 | Y20: 1000000 | Z20: =IF((E20+F20)>=160,Y20, Y20/208*(E20+F20)) -> 1000000 | AC20: 500000 | AD20: =G20*13000 -> 0 | AE20: 100000 | AH20: =V20+X20+Z20+AA20+AB20+AC20+AD20+AE20 -> 2900000 | AI20: =Q20+R20+S20+T20 -> 5190000 | AJ20: =AI20/D20 -> 24951.923 | AK20: =AJ20*E20 -> 4591153.8 | AL20: =AJ20*H20*150% -> 0 | AM20: =AJ20*I20*150%*130% -> 0 | AN20: =J20*200%*AJ20 -> 0 | AP20: =L20*AJ20*300% -> 0 | AR20: =AJ20*N20*300% -> 0 | AU20: =SUM(AL20:AT20) -> 0 | AV20: =AH20+AK20+AU20+AG20+AF20 -> 7491153.8 | AW20: =Q20+R20+S20+T20 -> 5190000 | AX20: =AW20*17.5% -> 908250 | AY20: =AW20*3% -> 155700 | AZ20: =AW20*1% -> 51900 | BA20: =AW20*2% -> 103800 | BB20: =AX20+AY20+AZ20+BA20 -> 1219650 | BC20: =AW20*8% -> 415200 | BD20: =AW20*1.5% -> 77850 | BE20: =AW20*1% -> 51900 | BF20: =BC20+BD20+BE20 -> 544950 | BG20: 11000000 | BI20: =BH20*4400000 -> 0 | BJ20: =V20 -> 300000 | BK20: =AV20-BJ20-AJ20*H20*0.5-AJ20*I20*0.95-AJ20*J20-AJ20*K20*1.6-AJ20*L20*2-AJ20*M20*2.9-AJ20*N20*2-AJ20*O20*2.9-P20*3.5 -> 7191153.8 | BL20: =IF(BK20-BI20-BG20-BF20<0,0,BK20-BI20-BG20-BF20) -> 0 | BM20: =ROUND(IF(BL20<=5000000,BL20*5%,IF(AND(BL20>5000000,BL20<=10000000),BL20*10%-250000,IF(AND(BL20>10000000,BL20<=18000000),BL20*15%-750000,IF(AND(BL20>18000000,BL20<=32000000),BL20*20%-1650000,IF(AND(BL20>32000000,BL20<=52000000),BL20*25%-3250000,IF(AND(BL20>52000000,BL20<80000000),BL20*30%-585000,IF(BL20>80000000,BL20*35%-9850000))))))),0) -> 0 | BN20: 35000 | BO20: =AV20-BF20-BM20-BN20 -> 6911203.8
A21: =A20+1 -> 12 | B21: Nghiêm Thị Ngọc Ánh | C21: NVKD | D21: 208 | E21: 184 | Q21: 5450000 | R21: 500000 | T21: 300000 | U21: 700000 | V21: =IF((E21+F21)>=160,U21, U21/D21*(E21+F21)) -> 700000 | W21: 800000 | X21: =IF((E21+F21)>=160,W21, W21/208*(E21+F21)) -> 800000 | Y21: 700000 | Z21: =IF((E21+F21)>=160,Y21, Y21/208*(E21+F21)) -> 700000 | AA21: 1710000 | AC21: 500000 | AD21: =G21*13000 -> 0 | AH21: =V21+X21+Z21+AA21+AB21+AC21+AD21+AE21 -> 4410000 | AI21: =Q21+R21+S21+T21 -> 6250000 | AJ21: =AI21/D21 -> 30048.077 | AK21: =AJ21*E21 -> 5528846.2 | AL21: =AJ21*H21*150% -> 0 | AM21: =AJ21*I21*150%*130% -> 0 | AN21: =J21*200%*AJ21 -> 0 | AO21: =AJ21*K21*200% -> 0 | AP21: =L21*AJ21*300% -> 0 | AR21: =AJ21*N21*300% -> 0 | AU21: =SUM(AL21:AT21) -> 0 | AV21: =AH21+AK21+AU21+AG21+AF21 -> 9938846.2 | AW21: =Q21+R21+S21+T21 -> 6250000 | AX21: =AW21*17.5% -> 1093750 | AY21: =AW21*3% -> 187500 | AZ21: =AW21*1% -> 62500 | BA21: =AW21*2% -> 125000 | BB21: =AX21+AY21+AZ21+BA21 -> 1468750 | BC21: =AW21*8% -> 500000 | BD21: =AW21*1.5% -> 93750 | BE21: =AW21*1% -> 62500 | BF21: =BC21+BD21+BE21 -> 656250 | BG21: 11000000 | BI21: =BH21*4400000 -> 0 | BJ21: =V21 -> 700000 | BK21: =AV21-BJ21-AJ21*H21*0.5-AJ21*I21*0.95-AJ21*J21-AJ21*K21*1.6-AJ21*L21*2-AJ21*M21*2.9-AJ21*N21*2-AJ21*O21*2.9-P21*3.5 -> 9238846.2 | BL21: =IF(BK21-BI21-BG21-BF21<0,0,BK21-BI21-BG21-BF21) -> 0 | BM21: =ROUND(IF(BL21<=5000000,BL21*5%,IF(AND(BL21>5000000,BL21<=10000000),BL21*10%-250000,IF(AND(BL21>10000000,BL21<=18000000),BL21*15%-750000,IF(AND(BL21>18000000,BL21<=32000000),BL21*20%-1650000,IF(AND(BL21>32000000,BL21<=52000000),BL21*25%-3250000,IF(AND(BL21>52000000,BL21<80000000),BL21*30%-585000,IF(BL21>80000000,BL21*35%-9850000))))))),0) -> 0 | BN21: 35000 | BO21: =AV21-BF21-BM21-BN21 -> 9247596.2 | BP21: 104877225771
A22: =A21+1 -> 13 | B22: Phan Thị Thanh Tâm | C22: XNK | D22: 208 | E22: 184 | Q22: 5190000 | R22: 500000 | V22: =IF((E22+F22)>=160,U22, U22/D22*(E22+F22)) -> 0 | W22: 1600000 | X22: =IF((E22+F22)>=160,W22, W22/208*(E22+F22)) -> 1600000 | Y22: 1600000 | Z22: =IF((E22+F22)>=160,Y22, Y22/208*(E22+F22)) -> 1600000 | AA22: 230000 | AC22: 500000 | AD22: =G22*13000 -> 0 | AH22: =V22+X22+Z22+AA22+AB22+AC22+AD22+AE22 -> 3930000 | AI22: =Q22+R22+S22+T22 -> 5690000 | AJ22: =AI22/D22 -> 27355.769 | AK22: =AJ22*E22 -> 5033461.5 | AL22: =AJ22*H22*150% -> 0 | AM22: =AJ22*I22*150%*130% -> 0 | AN22: =J22*200%*AJ22 -> 0 | AP22: =L22*AJ22*300% -> 0 | AR22: =AJ22*N22*300% -> 0 | AU22: =SUM(AL22:AT22) -> 0 | AV22: =AH22+AK22+AU22+AG22+AF22 -> 8963461.5 | AW22: =Q22+R22+S22+T22 -> 5690000 | AX22: =AW22*17.5% -> 995750 | AY22: =AW22*3% -> 170700 | AZ22: =AW22*1% -> 56900 | BA22: =AW22*2% -> 113800 | BB22: =AX22+AY22+AZ22+BA22 -> 1337150 | BC22: =AW22*8% -> 455200 | BD22: =AW22*1.5% -> 85350 | BE22: =AW22*1% -> 56900 | BF22: =BC22+BD22+BE22 -> 597450 | BG22: 11000000 | BH22: 0 | BI22: =BH22*4400000 -> 0 | BJ22: =V22 -> 0 | BK22: =AV22-BJ22-AJ22*H22*0.5-AJ22*I22*0.95-AJ22*J22-AJ22*K22*1.6-AJ22*L22*2-AJ22*M22*2.9-AJ22*N22*2-AJ22*O22*2.9-P22*3.5 -> 8963461.5 | BL22: =IF(BK22-BI22-BG22-BF22<0,0,BK22-BI22-BG22-BF22) -> 0 | BM22: =ROUND(IF(BL22<=5000000,BL22*5%,IF(AND(BL22>5000000,BL22<=10000000),BL22*10%-250000,IF(AND(BL22>10000000,BL22<=18000000),BL22*15%-750000,IF(AND(BL22>18000000,BL22<=32000000),BL22*20%-1650000,IF(AND(BL22>32000000,BL22<=52000000),BL22*25%-3250000,IF(AND(BL22>52000000,BL22<80000000),BL22*30%-585000,IF(BL22>80000000,BL22*35%-9850000))))))),0) -> 0 | BN22: 35000 | BO22: =AV22-BF22-BM22-BN22 -> 8331011.5
A23: Tổng | D23: =SUM(D10:D22) -> 2712 | E23: =SUM(E10:E22) -> 2311 | F23: =SUM(F10:F22) -> 0 | G23: =SUM(G10:G22) -> 0 | I23: =SUM(I10:I22) -> 1.5 | J23: =SUM(J10:J22) -> 1.5 | K23: =SUM(K10:K22) -> 2.5 | L23: =SUM(L10:L22) -> 0 | M23: =SUM(M10:M22) -> 0 | N23: =SUM(N10:N22) -> 0 | O23: =SUM(O10:O22) -> 0 | P23: =SUM(P10:P22) -> 0 | ... AE23: =SUM(AE10:AE22) -> 200000 | AG23: =SUM(AG10:AG22) -> 0 | AH23: =SUM(AH10:AH22) -> 43540000 | AI23: =SUM(AI10:AI22) -> 110326000 | AJ23: =SUM(AJ10:AJ22) -> 526309.12 | AK23: =SUM(AK10:AK22) -> 98107115 | AL23: =SUM(AL10:AL22) -> 1514870.2 | AM23: =SUM(AM10:AM22) -> 93937.5 | AN23: =SUM(AN10:AN22) -> 96346.154 | ... BO23: =SUM(BO10:BO22) -> 1.3407806e+08 | BQ23: =BO23+'Payroll of factory '!BO22+'Payroll of factory (SOI) '!BQ27+'Payroll of factory (DET).1'!BR40 -> 5.7076869e+08
B25: Scheduling | AF25: Manager | BO25: Director- general

Sheet Payroll of factory  
A1: CÔNG TY TNHH SHINSUNG VINA
A2: Lô CN04, khu công nghiệp Cẩm Khê, TT.Cẩm Khê, H.Cẩm Khê, T.Phú Thọ
A3: ='Payroll Office'!A3:BO3 -> PAYROLL AUGUST 2024
A4: ='Payroll Office'!A4:BO4 -> From 1st -31th August 2024
A6: STT (No) | B6: Họ và tên (First and last name) | C6: Vị trí (Location) | D6: Tổng giờ công chuẩn | E6: Giờ công cơ bản thực tế (The actual basic hourly) | G6: Số bữa phụ | H6: Giờ công làm thêm (Hours of overtime) | Q6: Lương cơ bản (Basic salary) | U6: Các khoản phụ cấp (Allowances) | AF6: Thưởng Tết Âm lịch 20% (Ngày lễ 02/09) | AG6: Khấu trừ khác | AH6: Tổng phụ cấp không đóng BH được nhận (Total allowances) | AI6: Lương đóng bảo hiểm | AJ6: Lương giờ công | AK6: Tổng lương giờ công cơ bản | AL6: Lương giờ công làm thêm | AV6: Tổng lương | AW6: BH tính vào chi phí / Isuarance payable by company | BC6: BH khấu trừ lương / Isuarance deductions from salary | BG6: Thuế TNCN | BN6: Đoàn phí | BO6: Thực nhận | BP6: Số tài khoản | BQ6: Ký nhận
E7: Ca ngày | F7: Ca đêm | H7: Tăng ca 150% | I7: Tăng ca đêm 195% | J7: CN ngày 200% | K7: CN đêm 260% | L7: Tăng ca ngày CN 300% | M7: Tăng ca đêm CN 390% | N7: Ngày lễ ngày 300% | O7: Ngày lễ đêm 390% | P7: TC lễ (450%) | Q7: Lương cơ bản (Basic salary) | R7: Phụ cấp trách nhiệm/ Responsibility allowance | S7: PC ngoại ngữ/ Foreign language support | T7: Phụ cấp thâm niên/ Seniority allowances | U7: HT điện thoại /Phone charges/ 26 Công | V7: HT điện thoại /Phone charges | W7: HT xăng xe /Fuel costs for vehicles/ 26 Công | X7: HT xăng xe /Fuel costs for vehicles | Y7: HT nhà ở /Housing support/ 26 Công | Z7: HT nhà ở /Housing support | AA7: Phụ cấp đi lại | AB7: HT con nhỏ /Supporting children | AC7: Thưởng Chuyên cần /Reward for diligence | AD7: Trợ cấp bữa phụ /Snack allowance | AE7: ='Payroll Office'!AE8 -> Thưởng sinh nhật tháng 08 /Birthday in August | AL7: Tăng ca ngày | AM7: Tăng ca đêm | AN7: CN ngày | AO7: CN đêm | AP7: Tăng ca ngày CN | AQ7: Tăng ca đêm CN | AR7: Ngày lễ ngày | AS7: Ngày lễ đêm | AT7: TC lễ | AU7: Tổng lương làm thêm | AW7: Lương đóng bảo hiểm/Salary base for insurance | AX7: BHXH / Social Insurance 17% | AY7: BHYT / Health Insurance 3%건강보험 (회사분) | AZ7: BHTN / Unemployment Insurance 1% | BA7: KPCĐ 2% | BB7: Cộng /Amount Isurance | BC7: BHXH / Social Insurance 8% | BD7: BHYT / Health Insurance 1,5% 건강보험 (개인분) | BE7: BHTN / Unemployment Insurance 1% | BF7: Cộng 10.5%/Amount Isurance | BG7: Giảm trừ bản thân (기본공제금 ) (VND) | BH7: Số người phụ thuộc /Number Deduction family | BI7: Giảm trừ người phụ thuộc /deduction-family 4400000/1person | BJ7: Tax excemption | BK7: Thu nhập chịu thuế | BL7: Thu nhập tính thuế (과세 대상 금액) VND | BM7: Thuế TNCN (개인소득세) ( VND)
A8: -1 | B8: -2 | C8: -3 | E8: (4a) | F8: (4b) | H8: (5a) | I8: (5b) | J8: (6a) | K8: (6b) | L8: (6c) | M8: (6d) | N8: 6e | O8: -7 | P8: 7a | Q8: -8 | R8: -9 | T8: (11c) | V8: -10 | X8: -11 | Z8: (11 a) | AB8: (11b) | AC8: -12 | AD8: -17 | AH8: -13 | AI8: -14 | AJ8: -15 | AK8: -16 | AL8: -18 | AM8: -19 | AN8: -20 | AO8: 17c=6b*15*200%*130% | AP8: (18)=(6c)* (15)*200%*150% | AQ8: 18a=6d*15*200%*150%*130% | AR8: (19)=(6e)* (15)*300% | AS8: 19a=7*15*130%*300% | AT8: 19b=7a*15*150%*300% | AU8: -21 | AV8: -22 | AW8: -23 | AX8: -24 | AY8: -25 | AZ8: -26 | BB8: -27 | BC8: -28 | BD8: -29 | BE8: -30 | BF8: -31 | BG8: -32 | BH8: -33 | BI8: -34 | BJ8: -35 | BK8: -36 | BL8: -36 | BM8: -37 | BO8: -39
A9: 1 | B9: Nguyễn Thị Hân | C9: TKS | D9: 208 | E9: 192 | H9: 0.5 | Q9: 5141000 | R9: 1300000 | T9: 600000 | U9: 1000000 | V9: =IF((E9+F9)>=160, U9, U9/D9*(E9+F9)) -> 1000000 | W9: 1000000 | X9: =IF((E9+F9)>=160, W9, W9/D9*(E9+F9)) -> 1000000 | Y9: 1000000 | Z9: =IF((E9+F9)>=160, Y9, Y9/D9*(E9+F9)) -> 1000000 | AA9: 0 | AB9: 20000 | AC9: =IF(E9>=184,500000,0) -> 500000 | AD9: =G9*13000 -> 0 | AE9: 0 | AH9: =V9+Z9+X9+AA9+AB9+AC9+AD9+AE9 -> 3520000 | AI9: =Q9+R9+T9 -> 7041000 | AJ9: =AI9/208 -> 33850.962 | AK9: =AJ9*(E9+F9*130%) -> 6499384.6 | AL9: =AJ9*H9*150% -> 25388.221 | AM9: =AJ9*I9*150%*130% -> 0 | AN9: =+AJ9*J9*200% -> 0 | AO9: =AJ9*K9*200%*130% -> 0 | AP9: =AJ9*L9*200%*150% -> 0 | AQ9: =AJ9*M9*200%*150%*130% -> 0 | AR9: =N9*AJ9*300% -> 0 | AS9: =AJ9*O9*300% -> 0 | AT9: =P9*AJ9*150%*300% -> 0 | AU9: =SUM(AL9:AT9) -> 25388.221 | AV9: =AH9+AK9+AU9+AG9+AF9 -> 10044773 | AW9: =Q9+R9+T9 -> 7041000 | AX9: =AW9*17.5% -> 1232175 | AY9: =AW9*3% -> 211230 | AZ9: =AW9*1% -> 70410 | BA9: =AW9*2% -> 140820 | BB9: =AX9+AY9+AZ9+BA9 -> 1654635 | BC9: =AW9*8% -> 563280 | BD9: =AW9*1.5% -> 105615 | BE9: =AW9*1% -> 70410 | BF9: =BC9+BD9+BE9 -> 739305 | BG9: 11000000 | BH9: 1 | BI9: =BH9*4400000 -> 4400000 | BJ9: =V9+AA9 -> 1000000 | BK9: =AV9-BJ9-AJ9*H9*0.5-AJ9*I9*0.95-AJ9*J9-AJ9*K9*1.6-AJ9*L9*2-AJ9*M9*2.9-AJ9*N9*2-AJ9*O9*2.9-AJ9*P9*3.5 -> 9036310.1 | BL9: =IF(BK9-BG9-BF9-BI9<0,0,BK9-BG9-BI9-BF9) -> 0 | BM9: =ROUND(IF(BL9<=5000000,BL9*5%,IF(AND(BL9>5000000,BL9<=10000000),BL9*10%-250000,IF(AND(BL9>10000000,BL9<=18000000),BL9*15%-750000,IF(AND(BL9>18000000,BL9<=32000000),BL9*20%-1650000,IF(AND(BL9>32000000,BL9<=52000000),BL9*25%-3250000,IF(AND(BL9>52000000,BL9<80000000),BL9*30%-585000,IF(BL9>80000000,BL9*35%-9850000))))))),0) -> 0 | BN9: 35000 | BO9: =AV9-BF9-BM9-BN9 -> 9270467.8 | BP9: 109878080755
