Workbook

Sheet Summary 
B2: Exchange Rate : | AK2: 26115 | AO2: 25695 | AS2: 25670 | AW2: 25550 | BA2: 25550
B3: Month | C3: Dec 2025 | F3: =LEFT(C3,3)&"/"&LEFT(G3,3) -> Dec/Nov | G3: Nov 2025 | J3: =LEFT(G3,3)&"/"&LEFT(K3,3) -> Nov/Oct | K3: Oct 2025 | N3: =LEFT(K3,3)&"/"&LEFT(O3,3) -> Oct/Sep | O3: Sep 2025 | R3: Sep/Aug | S3: 45870 | V3: Aug/Jul | W3: 45839 | Z3: Jul/Jun | AA3: 45809 | AD3: Jun/May | AE3: 45778 | AH3: May/ Apr | AI3: 45748 | AL3: Apr/Mar | AM3: 45717 | AP3: Mar/Feb | AQ3: 45689 | AT3: Feb/Jan | AU3: Jan 2025 | AX3: Jan/Dec 24 | AY3: Dec 2024
B4: Payment | C4: Workers qty | D4: Salary - Net | E4: USD | F4: VND % | G4: Workers qty | H4: Salary - Net | I4: USD | J4: VND % | K4: Workers qty | L4: Salary - Net | M4: USD | N4: VND % | O4: Workers qty | P4: Salary - Net | Q4: USD | R4: VND % | S4: Workers qty | T4: Salary - Net | U4: USD | V4: VND % | W4: Workers qty | X4: Salary - Net | Y4: USD | Z4: VND % | AA4: Workers qty | AB4: Salary - Net | AC4: USD | AD4: VND % | AE4: Workers qty | AF4: Salary - Net | AG4: USD | AH4: VND % | AI4: Workers qty | AJ4: Salary - Net | AK4: USD | AL4: VND % | AM4: Workers qty | AN4: Salary - Net | AO4: USD | AP4: VND % | AQ4: Workers qty | AR4: Salary - Net | AS4: USD | AT4: VND % | AU4: Workers qty | AV4: Salary - Net | AW4: USD | AX4: VND % | AY4: Workers qty | AZ4: Salary - Net | BA4: USD
B5: FACTORY A | AI5: =+COUNTIFS('Salary sheet'!$E$6:$E$1291,$B5) -> 284 | AJ5: =SUMIFS('Salary sheet'!$AT$6:$AT$1291,'Salary sheet'!$E$6:$E$1291,$B5) -> 2557339954 | AK5: =+AJ5/AK$2 -> 97926.094 | AL5: =+AJ5/AN5 -> 0.93402165 | AM5: 292 | AN5: 2737987890 | AO5: 106557.22 | AP5: =+AN5/AR5 -> 1.0615978 | AQ5: 294 | AR5: 2579119677 | AS5: =+AR5/AS$2 -> 100472.13 | AT5: =+AR5/AV5 -> 1.2425969 | AU5: 283 | AV5: 2075588342 | AW5: =+AV5/AW$2 -> 81236.334 | AX5: =+AV5/AZ5 -> 0.66709289 | AY5: 299 | AZ5: 3111393293 | BA5: =+AZ5/BA$2 -> 121776.65
B6: FACTORY B | AI6: =+COUNTIFS('Salary sheet'!$E$6:$E$1291,$B6) -> 179 | AJ6: =SUMIFS('Salary sheet'!$AT$6:$AT$1291,'Salary sheet'!$E$6:$E$1291,$B6) -> 1600986183 | AK6: =+AJ6/AK$2 -> 61305.234 | AL6: =+AJ6/AN6 -> 0.99214116 | AM6: 181 | AN6: 1613667746 | AO6: 62800.846 | AP6: =+AN6/AR6 -> 1.0191866 | AQ6: 183 | AR6: 1583289853 | AS6: =+AR6/AS$2 -> 61678.607 | AT6: =+AR6/AV6 -> 1.4817185 | AU6: 172 | AV6: 1068549731 | AW6: =+AV6/AW$2 -> 41821.907 | AX6: =+AV6/AZ6 -> 0.58605134 | AY6: 176 | AZ6: 1823303950 | BA6: =+AZ6/BA$2 -> 71362.19
B7: FACTORY D | AI7: =+COUNTIFS('Salary sheet'!$E$6:$E$1291,$B7) -> 184 | AJ7: =SUMIFS('Salary sheet'!$AT$6:$AT$1291,'Salary sheet'!$E$6:$E$1291,$B7) -> 1470715569 | AK7: =+AJ7/AK$2 -> 56316.889 | AL7: =+AJ7/AN7 -> 0.98769743 | AM7: 178 | AN7: 1489034513 | AO7: 57950.36 | AP7: =+AN7/AR7 -> 1.0954997 | AQ7: 182 | AR7: 1359228551 | AS7: =+AR7/AS$2 -> 52950.08 | AT7: =+AR7/AV7 -> 1.1558625 | AU7: 183 | AV7: 1175943112 | AW7: =+AV7/AW$2 -> 46025.171 | AX7: =+AV7/AZ7 -> 0.59832064 | AY7: 192 | AZ7: 1965406217 | BA7: =+AZ7/BA$2 -> 76923.922
A8: FACTORY H | B8: FACTORY O | AI8: =+COUNTIFS('Salary sheet'!$E$6:$E$1291,$B8) -> 155 | AJ8: =SUMIFS('Salary sheet'!$AT$6:$AT$1291,'Salary sheet'!$E$6:$E$1291,$B8) -> 1872902206 | AK8: =+AJ8/AK$2 -> 71717.488 | AL8: =+AJ8/AN8 -> 0.9867829 | AM8: 157 | AN8: 1897988109 | AO8: 73866.048 | AP8: =+AN8/AR8 -> 1.0056226 | AQ8: 155 | AR8: 1887376198 | AS8: =+AR8/AS$2 -> 73524.589 | AT8: =+AR8/AV8 -> 1.5306626 | AU8: 154 | AV8: 1233045199 | AW8: =+AV8/AW$2 -> 48260.086 | AX8: =+AV8/AZ8 -> 0.56642305 | AY8: 160 | AZ8: 2176898007 | BA8: =+AZ8/BA$2 -> 85201.488
B9: Foreign Salary SK1 | AI9: 2 | AJ9: =+'Foreign Salary'!$R8+'Foreign Salary'!$R9 -> 363503937 | AK9: =+AJ9/AK$2 -> 13919.354 | AL9: =+AJ9/AN9 -> 1.0152882 | AM9: 2 | AN9: 358030287 | AO9: 13933.85 | AP9: =+AN9/AR9 -> 1.0009108 | AQ9: 2 | AR9: 357704475 | AS9: =+AR9/AS$2 -> 13934.728 | AT9: =+AR9/AV9 -> 0.96952673 | AU9: 2 | AV9: 368947512 | AW9: =+AV9/AW$2 -> 14440.216 | AX9: =+AV9/AZ9 -> 1.2044588 | AY9: 2 | AZ9: 306318075 | BA9: =+AZ9/BA$2 -> 11988.966
B10: Total SK1 | AI10: =SUM(AI5:AI9) -> 804 | AJ10: =SUM(AJ5:AJ9) -> 7865447849 | AK10: =SUM(AK5:AK9) -> 301185.06 | AL10: =+AJ10/AN10 -> 0.97143769 | AM10: =SUM(AM5:AM9) -> 810 | AN10: =SUM(AN5:AN9) -> 8096708545 | AO10: =SUM(AO5:AO9) -> 315108.33 | AP10: =+AN10/AR10 -> 1.0424877 | AQ10: =SUM(AQ5:AQ9) -> 816 | AR10: =SUM(AR5:AR9) -> 7766718754 | AS10: =SUM(AS5:AS9) -> 302560.14 | AT10: =+AR10/AV10 -> 1.3114863 | AU10: =SUM(AU5:AU9) -> 794 | AV10: =SUM(AV5:AV9) -> 5922073896 | AW10: =SUM(AW5:AW9) -> 231783.71 | AX10: =+AV10/D42 -> 0.75292266 | AY10: =SUM(AY5:AY9) -> 829 | AZ10: =SUM(AZ5:AZ9) -> 9383319542 | BA10: =SUM(BA5:BA9) -> 367253.21
B11: %/ Total SNK | AI11: =+AI10/AI16 -> 0.62373933 | AJ11: =+AJ10/AJ16 -> 0.60194504 | AK11: =+AK10/AK16 -> 0.60194504 | AL11: =+AJ11/AN11 -> 0.94901159 | AM11: =+AM10/AM16 -> 0.625966 | AN11: =+AN10/AN16 -> 0.63428629 | AO11: =+AO10/AO16 -> 0.63428629 | AP11: =+AN11/AR11 -> 0.97150395 | AQ11: =+AQ10/AQ16 -> 0.63949843 | AR11: =+AR10/AR16 -> 0.65289111 | AS11: =+AS10/AS16 -> 0.65289111 | AT11: =+AR11/AV11 -> 0.99989139 | AU11: =+AU10/AU16 -> 0.63826367 | AV11: =+AV10/AV16 -> 0.65296202 | AW11: =+AW10/AW16 -> 0.65296202 | AX11: =+AV11/D43 -> 1.0847536 | AY11: =+AY10/AY16 -> 0.6357362 | AZ11: =+AZ10/AZ16 -> 0.63486324 | BA11: =+BA10/BA16 -> 0.63486324
B12: SK2 | AI12: =+COUNTIFS('Salary sheet'!$E$6:$E$1291,$B12) -> 484 | AJ12: =SUMIFS('Salary sheet'!$AT$6:$AT$1291,'Salary sheet'!$E$6:$E$1291,$B12) -> 5084279703 | AK12: =+AJ12/AK$2 -> 194688.1 | AL12: =+AJ12/AN12 -> 1.1156454 | AM12: 483 | AN12: 4557254283 | AO12: 177359.58 | AP12: =+AN12/AR12 -> 1.1365265 | AQ12: 459 | AR12: 4009809182 | AS12: =+AR12/AS$2 -> 156206.05 | AT12: =+AR12/AV12 -> 1.325788 | AU12: 449 | AV12: 3024472478 | AW12: =+AV12/AW$2 -> 118374.66 | AX12: =+AV12/AZ12 -> 0.57160649 | AY12: 474 | AZ12: 5291179390 | BA12: =+AZ12/BA$2 -> 207091.17
B13: Foreign Salary SK2 | AI13: 1 | AJ13: =+'Foreign Salary'!$R10 -> 116993364 | AK13: =+AJ13/AK$2 -> 4479.9297 | AL13: =+AJ13/AN13 -> 1.0529828 | AM13: 1 | AN13: 111106627 | AO13: 4324.0563 | AP13: =+AN13/AR13 -> 0.93086126 | AQ13: 1 | AR13: 119358955 | AS13: =+AR13/AS$2 -> 4649.745 | AT13: =+AR13/AV13 -> 0.97034311 | AU13: 1 | AV13: 123006959 | AW13: =+AV13/AW$2 -> 4814.3624 | AX13: =+AV13/AZ13 -> 1.1652191 | AY13: 1 | AZ13: 105565520 | BA13: =+AZ13/BA$2 -> 4131.7229
B14: Total SK2 | AI14: =SUM(AI12:AI13) -> 485 | AJ14: =SUM(AJ12:AJ13) -> 5201273067 | AK14: =SUM(AK12:AK13) -> 199168.03 | AL14: =+AJ14/AN14 -> 1.114154 | AM14: =SUM(AM12:AM13) -> 484 | AN14: =SUM(AN12:AN13) -> 4668360910 | AO14: =SUM(AO12:AO13) -> 181683.63 | AP14: =+AN14/AR14 -> 1.1305815 | AQ14: =SUM(AQ12:AQ13) -> 460 | AR14: =SUM(AR12:AR13) -> 4129168137 | AS14: =SUM(AS12:AS13) -> 160855.79 | AT14: =+AR14/AV14 -> 1.3118968 | AU14: =SUM(AU12:AU13) -> 450 | AV14: =SUM(AV12:AV13) -> 3147479437 | AW14: =SUM(AW12:AW13) -> 123189.02 | AX14: =+AV14/D46 -> 0.60513636 | AY14: =SUM(AY12:AY13) -> 475 | AZ14: =SUM(AZ12:AZ13) -> 5396744910 | BA14: =SUM(BA12:BA13) -> 211222.89
B15: %/ Total SNK | AI15: =+AI14/AI16 -> 0.37626067 | AJ15: =+AJ14/AJ16 -> 0.39805496 | AK15: =+AK14/AK16 -> 0.39805496 | AL15: =+AJ15/AN15 -> 1.0884332 | AM15: =+AM14/AM16 -> 0.374034 | AN15: =+AN14/AN16 -> 0.36571371 | AO15: =+AO14/AO16 -> 0.36571371 | AP15: =+AN15/AR15 -> 1.0535994 | AQ15: =+AQ14/AQ16 -> 0.36050157 | AR15: =+AR14/AR16 -> 0.34710889 | AS15: =+AS14/AS16 -> 0.34710889 | AT15: =+AR15/AV15 -> 1.0002043 | AU15: =+AU14/AU16 -> 0.36173633 | AV15: =+AV14/AV16 -> 0.34703798 | AW15: =+AW14/AW16 -> 0.34703798 | AX15: =+AV15/D47 -> 0.87183432 | AY15: =+AY14/AY16 -> 0.3642638 | AZ15: =+AZ14/AZ16 -> 0.36513676 | BA15: =+BA14/BA16 -> 0.36513676
B16: G. Total SNK | AI16: =+AI10+AI14 -> 1289 | AJ16: =+AJ14+AJ10 -> 13066720916 | AK16: =+AK14+AK10 -> 500353.09 | AL16: =+AJ16/AN16 -> 1.023631 | AM16: =+AM10+AM14 -> 1294 | AN16: =+AN14+AN10 -> 12765069455 | AO16: =+AO14+AO10 -> 496791.96 | AP16: =+AN16/AR16 -> 1.0730658 | AQ16: =+AQ10+AQ14 -> 1276 | AR16: =+AR14+AR10 -> 11895886891 | AS16: =+AS14+AS10 -> 463415.93 | AT16: =+AR16/AV16 -> 1.3116287 | AU16: =+AU10+AU14 -> 1244 | AV16: =+AV14+AV10 -> 9069553333 | AW16: =+AW14+AW10 -> 354972.73 | AX16: =+AV16/D48 -> 0.69409559 | AY16: =+AY10+AY14 -> 1304 | AZ16: =+AZ10+AZ14 -> 14780064452 | BA16: =+AZ16/BA$2 -> 578476.1
B17: 1st advance Jan 2025 | AV17: 3472403477 | AW17: =+AV17/AW$2 -> 135906.2 | AZ17: 0
B18: Total Salary (net) Jan 2025 | AV18: =+AV17+AV16 -> 12541956810 | AW18: =+AV18/AW$2 -> 490878.94 | AX18: =+AV18/AZ18 -> 0.84857254 | AZ18: =+AZ16 -> 14780064452 | BA18: =+AZ18/BA2 -> 578476.1
AJ19: =+AJ16-'TOTAL(payment)'!L119 -> 0 | AU19: Paid : 1. 13Th month bonus (Transfer 20 Jan):320,410 Usd (Including : Working: $292,479 + Quit $6,216 + Maternity ;$ 6,924 + Foreign $ 14,791) 2. 1ST - Salary Jan (Transfer 20 Jan): 135,906 Usd (Including : Working: $134,677 + Quit $1,229) 3. Balance: 354,973 Usd (Transfer 10 Feb) 4. Total: 811,289 Usd. | AZ19: Remark: 1. Dec salary: $ 509,979 2. Balance annual leave: $ 68,497 (including maternity leave workers) Total pay: $ 578,476
A21: Exchange Rate : | C21: =+C3 -> Dec 2025 | D21: =+E2 -> 0 | G21: =+G3 -> Nov 2025 | H21: =+I2 -> 0 | K21: =+K3 -> Oct 2025 | L21: =+M2 -> 0 | O21: =+O3 -> Sep 2025 | P21: =+Q2 -> 0 | S21: =+S3 -> 45870 | T21: =+U2 -> 0 | W21: =+W3 -> 45839 | X21: =+Y2 -> 0 | AA21: =+AA3 -> 45809 | AB21: =+AC2 -> 0 | AE21: =+AE3 -> 45778 | AF21: =+AG2 -> 0 | AI21: =+AI3 -> 45748 | AJ21: =+AK2 -> 26115 | AM21: =+AM3 -> 45717 | AN21: =+AO2 -> 25695 | AQ21: =+AQ3 -> 45689 | AR21: =+AS2 -> 25670 | AU21: =+AU3 -> Jan 2025 | AV21: =+AW2 -> 25550 | AY21: =+AY3 -> Dec 2024 | AZ21: =+BA2 -> 25550
B22: Payment | C22: Amount (vnd) | D22: Amount (usd) | G22: Amount (vnd) | H22: Amount (usd) | K22: Amount (vnd) | L22: Amount (usd) | O22: Amount (vnd) | P22: Amount (usd) | S22: Amount (vnd) | T22: Amount (usd) | W22: Amount (vnd) | X22: Amount (usd) | AA22: Amount (vnd) | AB22: Amount (usd) | AE22: Amount (vnd) | AF22: Amount (usd) | AI22: Amount (vnd) | AJ22: Amount (usd) | AM22: Amount (vnd) | AN22: Amount (usd) | AQ22: Amount (vnd) | AR22: Amount (usd) | AU22: Amount (vnd) | AV22: Amount (usd) | AY22: Amount (vnd) | AZ22: Amount (usd)
B23: Workers qty | C23: =+C16 -> 0 | G23: =+G16 -> 0 | K23: =+K16 -> 0 | O23: =+O16 -> 0 | S23: =+S16 -> 0 | W23: =+W16 -> 0 | AA23: =+AA16 -> 0 | AE23: =+AE16 -> 0 | AI23: =+AI16 -> 1289 | AM23: =+AM16 -> 1294 | AQ23: =+AQ16 -> 1276 | AU23: =+AU16 -> 1244 | AY23: =+AY16 -> 1304
B24: Audit - Transfer | D24: =+C24/D21 -> #DIV/0! | H24: =+G24/H21 -> #DIV/0! | L24: =+K24/L21 -> #DIV/0! | P24: =+O24/P21 -> #DIV/0! | T24: =+S24/T21 -> #DIV/0! | X24: =+W24/X21 -> #DIV/0! | AB24: =+AA24/AB21 -> #DIV/0! | AI24: 11404670194 | AJ24: =+AI24/AJ21 -> 436709.56 | AM24: 11233667325 | AN24: 437192.73 | AQ24: 10526744334 | AR24: 410079.64 | AU24: 7248978461 | AV24: 283717.36 | AY24: =+[1]Transfer!$E$1297 -> 12386227850 | AZ24: =+AY24/AZ21 -> 484783.87
B25: Audit - Cash | D25: =+C25/D21 -> #DIV/0! | H25: =+G25/H21 -> #DIV/0! | L25: =+K25/L21 -> #DIV/0! | P25: =+O25/P21 -> #DIV/0! | T25: =+S25/T21 -> #DIV/0! | X25: =+W25/X21 -> #DIV/0! | AB25: =+AA25/AB21 -> #DIV/0! | AI25: 39396723 | AJ25: =+AI25/AJ21 -> 1508.586 | AM25: 62018199 | AN25: 2413.6291 | AQ25: 86533289 | AR25: 3370.9891 | AU25: 25112048 | AV25: 982.85902 | AY25: =+[1]Cash!$F$15 -> 101169004 | AZ25: =+AY25/AZ21 -> 3959.6479
B26: Outside - Transfer | D26: =+C26/D21 -> #DIV/0! | H26: =+G26/H21 -> #DIV/0! | L26: =+K26/L21 -> #DIV/0! | P26: =+O26/P21 -> #DIV/0! | T26: =+S26/T21 -> #DIV/0! | X26: =+W26/X21 -> #DIV/0! | AB26: =+AA26/AB21 -> #DIV/0! | AI26: 1139015986 | AJ26: =+AI26/AJ21 -> 43615.393 | AM26: 997637463 | AN26: 38826.132 | AQ26: 795791116 | AR26: 31000.823 | AU26: 1297654296 | AV26: 50788.818 | AY26: =+'[2]Transfer - Outside'!$E$1120 -> 1862073874 | AZ26: =+AY26/AZ21 -> 72879.604
B27: Outside - Cash | D27: =+C27/D21 -> #DIV/0! | H27: =+G27/H21 -> #DIV/0! | L27: =+K27/L21 -> #DIV/0! | P27: =+O27/P21 -> #DIV/0! | T27: =+S27/T21 -> #DIV/0! | X27: =+W27/X21 -> #DIV/0! | AB27: =+AA27/AB21 -> #DIV/0! | AI27: 3140712 | AJ27: =+AI27/AJ21 -> 120.26468 | AM27: 2609554 | AN27: 101.55882 | AQ27: 9754722 | AR27: 380.00475 | AU27: 5854057 | AV27: 229.1216 | AY27: =+'[2]Cash - Outside'!$F$14 -> 18710129 | AZ27: =+AY27/AZ21 -> 732.29468
B28: Total Salary VN | D28: =SUM(D24:D27) -> #DIV/0! | G28: =SUM(G24:G27) -> 0 | H28: =SUM(H24:H27) -> #DIV/0! | K28: =SUM(K24:K27) -> 0 | L28: =SUM(L24:L27) -> #DIV/0! | O28: =SUM(O24:O27) -> 0 | P28: =SUM(P24:P27) -> #DIV/0! | S28: =SUM(S24:S27) -> 0 | T28: =SUM(T24:T27) -> #DIV/0! | W28: =SUM(W24:W27) -> 0 | X28: =SUM(X24:X27) -> #DIV/0! | AA28: =SUM(AA24:AA27) -> 0 | AB28: =SUM(AB24:AB27) -> #DIV/0! | AE28: =SUM(AE24:AE27) -> 0 | AF28: =SUM(AF24:AF27) -> 0 | AI28: =SUM(AI24:AI27) -> 12586223615 | AJ28: =SUM(AJ24:AJ27) -> 481953.8 | AM28: =SUM(AM24:AM27) -> 12295932541 | AN28: =SUM(AN24:AN27) -> 478534.05 | AQ28: =SUM(AQ24:AQ27) -> 11418823461 | AR28: =SUM(AR24:AR27) -> 444831.46 | AU28: =SUM(AU24:AU27) -> 8577598862 | AV28: =SUM(AV24:AV27) -> 335718.16 | AY28: =SUM(AY24:AY27) -> 14368180857 | AZ28: =SUM(AZ24:AZ27) -> 562355.42
B29: Foreign | D29: =+C29/D21 -> #DIV/0! | H29: =+G29/H21 -> #DIV/0! | L29: =+K29/L21 -> #DIV/0! | P29: =+O29/P21 -> #DIV/0! | T29: =+S29/T21 -> #DIV/0! | X29: =+W29/X21 -> #DIV/0! | AB29: =+AA29/AB21 -> #DIV/0! | AI29: 480497301 | AJ29: =+AI29/AJ21 -> 18399.284 | AM29: 469136914 | AN29: 18257.907 | AQ29: 477063430 | AR29: 18584.473 | AU29: =+'[3]Foreign Salary'!V11 -> 491954471 | AV29: =+AU29/AV$21 -> 19254.578 | AY29: 411883595 | AZ29: =+AY29/AZ21 -> 16120.689
B30: Total Slary VN & Foreign | C30: =+C29+C28 -> 0 | D30: =+D29+D28 -> #DIV/0! | G30: =+G29+G28 -> 0 | H30: =+H29+H28 -> #DIV/0! | K30: =+K29+K28 -> 0 | L30: =+L29+L28 -> #DIV/0! | O30: =+O29+O28 -> 0 | P30: =+P29+P28 -> #DIV/0! | S30: =+S29+S28 -> 0 | T30: =+T29+T28 -> #DIV/0! | W30: =+W29+W28 -> 0 | X30: =+X29+X28 -> #DIV/0! | AA30: =+AA29+AA28 -> 0 | AB30: =+AB29+AB28 -> #DIV/0! | AE30: =+AE29+AE28 -> 0 | AF30: =+AF29+AF28 -> 0 | AI30: =+AI29+AI28 -> 13066720916 | AJ30: =+AJ29+AJ28 -> 500353.09 | AM30: =+AM29+AM28 -> 12765069455 | AN30: =+AN29+AN28 -> 496791.96 | AQ30: =+AQ29+AQ28 -> 11895886891 | AR30: =+AR29+AR28 -> 463415.93 | AU30: =+AU29+AU28 -> 9069553333 | AV30: =+AV29+AV28 -> 354972.73 | AY30: =+AY29+AY28 -> 14780064452 | AZ30: =+AZ29+AZ28 -> 578476.1
C31: =+C30-D16 -> 0 | D31: =+D30-E16 -> #DIV/0! | G31: =+G30-H16 -> 0 | H31: =+H30-I16 -> #DIV/0! | K31: =+K30-L16 -> 0 | L31: =+L30-M16 -> #DIV/0! | O31: =+O30-P16 -> 0 | P31: =+P30-Q16 -> #DIV/0! | S31: =+S30-T16 -> 0 | T31: =+T30-U16 -> #DIV/0! | W31: =+W30-X16 -> 0 | X31: =+X30-Y16 -> #DIV/0! | AA31: =+AA30-AB16 -> 0 | AB31: =+AB30-AC16 -> #DIV/0! | AE31: =+AE30-AF16 -> 0 | AF31: =+AF30-AG16 -> 0 | AI31: =+AI30-AJ16 -> 0 | AJ31: =+AJ30-AK16 -> 0 | AM31: =+AM30-AN16 -> 0 | AQ31: =+AQ30-AR16 -> 0
B33: Exchange Rate : | E33: 25550 | I33: 25460 | M33: 25410 | Q33: 24695 | U33: 25000 | Y33: 25400 | AC33: 25473 | AG33: 25474 | AK33: 25435 | AO33: 24915 | AS33: 24770 | AW33: 24525
B34: Month | C34: Dec 2024 | F34: =LEFT(C34,3)&"/"&LEFT(G34,3) -> Dec/Nov | G34: Nov 2024 | J34: =LEFT(G34,3)&"/"&LEFT(K34,3) -> Nov/Oct | K34: Oct 2024 | N34: =LEFT(K34,3)&"/"&LEFT(O34,3) -> Oct/Sep | O34: Sep 2024 | R34: Sep/Aug | S34: Aug 2024 | V34: Aug/Jul | W34: Jul 2024 | Z34: Jul/Jun | AA34: Jun 2024 | AD34: Jun/May | AE34: May 2024 | AH34: May/ Apr | AI34: 45383 | AL34: Apr/Mar | AM34: 45352 | AP34: Mar/Feb | AQ34: 45323 | AT34: Feb/Jan | AU34: 45292 | AX34: Jan/Dec 23
B35: Actual working days | C35: 26 | G35: 26 | K35: 26 | O35: 26 | S35: 26 | W35: 26 | AA35: 26 | AE35: 26 | AI35: 26 | AM35: 26 | AQ35: 26 | AU35: 26
B36: Payment | C36: Workers qty | D36: Salary - Net | E36: USD | F36: VND % | G36: Workers qty | H36: Salary - Net | I36: USD | J36: VND % | K36: Workers qty | L36: Salary - Net | M36: USD | N36: VND % | O36: Workers qty | P36: Salary - Net | Q36: USD | R36: VND % | S36: Workers qty | T36: Salary - Net | U36: USD | V36: VND % | W36: Workers qty | X36: Salary - Net | Y36: USD | Z36: VND % | AA36: Workers qty | AB36: Salary - Net | AC36: USD | AD36: VND % | AE36: Workers qty | AF36: Salary - Net | AG36: USD | AH36: VND % | AI36: Workers qty | AJ36: Salary - Net | AK36: USD | AL36: VND % | AM36: Workers qty | AN36: Salary - Net | AO36: USD | AP36: VND % | AQ36: Workers qty | AR36: Salary - Net | AS36: USD | AT36: VND % | AU36: Workers qty | AV36: Salary - Net | AW36: USD | AX36: VND %
B37: FACTORY A | C37: =COUNTIFS('Salary sheet'!$E$6:$E$1291,'Summary '!$B37) -> 284 | D37: =SUMIFS('Salary sheet'!$AT$6:$AT$1291,'Salary sheet'!$E$6:$E$1291,'Summary '!$B37) -> 2557339954 | E37: =+D37/E$33 -> 100091.58 | F37: =+D37/H37 -> 0.99923511 | G37: 284 | H37: 2559297530 | I37: =+H37/I$33 -> 100522.29 | J37: =+H37/L37 -> 0.76376754 | K37: 280 | L37: 3350885451 | M37: =+L37/M$33 -> 131872.71 | N37: =+L37/P37 -> 1.210269 | O37: 275 | P37: 2768711215 | Q37: =+P37/Q$33 -> 112116.27 | R37: =+P37/T37 -> 0.99547932 | S37: 268 | T37: 2781284525 | U37: =+T37/U$33 -> 111251.38 | V37: =+T37/X37 -> 1.0905772 | W37: 276 | X37: 2550286758 | Y37: =+X37/Y$33 -> 100404.99 | Z37: =+X37/AB37 -> 1.3131807 | AA37: 279 | AB37: 1942068482 | AC37: =+AB37/AC$33 -> 76240.273 | AD37: =+AB37/AF37 -> 0.83625026 | AE37: 278 | AF37: 2322353211 | AG37: 91165.628 | AH37: =+AF37/AJ37 -> 1.0947982 | AI37: 286 | AJ37: 2121261444 | AK37: =+AJ37/AK$33 -> 83399.31 | AL37: =+AJ37/AN37 -> 0.90816188 | AM37: 283 | AN37: 2335774601 | AO37: 93749.733 | AP37: =+AN37/AR37 -> 1.3542485 | AQ37: 283 | AR37: 1724775425 | AS37: =+AR37/AS$33 -> 69631.628 | AT37: =+AR37/AV37 -> 0.45422459 | AU37: 284 | AV37: 3797186401 | AW37: =+AV37/AW$33 -> 154829.21 | AX37: =+AV37/C69 -> 1.5147269
B38: FACTORY B | C38: =COUNTIFS('Salary sheet'!$E$6:$E$1291,'Summary '!$B38) -> 179 | D38: =SUMIFS('Salary sheet'!$AT$6:$AT$1291,'Salary sheet'!$E$6:$E$1291,'Summary '!$B38) -> 1600986183 | E38: =+D38/E$33 -> 62660.907 | F38: =+D38/H38 -> 1.0189403 | G38: 176 | H38: 1571226754 | I38: =+H38/I$33 -> 61713.541 | J38: =+H38/L38 -> 0.83445991 | K38: 175 | L38: 1882926592 | M38: =+L38/M$33 -> 74101.794 | N38: =+L38/P38 -> 0.99921757 | O38: 179 | P38: 1884401007 | Q38: =+P38/Q$33 -> 76306.986 | R38: =+P38/T38 -> 1.1920416 | S38: 166 | T38: 1580818209 | U38: =+T38/U$33 -> 63232.728 | V38: =+T38/X38 -> 1.1442225 | W38: 154 | X38: 1381565351 | Y38: =+X38/Y$33 -> 54392.337 | Z38: =+X38/AB38 -> 1.1405857 | AA38: 151 | AB38: 1211277153 | AC38: =+AB38/AC$33 -> 47551.413 | AD38: =+AB38/AF38 -> 0.92195726 | AE38: 159 | AF38: 1313810533 | AG38: 51574.568 | AH38: =+AF38/AJ38 -> 1.1575076 | AI38: 149 | AJ38: 1135034061 | AK38: =+AJ38/AK$33 -> 44624.889 | AL38: =+AJ38/AN38 -> 0.97302649 | AM38: 146 | AN38: 1166498628 | AO38: 46819.13 | AP38: =+AN38/AR38 -> 1.2683849 | AQ38: 138 | AR38: 919672454 | AS38: =+AR38/AS$33 -> 37128.48 | AT38: =+AR38/AV38 -> 0.50498659 | AU38: 129 | AV38: 1821181916 | AW38: =+AV38/AW$33 -> 74258.182 | AX38: =+AV38/C70 -> 1.5029032
B39: FACTORY D | C39: =COUNTIFS('Salary sheet'!$E$6:$E$1291,'Summary '!$B39) -> 184 | D39: =SUMIFS('Salary sheet'!$AT$6:$AT$1291,'Salary sheet'!$E$6:$E$1291,'Summary '!$B39) -> 1470715569 | E39: =+D39/E$33 -> 57562.253 | F39: =+D39/H39 -> 0.88311721 | G39: 189 | H39: 1665368487 | I39: =+H39/I$33 -> 65411.174 | J39: =+H39/L39 -> 0.85546819 | K39: 190 | L39: 1946733389 | M39: =+L39/M$33 -> 76612.884 | N39: =+L39/P39 -> 1.0779244 | O39: 183 | P39: 1806001732 | Q39: =+P39/Q$33 -> 73132.283 | R39: =+P39/T39 -> 1.0681507 | S39: 172 | T39: 1690774336 | U39: =+T39/U$33 -> 67630.973 | V39: =+T39/X39 -> 0.9885454 | W39: 175 | X39: 1710365888 | Y39: =+X39/Y$33 -> 67337.24 | Z39: =+X39/AB39 -> 1.2684615 | AA39: 180 | AB39: 1348378264 | AC39: =+AB39/AC$33 -> 52933.626 | AD39: =+AB39/AF39 -> 0.77249546 | AE39: 188 | AF39: 1745483744 | AG39: 68520.207 | AH39: =+AF39/AJ39 -> 1.1435757 | AI39: 205 | AJ39: 1526338648 | AK39: =+AJ39/AK$33 -> 60009.383 | AL39: =+AJ39/AN39 -> 1.0036466 | AM39: 199 | AN39: 1520792976 | AO39: 61039.252 | AP39: =+AN39/AR39 -> 1.2604651 | AQ39: 188 | AR39: 1206533181 | AS39: =+AR39/AS$33 -> 48709.454 | AT39: =+AR39/AV39 -> 0.46778096 | AU39: 194 | AV39: 2579269513 | AW39: =+AV39/AW$33 -> 105168.99 | AX39: =+AV39/C71 -> 1.5996359
A40: FACTORY H | B40: FACTORY O | C40: =COUNTIFS('Salary sheet'!$E$6:$E$1291,'Summary '!$B40) -> 155 | D40: =SUMIFS('Salary sheet'!$AT$6:$AT$1291,'Salary sheet'!$E$6:$E$1291,'Summary '!$B40) -> 1872902206 | E40: =+D40/E$33 -> 73303.413 | F40: =+D40/H40 -> 1.0410426 | G40: 156 | H40: 1799064027 | I40: =+H40/I$33 -> 70662.373 | J40: =+H40/L40 -> 0.89633304 | K40: 160 | L40: 2007137919 | M40: =+L40/M$33 -> 78990.079 | N40: =+L40/P40 -> 1.0470994 | O40: 160 | P40: 1916855199 | Q40: =+P40/Q$33 -> 77621.186 | R40: =+P40/T40 -> 0.92674332 | S40: 160 | T40: 2068377682 | U40: =+T40/U$33 -> 82735.107 | V40: =+T40/X40 -> 1.0534306 | W40: 158 | X40: 1963468458 | Y40: =+X40/Y$33 -> 77301.908 | Z40: =+X40/AB40 -> 1.128515 | AA40: 154 | AB40: 1739869178 | AC40: =+AB40/AC$33 -> 68302.484 | AD40: =+AB40/AF40 -> 0.95925352 | AE40: 154 | AF40: 1813774087 | AG40: 71200.993 | AH40: =+AF40/AJ40 -> 1.0596974 | AI40: 152 | AJ40: 1711596163 | AK40: =+AJ40/AK$33 -> 67292.949 | AL40: =+AJ40/AN40 -> 1.0303208 | AM40: 157 | AN40: 1661226461 | AO40: 66675.756 | AP40: =+AN40/AR40 -> 1.144399 | AQ40: 151 | AR40: 1451614713 | AS40: =+AR40/AS$33 -> 58603.743 | AT40: =+AR40/AV40 -> 0.47044582 | AU40: 150 | AV40: 3085615057 | AW40: =+AV40/AW$33 -> 125815.09 | AX40: =+AV40/C72 -> 1.5996506
B41: Foreign Salary SK1 | C41: 2 | D41: =+'Foreign Salary'!$R8+'Foreign Salary'!$R9 -> 363503937 | E41: =+D41/E$33 -> 14227.16 | F41: =+D41/H41 -> 1.1905645 | G41: 2 | H41: 305320650 | I41: =+H41/I$33 -> 11992.17 | J41: =+H41/L41 -> 0.96743673 | K41: 2 | L41: 315597537 | M41: =+L41/M$33 -> 12420.21 | N41: =+L41/P41 -> 1.0687261 | O41: 2 | P41: 295302537 | Q41: =+P41/Q$33 -> 11957.989 | R41: =+P41/T41 -> 0.95462449 | S41: 2 | T41: 309338950 | U41: =+T41/U$33 -> 12373.558 | V41: =+T41/X41 -> 0.98533648 | W41: 2 | X41: 313942450 | Y41: =+X41/Y$33 -> 12359.939 | Z41: =+X41/AB41 -> 1.0284478 | AA41: 2 | AB41: 305258522 | AC41: =+AB41/AC$33 -> 11983.611 | AD41: =+AB41/AF41 -> 0.96561716 | AE41: 2 | AF41: 316127897 | AG41: 12409.826 | AH41: =+AF41/AJ41 -> 1.0370378 | AI41: 2 | AJ41: 304837387 | AK41: =+AJ41/AK$33 -> 11984.957 | AL41: =+AJ41/AN41 -> 1.0192691 | AM41: 2 | AN41: 299074487 | AO41: 12235.095 | AP41: =+AN41/AR41 -> 1.0054021 | AQ41: 2 | AR41: 297467525 | AS41: =+AR41/AS$33 -> 12009.186 | AT41: =+AR41/AV41 -> 0.5155377 | AU41: 2 | AV41: 577004406 | AW41: =+AV41/AW$33 -> 23527.193 | AX41: =+AV41/C73 -> 1.9705568
B42: Total SK1 | C42: =SUM(C37:C41) -> 804 | D42: =SUM(D37:D41) -> 7865447849 | E42: =SUM(E37:E41) -> 307845.32 | F42: =+D42/H42 -> 0.99559134 | G42: =SUM(G37:G41) -> 807 | H42: =SUM(H37:H41) -> 7900277448 | I42: =SUM(I37:I41) -> 310301.55 | J42: =+H42/L42 -> 0.83132105 | K42: =SUM(K37:K41) -> 807 | L42: =SUM(L37:L41) -> 9503280888 | M42: =SUM(M37:M41) -> 373997.67 | N42: =+L42/P42 -> 1.0959501 | O42: =SUM(O37:O41) -> 799 | P42: =SUM(P37:P41) -> 8671271690 | Q42: =SUM(Q37:Q41) -> 351134.71 | R42: =+P42/T42 -> 1.0285482 | S42: =SUM(S37:S41) -> 768 | T42: =SUM(T37:T41) -> 8430593702 | U42: =SUM(U37:U41) -> 337223.75 | V42: =+T42/X42 -> 1.0645188 | W42: =SUM(W37:W41) -> 765 | X42: =SUM(X37:X41) -> 7919628905 | Y42: =SUM(Y37:Y41) -> 311796.41 | Z42: =+X42/AB42 -> 1.2096851 | AA42: =SUM(AA37:AA41) -> 766 | AB42: =SUM(AB37:AB41) -> 6546851599 | AC42: =SUM(AC37:AC41) -> 257011.41 | AD42: =+AB42/AF42 -> 0.87157139 | AE42: =SUM(AE37:AE41) -> 781 | AF42: =SUM(AF37:AF41) -> 7511549472 | AG42: =SUM(AG37:AG41) -> 294871.22 | AH42: =+AF42/AJ42 -> 1.1047911 | AI42: =SUM(AI37:AI41) -> 794 | AJ42: =SUM(AJ37:AJ41) -> 6799067703 | AK42: =SUM(AK37:AK41) -> 267311.49 | AL42: =+AJ42/AN42 -> 0.9736088 | AM42: =SUM(AM37:AM41) -> 787 | AN42: =SUM(AN37:AN41) -> 6983367153 | AO42: =SUM(AO37:AO41) -> 280518.97 | AP42: =+AN42/AR42 -> 1.2470158 | AQ42: =SUM(AQ37:AQ41) -> 762 | AR42: =SUM(AR37:AR41) -> 5600063298 | AS42: =SUM(AS37:AS41) -> 226082.49 | AT42: =+AR42/AV42 -> 0.47217047 | AU42: =SUM(AU37:AU41) -> 759 | AV42: =SUM(AV37:AV41) -> 11860257293 | AW42: =SUM(AW37:AW41) -> 483598.67 | AX42: =+AV42/C74 -> 1.5703178
B43: %/ Total SNK | C43: =+C42/C48 -> 0.62373933 | D43: =+D42/D48 -> 0.60194504 | E43: =+E42/E48 -> 0.60194504 | G43: =+G42/G48 -> 0.624613 | H43: =+H42/H48 -> 0.6287349 | I43: =+I42/I48 -> 0.6287349 | K43: =+K42/K48 -> 0.6236476 | L43: =+L42/L48 -> 0.65573114 | M43: =+M42/M48 -> 0.65573114 | O43: =+O42/O48 -> 0.62913386 | P43: =+P42/P48 -> 0.63335215 | Q43: =+Q42/Q48 -> 0.63335215 | S43: =+S42/S48 -> 0.62693878 | T43: =+T42/T48 -> 0.61244505 | U43: =+U42/U48 -> 0.61244505 | W43: =+W42/W48 -> 0.62859491 | X43: =+X42/X48 -> 0.60180683 | Y43: =+Y42/Y48 -> 0.60180683 | AA43: =+AA42/AA48 -> 0.63253509 | AB43: =+AB42/AB48 -> 0.60725431 | AC43: =+AC42/AC48 -> 0.60725431 | AE43: =+AE42/AE48 -> 0.63444354 | AF43: =+AF42/AF48 -> 0.60886068 | AG43: =+AG42/AG48 -> 0.60886068 | AI43: =+AI42/AI48 -> 0.63367917 | AJ43: =+AJ42/AJ48 -> 0.60390815 | AK43: =+AK42/AK48 -> 0.60390815 | AM43: =+AM42/AM48 -> 0.63010408 | AN43: =+AN42/AN48 -> 0.63871048 | AO43: =+AO42/AO48 -> 0.63923756 | AP43: =+AN43/AR43 -> 1.0061164 | AQ43: =+AQ42/AQ48 -> 0.6387259 | AR43: =+AR42/AR48 -> 0.63482763 | AS43: =+AS42/AS48 -> 0.63482763 | AT43: =+AR43/AV43 -> 0.98830034 | AU43: =+AU42/AU48 -> 0.64816396 | AV43: =+AV42/AV48 -> 0.64234282 | AW43: =+AW42/AW48 -> 0.64234282 | AX43: =+AV43/C75 -> 1.0221616
...

Sheet Sheet1
D2: Inside | E2: Outside | F2: Total
B3: 1 | C3: Payment Transfer - Foreign | D3: =+'Foreign Salary'!R11 -> 480497301 | E3: 0 | F3: =SUM(D3:E3) -> 480497301 | G3: =+F3-'Foreign Salary'!R11 -> 0
B4: 2 | C4: Payment Transfer | D4: 10547466313 | E4: 1126799307 | F4: =SUM(D4:E4) -> 11674265620 | G4: =+F4-Transfer!E1279 -> -869420560
B5: 3 | C5: Payment Cash | D5: 215764202 | E5: 21316040 | F5: =SUM(D5:E5) -> 237080242 | G5: =+F5-Cash!F18 -> 194542807
B6: 4 | C6: Payment cash - Ms Quyên Nurse Staff | D6: 0 | E6: 11464288 | F6: =SUM(D6:E6) -> 11464288
C7: Total | D7: =SUM(D3:D6) -> 11243727816 | E7: =SUM(E3:E6) -> 1159579635 | F7: =SUM(F3:F6) -> 12403307451
F8: =+F7-'TOTAL(payment)'!L119 -> -663413465

Sheet Manager
A1: STT | B1: Code | C1: Name | D1: Tổng thu nhập Total Gross Salary | E1: Phụ cấp Phụ Nữ Menstruation allowance | F1: Tiền thực lãnh Net Salary | G1: Bộ phận Dep | H1: Title/ Chức danh
A2: 1 | B2: C3402 | C2: Đoàn Thị Hiếu Loan | D2: =+VLOOKUP(B2,'Salary sheet'!$B$6:$AS$1291,40,0) -> 2562000 | E2: =VLOOKUP(B2,'Salary sheet'!$B$6:$AE$1318,30,0) -> 175961.54 | F2: =+D2-E2 -> 2386038.5 | G2: =VLOOKUP(B2,'Salary sheet'!$B$3:$G$1318,5,0) -> P6 - Production Office | H2: =VLOOKUP(B2,'Salary sheet'!$B$3:$G$1318,6,0) -> Factory manager
A3: 2 | B3: C5841 | C3: Trần Văn Nhân | D3: =+VLOOKUP(B3,'Salary sheet'!$B$6:$AS$1291,40,0) -> 2566200 | E3: =VLOOKUP(B3,'Salary sheet'!$B$6:$AE$1318,30,0) -> 0 | F3: =+D3-E3 -> 2566200 | G3: =VLOOKUP(B3,'Salary sheet'!$B$3:$G$1318,5,0) -> P6 - Production Office | H3: =VLOOKUP(B3,'Salary sheet'!$B$3:$G$1318,6,0) -> Factory manager
A4: 3 | B4: C3465 | C4: Lê Văn Khỏe | D4: =+VLOOKUP(B4,'Salary sheet'!$B$6:$AS$1291,40,0) -> 1944495 | E4: =VLOOKUP(B4,'Salary sheet'!$B$6:$AE$1318,30,0) -> 0 | F4: =+D4-E4 -> 1944495 | G4: =VLOOKUP(B4,'Salary sheet'!$B$3:$G$1318,5,0) -> P5 - Production Office | H4: =VLOOKUP(B4,'Salary sheet'!$B$3:$G$1318,6,0) -> Factory vice manager
A5: 4 | B5: C6068 | C5: Trần Thị Cẩm Linh | D5: =+VLOOKUP(B5,'Salary sheet'!$B$6:$AS$1291,40,0) -> 3034500 | E5: =VLOOKUP(B5,'Salary sheet'!$B$6:$AE$1318,30,0) -> 208413.46 | F5: =+D5-E5 -> 2826086.5 | G5: =VLOOKUP(B5,'Salary sheet'!$B$3:$G$1318,5,0) -> P4 - Production Office | H5: =VLOOKUP(B5,'Salary sheet'!$B$3:$G$1318,6,0) -> Factory manager
A6: 5 | B6: C6347 | C6: Đỗ Thị Thanh Tú | D6: =+VLOOKUP(B6,'Salary sheet'!$B$6:$AS$1291,40,0) -> 3066000 | E6: =VLOOKUP(B6,'Salary sheet'!$B$6:$AE$1318,30,0) -> 210576.93 | F6: =+D6-E6 -> 2855423.1 | G6: =VLOOKUP(B6,'Salary sheet'!$B$3:$G$1318,5,0) -> P0 - Design | H6: =VLOOKUP(B6,'Salary sheet'!$B$3:$G$1318,6,0) -> Design manager
A7: 6 | B7: C6407 | C7: Điểu Dũng | D7: =+VLOOKUP(B7,'Salary sheet'!$B$6:$AS$1291,40,0) -> 2551500 | E7: =VLOOKUP(B7,'Salary sheet'!$B$6:$AE$1318,30,0) -> 0 | F7: =+D7-E7 -> 2551500 | G7: =VLOOKUP(B7,'Salary sheet'!$B$3:$G$1318,5,0) -> P0 - Development | H7: =VLOOKUP(B7,'Salary sheet'!$B$3:$G$1318,6,0) -> Development manager
A8: 7 | B8: V004 | C8: Hồ Mạnh Hoàng | D8: =+VLOOKUP(B8,'Salary sheet'!$B$6:$AS$1291,40,0) -> 1850520 | E8: =VLOOKUP(B8,'Salary sheet'!$B$6:$AE$1318,30,0) -> 0 | F8: =+D8-E8 -> 1850520 | G8: =VLOOKUP(B8,'Salary sheet'!$B$3:$G$1318,5,0) -> P0 - Maintenance | H8: =VLOOKUP(B8,'Salary sheet'!$B$3:$G$1318,6,0) -> Maintenance Leader
A9: 8 | B9: C5097 | C9: Kiều Quốc Minh | D9: =+VLOOKUP(B9,'Salary sheet'!$B$6:$AS$1291,40,0) -> 3227700 | E9: =VLOOKUP(B9,'Salary sheet'!$B$6:$AE$1318,30,0) -> 0 | F9: =+D9-E9 -> 3227700 | G9: =VLOOKUP(B9,'Salary sheet'!$B$3:$G$1318,5,0) -> P0 - GC WIP | H9: =VLOOKUP(B9,'Salary sheet'!$B$3:$G$1318,6,0) -> GC WIP Manager
A10: 9 | B10: C5107 | C10: Roãn Văn Hòa | D10: =+VLOOKUP(B10,'Salary sheet'!$B$6:$AS$1291,40,0) -> 3969000 | E10: =VLOOKUP(B10,'Salary sheet'!$B$6:$AE$1318,30,0) -> 0 | F10: =+D10-E10 -> 3969000 | G10: =VLOOKUP(B10,'Salary sheet'!$B$3:$G$1318,5,0) -> P0 - Production Office | H10: =VLOOKUP(B10,'Salary sheet'!$B$3:$G$1318,6,0) -> Production Manager
A11: 10 | B11: C6332 | C11: Đỗ Văn Thái | D11: =+VLOOKUP(B11,'Salary sheet'!$B$6:$AS$1291,40,0) -> 3097500 | E11: =VLOOKUP(B11,'Salary sheet'!$B$6:$AE$1318,30,0) -> 0 | F11: =+D11-E11 -> 3097500 | G11: =VLOOKUP(B11,'Salary sheet'!$B$3:$G$1318,5,0) -> P1 - Production Office | H11: =VLOOKUP(B11,'Salary sheet'!$B$3:$G$1318,6,0) -> Factory manager
A12: 11 | B12: C0020 | C12: Phan Tuấn Khanh | D12: =+VLOOKUP(B12,'Salary sheet'!$B$6:$AS$1291,40,0) -> 3070200 | E12: =VLOOKUP(B12,'Salary sheet'!$B$6:$AE$1318,30,0) -> 0 | F12: =+D12-E12 -> 3070200 | G12: =VLOOKUP(B12,'Salary sheet'!$B$3:$G$1318,5,0) -> P2 - Production Office | H12: =VLOOKUP(B12,'Salary sheet'!$B$3:$G$1318,6,0) -> Factory manager
A13: 12 | B13: V054 | C13: Huỳnh Ngọc Thảo | D13: =+VLOOKUP(B13,'Salary sheet'!$B$6:$AS$1291,40,0) -> 3301200 | E13: =VLOOKUP(B13,'Salary sheet'!$B$6:$AE$1318,30,0) -> 226730.77 | F13: =+D13-E13 -> 3074469.2 | G13: =VLOOKUP(B13,'Salary sheet'!$B$3:$G$1318,5,0) -> P3 - Production Office | H13: =VLOOKUP(B13,'Salary sheet'!$B$3:$G$1318,6,0) -> Factory manager
... A17: 16 | B17: C14623 | C17: Trần Văn Hoài | D17: =+VLOOKUP(B17,'Salary sheet'!$B$6:$AS$1291,40,0) -> 3811500 | E17: =VLOOKUP(B17,'Salary sheet'!$B$6:$AE$1318,30,0) -> 0 | F17: =+D17-E17 -> 3811500 | G17: =VLOOKUP(B17,'Salary sheet'!$B$3:$G$1318,5,0) -> P5 - Production Office | H17: =VLOOKUP(B17,'Salary sheet'!$B$3:$G$1318,6,0) -> Factory manager
C18: Total | D18: =SUM(D2:D17) -> #N/A | E18: =SUM(E2:E17) -> #N/A | F18: =SUM(F2:F17) -> #N/A | G18: =SUM(G2:G17) -> #N/A | H18: =SUM(H2:H17) -> #N/A

Sheet SS
B1: Content | C1: Jun-May | D1: % | E1: Noted
B2: Working day | C2: 4186.2 | D2: 0.11849927 | E2: Working: Jun.2020: 26 days - May.2020: 24 days
B3: Paid leave | C3: -2887 | D3: -0.86076327 | E3: After Corona epidemic situationm,After Transportation of machinery SK1: Box - SK2: Bag - Normal working
B4: Night work + 30% | C4: 3478.5 | D4: 1.9775441 | E4: After Corona epidemic situation - Normal overtime
B5: Overtime 150% | C5: 41402.5 | D5: 9.3123032 | E5: After Corona epidemic situation - Normal overtime
B6: Overtime 200% | C6: 0 | D6: 0
B7: Overtime 210% | C7: 1267 | D7: 4.4770318 | E7: After Corona epidemic situation - Normal overtime
B9: Content | C9: Jan-Dec | D9: % | E9: Noted
B10: Working day | C10: -7837.9 | D10: -0.22161745 | E10: Jan.22: working day 22 day
E11: Dec: Isolate (7 day) working day 27 day (Total 35.366 day/ 1681 Preson)
B12: Paid leave | C12: 3842 | D12: 6.4033333 | E12: Jan.2022 Holiday 2 day (01+31/Jan/2022)
E13: Dec: No holiday
B14: Night work + 30% | C14: -2045.8 | D14: -0.71232591 | E14: Jan.22: working day 22 day
E15: Dec: Working day 27 day &Night work 2872 Hour
B16: Overtime 150% | C16: -12945 | D16: -0.19960834 | E16: Jan.22: working day 22 day
E17: Dec: Working day 27 day (Overtime 64.852 hour)
B18: Overtime 200% | C18: 1152 | D18: 33.882353 | E18: Jan.2022: Overtime Sunday 1186 Hour
E19: Dec: Overtime Sunday 34 Hour
B20: Overtime 210% | C20: -251 | D20: -0.47809524 | E20: Jan.2022: Working day 22 day (274 Hour)
E21: Dec: Working day 27 day (525 Hour)
B22: Overtime 300% | C22: -254.5 | D22: -1 | E22: Oct.2021 No overtime 300%
B25: Content | C25: Apr | D25: Mar | E25: ="Amount "&C25&" ~ "&D25 -> Amount Apr ~ Mar | F25: % | G25: Note
B26: Working Day | C26: 28967.6 | D26: 31007.9 | E26: =+C26-D26 -> -2040.3 | F26: =+E26/D26 -> -0.065799361 | G26: Apr: Working day 24 day Mar Working day 26 day
B27: Paid Leave | C27: 2981 | D27: 87 | E27: =+C27-D27 -> 2894 | F27: =+E27/D27 -> 33.264368 | G27: Apr: Holiday: 2 day (10/03AL & 30/04) Mar: Marriage leave, funeral | J27: Marriage leave, labor accidents leave, funeral
B28: Annual Leave | E28: =+C28-D28 -> 0 | G28: Balance annual leave 2024
B29: extra pay for night work + 30% | C29: 4497 | D29: 4387 | E29: =+C29-D29 -> 110 | F29: =+E29/D29 -> 0.025074083 | G29: Increased night working hours (due to higher actual working days than last month)
B30: Overtime 150% | C30: 46478.5 | D30: 46222.5 | E30: =+C30-D30 -> 256 | F30: =+E30/D30 -> 0.0055384283 | G30: ~ | K30: Increased overtime 150% : (due to higher actual working days than last month)
B31: Overtime 200% | C31: 568 | D31: 199.5 | E31: =+C31-D31 -> 368.5 | F31: =+E31/D31 -> 1.8471178 | G31: Overtime Sunday
B32: Overtime 210% | C32: 423 | D32: 506.5 | E32: =+C32-D32 -> -83.5 | F32: =+E32/D32 -> -0.16485686 | G32: Increased night working hours (due to higher actual working days than last month)
B33: Overtime 270% | C33: 0 | E33: =+C33-D33 -> 0
B34: Overtime 300% | C34: 136 | D34: 0 | E34: =+C34-D34 -> 136

Sheet TOTAL(payment)
A1: Công ty TNHH Bao Bì Cao Cấp S&K Vina
A3: REPORT - BẢNG TỔNG KẾT LƯƠNG THÁNG 04 2025
A4: SUM OF SALARY OF APR 2025
A6: 0.54444444 | B6: Fac | C6: Dep new | D6: Dep Code | E6: # of worker | F6: Tổng thu nhập Total gross salary | G6: BHXH&BHYT, BHTN Social & Health Ins, Unempl-oyment Benefit | H6: KPCĐ Union Dues | I6: Thuế TNCN Personal Income Tax | J6: Đồng Phục Uniform | K6: Ứng Lương Advance | L6: Số Tiền (VND) Net salary | M6: Average
A7: =SUBTOTAL(3,B$7:B7) -> 1 | B7: Foreigners | C7: Foreigners | E7: 3 | F7: =+'Foreign Salary'!L11 -> 686964617 | G7: =+'Foreign Salary'!M11 -> 13338000 | H7: 0 | I7: =+'Foreign Salary'!P11 -> 193129316 | J7: 0 | K7: 0 | L7: =+(F7)-SUM(G7:K7) -> 480497301 | M7: =+L7/E7 -> 160165767
A8: =SUBTOTAL(3,B$7:B8) -> 2 | B8: SK2 | C8: P0 - Cleaning | D8: P0-CL-1-01 | E8: =COUNTIFS('Salary sheet'!$F$6:$F$2288,C8,'Salary sheet'!$E$6:$E$2288,B8) -> 4 | F8: =+SUMIFS('Salary sheet'!$AN$6:$AN$1292,'Salary sheet'!$F$6:$F$1292,'TOTAL(payment)'!C8,'Salary sheet'!$E$6:$E$1292,'TOTAL(payment)'!B8) -> 38438407 | G8: =+SUMIFS('Salary sheet'!$AO$6:$AO$2288,'Salary sheet'!$F$6:$F$2288,C8,'Salary sheet'!$E$6:$E$2288,B8) -> 2962470 | H8: =+SUMIFS('Salary sheet'!$AP$6:$AP$2288,'Salary sheet'!$F$6:$F$2288,C8,'Salary sheet'!$E$6:$E$2288,B8) -> 176400 | I8: =+SUMIFS('Salary sheet'!$AQ$6:$AQ$2288,'Salary sheet'!$F$6:$F$2288,C8,'Salary sheet'!$E$6:$E$2288,B8) -> 0 | J8: =+SUMIFS('Salary sheet'!$AR$6:$AR$2288,'Salary sheet'!$F$6:$F$2288,C8,'Salary sheet'!$E$6:$E$2288,B8) -> 0 | K8: =SUMIFS('Salary sheet'!$AS$6:$AS$1291,'Salary sheet'!$F$6:$F$1291,'TOTAL(payment)'!C8) -> 0 | L8: =+(F8)-SUM(G8:K8) -> 35299537 | M8: =+L8/E8 -> 8824884.2
A9: =SUBTOTAL(3,B$7:B9) -> 3 | B9: SK2 | C9: P0 - Design | D9: P0-DS-1-01 | E9: =COUNTIFS('Salary sheet'!$F$6:$F$2288,C9,'Salary sheet'!$E$6:$E$2288,B9) -> 4 | F9: =+SUMIFS('Salary sheet'!$AN$6:$AN$1292,'Salary sheet'!$F$6:$F$1292,'TOTAL(payment)'!C9,'Salary sheet'!$E$6:$E$1292,'TOTAL(payment)'!B9) -> 70351442 | G9: =+SUMIFS('Salary sheet'!$AO$6:$AO$2288,'Salary sheet'!$F$6:$F$2288,C9,'Salary sheet'!$E$6:$E$2288,B9) -> 7350000 | H9: =+SUMIFS('Salary sheet'!$AP$6:$AP$2288,'Salary sheet'!$F$6:$F$2288,C9,'Salary sheet'!$E$6:$E$2288,B9) -> 176400 | I9: =+SUMIFS('Salary sheet'!$AQ$6:$AQ$2288,'Salary sheet'!$F$6:$F$2288,C9,'Salary sheet'!$E$6:$E$2288,B9) -> 364524 | J9: =+SUMIFS('Salary sheet'!$AR$6:$AR$2288,'Salary sheet'!$F$6:$F$2288,C9,'Salary sheet'!$E$6:$E$2288,B9) -> 0 | K9: =SUMIFS('Salary sheet'!$AS$6:$AS$1291,'Salary sheet'!$F$6:$F$1291,'TOTAL(payment)'!C9) -> 0 | L9: =+(F9)-SUM(G9:K9) -> 62460518 | M9: =+L9/E9 -> 15615130
A10: =SUBTOTAL(3,B$7:B10) -> 4 | B10: SK2 | C10: P0 - Development | D10: P0-DE-1-01 | E10: =COUNTIFS('Salary sheet'!$F$6:$F$2288,C10,'Salary sheet'!$E$6:$E$2288,B10) -> 13 | F10: =+SUMIFS('Salary sheet'!$AN$6:$AN$1292,'Salary sheet'!$F$6:$F$1292,'TOTAL(payment)'!C10,'Salary sheet'!$E$6:$E$1292,'TOTAL(payment)'!B10) -> 207934161 | G10: =+SUMIFS('Salary sheet'!$AO$6:$AO$2288,'Salary sheet'!$F$6:$F$2288,C10,'Salary sheet'!$E$6:$E$2288,B10) -> 12238905 | H10: =+SUMIFS('Salary sheet'!$AP$6:$AP$2288,'Salary sheet'!$F$6:$F$2288,C10,'Salary sheet'!$E$6:$E$2288,B10) -> 573300 | I10: =+SUMIFS('Salary sheet'!$AQ$6:$AQ$2288,'Salary sheet'!$F$6:$F$2288,C10,'Salary sheet'!$E$6:$E$2288,B10) -> 428727 | J10: =+SUMIFS('Salary sheet'!$AR$6:$AR$2288,'Salary sheet'!$F$6:$F$2288,C10,'Salary sheet'!$E$6:$E$2288,B10) -> 0 | K10: =SUMIFS('Salary sheet'!$AS$6:$AS$1291,'Salary sheet'!$F$6:$F$1291,'TOTAL(payment)'!C10) -> 0 | L10: =+(F10)-SUM(G10:K10) -> 194693229 | M10: =+L10/E10 -> 14976402
A11: =SUBTOTAL(3,B$7:B11) -> 5 | B11: SK2 | C11: P0 - FG Warehouse | D11: P0-FG-1-01 | E11: =COUNTIFS('Salary sheet'!$F$6:$F$2288,C11,'Salary sheet'!$E$6:$E$2288,B11) -> 3 | F11: =+SUMIFS('Salary sheet'!$AN$6:$AN$1292,'Salary sheet'!$F$6:$F$1292,'TOTAL(payment)'!C11,'Salary sheet'!$E$6:$E$1292,'TOTAL(payment)'!B11) -> 34202056 | G11: =+SUMIFS('Salary sheet'!$AO$6:$AO$2288,'Salary sheet'!$F$6:$F$2288,C11,'Salary sheet'!$E$6:$E$2288,B11) -> 2592345 | H11: =+SUMIFS('Salary sheet'!$AP$6:$AP$2288,'Salary sheet'!$F$6:$F$2288,C11,'Salary sheet'!$E$6:$E$2288,B11) -> 132300 | I11: =+SUMIFS('Salary sheet'!$AQ$6:$AQ$2288,'Salary sheet'!$F$6:$F$2288,C11,'Salary sheet'!$E$6:$E$2288,B11) -> 0 | J11: =+SUMIFS('Salary sheet'!$AR$6:$AR$2288,'Salary sheet'!$F$6:$F$2288,C11,'Salary sheet'!$E$6:$E$2288,B11) -> 0 | K11: =SUMIFS('Salary sheet'!$AS$6:$AS$1291,'Salary sheet'!$F$6:$F$1291,'TOTAL(payment)'!C11) -> 0 | L11: =+(F11)-SUM(G11:K11) -> 31477411 | M11: =+L11/E11 -> 10492470
A12: =SUBTOTAL(3,B$7:B12) -> 6 | B12: SK2 | C12: P0 - GA-HR | D12: P0-HR-1-01 | E12: =COUNTIFS('Salary sheet'!$F$6:$F$2288,C12,'Salary sheet'!$E$6:$E$2288,B12) -> 3 | F12: =+SUMIFS('Salary sheet'!$AN$6:$AN$1292,'Salary sheet'!$F$6:$F$1292,'TOTAL(payment)'!C12,'Salary sheet'!$E$6:$E$1292,'TOTAL(payment)'!B12) -> 36890624 | G12: =+SUMIFS('Salary sheet'!$AO$6:$AO$2288,'Salary sheet'!$F$6:$F$2288,C12,'Salary sheet'!$E$6:$E$2288,B12) -> 3727500 | H12: =+SUMIFS('Salary sheet'!$AP$6:$AP$2288,'Salary sheet'!$F$6:$F$2288,C12,'Salary sheet'!$E$6:$E$2288,B12) -> 132300 | I12: =+SUMIFS('Salary sheet'!$AQ$6:$AQ$2288,'Salary sheet'!$F$6:$F$2288,C12,'Salary sheet'!$E$6:$E$2288,B12) -> 0 | J12: =+SUMIFS('Salary sheet'!$AR$6:$AR$2288,'Salary sheet'!$F$6:$F$2288,C12,'Salary sheet'!$E$6:$E$2288,B12) -> 0 | K12: =SUMIFS('Salary sheet'!$AS$6:$AS$1291,'Salary sheet'!$F$6:$F$1291,'TOTAL(payment)'!C12) -> 0 | L12: =+(F12)-SUM(G12:K12) -> 33030824 | M12: =+L12/E12 -> 11010275
A13: =SUBTOTAL(3,B$7:B13) -> 7 | B13: SK2 | C13: P0 - GC WIP | D13: P0-WP-1-01 | E13: =COUNTIFS('Salary sheet'!$F$6:$F$2288,C13,'Salary sheet'!$E$6:$E$2288,B13) -> 10 | F13: =+SUMIFS('Salary sheet'!$AN$6:$AN$1292,'Salary sheet'!$F$6:$F$1292,'TOTAL(payment)'!C13,'Salary sheet'!$E$6:$E$1292,'TOTAL(payment)'!B13) -> 139072979 | G13: =+SUMIFS('Salary sheet'!$AO$6:$AO$2288,'Salary sheet'!$F$6:$F$2288,C13,'Salary sheet'!$E$6:$E$2288,B13) -> 11025420 | H13: =+SUMIFS('Salary sheet'!$AP$6:$AP$2288,'Salary sheet'!$F$6:$F$2288,C13,'Salary sheet'!$E$6:$E$2288,B13) -> 441000 | I13: =+SUMIFS('Salary sheet'!$AQ$6:$AQ$2288,'Salary sheet'!$F$6:$F$2288,C13,'Salary sheet'!$E$6:$E$2288,B13) -> 170615 | J13: =+SUMIFS('Salary sheet'!$AR$6:$AR$2288,'Salary sheet'!$F$6:$F$2288,C13,'Salary sheet'!$E$6:$E$2288,B13) -> 0 | K13: =SUMIFS('Salary sheet'!$AS$6:$AS$1291,'Salary sheet'!$F$6:$F$1291,'TOTAL(payment)'!C13) -> 0 | L13: =+(F13)-SUM(G13:K13) -> 127435944 | M13: =+L13/E13 -> 12743594
A14: =SUBTOTAL(3,B$7:B14) -> 8 | B14: SK2 | C14: P0 - Maintenance | D14: P0-MA-1-01 | E14: =COUNTIFS('Salary sheet'!$F$6:$F$2288,C14,'Salary sheet'!$E$6:$E$2288,B14) -> 5 | F14: =+SUMIFS('Salary sheet'!$AN$6:$AN$1292,'Salary sheet'!$F$6:$F$1292,'TOTAL(payment)'!C14,'Salary sheet'!$E$6:$E$1292,'TOTAL(payment)'!B14) -> 81855000 | G14: =+SUMIFS('Salary sheet'!$AO$6:$AO$2288,'Salary sheet'!$F$6:$F$2288,C14,'Salary sheet'!$E$6:$E$2288,B14) -> 6744990 | H14: =+SUMIFS('Salary sheet'!$AP$6:$AP$2288,'Salary sheet'!$F$6:$F$2288,C14,'Salary sheet'!$E$6:$E$2288,B14) -> 220500 | I14: =+SUMIFS('Salary sheet'!$AQ$6:$AQ$2288,'Salary sheet'!$F$6:$F$2288,C14,'Salary sheet'!$E$6:$E$2288,B14) -> 132102 | J14: =+SUMIFS('Salary sheet'!$AR$6:$AR$2288,'Salary sheet'!$F$6:$F$2288,C14,'Salary sheet'!$E$6:$E$2288,B14) -> 0 | K14: =SUMIFS('Salary sheet'!$AS$6:$AS$1291,'Salary sheet'!$F$6:$F$1291,'TOTAL(payment)'!C14) -> 0 | L14: =+(F14)-SUM(G14:K14) -> 74757408 | M14: =+L14/E14 -> 14951482
A15: =SUBTOTAL(3,B$7:B15) -> 9 | B15: SK2 | C15: P0 - Marketing | D15: P0-MK-1-01 | E15: =COUNTIFS('Salary sheet'!$F$6:$F$2288,C15,'Salary sheet'!$E$6:$E$2288,B15) -> 9 | F15: =+SUMIFS('Salary sheet'!$AN$6:$AN$1292,'Salary sheet'!$F$6:$F$1292,'TOTAL(payment)'!C15,'Salary sheet'!$E$6:$E$1292,'TOTAL(payment)'!B15) -> 160153125 | G15: =+SUMIFS('Salary sheet'!$AO$6:$AO$2288,'Salary sheet'!$F$6:$F$2288,C15,'Salary sheet'!$E$6:$E$2288,B15) -> 16695000 | H15: =+SUMIFS('Salary sheet'!$AP$6:$AP$2288,'Salary sheet'!$F$6:$F$2288,C15,'Salary sheet'!$E$6:$E$2288,B15) -> 396900 | I15: =+SUMIFS('Salary sheet'!$AQ$6:$AQ$2288,'Salary sheet'!$F$6:$F$2288,C15,'Salary sheet'!$E$6:$E$2288,B15) -> 659735 | J15: =+SUMIFS('Salary sheet'!$AR$6:$AR$2288,'Salary sheet'!$F$6:$F$2288,C15,'Salary sheet'!$E$6:$E$2288,B15) -> 0 | K15: =SUMIFS('Salary sheet'!$AS$6:$AS$1291,'Salary sheet'!$F$6:$F$1291,'TOTAL(payment)'!C15) -> 0 | L15: =+(F15)-SUM(G15:K15) -> 142401490 | M15: =+L15/E15 -> 15822388
A16: =SUBTOTAL(3,B$7:B16) -> 10 | B16: SK2 | C16: P0 - Material Warehouse | D16: P0-MW-1-01 | E16: =COUNTIFS('Salary sheet'!$F$6:$F$2288,C16,'Salary sheet'!$E$6:$E$2288,B16) -> 5 | F16: =+SUMIFS('Salary sheet'!$AN$6:$AN$1292,'Salary sheet'!$F$6:$F$1292,'TOTAL(payment)'!C16,'Salary sheet'!$E$6:$E$1292,'TOTAL(payment)'!B16) -> 56711533 | G16: =+SUMIFS('Salary sheet'!$AO$6:$AO$2288,'Salary sheet'!$F$6:$F$2288,C16,'Salary sheet'!$E$6:$E$2288,B16) -> 4168306 | H16: =+SUMIFS('Salary sheet'!$AP$6:$AP$2288,'Salary sheet'!$F$6:$F$2288,C16,'Salary sheet'!$E$6:$E$2288,B16) -> 132300 | I16: =+SUMIFS('Salary sheet'!$AQ$6:$AQ$2288,'Salary sheet'!$F$6:$F$2288,C16,'Salary sheet'!$E$6:$E$2288,B16) -> 33447 | J16: =+SUMIFS('Salary sheet'!$AR$6:$AR$2288,'Salary sheet'!$F$6:$F$2288,C16,'Salary sheet'!$E$6:$E$2288,B16) -> 0 | K16: =SUMIFS('Salary sheet'!$AS$6:$AS$1291,'Salary sheet'!$F$6:$F$1291,'TOTAL(payment)'!C16) -> 186299 | L16: =+(F16)-SUM(G16:K16) -> 52191181 | M16: =+L16/E16 -> 10438236
A17: =SUBTOTAL(3,B$7:B17) -> 11 | B17: SK2 | C17: P0 - Planning | D17: P0-PL-1-01 | E17: =COUNTIFS('Salary sheet'!$F$6:$F$2288,C17,'Salary sheet'!$E$6:$E$2288,B17) -> 9 | F17: =+SUMIFS('Salary sheet'!$AN$6:$AN$1292,'Salary sheet'!$F$6:$F$1292,'TOTAL(payment)'!C17,'Salary sheet'!$E$6:$E$1292,'TOTAL(payment)'!B17) -> 104930197 | G17: =+SUMIFS('Salary sheet'!$AO$6:$AO$2288,'Salary sheet'!$F$6:$F$2288,C17,'Salary sheet'!$E$6:$E$2288,B17) -> 10774995 | H17: =+SUMIFS('Salary sheet'!$AP$6:$AP$2288,'Salary sheet'!$F$6:$F$2288,C17,'Salary sheet'!$E$6:$E$2288,B17) -> 352800 | I17: =+SUMIFS('Salary sheet'!$AQ$6:$AQ$2288,'Salary sheet'!$F$6:$F$2288,C17,'Salary sheet'!$E$6:$E$2288,B17) -> 113181 | J17: =+SUMIFS('Salary sheet'!$AR$6:$AR$2288,'Salary sheet'!$F$6:$F$2288,C17,'Salary sheet'!$E$6:$E$2288,B17) -> 0 | K17: =SUMIFS('Salary sheet'!$AS$6:$AS$1291,'Salary sheet'!$F$6:$F$1291,'TOTAL(payment)'!C17) -> 0 | L17: =+(F17)-SUM(G17:K17) -> 93689221 | M17: =+L17/E17 -> 10409913
A18: =SUBTOTAL(3,B$7:B18) -> 12 | B18: SK2 | C18: P0 - Production Office | D18: P0-PO-1-01 | E18: =COUNTIFS('Salary sheet'!$F$6:$F$2288,C18,'Salary sheet'!$E$6:$E$2288,B18) -> 1 | F18: =+SUMIFS('Salary sheet'!$AN$6:$AN$1292,'Salary sheet'!$F$6:$F$1292,'TOTAL(payment)'!C18,'Salary sheet'!$E$6:$E$1292,'TOTAL(payment)'!B18) -> 38500000 | G18: =+SUMIFS('Salary sheet'!$AO$6:$AO$2288,'Salary sheet'!$F$6:$F$2288,C18,'Salary sheet'!$E$6:$E$2288,B18) -> 3969000 | H18: =+SUMIFS('Salary sheet'!$AP$6:$AP$2288,'Salary sheet'!$F$6:$F$2288,C18,'Salary sheet'!$E$6:$E$2288,B18) -> 44100 | I18: =+SUMIFS('Salary sheet'!$AQ$6:$AQ$2288,'Salary sheet'!$F$6:$F$2288,C18,'Salary sheet'!$E$6:$E$2288,B18) -> 283100 | J18: =+SUMIFS('Salary sheet'!$AR$6:$AR$2288,'Salary sheet'!$F$6:$F$2288,C18,'Salary sheet'!$E$6:$E$2288,B18) -> 0 | K18: =SUMIFS('Salary sheet'!$AS$6:$AS$1291,'Salary sheet'!$F$6:$F$1291,'TOTAL(payment)'!C18) -> 0 | L18: =+(F18)-SUM(G18:K18) -> 34203800 | M18: =+L18/E18 -> 34203800
A19: =SUBTOTAL(3,B$7:B19) -> 13 | B19: SK2 | C19: P0 - Purchasing | D19: P0-PU-1-01 | E19: =COUNTIFS('Salary sheet'!$F$6:$F$2288,C19,'Salary sheet'!$E$6:$E$2288,B19) -> 1 | F19: =+SUMIFS('Salary sheet'!$AN$6:$AN$1292,'Salary sheet'!$F$6:$F$1292,'TOTAL(payment)'!C19,'Salary sheet'!$E$6:$E$1292,'TOTAL(payment)'!B19) -> 9706348 | G19: =+SUMIFS('Salary sheet'!$AO$6:$AO$2288,'Salary sheet'!$F$6:$F$2288,C19,'Salary sheet'!$E$6:$E$2288,B19) -> 1012620 | H19: =+SUMIFS('Salary sheet'!$AP$6:$AP$2288,'Salary sheet'!$F$6:$F$2288,C19,'Salary sheet'!$E$6:$E$2288,B19) -> 44100 | I19: =+SUMIFS('Salary sheet'!$AQ$6:$AQ$2288,'Salary sheet'!$F$6:$F$2288,C19,'Salary sheet'!$E$6:$E$2288,B19) -> 0 | J19: =+SUMIFS('Salary sheet'!$AR$6:$AR$2288,'Salary sheet'!$F$6:$F$2288,C19,'Salary sheet'!$E$6:$E$2288,B19) -> 0 | K19: =SUMIFS('Salary sheet'!$AS$6:$AS$1291,'Salary sheet'!$F$6:$F$1291,'TOTAL(payment)'!C19) -> 0 | L19: =+(F19)-SUM(G19:K19) -> 8649628 | M19: =+L19/E19 -> 8649628
... A118: =SUBTOTAL(3,B$7:B118) -> 112 | B118: FACTORY A | C118: P8 - Slitter | D118: P8-CU-1-01 | E118: =COUNTIFS('Salary sheet'!$F$6:$F$2288,C118,'Salary sheet'!$E$6:$E$2288,B118) -> 1 | F118: =+SUMIFS('Salary sheet'!$AN$6:$AN$1292,'Salary sheet'!$F$6:$F$1292,'TOTAL(payment)'!C118,'Salary sheet'!$E$6:$E$1292,'TOTAL(payment)'!B118) -> 8278438 | G118: =+SUMIFS('Salary sheet'!$AO$6:$AO$2288,'Salary sheet'!$F$6:$F$2288,C118,'Salary sheet'!$E$6:$E$2288,B118) -> 627270 | H118: =+SUMIFS('Salary sheet'!$AP$6:$AP$2288,'Salary sheet'!$F$6:$F$2288,C118,'Salary sheet'!$E$6:$E$2288,B118) -> 44100 | I118: =+SUMIFS('Salary sheet'!$AQ$6:$AQ$2288,'Salary sheet'!$F$6:$F$2288,C118,'Salary sheet'!$E$6:$E$2288,B118) -> 0 | J118: =+SUMIFS('Salary sheet'!$AR$6:$AR$2288,'Salary sheet'!$F$6:$F$2288,C118,'Salary sheet'!$E$6:$E$2288,B118) -> 0 | K118: =SUMIFS('Salary sheet'!$AS$6:$AS$1291,'Salary sheet'!$F$6:$F$1291,'TOTAL(payment)'!C118) -> 0 | L118: =+(F118)-SUM(G118:K118) -> 7607068 | M118: =+L118/E118 -> 7607068
A119: x | E119: =SUM(E7:E118) -> 1289 | F119: =SUM(F7:F118) -> 14329763701 | G119: =SUM(G7:G118) -> 998000257 | H119: =SUM(H7:H118) -> 52434900 | I119: =SUM(I7:I118) -> 208839267 | J119: =SUM(J7:J118) -> 568500 | K119: =SUM(K7:K118) -> 3199861 | L119: =SUM(L7:L118) -> 13066720916 | M119: =SUM(M7:M112) -> 1.3132829e+09 | N119: =+L119-(L7+'Salary sheet'!AT1292) -> 0
E120: =+E119-E7 -> 1286 | F120: =+F119-F7 -> 13642799084 | G120: =+G119-G7 -> 984662257 | H120: =+H119-H7 -> 52434900 | I120: =+I119-I7 -> 15709951 | J120: =+J119-J7 -> 568500 | K120: =+K119-K7 -> 3199861 | L120: =+L119-L7 -> 12586223615 | M120: =+M119-M7 -> 1.1531171e+09
E121: =+E119-E7-E120 -> 0 | F121: =+F119-F7-F120 -> 0 | G121: =+G119-G7-G120 -> 0 | H121: =+H119-H7-H120 -> 0 | I121: =+I119-I7-I120 -> 0 | J121: =+J119-J7-J120 -> 0 | K121: =+K119-K7-K120 -> 0 | L121: =+L119-L7-L120 -> 0
K123: Bình Phước, Ngày 30 tháng 04 năm 2025
B124: Người lập / Prepare by | G124: Kiểm tra/ Checked by | K124: Giám Đốc /Director
B132: Đỗ Thị Vân | G132: Nguyễn Thị Hà | K132: Kim Dong Woo

Sheet Foreign Salary
A1: Công ty TNHH Bao Bì Cao Cấp S&K Vina | H1: 26
A2: Lô B1 -B4 KCn Minh Hưng - Hàn Quốc | V2: SK1 Box | W2: =ROUND(R8/2,0)+ROUND(R9/2,0) -> 181751969
A3: H. Chơn Thành - Bình Phước | V3: SK1 Bag | W3: =+(R9+R8)-W2 -> 181751968
V4: SK2 | W4: =+R10 -> 116993364
A5: BẢNG LƯƠNG THÁNG 04 NĂM 2025 PAY-SHEET OF SALARY APR 2025 | W5: =+W4+W2+W3 -> 480497301
A6: Exchange Rate : 26,115 VND/USD | L6: 26115
A7: Stt No. | B7: Họ và tên Name | C7: Tên người thụ hưởng Beneficiary Name | D7: English name | E7: Fac | F7: Lương cơ bản Basic Salary (USD) | G7: Lương cơ bản Basic Salary (VND) | H7: Ngày công thực tế Actual Workday | I7: Lương cơ bản Basic Salary (USD) | J7: Month | K7: 13Th month bonus | L7: Lương CB Gross Salary VND | M7: BHXH,YT (9.5%) Insurance | N7: Nha o | O7: TNTT | P7: Thuế TNCN Personal income Tax | Q7: Advance | R7: Tiền thực lãnh Net salary VND | S7: Tiền thực lãnh Net salary USD (Paid) | T7: Contract salary | U7: Note
A8: 1 | B8: KIM DONG WOO | C8: KIM DONG WOO | D8: Mr DW | E8: FACTORY O | F8: 10300 | G8: =+F8*$L$6 -> 268984500 | H8: 26 | I8: =+F8/$H$1*H8 -> 10300 | L8: =ROUND((((K8+I8)*$L$6)),0) -> 268984500 | M8: =2340000*20*9.5% -> 4446000 | O8: =L8+N8-M8-11000000 -> 253538500 | P8: =ROUND(35%*O8-9850000,0) -> 78888475 | R8: =ROUND(L8-P8-M8-Q8,0) -> 185650025 | S8: =ROUND(R8/$L$6,2) -> 7108.94 | U8: SK1 Bag/Box
A9: 2 | B9: KIM JE MIN | C9: KIM JE MIN | D9: Mr JM | E9: FACTORY O | F9: 9750 | G9: =+F9*$L$6 -> 254621250 | H9: 26 | I9: =+F9/$H$1*H9 -> 9750 | L9: =ROUND((((K9+I9)*$L$6)),0) -> 254621250 | M9: =2340000*20*9.5% -> 4446000 | O9: =L9+N9-M9-11000000-4400000 -> 234775250 | P9: =ROUND(35%*O9-9850000,0) -> 72321338 | R9: =ROUND(L9-P9-M9-Q9,0) -> 177853912 | S9: =ROUND(R9/$L$6,2) -> 6810.41 | U9: SK1 Bag/Box | V9: ĐK 1 Người phụ thuộc từ tháng 10/2024
A10: 3 | B10: YUE FAMENG | C10: YUE FAMENG | D10: Mr Happy | E10: FACTORY H | F10: 6505.58 | G10: =+F10*$L$6 -> 1.6989322e+08 | H10: 25 | I10: =+F10/$H$1*H10 -> 6255.3654 | L10: =ROUND((((K10+I10)*$L$6)),0) -> 163358867 | M10: =2340000*20*9.5% -> 4446000 | O10: =L10+N10-M10-11000000 -> 147912867 | P10: =ROUND(35%*O10-9850000,0) -> 41919503 | R10: =ROUND(L10-P10-M10-Q10,0) -> 116993364 | S10: =ROUND(R10/$L$6,2) -> 4479.93 | U10: SK2
A11: TOTAL | F11: =SUM(F8:F10) -> 26555.58 | G11: =SUM(G8:G10) -> 6.9349897e+08 | H11: =SUM(H8:H10) -> 77 | I11: =SUM(I8:I10) -> 26305.365 | J11: =SUM(J8:J10) -> 0 | K11: =SUM(K8:K10) -> 0 | L11: =SUM(L8:L10) -> 686964617 | M11: =SUM(M8:M10) -> 13338000 | ... S11: =SUM(S8:S10) -> 18399.28
P14: =+'TOTAL(payment)'!K123 -> Bình Phước, Ngày 30 tháng 04 năm 2025
B15: Người lập / Prepare by | H15: Kiểm tra/ Checked by | P15: Giám Đốc /Director
B23: Đỗ Thị Vân | H23: Nguyễn Thị Hà | P23: Kim Dong Woo

Sheet Salary sheet
M2: 26
A3: REPORT - BẢNG LƯƠNG THÁNG 04 NĂM 2025 PAY - SHEET OF APR 2025
A4: TT No. | B4: Mã thẻ Code | C4: Họ và tên Name | D4: Ngày vào Entry day | F4: Bộ phận Dep | G4: Title/ Chức danh | H4: Lương hợp đồng Contract salary | M4: Ngày làm việc thực tế Actual Working day | O4: Nghỉ có hưởng lương Paid leave | Q4: Ca đêm extra pay for night work + 30%) | S4: Lương, thưởng và các khoản hỗ trợ Salary, bonus, support fee | AG4: Cộng Total | AH4: Tăng ca Overtime | AN4: Tổng thu nhập Total Gross Salary | AO4: Khấu trừ Reduction | AT4: Tiền thực lãnh Net Salary | AU4: Ký nhận Signature | AW4: Tên TK | AX4: Số TK
E5: Fac | H5: Cơ bản Basic salary | I5: Trách nhiệm Responsibility | J5: Phụ cấp NNĐH Hazadouse allowance (>=5% of basic salary) | K5: Phụ cấp chức danh/Title Allowance | L5: Cộng Total | M5: Ngày công Day | N5: Lương CB + trách nhiệm Basic Salary + Responsibility | O5: Ngày công Day | P5: Lương CB + trách nhiệm Basic Salary + Responsibility | Q5: Giờ công Hour | R5: Lương CB + trách nhiệm Basic Salary + Responsibility | S5: Lương CB + trách nhiệm Basic salary + Responsibility | T5: Điện thoại, Telephone fee | U5: Tiền cơm Meal Allowance | V5: Hỗ trợ xăng + nhà trọ, Mileage, house | W5: Thưởng chuyên cần Diligent Bonus | X5: Phụ cấp PCCC PCCC / ATVSV allowance (30% of government basic salary and safety - hygency team) | Y5: Thưởng ABC ABC Bonus | Z5: Thưởng năng suất Production bonus | AA5: Ngày phép | AB5: Phép năm Annual Leave | AC5: Con nhỏ Support for baby (1-6) | AD5: Bảo hiểm, thất nghiệp Additional salary , insurance, Unempl-oyment Benefit, Bù Lương, Công Tác phí | AE5: Phụ cấp Phụ Nữ Menstruation allowance | AF5: 13Th Month Bonus | AH5: 1.5 | AI5: 2 | AJ5: 2.1 | AK5: 2.7 | AL5: 3 | AM5: Tổng tiền Amount | AO5: BHXH +YT, +TN Insurance | AP5: KPCĐ Union Dues | AQ5: Personal Income Tax Thuế TNCN | AR5: Đồng phục Uniform | AS5: Advance Chênh lệch HĐ/ Biên bản Paid | AY5: =+IF(B5="SK2","SK2",IF(B5="FACTORY A","SK1 Box",IF(B5="FACTORY D","SK1 Bag","Chia"))) -> Chia | BA5: =+IF(AY5="SK1 Box","Box",IF(AY5="Seaman","Seaman","Bag")) -> Bag
A6: =SUBTOTAL(3,B$6:B6) -> 1 | B6: C0873 | C6: Trần Thị Kim Phấn | D6: 39707 | E6: FACTORY A | F6: P6 - C.Box Assembly | G6: Box Positioning worker | H6: 5931000 | I6: 200000 | J6: 0 | K6: 0 | L6: =SUM(H6:K6) -> 6131000 | M6: 24 | N6: =ROUND((H6+I6+J6+K6)/IF($M$2>26,26,$M$2)*M6,0) -> 5659385 | O6: 2 | P6: =ROUND((H6+I6+J6+K6)/IF($M$2>26,26,$M$2)*O6,0) -> 471615 | Q6: 0 | R6: =IF(M6>0,ROUND(N6/IF(M6>26,26,M6)/8*Q6*30%,0),0) -> 0 | S6: =N6+P6+R6 -> 6131000 | T6: 0 | U6: 0 | V6: 200000 | W6: 500000 | X6: 0 | Y6: 0 | Z6: 188548 | AC6: 0 | AD6: 0 | AE6: 44213.945 | AG6: =ROUND(SUM(S6:AF6)-AA6,0) -> 7063762 | AH6: 48 | AI6: 0 | AJ6: 0 | AK6: 0 | AL6: 0 | AM6: =ROUND((N6/IF(M6>26,26,M6)/8*(AH6*$AH$5+AI6*$AI$5+AJ6*$AJ$5+AK6*$AK$5+AL6*$AL$5)),0) -> 2122269 | AN6: =ROUND(AG6+AM6,0) -> 9186031 | AO6: 643755 | AP6: 44100 | AQ6: 0 | AR6: 0 | AS6: 0 | AT6: =+ROUND(SUM(AN6:AN6)-SUM(AO6:AS6),0) -> 8498176 | AW6: TRAN THI KIM PHAN | AX6: 050040964964 | AY6: SK1 Box | AZ6: 622 | BA6: =+IF(AY6="SK1 Box","Box",IF(AY6="Seaman","Seaman","Bag")) -> Box
A7: =SUBTOTAL(3,B$6:B7) -> 2 | B7: C1007 | C7: Nguyễn Thị Hướng | D7: 39707 | E7: FACTORY A | F7: P6 - C.Box Assembly | G7: Box Positioning worker | H7: 5931000 | I7: 200000 | J7: 0 | K7: 300000 | L7: =SUM(H7:K7) -> 6431000 | M7: 23.8 | N7: =ROUND((H7+I7+J7+K7)/IF($M$2>26,26,$M$2)*M7,0) -> 5886838 | O7: 2 | P7: =ROUND((H7+I7+J7+K7)/IF($M$2>26,26,$M$2)*O7,0) -> 494692 | Q7: 0 | R7: =IF(M7>0,ROUND(N7/IF(M7>26,26,M7)/8*Q7*30%,0),0) -> 0 | S7: =N7+P7+R7 -> 6381530 | T7: 0 | U7: 0 | V7: 200000 | W7: 500000 | X7: 0 | Y7: 400000 | Z7: 603480 | AC7: 0 | AD7: 0 | AE7: 46377.4 | AG7: =ROUND(SUM(S7:AF7)-AA7,0) -> 8131387 | AH7: 52 | AI7: 0 | AJ7: 0 | AK7: 0 | AL7: 0 | AM7: =ROUND((N7/IF(M7>26,26,M7)/8*(AH7*$AH$5+AI7*$AI$5+AJ7*$AJ$5+AK7*$AK$5+AL7*$AL$5)),0) -> 2411625 | AN7: =ROUND(AG7+AM7,0) -> 10543012 | AO7: 675255 | AP7: 44100 | AQ7: 0 | AR7: 0 | AS7: 0 | AT7: =+ROUND(SUM(AN7:AN7)-SUM(AO7:AS7),0) -> 9823657 | AW7: NGUYEN THI HUONG | AX7: 050040850950 | AY7: SK1 Box | AZ7: 622 | BA7: =+IF(AY7="SK1 Box","Box",IF(AY7="Seaman","Seaman","Bag")) -> Box
A8: =SUBTOTAL(3,B$6:B8) -> 3 | B8: C1009 | C8: Hồ Thị Nga | D8: 39707 | E8: FACTORY A | F8: P6 - C.Box Assembly | G8: Box Positioning worker | H8: 5931000 | I8: 200000 | J8: 0 | K8: 0 | L8: =SUM(H8:K8) -> 6131000 | M8: 24 | N8: =ROUND((H8+I8+J8+K8)/IF($M$2>26,26,$M$2)*M8,0) -> 5659385 | O8: 2 | P8: =ROUND((H8+I8+J8+K8)/IF($M$2>26,26,$M$2)*O8,0) -> 471615 | Q8: 0 | R8: =IF(M8>0,ROUND(N8/IF(M8>26,26,M8)/8*Q8*30%,0),0) -> 0 | S8: =N8+P8+R8 -> 6131000 | T8: 0 | U8: 0 | V8: 200000 | W8: 500000 | X8: 0 | Y8: 400000 | Z8: 600597 | AC8: 0 | AD8: 0 | AE8: 44213.945 | AG8: =ROUND(SUM(S8:AF8)-AA8,0) -> 7875811 | AH8: 52 | AI8: 0 | AJ8: 0 | AK8: 0 | AL8: 0 | AM8: =ROUND((N8/IF(M8>26,26,M8)/8*(AH8*$AH$5+AI8*$AI$5+AJ8*$AJ$5+AK8*$AK$5+AL8*$AL$5)),0) -> 2299125 | AN8: =ROUND(AG8+AM8,0) -> 10174936 | AO8: 643755 | AP8: 44100 | AQ8: 0 | AR8: 0 | AS8: 0 | AT8: =+ROUND(SUM(AN8:AN8)-SUM(AO8:AS8),0) -> 9487081 | AW8: HO THI NGA | AX8: 050040952974 | AY8: SK1 Box | AZ8: 622 | BA8: =+IF(AY8="SK1 Box","Box",IF(AY8="Seaman","Seaman","Bag")) -> Box
A9: =SUBTOTAL(3,B$6:B9) -> 4 | B9: C10454 | C9: Trần Thị Liên | D9: 43556 | E9: FACTORY A | F9: P6 - C.Box Assembly | G9: Box Positioning worker | H9: 5931000 | I9: 200000 | J9: 0 | K9: 0 | L9: =SUM(H9:K9) -> 6131000 | M9: 24 | N9: =ROUND((H9+I9+J9+K9)/IF($M$2>26,26,$M$2)*M9,0) -> 5659385 | O9: 2 | P9: =ROUND((H9+I9+J9+K9)/IF($M$2>26,26,$M$2)*O9,0) -> 471615 | Q9: 0 | R9: =IF(M9>0,ROUND(N9/IF(M9>26,26,M9)/8*Q9*30%,0),0) -> 0 | S9: =N9+P9+R9 -> 6131000 | T9: 0 | U9: 0 | V9: 200000 | W9: 500000 | X9: 0 | Y9: 400000 | Z9: 606304 | AC9: 0 | AD9: 0 | AE9: 44213.945 | AG9: =ROUND(SUM(S9:AF9)-AA9,0) -> 7881518 | AH9: 48 | AI9: 0 | AJ9: 0 | AK9: 0 | AL9: 0 | AM9: =ROUND((N9/IF(M9>26,26,M9)/8*(AH9*$AH$5+AI9*$AI$5+AJ9*$AJ$5+AK9*$AK$5+AL9*$AL$5)),0) -> 2122269 | AN9: =ROUND(AG9+AM9,0) -> 10003787 | AO9: 643755 | AP9: 44100 | AQ9: 0 | AR9: 0 | AS9: 0 | AT9: =+ROUND(SUM(AN9:AN9)-SUM(AO9:AS9),0) -> 9315932 | AW9: TRAN THI LIEN | AX9: 050104743444 | AY9: SK1 Box | AZ9: 622 | BA9: =+IF(AY9="SK1 Box","Box",IF(AY9="Seaman","Seaman","Bag")) -> Box
A10: =SUBTOTAL(3,B$6:B10) -> 5 | B10: C10664 | C10: Nguyễn Hoài Hận | D10: 43595 | E10: FACTORY A | F10: P6 - C.Box Assembly | G10: Box Positioning worker | H10: 5931000 | I10: 200000 | J10: 0 | K10: 0 | L10: =SUM(H10:K10) -> 6131000 | M10: 23.7 | N10: =ROUND((H10+I10+J10+K10)/IF($M$2>26,26,$M$2)*M10,0) -> 5588642 | O10: 2 | P10: =ROUND((H10+I10+J10+K10)/IF($M$2>26,26,$M$2)*O10,0) -> 471615 | Q10: 0 | R10: =IF(M10>0,ROUND(N10/IF(M10>26,26,M10)/8*Q10*30%,0),0) -> 0 | S10: =N10+P10+R10 -> 6060257 | T10: 0 | U10: 0 | V10: 200000 | W10: 500000 | X10: 0 | Y10: 400000 | Z10: 603480 | AC10: 0 | AD10: 0 | AE10: 0 | AG10: =ROUND(SUM(S10:AF10)-AA10,0) -> 7763737 | AH10: 52 | AI10: 0 | AJ10: 0 | AK10: 0 | AL10: 0 | AM10: =ROUND((N10/IF(M10>26,26,M10)/8*(AH10*$AH$5+AI10*$AI$5+AJ10*$AJ$5+AK10*$AK$5+AL10*$AL$5)),0) -> 2299125 | AN10: =ROUND(AG10+AM10,0) -> 10062862 | AO10: 643755 | AP10: 44100 | AQ10: 0 | AR10: 0 | AS10: 0 | AT10: =+ROUND(SUM(AN10:AN10)-SUM(AO10:AS10),0) -> 9375007 | AW10: NGUYEN HOAI HAN | AX10: 050073573855 | AY10: SK1 Box | AZ10: 622 | BA10: =+IF(AY10="SK1 Box","Box",IF(AY10="Seaman","Seaman","Bag")) -> Box
A11: =SUBTOTAL(3,B$6:B11) -> 6 | B11: C10665 | C11: Lê Thị Kiều Loan | D11: 43595 | E11: FACTORY A | F11: P6 - C.Box Assembly | G11: Normal worker | H11: 5931000 | I11: 0 | J11: 0 | K11: 0 | L11: =SUM(H11:K11) -> 5931000 | M11: 24 | N11: =ROUND((H11+I11+J11+K11)/IF($M$2>26,26,$M$2)*M11,0) -> 5474769 | O11: 2 | P11: =ROUND((H11+I11+J11+K11)/IF($M$2>26,26,$M$2)*O11,0) -> 456231 | Q11: 0 | R11: =IF(M11>0,ROUND(N11/IF(M11>26,26,M11)/8*Q11*30%,0),0) -> 0 | S11: =N11+P11+R11 -> 5931000 | T11: 0 | U11: 0 | V11: 200000 | W11: 500000 | X11: 0 | Y11: 300000 | Z11: 606304 | AC11: 0 | AD11: 0 | AE11: 42771.633 | AG11: =ROUND(SUM(S11:AF11)-AA11,0) -> 7580076 | AH11: 40 | AI11: 0 | AJ11: 0 | AK11: 0 | AL11: 0 | AM11: =ROUND((N11/IF(M11>26,26,M11)/8*(AH11*$AH$5+AI11*$AI$5+AJ11*$AJ$5+AK11*$AK$5+AL11*$AL$5)),0) -> 1710865 | AN11: =ROUND(AG11+AM11,0) -> 9290941 | AO11: 622755 | AP11: 44100 | AQ11: 0 | AR11: 0 | AS11: 0 | AT11: =+ROUND(SUM(AN11:AN11)-SUM(AO11:AS11),0) -> 8624086 | AW11: LE THI KIEU LOAN | AX11: 050106514035 | AY11: SK1 Box | AZ11: 622 | BA11: =+IF(AY11="SK1 Box","Box",IF(AY11="Seaman","Seaman","Bag")) -> Box
