Workbook

Sheet Sheet1
D2: Inside | E2: Outside | F2: Total
B3: 1 | C3: Payment Transfer - Foreign | D3: =+'Foreign Salary'!R11 -> 480497301 | E3: 0 | F3: =SUM(D3:E3) -> 480497301 | G3: =+F3-'Foreign Salary'!R11 -> 0
B4: 2 | C4: Payment Transfer | D4: 10547466313 | E4: 1126799307 | F4: =SUM(D4:E4) -> 11674265620 | G4: =+F4-Transfer!E1279 -> 269595426
B5: 3 | C5: Payment Cash | D5: 215764202 | E5: 21316040 | F5: =SUM(D5:E5) -> 237080242 | G5: =+F5-Cash!F18 -> 197683519
B6: 4 | C6: Payment cash - Ms Quyên Nurse Staff | D6: 0 | E6: 11464288 | F6: =SUM(D6:E6) -> 11464288
C7: Total | D7: =SUM(D3:D6) -> 11243727816 | E7: =SUM(E3:E6) -> 1159579635 | F7: =SUM(F3:F6) -> 12403307451
F8: =+F7-'TOTAL(payment)'!L119 -> 478743233

Sheet Manager
A1: STT | B1: Code | C1: Name | D1: Tổng thu nhập Total Gross Salary | E1: Phụ cấp Phụ Nữ Menstruation allowance | F1: Tiền thực lãnh Net Salary | G1: Bộ phận Dep | H1: Title/ Chức danh
A2: 1 | B2: C3402 | C2: Đoàn Thị Hiếu Loan | D2: =+VLOOKUP(B2,'Salary sheet'!$B$6:$AS$1291,40,0) -> 2562000 | E2: =VLOOKUP(B2,'Salary sheet'!$B$6:$AE$1318,30,0) -> 175961.54 | F2: =+D2-E2 -> 2386038.5 | G2: =VLOOKUP(B2,'Salary sheet'!$B$3:$G$1318,5,0) -> P6 - Production Office | H2: =VLOOKUP(B2,'Salary sheet'!$B$3:$G$1318,6,0) -> Factory manager
A3: 2 | B3: C5841 | C3: Trần Văn Nhân | D3: =+VLOOKUP(B3,'Salary sheet'!$B$6:$AS$1291,40,0) -> 2566200 | E3: =VLOOKUP(B3,'Salary sheet'!$B$6:$AE$1318,30,0) -> 0 | F3: =+D3-E3 -> 2566200 | G3: =VLOOKUP(B3,'Salary sheet'!$B$3:$G$1318,5,0) -> P6 - Production Office | H3: =VLOOKUP(B3,'Salary sheet'!$B$3:$G$1318,6,0) -> Factory manager
A4: 3 | B4: C3465 | C4: Lê Văn Khỏe | D4: =+VLOOKUP(B4,'Salary sheet'!$B$6:$AS$1291,40,0) -> 1944495 | E4: =VLOOKUP(B4,'Salary sheet'!$B$6:$AE$1318,30,0) -> 0 | F4: =+D4-E4 -> 1944495 | G4: =VLOOKUP(B4,'Salary sheet'!$B$3:$G$1318,5,0) -> P5 - Production Office | H4: =VLOOKUP(B4,'Salary sheet'!$B$3:$G$1318,6,0) -> Factory vice manager
A5: 4 | B5: C6068 | C5: Trần Thị Cẩm Linh | D5: =+VLOOKUP(B5,'Salary sheet'!$B$6:$AS$1291,40,0) -> 3034500 | E5: =VLOOKUP(B5,'Salary sheet'!$B$6:$AE$1318,30,0) -> 208413.46 | F5: =+D5-E5 -> 2826086.5 | G5: =VLOOKUP(B5,'Salary sheet'!$B$3:$G$1318,5,0) -> P4 - Production Office | H5: =VLOOKUP(B5,'Salary sheet'!$B$3:$G$1318,6,0) -> Factory manager
A6: 5 | B6: C6347 | C6: Đỗ Thị Thanh Tú | D6: =+VLOOKUP(B6,'Salary sheet'!$B$6:$AS$1291,40,0) -> 3066000 | E6: =VLOOKUP(B6,'Salary sheet'!$B$6:$AE$1318,30,0) -> 210576.93 | F6: =+D6-E6 -> 2855423.1 | G6: =VLOOKUP(B6,'Salary sheet'!$B$3:$G$1318,5,0) -> P0 - Design | H6: =VLOOKUP(B6,'Salary sheet'!$B$3:$G$1318,6,0) -> Design manager
A7: 6 | B7: C6407 | C7: Điểu Dũng | D7: =+VLOOKUP(B7,'Salary sheet'!$B$6:$AS$1291,40,0) -> 2551500 | E7: =VLOOKUP(B7,'Salary sheet'!$B$6:$AE$1318,30,0) -> 0 | F7: =+D7-E7 -> 2551500 | G7: =VLOOKUP(B7,'Salary sheet'!$B$3:$G$1318,5,0) -> P0 - Development | H7: =VLOOKUP(B7,'Salary sheet'!$B$3:$G$1318,6,0) -> Development manager
A8: 7 | B8: V004 | C8: Hồ Mạnh Hoàng | D8: =+VLOOKUP(B8,'Salary sheet'!$B$6:$AS$1291,40,0) -> 1850520 | E8: =VLOOKUP(B8,'Salary sheet'!$B$6:$AE$1318,30,0) -> 0 | F8: =+D8-E8 -> 1850520 | G8: =VLOOKUP(B8,'Salary sheet'!$B$3:$G$1318,5,0) -> P0 - Maintenance | H8: =VLOOKUP(B8,'Salary sheet'!$B$3:$G$1318,6,0) -> Maintenance Leader
A9: 8 | B9: C5097 | C9: Kiều Quốc Minh | D9: =+VLOOKUP(B9,'Salary sheet'!$B$6:$AS$1291,40,0) -> 3227700 | E9: =VLOOKUP(B9,'Salary sheet'!$B$6:$AE$1318,30,0) -> 0 | F9: =+D9-E9 -> 3227700 | G9: =VLOOKUP(B9,'Salary sheet'!$B$3:$G$1318,5,0) -> P0 - GC WIP | H9: =VLOOKUP(B9,'Salary sheet'!$B$3:$G$1318,6,0) -> GC WIP Manager
A10: 9 | B10: C5107 | C10: Roãn Văn Hòa | D10: =+VLOOKUP(B10,'Salary sheet'!$B$6:$AS$1291,40,0) -> 3969000 | E10: =VLOOKUP(B10,'Salary sheet'!$B$6:$AE$1318,30,0) -> 0 | F10: =+D10-E10 -> 3969000 | G10: =VLOOKUP(B10,'Salary sheet'!$B$3:$G$1318,5,0) -> P0 - Production Office | H10: =VLOOKUP(B10,'Salary sheet'!$B$3:$G$1318,6,0) -> Production Manager
A11: 10 | B11: C6332 | C11: Đỗ Văn Thái | D11: =+VLOOKUP(B11,'Salary sheet'!$B$6:$AS$1291,40,0) -> 3097500 | E11: =VLOOKUP(B11,'Salary sheet'!$B$6:$AE$1318,30,0) -> 0 | F11: =+D11-E11 -> 3097500 | G11: =VLOOKUP(B11,'Salary sheet'!$B$3:$G$1318,5,0) -> P1 - Production Office | H11: =VLOOKUP(B11,'Salary sheet'!$B$3:$G$1318,6,0) -> Factory manager
A12: 11 | B12: C0020 | C12: Phan Tuấn Khanh | D12: =+VLOOKUP(B12,'Salary sheet'!$B$6:$AS$1291,40,0) -> 3070200 | E12: =VLOOKUP(B12,'Salary sheet'!$B$6:$AE$1318,30,0) -> 0 | F12: =+D12-E12 -> 3070200 | G12: =VLOOKUP(B12,'Salary sheet'!$B$3:$G$1318,5,0) -> P2 - Production Office | H12: =VLOOKUP(B12,'Salary sheet'!$B$3:$G$1318,6,0) -> Factory manager
A13: 12 | B13: V054 | C13: Huỳnh Ngọc Thảo | D13: =+VLOOKUP(B13,'Salary sheet'!$B$6:$AS$1291,40,0) -> 3301200 | E13: =VLOOKUP(B13,'Salary sheet'!$B$6:$AE$1318,30,0) -> 226730.77 | F13: =+D13-E13 -> 3074469.2 | G13: =VLOOKUP(B13,'Salary sheet'!$B$3:$G$1318,5,0) -> P3 - Production Office | H13: =VLOOKUP(B13,'Salary sheet'!$B$3:$G$1318,6,0) -> Factory manager
... A17: 16 | B17: C14623 | C17: Trần Văn Hoài | D17: =+VLOOKUP(B17,'Salary sheet'!$B$6:$AS$1291,40,0) -> 3811500 | E17: =VLOOKUP(B17,'Salary sheet'!$B$6:$AE$1318,30,0) -> 0 | F17: =+D17-E17 -> 3811500 | G17: =VLOOKUP(B17,'Salary sheet'!$B$3:$G$1318,5,0) -> P5 - Production Office | H17: =VLOOKUP(B17,'Salary sheet'!$B$3:$G$1318,6,0) -> Factory manager
C18: Total | D18: =SUM(D2:D17) -> #N/A | E18: =SUM(E2:E17) -> #N/A | F18: =SUM(F2:F17) -> #N/A | G18: =SUM(G2:G17) -> #N/A | H18: =SUM(H2:H17) -> #N/A

Sheet SS
B1: Content | C1: Jun-May | D1: % | E1: Noted
B2: Working day | C2: 4186.2 | D2: 0.11849927 | E2: Working: Jun.2020: 26 days - May.2020: 24 days
B3: Paid leave | C3: -2887 | D3: -0.86076327 | E3: After Corona epidemic situationm,After Transportation of machinery SK1: Box - SK2: Bag - Normal working
B4: Night work + 30% | C4: 3478.5 | D4: 1.9775441 | E4: After Corona epidemic situation - Normal overtime
B5: Overtime 150% | C5: 41402.5 | D5: 9.3123032 | E5: After Corona epidemic situation - Normal overtime
B6: Overtime 200% | C6: 0 | D6: 0
B7: Overtime 210% | C7: 1267 | D7: 4.4770318 | E7: After Corona epidemic situation - Normal overtime
B9: Content | C9: Jan-Dec | D9: % | E9: Noted
B10: Working day | C10: -7837.9 | D10: -0.22161745 | E10: Jan.22: working day 22 day
E11: Dec: Isolate (7 day) working day 27 day (Total 35.366 day/ 1681 Preson)
B12: Paid leave | C12: 3842 | D12: 6.4033333 | E12: Jan.2022 Holiday 2 day (01+31/Jan/2022)
E13: Dec: No holiday
B14: Night work + 30% | C14: -2045.8 | D14: -0.71232591 | E14: Jan.22: working day 22 day
E15: Dec: Working day 27 day &Night work 2872 Hour
B16: Overtime 150% | C16: -12945 | D16: -0.19960834 | E16: Jan.22: working day 22 day
E17: Dec: Working day 27 day (Overtime 64.852 hour)
B18: Overtime 200% | C18: 1152 | D18: 33.882353 | E18: Jan.2022: Overtime Sunday 1186 Hour
E19: Dec: Overtime Sunday 34 Hour
B20: Overtime 210% | C20: -251 | D20: -0.47809524 | E20: Jan.2022: Working day 22 day (274 Hour)
E21: Dec: Working day 27 day (525 Hour)
B22: Overtime 300% | C22: -254.5 | D22: -1 | E22: Oct.2021 No overtime 300%
B25: Content | C25: Mar | D25: Feb | E25: ="Amount "&C25&" ~ "&D25 -> Amount Mar ~ Feb | F25: % | G25: Note
B26: Working Day | C26: 31007.9 | D26: 25659.4 | E26: =+C26-D26 -> 5348.5 | F26: =+E26/D26 -> 0.20844213 | G26: Feb: Working day 22 day Mar Working day 26 day
B27: Paid Leave | C27: 87 | D27: 2435 | E27: =+C27-D27 -> -2348 | F27: =+E27/D27 -> -0.96427105 | G27: Feb: Tet Holiday: 1 day (01/02) & Annual leave: 1 day (03/02) Mar: Marriage leave, funeral | J27: Marriage leave, labor accidents leave, funeral
B28: Annual Leave | E28: =+C28-D28 -> 0 | G28: Balance annual leave 2024
B29: extra pay for night work + 30% | C29: 4387 | D29: 3546.5 | E29: =+C29-D29 -> 840.5 | F29: =+E29/D29 -> 0.23699422 | G29: Increased night working hours (due to higher actual working days than last month)
B30: Overtime 150% | C30: 46222.5 | D30: 32182 | E30: =+C30-D30 -> 14040.5 | F30: =+E30/D30 -> 0.43628426 | G30: Increased overtime 150% : (due to higher actual working days than last month)
B31: Overtime 200% | C31: 199.5 | D31: 185.5 | E31: =+C31-D31 -> 14 | F31: =+E31/D31 -> 0.075471698 | G31: Overtime Sunday
B32: Overtime 210% | C32: 506.5 | D32: 240 | E32: =+C32-D32 -> 266.5 | F32: =+E32/D32 -> 1.1104167 | G32: Increased night working hours (due to higher actual working days than last month)
B33: Overtime 270% | E33: =+C33-D33 -> 0
B34: Overtime 300% | D34: 0 | E34: =+C34-D34 -> 0

Sheet TOTAL(payment)
A1: Công ty TNHH Bao Bì Cao Cấp S&K Vina
A3: BẢNG TỔNG KẾT LƯƠNG THÁNG 04 2025
A4: SUM OF SALARY OF APR 2025
A6: 0.54444444 | B6: Fac | C6: Dep new | D6: Dep Code | E6: # of worker | F6: Tổng thu nhập Total gross salary | G6: BHXH&BHYT, BHTN Social & Health Ins, Unempl-oyment Benefit | H6: KPCĐ Union Dues | I6: Thuế TNCN Personal Income Tax | J6: Đồng Phục Uniform | K6: Ứng Lương Advance | L6: Số Tiền (VND) Net salary | M6: Average
A7: =SUBTOTAL(3,B$7:B7) -> 1 | B7: Foreigners | C7: Foreigners | E7: 3 | F7: =+'Foreign Salary'!L11 -> 686964617 | G7: =+'Foreign Salary'!M11 -> 13338000 | H7: 0 | I7: =+'Foreign Salary'!P11 -> 193129316 | J7: 0 | K7: 0 | L7: =+(F7)-SUM(G7:K7) -> 480497301 | M7: =+L7/E7 -> 160165767
A8: =SUBTOTAL(3,B$7:B8) -> 2 | B8: SK2 | C8: P0 - Cleaning | D8: P0-CL-1-01 | E8: =COUNTIFS('Salary sheet'!$F$6:$F$2288,C8,'Salary sheet'!$E$6:$E$2288,B8) -> 4 | F8: =+SUMIFS('Salary sheet'!$AN$6:$AN$1292,'Salary sheet'!$F$6:$F$1292,'TOTAL(payment)'!C8,'Salary sheet'!$E$6:$E$1292,'TOTAL(payment)'!B8) -> 37891917 | G8: =+SUMIFS('Salary sheet'!$AO$6:$AO$2288,'Salary sheet'!$F$6:$F$2288,C8,'Salary sheet'!$E$6:$E$2288,B8) -> 2962470 | H8: =+SUMIFS('Salary sheet'!$AP$6:$AP$2288,'Salary sheet'!$F$6:$F$2288,C8,'Salary sheet'!$E$6:$E$2288,B8) -> 176400 | I8: =+SUMIFS('Salary sheet'!$AQ$6:$AQ$2288,'Salary sheet'!$F$6:$F$2288,C8,'Salary sheet'!$E$6:$E$2288,B8) -> 0 | J8: =+SUMIFS('Salary sheet'!$AR$6:$AR$2288,'Salary sheet'!$F$6:$F$2288,C8,'Salary sheet'!$E$6:$E$2288,B8) -> 0 | K8: =SUMIFS('Salary sheet'!$AS$6:$AS$1291,'Salary sheet'!$F$6:$F$1291,'TOTAL(payment)'!C8) -> 0 | L8: =+(F8)-SUM(G8:K8) -> 34753047 | M8: =+L8/E8 -> 8688261.8
A9: =SUBTOTAL(3,B$7:B9) -> 3 | B9: SK2 | C9: P0 - Design | D9: P0-DS-1-01 | E9: =COUNTIFS('Salary sheet'!$F$6:$F$2288,C9,'Salary sheet'!$E$6:$E$2288,B9) -> 4 | F9: =+SUMIFS('Salary sheet'!$AN$6:$AN$1292,'Salary sheet'!$F$6:$F$1292,'TOTAL(payment)'!C9,'Salary sheet'!$E$6:$E$1292,'TOTAL(payment)'!B9) -> 69105288 | G9: =+SUMIFS('Salary sheet'!$AO$6:$AO$2288,'Salary sheet'!$F$6:$F$2288,C9,'Salary sheet'!$E$6:$E$2288,B9) -> 7350000 | H9: =+SUMIFS('Salary sheet'!$AP$6:$AP$2288,'Salary sheet'!$F$6:$F$2288,C9,'Salary sheet'!$E$6:$E$2288,B9) -> 176400 | I9: =+SUMIFS('Salary sheet'!$AQ$6:$AQ$2288,'Salary sheet'!$F$6:$F$2288,C9,'Salary sheet'!$E$6:$E$2288,B9) -> 333370 | J9: =+SUMIFS('Salary sheet'!$AR$6:$AR$2288,'Salary sheet'!$F$6:$F$2288,C9,'Salary sheet'!$E$6:$E$2288,B9) -> 0 | K9: =SUMIFS('Salary sheet'!$AS$6:$AS$1291,'Salary sheet'!$F$6:$F$1291,'TOTAL(payment)'!C9) -> 0 | L9: =+(F9)-SUM(G9:K9) -> 61245518 | M9: =+L9/E9 -> 15311380
A10: =SUBTOTAL(3,B$7:B10) -> 4 | B10: SK2 | C10: P0 - Development | D10: P0-DE-1-01 | E10: =COUNTIFS('Salary sheet'!$F$6:$F$2288,C10,'Salary sheet'!$E$6:$E$2288,B10) -> 13 | F10: =+SUMIFS('Salary sheet'!$AN$6:$AN$1292,'Salary sheet'!$F$6:$F$1292,'TOTAL(payment)'!C10,'Salary sheet'!$E$6:$E$1292,'TOTAL(payment)'!B10) -> 148995921 | G10: =+SUMIFS('Salary sheet'!$AO$6:$AO$2288,'Salary sheet'!$F$6:$F$2288,C10,'Salary sheet'!$E$6:$E$2288,B10) -> 12238905 | H10: =+SUMIFS('Salary sheet'!$AP$6:$AP$2288,'Salary sheet'!$F$6:$F$2288,C10,'Salary sheet'!$E$6:$E$2288,B10) -> 573300 | I10: =+SUMIFS('Salary sheet'!$AQ$6:$AQ$2288,'Salary sheet'!$F$6:$F$2288,C10,'Salary sheet'!$E$6:$E$2288,B10) -> 97752 | J10: =+SUMIFS('Salary sheet'!$AR$6:$AR$2288,'Salary sheet'!$F$6:$F$2288,C10,'Salary sheet'!$E$6:$E$2288,B10) -> 0 | K10: =SUMIFS('Salary sheet'!$AS$6:$AS$1291,'Salary sheet'!$F$6:$F$1291,'TOTAL(payment)'!C10) -> 0 | L10: =+(F10)-SUM(G10:K10) -> 136085964 | M10: =+L10/E10 -> 10468151
A11: =SUBTOTAL(3,B$7:B11) -> 5 | B11: SK2 | C11: P0 - FG Warehouse | D11: P0-FG-1-01 | E11: =COUNTIFS('Salary sheet'!$F$6:$F$2288,C11,'Salary sheet'!$E$6:$E$2288,B11) -> 3 | F11: =+SUMIFS('Salary sheet'!$AN$6:$AN$1292,'Salary sheet'!$F$6:$F$1292,'TOTAL(payment)'!C11,'Salary sheet'!$E$6:$E$1292,'TOTAL(payment)'!B11) -> 32157502 | G11: =+SUMIFS('Salary sheet'!$AO$6:$AO$2288,'Salary sheet'!$F$6:$F$2288,C11,'Salary sheet'!$E$6:$E$2288,B11) -> 2592345 | H11: =+SUMIFS('Salary sheet'!$AP$6:$AP$2288,'Salary sheet'!$F$6:$F$2288,C11,'Salary sheet'!$E$6:$E$2288,B11) -> 132300 | I11: =+SUMIFS('Salary sheet'!$AQ$6:$AQ$2288,'Salary sheet'!$F$6:$F$2288,C11,'Salary sheet'!$E$6:$E$2288,B11) -> 0 | J11: =+SUMIFS('Salary sheet'!$AR$6:$AR$2288,'Salary sheet'!$F$6:$F$2288,C11,'Salary sheet'!$E$6:$E$2288,B11) -> 0 | K11: =SUMIFS('Salary sheet'!$AS$6:$AS$1291,'Salary sheet'!$F$6:$F$1291,'TOTAL(payment)'!C11) -> 0 | L11: =+(F11)-SUM(G11:K11) -> 29432857 | M11: =+L11/E11 -> 9810952.3
A12: =SUBTOTAL(3,B$7:B12) -> 6 | B12: SK2 | C12: P0 - GA-HR | D12: P0-HR-1-01 | E12: =COUNTIFS('Salary sheet'!$F$6:$F$2288,C12,'Salary sheet'!$E$6:$E$2288,B12) -> 3 | F12: =+SUMIFS('Salary sheet'!$AN$6:$AN$1292,'Salary sheet'!$F$6:$F$1292,'TOTAL(payment)'!C12,'Salary sheet'!$E$6:$E$1292,'TOTAL(payment)'!B12) -> 36890624 | G12: =+SUMIFS('Salary sheet'!$AO$6:$AO$2288,'Salary sheet'!$F$6:$F$2288,C12,'Salary sheet'!$E$6:$E$2288,B12) -> 3727500 | H12: =+SUMIFS('Salary sheet'!$AP$6:$AP$2288,'Salary sheet'!$F$6:$F$2288,C12,'Salary sheet'!$E$6:$E$2288,B12) -> 132300 | I12: =+SUMIFS('Salary sheet'!$AQ$6:$AQ$2288,'Salary sheet'!$F$6:$F$2288,C12,'Salary sheet'!$E$6:$E$2288,B12) -> 0 | J12: =+SUMIFS('Salary sheet'!$AR$6:$AR$2288,'Salary sheet'!$F$6:$F$2288,C12,'Salary sheet'!$E$6:$E$2288,B12) -> 0 | K12: =SUMIFS('Salary sheet'!$AS$6:$AS$1291,'Salary sheet'!$F$6:$F$1291,'TOTAL(payment)'!C12) -> 0 | L12: =+(F12)-SUM(G12:K12) -> 33030824 | M12: =+L12/E12 -> 11010275
A13: =SUBTOTAL(3,B$7:B13) -> 7 | B13: SK2 | C13: P0 - GC WIP | D13: P0-WP-1-01 | E13: =COUNTIFS('Salary sheet'!$F$6:$F$2288,C13,'Salary sheet'!$E$6:$E$2288,B13) -> 10 | F13: =+SUMIFS('Salary sheet'!$AN$6:$AN$1292,'Salary sheet'!$F$6:$F$1292,'TOTAL(payment)'!C13,'Salary sheet'!$E$6:$E$1292,'TOTAL(payment)'!B13) -> 132468353 | G13: =+SUMIFS('Salary sheet'!$AO$6:$AO$2288,'Salary sheet'!$F$6:$F$2288,C13,'Salary sheet'!$E$6:$E$2288,B13) -> 11025420 | H13: =+SUMIFS('Salary sheet'!$AP$6:$AP$2288,'Salary sheet'!$F$6:$F$2288,C13,'Salary sheet'!$E$6:$E$2288,B13) -> 441000 | I13: =+SUMIFS('Salary sheet'!$AQ$6:$AQ$2288,'Salary sheet'!$F$6:$F$2288,C13,'Salary sheet'!$E$6:$E$2288,B13) -> 170615 | J13: =+SUMIFS('Salary sheet'!$AR$6:$AR$2288,'Salary sheet'!$F$6:$F$2288,C13,'Salary sheet'!$E$6:$E$2288,B13) -> 0 | K13: =SUMIFS('Salary sheet'!$AS$6:$AS$1291,'Salary sheet'!$F$6:$F$1291,'TOTAL(payment)'!C13) -> 0 | L13: =+(F13)-SUM(G13:K13) -> 120831318 | M13: =+L13/E13 -> 12083132
A14: =SUBTOTAL(3,B$7:B14) -> 8 | B14: SK2 | C14: P0 - Maintenance | D14: P0-MA-1-01 | E14: =COUNTIFS('Salary sheet'!$F$6:$F$2288,C14,'Salary sheet'!$E$6:$E$2288,B14) -> 5 | F14: =+SUMIFS('Salary sheet'!$AN$6:$AN$1292,'Salary sheet'!$F$6:$F$1292,'TOTAL(payment)'!C14,'Salary sheet'!$E$6:$E$1292,'TOTAL(payment)'!B14) -> 75720308 | G14: =+SUMIFS('Salary sheet'!$AO$6:$AO$2288,'Salary sheet'!$F$6:$F$2288,C14,'Salary sheet'!$E$6:$E$2288,B14) -> 6744990 | H14: =+SUMIFS('Salary sheet'!$AP$6:$AP$2288,'Salary sheet'!$F$6:$F$2288,C14,'Salary sheet'!$E$6:$E$2288,B14) -> 220500 | I14: =+SUMIFS('Salary sheet'!$AQ$6:$AQ$2288,'Salary sheet'!$F$6:$F$2288,C14,'Salary sheet'!$E$6:$E$2288,B14) -> 87760 | J14: =+SUMIFS('Salary sheet'!$AR$6:$AR$2288,'Salary sheet'!$F$6:$F$2288,C14,'Salary sheet'!$E$6:$E$2288,B14) -> 0 | K14: =SUMIFS('Salary sheet'!$AS$6:$AS$1291,'Salary sheet'!$F$6:$F$1291,'TOTAL(payment)'!C14) -> 0 | L14: =+(F14)-SUM(G14:K14) -> 68667058 | M14: =+L14/E14 -> 13733412
A15: =SUBTOTAL(3,B$7:B15) -> 9 | B15: SK2 | C15: P0 - Marketing | D15: P0-MK-1-01 | E15: =COUNTIFS('Salary sheet'!$F$6:$F$2288,C15,'Salary sheet'!$E$6:$E$2288,B15) -> 9 | F15: =+SUMIFS('Salary sheet'!$AN$6:$AN$1292,'Salary sheet'!$F$6:$F$1292,'TOTAL(payment)'!C15,'Salary sheet'!$E$6:$E$1292,'TOTAL(payment)'!B15) -> 160153125 | G15: =+SUMIFS('Salary sheet'!$AO$6:$AO$2288,'Salary sheet'!$F$6:$F$2288,C15,'Salary sheet'!$E$6:$E$2288,B15) -> 16695000 | H15: =+SUMIFS('Salary sheet'!$AP$6:$AP$2288,'Salary sheet'!$F$6:$F$2288,C15,'Salary sheet'!$E$6:$E$2288,B15) -> 396900 | I15: =+SUMIFS('Salary sheet'!$AQ$6:$AQ$2288,'Salary sheet'!$F$6:$F$2288,C15,'Salary sheet'!$E$6:$E$2288,B15) -> 659735 | J15: =+SUMIFS('Salary sheet'!$AR$6:$AR$2288,'Salary sheet'!$F$6:$F$2288,C15,'Salary sheet'!$E$6:$E$2288,B15) -> 0 | K15: =SUMIFS('Salary sheet'!$AS$6:$AS$1291,'Salary sheet'!$F$6:$F$1291,'TOTAL(payment)'!C15) -> 0 | L15: =+(F15)-SUM(G15:K15) -> 142401490 | M15: =+L15/E15 -> 15822388
A16: =SUBTOTAL(3,B$7:B16) -> 10 | B16: SK2 | C16: P0 - Material Warehouse | D16: P0-MW-1-01 | E16: =COUNTIFS('Salary sheet'!$F$6:$F$2288,C16,'Salary sheet'!$E$6:$E$2288,B16) -> 5 | F16: =+SUMIFS('Salary sheet'!$AN$6:$AN$1292,'Salary sheet'!$F$6:$F$1292,'TOTAL(payment)'!C16,'Salary sheet'!$E$6:$E$1292,'TOTAL(payment)'!B16) -> 52639614 | G16: =+SUMIFS('Salary sheet'!$AO$6:$AO$2288,'Salary sheet'!$F$6:$F$2288,C16,'Salary sheet'!$E$6:$E$2288,B16) -> 4168306 | H16: =+SUMIFS('Salary sheet'!$AP$6:$AP$2288,'Salary sheet'!$F$6:$F$2288,C16,'Salary sheet'!$E$6:$E$2288,B16) -> 132300 | I16: =+SUMIFS('Salary sheet'!$AQ$6:$AQ$2288,'Salary sheet'!$F$6:$F$2288,C16,'Salary sheet'!$E$6:$E$2288,B16) -> 0 | J16: =+SUMIFS('Salary sheet'!$AR$6:$AR$2288,'Salary sheet'!$F$6:$F$2288,C16,'Salary sheet'!$E$6:$E$2288,B16) -> 0 | K16: =SUMIFS('Salary sheet'!$AS$6:$AS$1291,'Salary sheet'!$F$6:$F$1291,'TOTAL(payment)'!C16) -> 186299 | L16: =+(F16)-SUM(G16:K16) -> 48152709 | M16: =+L16/E16 -> 9630541.8
A17: =SUBTOTAL(3,B$7:B17) -> 11 | B17: SK2 | C17: P0 - Planning | D17: P0-PL-1-01 | E17: =COUNTIFS('Salary sheet'!$F$6:$F$2288,C17,'Salary sheet'!$E$6:$E$2288,B17) -> 9 | F17: =+SUMIFS('Salary sheet'!$AN$6:$AN$1292,'Salary sheet'!$F$6:$F$1292,'TOTAL(payment)'!C17,'Salary sheet'!$E$6:$E$1292,'TOTAL(payment)'!B17) -> 104930197 | G17: =+SUMIFS('Salary sheet'!$AO$6:$AO$2288,'Salary sheet'!$F$6:$F$2288,C17,'Salary sheet'!$E$6:$E$2288,B17) -> 10774995 | H17: =+SUMIFS('Salary sheet'!$AP$6:$AP$2288,'Salary sheet'!$F$6:$F$2288,C17,'Salary sheet'!$E$6:$E$2288,B17) -> 352800 | I17: =+SUMIFS('Salary sheet'!$AQ$6:$AQ$2288,'Salary sheet'!$F$6:$F$2288,C17,'Salary sheet'!$E$6:$E$2288,B17) -> 113181 | J17: =+SUMIFS('Salary sheet'!$AR$6:$AR$2288,'Salary sheet'!$F$6:$F$2288,C17,'Salary sheet'!$E$6:$E$2288,B17) -> 0 | K17: =SUMIFS('Salary sheet'!$AS$6:$AS$1291,'Salary sheet'!$F$6:$F$1291,'TOTAL(payment)'!C17) -> 0 | L17: =+(F17)-SUM(G17:K17) -> 93689221 | M17: =+L17/E17 -> 10409913
A18: =SUBTOTAL(3,B$7:B18) -> 12 | B18: SK2 | C18: P0 - Production Office | D18: P0-PO-1-01 | E18: =COUNTIFS('Salary sheet'!$F$6:$F$2288,C18,'Salary sheet'!$E$6:$E$2288,B18) -> 1 | F18: =+SUMIFS('Salary sheet'!$AN$6:$AN$1292,'Salary sheet'!$F$6:$F$1292,'TOTAL(payment)'!C18,'Salary sheet'!$E$6:$E$1292,'TOTAL(payment)'!B18) -> 38500000 | G18: =+SUMIFS('Salary sheet'!$AO$6:$AO$2288,'Salary sheet'!$F$6:$F$2288,C18,'Salary sheet'!$E$6:$E$2288,B18) -> 3969000 | H18: =+SUMIFS('Salary sheet'!$AP$6:$AP$2288,'Salary sheet'!$F$6:$F$2288,C18,'Salary sheet'!$E$6:$E$2288,B18) -> 44100 | I18: =+SUMIFS('Salary sheet'!$AQ$6:$AQ$2288,'Salary sheet'!$F$6:$F$2288,C18,'Salary sheet'!$E$6:$E$2288,B18) -> 283100 | J18: =+SUMIFS('Salary sheet'!$AR$6:$AR$2288,'Salary sheet'!$F$6:$F$2288,C18,'Salary sheet'!$E$6:$E$2288,B18) -> 0 | K18: =SUMIFS('Salary sheet'!$AS$6:$AS$1291,'Salary sheet'!$F$6:$F$1291,'TOTAL(payment)'!C18) -> 0 | L18: =+(F18)-SUM(G18:K18) -> 34203800 | M18: =+L18/E18 -> 34203800
A19: =SUBTOTAL(3,B$7:B19) -> 13 | B19: SK2 | C19: P0 - Purchasing | D19: P0-PU-1-01 | E19: =COUNTIFS('Salary sheet'!$F$6:$F$2288,C19,'Salary sheet'!$E$6:$E$2288,B19) -> 1 | F19: =+SUMIFS('Salary sheet'!$AN$6:$AN$1292,'Salary sheet'!$F$6:$F$1292,'TOTAL(payment)'!C19,'Salary sheet'!$E$6:$E$1292,'TOTAL(payment)'!B19) -> 9706348 | G19: =+SUMIFS('Salary sheet'!$AO$6:$AO$2288,'Salary sheet'!$F$6:$F$2288,C19,'Salary sheet'!$E$6:$E$2288,B19) -> 1012620 | H19: =+SUMIFS('Salary sheet'!$AP$6:$AP$2288,'Salary sheet'!$F$6:$F$2288,C19,'Salary sheet'!$E$6:$E$2288,B19) -> 44100 | I19: =+SUMIFS('Salary sheet'!$AQ$6:$AQ$2288,'Salary sheet'!$F$6:$F$2288,C19,'Salary sheet'!$E$6:$E$2288,B19) -> 0 | J19: =+SUMIFS('Salary sheet'!$AR$6:$AR$2288,'Salary sheet'!$F$6:$F$2288,C19,'Salary sheet'!$E$6:$E$2288,B19) -> 0 | K19: =SUMIFS('Salary sheet'!$AS$6:$AS$1291,'Salary sheet'!$F$6:$F$1291,'TOTAL(payment)'!C19) -> 0 | L19: =+(F19)-SUM(G19:K19) -> 8649628 | M19: =+L19/E19 -> 8649628
... A118: =SUBTOTAL(3,B$7:B118) -> 112 | B118: FACTORY A | C118: P8 - Slitter | D118: P8-CU-1-01 | E118: =COUNTIFS('Salary sheet'!$F$6:$F$2288,C118,'Salary sheet'!$E$6:$E$2288,B118) -> 1 | F118: =+SUMIFS('Salary sheet'!$AN$6:$AN$1292,'Salary sheet'!$F$6:$F$1292,'TOTAL(payment)'!C118,'Salary sheet'!$E$6:$E$1292,'TOTAL(payment)'!B118) -> 7912244 | G118: =+SUMIFS('Salary sheet'!$AO$6:$AO$2288,'Salary sheet'!$F$6:$F$2288,C118,'Salary sheet'!$E$6:$E$2288,B118) -> 627270 | H118: =+SUMIFS('Salary sheet'!$AP$6:$AP$2288,'Salary sheet'!$F$6:$F$2288,C118,'Salary sheet'!$E$6:$E$2288,B118) -> 44100 | I118: =+SUMIFS('Salary sheet'!$AQ$6:$AQ$2288,'Salary sheet'!$F$6:$F$2288,C118,'Salary sheet'!$E$6:$E$2288,B118) -> 0 | J118: =+SUMIFS('Salary sheet'!$AR$6:$AR$2288,'Salary sheet'!$F$6:$F$2288,C118,'Salary sheet'!$E$6:$E$2288,B118) -> 0 | K118: =SUMIFS('Salary sheet'!$AS$6:$AS$1291,'Salary sheet'!$F$6:$F$1291,'TOTAL(payment)'!C118) -> 0 | L118: =+(F118)-SUM(G118:K118) -> 7240874 | M118: =+L118/E118 -> 7240874
A119: x | E119: =SUM(E7:E118) -> 1289 | F119: =SUM(F7:F118) -> 13183558924 | G119: =SUM(G7:G118) -> 998000257 | H119: =SUM(H7:H118) -> 52434900 | I119: =SUM(I7:I118) -> 204791188 | J119: =SUM(J7:J118) -> 568500 | K119: =SUM(K7:K118) -> 3199861 | L119: =SUM(L7:L118) -> 11924564218 | M119: =SUM(M7:M112) -> 1.2193436e+09 | N119: =+L119-(L7+'Salary sheet'!AT1292) -> 11436826043
E120: =+E119-E7 -> 1286 | F120: =+F119-F7 -> 12496594307 | G120: =+G119-G7 -> 984662257 | H120: =+H119-H7 -> 52434900 | I120: =+I119-I7 -> 11661872 | J120: =+J119-J7 -> 568500 | K120: =+K119-K7 -> 3199861 | L120: =+L119-L7 -> 11444066917 | M120: =+M119-M7 -> 1.0591778e+09
E121: =+E119-E7-E120 -> 0 | F121: =+F119-F7-F120 -> 0 | G121: =+G119-G7-G120 -> 0 | H121: =+H119-H7-H120 -> 0 | I121: =+I119-I7-I120 -> 0 | J121: =+J119-J7-J120 -> 0 | K121: =+K119-K7-K120 -> 0 | L121: =+L119-L7-L120 -> 0
K123: Bình Phước, Ngày 30 tháng 04 năm 2025
B124: Người lập / Prepare by | G124: Kiểm tra/ Checked by | K124: Giám Đốc /Director
B132: Đỗ Thị Vân | G132: Nguyễn Thị Hà | K132: Kim Dong Woo

Sheet Foreign Salary
A1: Công ty TNHH Bao Bì Cao Cấp S&K Vina | H1: 26
A2: Lô B1 -B4 KCn Minh Hưng - Hàn Quốc | V2: SK1 Box | W2: =ROUND(R8/2,0)+ROUND(R9/2,0) -> 181751969
A3: H. Chơn Thành - Bình Phước | V3: SK1 Bag | W3: =+(R9+R8)-W2 -> 181751968
V4: SK2 | W4: =+R10 -> 116993364
A5: BẢNG LƯƠNG THÁNG 04 NĂM 2025 PAY-SHEET OF SALARY APR 2025 | W5: =+W4+W2+W3 -> 480497301
A6: Exchange Rate : 26,115 VND/USD | L6: 26115
A7: Stt No. | B7: Họ và tên Name | C7: Tên người thụ hưởng Beneficiary Name | D7: English name | E7: Fac | F7: Lương cơ bản Basic Salary (USD) | G7: Lương cơ bản Basic Salary (VND) | H7: Ngày công thực tế Actual Workday | I7: Lương cơ bản Basic Salary (USD) | J7: Month | K7: 13Th month bonus | L7: Lương CB Gross Salary VND | M7: BHXH,YT (9.5%) Insurance | N7: Nha o | O7: TNTT | P7: Thuế TNCN Personal income Tax | Q7: Advance | R7: Tiền thực lãnh Net salary VND | S7: Tiền thực lãnh Net salary USD (Paid) | T7: Contract salary | U7: Note
A8: 1 | B8: KIM DONG WOO | C8: KIM DONG WOO | D8: Mr DW | E8: FACTORY O | F8: 10300 | G8: =+F8*$L$6 -> 268984500 | H8: 26 | I8: =+F8/$H$1*H8 -> 10300 | L8: =ROUND((((K8+I8)*$L$6)),0) -> 268984500 | M8: =2340000*20*9.5% -> 4446000 | O8: =L8+N8-M8-11000000 -> 253538500 | P8: =ROUND(35%*O8-9850000,0) -> 78888475 | R8: =ROUND(L8-P8-M8-Q8,0) -> 185650025 | S8: =ROUND(R8/$L$6,2) -> 7108.94 | U8: SK1 Bag/Box
A9: 2 | B9: KIM JE MIN | C9: KIM JE MIN | D9: Mr JM | E9: FACTORY O | F9: 9750 | G9: =+F9*$L$6 -> 254621250 | H9: 26 | I9: =+F9/$H$1*H9 -> 9750 | L9: =ROUND((((K9+I9)*$L$6)),0) -> 254621250 | M9: =2340000*20*9.5% -> 4446000 | O9: =L9+N9-M9-11000000-4400000 -> 234775250 | P9: =ROUND(35%*O9-9850000,0) -> 72321338 | R9: =ROUND(L9-P9-M9-Q9,0) -> 177853912 | S9: =ROUND(R9/$L$6,2) -> 6810.41 | U9: SK1 Bag/Box | V9: ĐK 1 Người phụ thuộc từ tháng 10/2024
A10: 3 | B10: YUE FAMENG | C10: YUE FAMENG | D10: Mr Happy | E10: FACTORY H | F10: 6505.58 | G10: =+F10*$L$6 -> 1.6989322e+08 | H10: 25 | I10: =+F10/$H$1*H10 -> 6255.3654 | L10: =ROUND((((K10+I10)*$L$6)),0) -> 163358867 | M10: =2340000*20*9.5% -> 4446000 | O10: =L10+N10-M10-11000000 -> 147912867 | P10: =ROUND(35%*O10-9850000,0) -> 41919503 | R10: =ROUND(L10-P10-M10-Q10,0) -> 116993364 | S10: =ROUND(R10/$L$6,2) -> 4479.93 | U10: SK2
A11: TOTAL | F11: =SUM(F8:F10) -> 26555.58 | G11: =SUM(G8:G10) -> 6.9349897e+08 | H11: =SUM(H8:H10) -> 77 | I11: =SUM(I8:I10) -> 26305.365 | J11: =SUM(J8:J10) -> 0 | K11: =SUM(K8:K10) -> 0 | L11: =SUM(L8:L10) -> 686964617 | M11: =SUM(M8:M10) -> 13338000 | ... S11: =SUM(S8:S10) -> 18399.28
P14: =+'TOTAL(payment)'!K123 -> Bình Phước, Ngày 30 tháng 04 năm 2025
B15: Người lập / Prepare by | H15: Kiểm tra/ Checked by | P15: Giám Đốc /Director
B23: Đỗ Thị Vân | H23: Nguyễn Thị Hà | P23: Kim Dong Woo

Sheet Salary sheet
M2: 26
A3: BẢNG LƯƠNG THÁNG 04 NĂM 2025 PAY - SHEET OF APR 2025
A4: TT No. | B4: Mã thẻ Code | C4: Họ và tên Name | D4: Ngày vào Entry day | F4: Bộ phận Dep | G4: Title/ Chức danh | H4: Lương hợp đồng Contract salary | M4: Ngày làm việc thực tế Actual Working day | O4: Nghỉ có hưởng lương Paid leave | Q4: Ca đêm extra pay for night work + 30%) | S4: Lương, thưởng và các khoản hỗ trợ Salary, bonus, support fee | AG4: Cộng Total | AH4: Tăng ca Overtime | AN4: Tổng thu nhập Total Gross Salary | AO4: Khấu trừ Reduction | AT4: Tiền thực lãnh Net Salary | AU4: Ký nhận Signature | AW4: Tên TK | AX4: Số TK
E5: Fac | H5: Cơ bản Basic salary | I5: Trách nhiệm Responsibility | J5: Phụ cấp NNĐH Hazadouse allowance (>=5% of basic salary) | K5: Phụ cấp chức danh/Title Allowance | L5: Cộng Total | M5: Ngày công Day | N5: Lương CB + trách nhiệm Basic Salary + Responsibility | O5: Ngày công Day | P5: Lương CB + trách nhiệm Basic Salary + Responsibility | Q5: Giờ công Hour | R5: Lương CB + trách nhiệm Basic Salary + Responsibility | S5: Lương CB + trách nhiệm Basic salary + Responsibility | T5: Điện thoại, Telephone fee | U5: Tiền cơm Meal Allowance | V5: Hỗ trợ xăng + nhà trọ, Mileage, house | W5: Thưởng chuyên cần Diligent Bonus | X5: Phụ cấp PCCC PCCC / ATVSV allowance (30% of government basic salary and safety - hygency team) | Y5: Thưởng ABC ABC Bonus | Z5: Thưởng năng suất Production bonus | AA5: Ngày phép | AB5: Phép năm Annual Leave | AC5: Con nhỏ Support for baby (1-6) | AD5: Bảo hiểm, thất nghiệp Additional salary , insurance, Unempl-oyment Benefit, Bù Lương, Công Tác phí | AE5: Phụ cấp Phụ Nữ Menstruation allowance | AF5: 13Th Month Bonus | AH5: 1.5 | AI5: 2 | AJ5: 2.1 | AK5: 2.7 | AL5: 3 | AM5: Tổng tiền Amount | AO5: BHXH +YT, +TN Insurance | AP5: KPCĐ Union Dues | AQ5: Personal Income Tax Thuế TNCN | AR5: Đồng phục Uniform | AS5: Advance Chênh lệch HĐ/ Biên bản Paid | AY5: =+IF(B5="SK2","SK2",IF(B5="FACTORY A","SK1 Box",IF(B5="FACTORY D","SK1 Bag","Chia"))) -> Chia | BA5: =+IF(AY5="SK1 Box","Box",IF(AY5="Seaman","Seaman","Bag")) -> Bag
A6: =SUBTOTAL(3,B$6:B6) -> 0 | B6: C0873 | C6: Trần Thị Kim Phấn | D6: 39707 | E6: FACTORY A | F6: P6 - C.Box Assembly | G6: Box Positioning worker | H6: 5931000 | I6: 200000 | J6: 0 | K6: 0 | L6: =SUM(H6:K6) -> 6131000 | M6: 24 | N6: =ROUND((H6+I6+J6+K6)/IF($M$2>26,26,$M$2)*M6,0) -> 5659385 | O6: 2 | P6: =ROUND((H6+I6+J6+K6)/IF($M$2>26,26,$M$2)*O6,0) -> 471615 | Q6: 0 | R6: =IF(M6>0,ROUND(N6/IF(M6>26,26,M6)/8*Q6*30%,0),0) -> 0 | S6: =N6+P6+R6 -> 6131000 | T6: 0 | U6: 0 | V6: 200000 | W6: 500000 | X6: 0 | Y6: 0 | Z6: 188548 | AC6: 0 | AD6: 0 | AE6: 44213.945 | AG6: =ROUND(SUM(S6:AF6)-AA6,0) -> 7063762 | AH6: 28 | AI6: 0 | AJ6: 0 | AK6: 0 | AL6: 0 | AM6: =ROUND((N6/IF(M6>26,26,M6)/8*(AH6*$AH$5+AI6*$AI$5+AJ6*$AJ$5+AK6*$AK$5+AL6*$AL$5)),0) -> 1237990 | AN6: =ROUND(AG6+AM6,0) -> 8301752 | AO6: 643755 | AP6: 44100 | AQ6: =+VLOOKUP($B6,[1]Sheet1!$C$15:$BW$1300,52,0) -> 0 | AR6: 0 | AS6: 0 | AT6: =+ROUND(SUM(AN6:AN6)-SUM(AO6:AS6),0) -> 7613897 | AW6: TRAN THI KIM PHAN | AX6: 050040964964 | AY6: SK1 Box | AZ6: 622 | BA6: =+IF(AY6="SK1 Box","Box",IF(AY6="Seaman","Seaman","Bag")) -> Box
A7: =SUBTOTAL(3,B$6:B7) -> 0 | B7: C1007 | C7: Nguyễn Thị Hướng | D7: 39707 | E7: FACTORY A | F7: P6 - C.Box Assembly | G7: Box Positioning worker | H7: 5931000 | I7: 200000 | J7: 0 | K7: 300000 | L7: =SUM(H7:K7) -> 6431000 | M7: 23.8 | N7: =ROUND((H7+I7+J7+K7)/IF($M$2>26,26,$M$2)*M7,0) -> 5886838 | O7: 2 | P7: =ROUND((H7+I7+J7+K7)/IF($M$2>26,26,$M$2)*O7,0) -> 494692 | Q7: 0 | R7: =IF(M7>0,ROUND(N7/IF(M7>26,26,M7)/8*Q7*30%,0),0) -> 0 | S7: =N7+P7+R7 -> 6381530 | T7: 0 | U7: 0 | V7: 200000 | W7: 500000 | X7: 0 | Y7: 400000 | Z7: 603480 | AC7: 0 | AD7: 0 | AE7: 46377.4 | AG7: =ROUND(SUM(S7:AF7)-AA7,0) -> 8131387 | AH7: 28 | AI7: 0 | AJ7: 0 | AK7: 0 | AL7: 0 | AM7: =ROUND((N7/IF(M7>26,26,M7)/8*(AH7*$AH$5+AI7*$AI$5+AJ7*$AJ$5+AK7*$AK$5+AL7*$AL$5)),0) -> 1298567 | AN7: =ROUND(AG7+AM7,0) -> 9429954 | AO7: 675255 | AP7: 44100 | AQ7: =+VLOOKUP($B7,[1]Sheet1!$C$15:$BW$1300,52,0) -> 0 | AR7: 0 | AS7: 0 | AT7: =+ROUND(SUM(AN7:AN7)-SUM(AO7:AS7),0) -> 8710599 | AW7: NGUYEN THI HUONG | AX7: 050040850950 | AY7: SK1 Box | AZ7: 622 | BA7: =+IF(AY7="SK1 Box","Box",IF(AY7="Seaman","Seaman","Bag")) -> Box
A8: =SUBTOTAL(3,B$6:B8) -> 0 | B8: C1009 | C8: Hồ Thị Nga | D8: 39707 | E8: FACTORY A | F8: P6 - C.Box Assembly | G8: Box Positioning worker | H8: 5931000 | I8: 200000 | J8: 0 | K8: 0 | L8: =SUM(H8:K8) -> 6131000 | M8: 24 | N8: =ROUND((H8+I8+J8+K8)/IF($M$2>26,26,$M$2)*M8,0) -> 5659385 | O8: 2 | P8: =ROUND((H8+I8+J8+K8)/IF($M$2>26,26,$M$2)*O8,0) -> 471615 | Q8: 0 | R8: =IF(M8>0,ROUND(N8/IF(M8>26,26,M8)/8*Q8*30%,0),0) -> 0 | S8: =N8+P8+R8 -> 6131000 | T8: 0 | U8: 0 | V8: 200000 | W8: 500000 | X8: 0 | Y8: 400000 | Z8: 600597 | AC8: 0 | AD8: 0 | AE8: 44213.945 | AG8: =ROUND(SUM(S8:AF8)-AA8,0) -> 7875811 | AH8: 28 | AI8: 0 | AJ8: 0 | AK8: 0 | AL8: 0 | AM8: =ROUND((N8/IF(M8>26,26,M8)/8*(AH8*$AH$5+AI8*$AI$5+AJ8*$AJ$5+AK8*$AK$5+AL8*$AL$5)),0) -> 1237990 | AN8: =ROUND(AG8+AM8,0) -> 9113801 | AO8: 643755 | AP8: 44100 | AQ8: =+VLOOKUP($B8,[1]Sheet1!$C$15:$BW$1300,52,0) -> 0 | AR8: 0 | AS8: 0 | AT8: =+ROUND(SUM(AN8:AN8)-SUM(AO8:AS8),0) -> 8425946 | AW8: HO THI NGA | AX8: 050040952974 | AY8: SK1 Box | AZ8: 622 | BA8: =+IF(AY8="SK1 Box","Box",IF(AY8="Seaman","Seaman","Bag")) -> Box
A9: =SUBTOTAL(3,B$6:B9) -> 0 | B9: C10454 | C9: Trần Thị Liên | D9: 43556 | E9: FACTORY A | F9: P6 - C.Box Assembly | G9: Box Positioning worker | H9: 5931000 | I9: 200000 | J9: 0 | K9: 0 | L9: =SUM(H9:K9) -> 6131000 | M9: 24 | N9: =ROUND((H9+I9+J9+K9)/IF($M$2>26,26,$M$2)*M9,0) -> 5659385 | O9: 2 | P9: =ROUND((H9+I9+J9+K9)/IF($M$2>26,26,$M$2)*O9,0) -> 471615 | Q9: 0 | R9: =IF(M9>0,ROUND(N9/IF(M9>26,26,M9)/8*Q9*30%,0),0) -> 0 | S9: =N9+P9+R9 -> 6131000 | T9: 0 | U9: 0 | V9: 200000 | W9: 500000 | X9: 0 | Y9: 400000 | Z9: 606304 | AC9: 0 | AD9: 0 | AE9: 44213.945 | AG9: =ROUND(SUM(S9:AF9)-AA9,0) -> 7881518 | AH9: 28 | AI9: 0 | AJ9: 0 | AK9: 0 | AL9: 0 | AM9: =ROUND((N9/IF(M9>26,26,M9)/8*(AH9*$AH$5+AI9*$AI$5+AJ9*$AJ$5+AK9*$AK$5+AL9*$AL$5)),0) -> 1237990 | AN9: =ROUND(AG9+AM9,0) -> 9119508 | AO9: 643755 | AP9: 44100 | AQ9: =+VLOOKUP($B9,[1]Sheet1!$C$15:$BW$1300,52,0) -> 0 | AR9: 0 | AS9: 0 | AT9: =+ROUND(SUM(AN9:AN9)-SUM(AO9:AS9),0) -> 8431653 | AW9: TRAN THI LIEN | AX9: 050104743444 | AY9: SK1 Box | AZ9: 622 | BA9: =+IF(AY9="SK1 Box","Box",IF(AY9="Seaman","Seaman","Bag")) -> Box
A10: =SUBTOTAL(3,B$6:B10) -> 0 | B10: C10664 | C10: Nguyễn Hoài Hận | D10: 43595 | E10: FACTORY A | F10: P6 - C.Box Assembly | G10: Box Positioning worker | H10: 5931000 | I10: 200000 | J10: 0 | K10: 0 | L10: =SUM(H10:K10) -> 6131000 | M10: 23.7 | N10: =ROUND((H10+I10+J10+K10)/IF($M$2>26,26,$M$2)*M10,0) -> 5588642 | O10: 2 | P10: =ROUND((H10+I10+J10+K10)/IF($M$2>26,26,$M$2)*O10,0) -> 471615 | Q10: 0 | R10: =IF(M10>0,ROUND(N10/IF(M10>26,26,M10)/8*Q10*30%,0),0) -> 0 | S10: =N10+P10+R10 -> 6060257 | T10: 0 | U10: 0 | V10: 200000 | W10: 500000 | X10: 0 | Y10: 400000 | Z10: 603480 | AC10: 0 | AD10: 0 | AE10: 0 | AG10: =ROUND(SUM(S10:AF10)-AA10,0) -> 7763737 | AH10: 28 | AI10: 0 | AJ10: 0 | AK10: 0 | AL10: 0 | AM10: =ROUND((N10/IF(M10>26,26,M10)/8*(AH10*$AH$5+AI10*$AI$5+AJ10*$AJ$5+AK10*$AK$5+AL10*$AL$5)),0) -> 1237990 | AN10: =ROUND(AG10+AM10,0) -> 9001727 | AO10: 643755 | AP10: 44100 | AQ10: =+VLOOKUP($B10,[1]Sheet1!$C$15:$BW$1300,52,0) -> 0 | AR10: 0 | AS10: 0 | AT10: =+ROUND(SUM(AN10:AN10)-SUM(AO10:AS10),0) -> 8313872 | AW10: NGUYEN HOAI HAN | AX10: 050073573855 | AY10: SK1 Box | AZ10: 622 | BA10: =+IF(AY10="SK1 Box","Box",IF(AY10="Seaman","Seaman","Bag")) -> Box
A11: =SUBTOTAL(3,B$6:B11) -> 0 | B11: C10665 | C11: Lê Thị Kiều Loan | D11: 43595 | E11: FACTORY A | F11: P6 - C.Box Assembly | G11: Normal worker | H11: 5931000 | I11: 0 | J11: 0 | K11: 0 | L11: =SUM(H11:K11) -> 5931000 | M11: 24 | N11: =ROUND((H11+I11+J11+K11)/IF($M$2>26,26,$M$2)*M11,0) -> 5474769 | O11: 2 | P11: =ROUND((H11+I11+J11+K11)/IF($M$2>26,26,$M$2)*O11,0) -> 456231 | Q11: 0 | R11: =IF(M11>0,ROUND(N11/IF(M11>26,26,M11)/8*Q11*30%,0),0) -> 0 | S11: =N11+P11+R11 -> 5931000 | T11: 0 | U11: 0 | V11: 200000 | W11: 500000 | X11: 0 | Y11: 300000 | Z11: 606304 | AC11: 0 | AD11: 0 | AE11: 42771.633 | AG11: =ROUND(SUM(S11:AF11)-AA11,0) -> 7580076 | AH11: 24 | AI11: 0 | AJ11: 0 | AK11: 0 | AL11: 0 | AM11: =ROUND((N11/IF(M11>26,26,M11)/8*(AH11*$AH$5+AI11*$AI$5+AJ11*$AJ$5+AK11*$AK$5+AL11*$AL$5)),0) -> 1026519 | AN11: =ROUND(AG11+AM11,0) -> 8606595 | AO11: 622755 | AP11: 44100 | AQ11: =+VLOOKUP($B11,[1]Sheet1!$C$15:$BW$1300,52,0) -> 0 | AR11: 0 | AS11: 0 | AT11: =+ROUND(SUM(AN11:AN11)-SUM(AO11:AS11),0) -> 7939740 | AW11: LE THI KIEU LOAN | AX11: 050106514035 | AY11: SK1 Box | AZ11: 622 | BA11: =+IF(AY11="SK1 Box","Box",IF(AY11="Seaman","Seaman","Bag")) -> Box
A12: =SUBTOTAL(3,B$6:B12) -> 0 | B12: C1074 | C12: Phan Thị Thanh Tâm | D12: 39715 | E12: FACTORY A | F12: P6 - C.Box Assembly | G12: Box Positioning worker | H12: 5931000 | I12: 200000 | J12: 0 | K12: 0 | L12: =SUM(H12:K12) -> 6131000 | M12: 23.9 | N12: =ROUND((H12+I12+J12+K12)/IF($M$2>26,26,$M$2)*M12,0) -> 5635804 | O12: 2 | P12: =ROUND((H12+I12+J12+K12)/IF($M$2>26,26,$M$2)*O12,0) -> 471615 | Q12: 0 | R12: =IF(M12>0,ROUND(N12/IF(M12>26,26,M12)/8*Q12*30%,0),0) -> 0 | S12: =N12+P12+R12 -> 6107419 | T12: 0 | U12: 0 | V12: 200000 | W12: 500000 | X12: 0 | Y12: 400000 | Z12: 590658 | AC12: 100000 | AD12: 0 | AE12: 44213.944 | AG12: =ROUND(SUM(S12:AF12)-AA12,0) -> 7942291 | AH12: 28 | AI12: 0 | AJ12: 0 | AK12: 0 | AL12: 0 | AM12: =ROUND((N12/IF(M12>26,26,M12)/8*(AH12*$AH$5+AI12*$AI$5+AJ12*$AJ$5+AK12*$AK$5+AL12*$AL$5)),0) -> 1237990 | AN12: =ROUND(AG12+AM12,0) -> 9180281 | AO12: 643755 | AP12: 44100 | AQ12: =+VLOOKUP($B12,[1]Sheet1!$C$15:$BW$1300,52,0) -> 0 | AR12: 0 | AS12: 0 | AT12: =+ROUND(SUM(AN12:AN12)-SUM(AO12:AS12),0) -> 8492426 | AW12: PHAN THI THANH TAM | AX12: 050040932884 | AY12: SK1 Box | AZ12: 622 | BA12: =+IF(AY12="SK1 Box","Box",IF(AY12="Seaman","Seaman","Bag")) -> Box
A13: =SUBTOTAL(3,B$6:B13) -> 0 | B13: C11208 | C13: Lê Thị Bích Linh | D13: 43684 | E13: FACTORY A | F13: P6 - C.Box Assembly | G13: Box Positioning worker | H13: 5931000 | I13: 200000 | J13: 0 | K13: 0 | L13: =SUM(H13:K13) -> 6131000 | M13: 22.6 | N13: =ROUND((H13+I13+J13+K13)/IF($M$2>26,26,$M$2)*M13,0) -> 5329254 | O13: 3 | P13: =ROUND((H13+I13+J13+K13)/IF($M$2>26,26,$M$2)*O13,0) -> 707423 | Q13: 0 | R13: =IF(M13>0,ROUND(N13/IF(M13>26,26,M13)/8*Q13*30%,0),0) -> 0 | S13: =N13+P13+R13 -> 6036677 | T13: 0 | U13: 0 | V13: 200000 | W13: 500000 | X13: 0 | Y13: 400000 | Z13: 558491 | AC13: 0 | AD13: 0 | AE13: 44213.944 | AG13: =ROUND(SUM(S13:AF13)-AA13,0) -> 7739382 | AH13: 24 | AI13: 0 | AJ13: 0 | AK13: 0 | AL13: 0 | AM13: =ROUND((N13/IF(M13>26,26,M13)/8*(AH13*$AH$5+AI13*$AI$5+AJ13*$AJ$5+AK13*$AK$5+AL13*$AL$5)),0) -> 1061135 | AN13: =ROUND(AG13+AM13,0) -> 8800517 | AO13: 643755 | AP13: 44100 | AQ13: =+VLOOKUP($B13,[1]Sheet1!$C$15:$BW$1300,52,0) -> 0 | AR13: 0 | AS13: 0 | AT13: =+ROUND(SUM(AN13:AN13)-SUM(AO13:AS13),0) -> 8112662 | AW13: LE THI BICH LINH | AX13: 050111434058 | AY13: SK1 Box | AZ13: 622 | BA13: =+IF(AY13="SK1 Box","Box",IF(AY13="Seaman","Seaman","Bag")) -> Box
A14: =SUBTOTAL(3,B$6:B14) -> 0 | B14: C11863 | C14: Trần Hải Nam | D14: 43874 | E14: FACTORY A | F14: P6 - C.Box Assembly | G14: Stickers Box worker | H14: 5931000 | I14: 200000 | J14: 0 | K14: 0 | L14: =SUM(H14:K14) -> 6131000 | M14: 24 | N14: =ROUND((H14+I14+J14+K14)/IF($M$2>26,26,$M$2)*M14,0) -> 5659385 | O14: 2 | P14: =ROUND((H14+I14+J14+K14)/IF($M$2>26,26,$M$2)*O14,0) -> 471615 | Q14: 0 | R14: =IF(M14>0,ROUND(N14/IF(M14>26,26,M14)/8*Q14*30%,0),0) -> 0 | S14: =N14+P14+R14 -> 6131000 | T14: 0 | U14: 0 | V14: 200000 | W14: 500000 | X14: 0 | Y14: 400000 | Z14: 906304 | AC14: 0 | AD14: 0 | AE14: 0 | AG14: =ROUND(SUM(S14:AF14)-AA14,0) -> 8137304 | AH14: 28 | AI14: 0 | AJ14: 0 | AK14: 0 | AL14: 0 | AM14: =ROUND((N14/IF(M14>26,26,M14)/8*(AH14*$AH$5+AI14*$AI$5+AJ14*$AJ$5+AK14*$AK$5+AL14*$AL$5)),0) -> 1237990 | AN14: =ROUND(AG14+AM14,0) -> 9375294 | AO14: 643755 | AP14: 44100 | AQ14: =+VLOOKUP($B14,[1]Sheet1!$C$15:$BW$1300,52,0) -> 0 | AR14: 0 | AS14: 0 | AT14: =+ROUND(SUM(AN14:AN14)-SUM(AO14:AS14),0) -> 8687439 | AW14: TRAN HAI NAM | AX14: 050116653033 | AY14: SK1 Box | AZ14: 622 | BA14: =+IF(AY14="SK1 Box","Box",IF(AY14="Seaman","Seaman","Bag")) -> Box
A15: =SUBTOTAL(3,B$6:B15) -> 0 | B15: C1271 | C15: Hồ Thị Nga | D15: 39766 | E15: FACTORY A | F15: P6 - C.Box Assembly | G15: Box Positioning worker | H15: 5931000 | I15: 200000 | J15: 0 | K15: 0 | L15: =SUM(H15:K15) -> 6131000 | M15: 24 | N15: =ROUND((H15+I15+J15+K15)/IF($M$2>26,26,$M$2)*M15,0) -> 5659385 | O15: 2 | P15: =ROUND((H15+I15+J15+K15)/IF($M$2>26,26,$M$2)*O15,0) -> 471615 | Q15: 0 | R15: =IF(M15>0,ROUND(N15/IF(M15>26,26,M15)/8*Q15*30%,0),0) -> 0 | S15: =N15+P15+R15 -> 6131000 | T15: 0 | U15: 0 | V15: 200000 | W15: 500000 | X15: 0 | Y15: 0 | Z15: 181391 | AC15: 0 | AD15: 0 | AE15: 44213.945 | AG15: =ROUND(SUM(S15:AF15)-AA15,0) -> 7056605 | AH15: 28 | AI15: 0 | AJ15: 0 | AK15: 0 | AL15: 0 | AM15: =ROUND((N15/IF(M15>26,26,M15)/8*(AH15*$AH$5+AI15*$AI$5+AJ15*$AJ$5+AK15*$AK$5+AL15*$AL$5)),0) -> 1237990 | AN15: =ROUND(AG15+AM15,0) -> 8294595 | AO15: 643755 | AP15: 44100 | AQ15: =+VLOOKUP($B15,[1]Sheet1!$C$15:$BW$1300,52,0) -> 0 | AR15: 0 | AS15: 0 | AT15: =+ROUND(SUM(AN15:AN15)-SUM(AO15:AS15),0) -> 7606740 | AW15: HO THI NGA | AX15: 050040933910 | AY15: SK1 Box | AZ15: 622 | BA15: =+IF(AY15="SK1 Box","Box",IF(AY15="Seaman","Seaman","Bag")) -> Box
A16: =SUBTOTAL(3,B$6:B16) -> 0 | B16: C12741 | C16: Nguyễn Thị Trúc Ly | D16: 44064 | E16: FACTORY A | F16: P6 - C.Box Assembly | G16: Box Positioning worker | H16: 5931000 | I16: 200000 | J16: 0 | K16: 0 | L16: =SUM(H16:K16) -> 6131000 | M16: 24 | N16: =ROUND((H16+I16+J16+K16)/IF($M$2>26,26,$M$2)*M16,0) -> 5659385 | O16: 2 | P16: =ROUND((H16+I16+J16+K16)/IF($M$2>26,26,$M$2)*O16,0) -> 471615 | Q16: 0 | R16: =IF(M16>0,ROUND(N16/IF(M16>26,26,M16)/8*Q16*30%,0),0) -> 0 | S16: =N16+P16+R16 -> 6131000 | T16: 0 | U16: 0 | V16: 200000 | W16: 500000 | X16: 0 | Y16: 400000 | Z16: 603480 | AC16: 200000 | AD16: 0 | AE16: 44213.945 | AG16: =ROUND(SUM(S16:AF16)-AA16,0) -> 8078694 | AH16: 28 | AI16: 0 | AJ16: 0 | AK16: 0 | AL16: 0 | AM16: =ROUND((N16/IF(M16>26,26,M16)/8*(AH16*$AH$5+AI16*$AI$5+AJ16*$AJ$5+AK16*$AK$5+AL16*$AL$5)),0) -> 1237990 | AN16: =ROUND(AG16+AM16,0) -> 9316684 | AO16: 643755 | AP16: 44100 | AQ16: =+VLOOKUP($B16,[1]Sheet1!$C$15:$BW$1300,52,0) -> 0 | AR16: 0 | AS16: 0 | AT16: =+ROUND(SUM(AN16:AN16)-SUM(AO16:AS16),0) -> 8628829 | AW16: NGUYEN THI TRUC LY | AX16: 050114056372 | AY16: SK1 Box | AZ16: 622 | BA16: =+IF(AY16="SK1 Box","Box",IF(AY16="Seaman","Seaman","Bag")) -> Box
A17: =SUBTOTAL(3,B$6:B17) -> 0 | B17: C12781 | C17: Lê Thị Ánh Thương | D17: 44069 | E17: FACTORY A | F17: P6 - C.Box Assembly | G17: Technician worker | H17: 5931000 | I17: 1100000 | J17: 0 | K17: 0 | L17: =SUM(H17:K17) -> 7031000 | M17: 23.7 | N17: =ROUND((H17+I17+J17+K17)/IF($M$2>26,26,$M$2)*M17,0) -> 6409027 | O17: 2 | P17: =ROUND((H17+I17+J17+K17)/IF($M$2>26,26,$M$2)*O17,0) -> 540846 | Q17: 0 | R17: =IF(M17>0,ROUND(N17/IF(M17>26,26,M17)/8*Q17*30%,0),0) -> 0 | S17: =N17+P17+R17 -> 6949873 | T17: 0 | U17: 0 | V17: 200000 | W17: 500000 | X17: 0 | Y17: 400000 | Z17: 585715 | AC17: 100000 | AD17: 0 | AE17: 50704.328 | AG17: =ROUND(SUM(S17:AF17)-AA17,0) -> 8786292 | AH17: 28 | AI17: 0 | AJ17: 0 | AK17: 0 | AL17: 0 | AM17: =ROUND((N17/IF(M17>26,26,M17)/8*(AH17*$AH$5+AI17*$AI$5+AJ17*$AJ$5+AK17*$AK$5+AL17*$AL$5)),0) -> 1419721 | AN17: =ROUND(AG17+AM17,0) -> 10206013 | AO17: 738255 | AP17: 44100 | AQ17: =+VLOOKUP($B17,[1]Sheet1!$C$15:$BW$1300,52,0) -> 0 | AR17: 0 | AS17: 0 | AT17: =+ROUND(SUM(AN17:AN17)-SUM(AO17:AS17),0) -> 9423658 | AW17: LE THI ANH THUONG | AX17: 050040933661 | AY17: SK1 Box | AZ17: 622 | BA17: =+IF(AY17="SK1 Box","Box",IF(AY17="Seaman","Seaman","Bag")) -> Box
... A261: =SUBTOTAL(3,B$6:B261) -> 0 | B261: C11922 | C261: Nguyễn Thị Hồng Thuận | D261: 43878 | E261: FACTORY A | F261: P6 - Production Office | G261: Factory vice manager | H261: 7643000 | I261: 7300000 | J261: 0 | K261: 0 | L261: =SUM(H261:K261) -> 14943000 | M261: 23.6 | N261: =ROUND((H261+I261+J261+K261)/IF($M$2>26,26,$M$2)*M261,0) -> 13563646 | O261: 2 | P261: =ROUND((H261+I261+J261+K261)/IF($M$2>26,26,$M$2)*O261,0) -> 1149462 | Q261: 0 | R261: =IF(M261>0,ROUND(N261/IF(M261>26,26,M261)/8*Q261*30%,0),0) -> 0 | S261: =N261+P261+R261 -> 14713108 | T261: 0 | U261: 0 | V261: 200000 | W261: 500000 | X261: 0 | Y261: 400000 | Z261: 0 | AC261: 0 | AD261: 0 | AE261: 107762.02 | AG261: =ROUND(SUM(S261:AF261)-AA261,0) -> 15920870 | AH261: 28 | AI261: 0 | AJ261: 0 | AK261: 0 | AL261: 0 | AM261: =ROUND((N261/IF(M261>26,26,M261)/8*(AH261*$AH$5+AI261*$AI$5+AJ261*$AJ$5+AK261*$AK$5+AL261*$AL$5)),0) -> 3017337 | AN261: =ROUND(AG261+AM261,0) -> 18938207 | AO261: 1569015 | AP261: 44100 | AQ261: =+VLOOKUP($B261,[1]Sheet1!$C$15:$BW$1300,52,0) -> 0 | AR261: 0 | AS261: 0 | AT261: =+ROUND(SUM(AN261:AN261)-SUM(AO261:AS261),0) -> 17325092 | AW261: NGUYEN THI HONG THUAN | AX261: 050040933090 | AY261: SK1 Box | AZ261: 627 | BA261: =+IF(AY261="SK1 Box","Box",IF(AY261="Seaman","Seaman","Bag")) -> Box
A262: =SUBTOTAL(3,B$6:B262) -> 0 | B262: C3402 | C262: Đoàn Thị Hiếu Loan | D262: 40589 | E262: FACTORY A | F262: P6 - Production Office | G262: Factory manager | H262: 13094000 | I262: 11306000 | J262: 0 | K262: 0 | L262: =SUM(H262:K262) -> 24400000 | M262: 24 | N262: =ROUND((H262+I262+J262+K262)/IF($M$2>26,26,$M$2)*M262,0) -> 22523077 | O262: 2 | P262: =ROUND((H262+I262+J262+K262)/IF($M$2>26,26,$M$2)*O262,0) -> 1876923 | Q262: 0 | R262: =IF(M262>0,ROUND(N262/IF(M262>26,26,M262)/8*Q262*30%,0),0) -> 0 | S262: =N262+P262+R262 -> 24400000 | T262: 150000 | U262: 0 | V262: 0 | W262: 0 | X262: 0 | Y262: 0 | Z262: 0 | AC262: 0 | AD262: 0 | AE262: 175961.54 | AG262: =ROUND(SUM(S262:AF262)-AA262,0) -> 24725962 | AH262: 0 | AI262: 0 | AJ262: 0 | AK262: 0 | AL262: 0 | AM262: =ROUND((N262/IF(M262>26,26,M262)/8*(AH262*$AH$5+AI262*$AI$5+AJ262*$AJ$5+AK262*$AK$5+AL262*$AL$5)),0) -> 0 | AN262: =ROUND(AG262+AM262,0) -> 24725962 | AO262: 2562000 | AP262: 44100 | AQ262: =+VLOOKUP($B262,[1]Sheet1!$C$15:$BW$1300,52,0) -> 115698 | AR262: 0 | AS262: 0 | AT262: =+ROUND(SUM(AN262:AN262)-SUM(AO262:AS262),0) -> 22004164 | AW262: DOAN THI HIEU LOAN | AX262: 050153746262 | AY262: SK1 Box | AZ262: 627 | BA262: Manager
A263: =SUBTOTAL(3,B$6:B263) -> 0 | B263: C5606 | C263: Nguyễn Thị Liên | D263: 41369 | E263: FACTORY A | F263: P6 - Production Office | G263: Factory assistant | H263: 6576000 | I263: 2000000 | J263: 0 | K263: 0 | L263: =SUM(H263:K263) -> 8576000 | M263: 23.8 | N263: =ROUND((H263+I263+J263+K263)/IF($M$2>26,26,$M$2)*M263,0) -> 7850338 | O263: 2 | P263: =ROUND((H263+I263+J263+K263)/IF($M$2>26,26,$M$2)*O263,0) -> 659692 | Q263: 0 | R263: =IF(M263>0,ROUND(N263/IF(M263>26,26,M263)/8*Q263*30%,0),0) -> 0 | S263: =N263+P263+R263 -> 8510030 | T263: 0 | U263: 0 | V263: 200000 | W263: 500000 | X263: 0 | Y263: 400000 | Z263: 411209 | AC263: 0 | AD263: 0 | AE263: 61846.15 | AG263: =ROUND(SUM(S263:AF263)-AA263,0) -> 10083085 | AH263: 28 | AI263: 0 | AJ263: 0 | AK263: 0 | AL263: 0 | AM263: =ROUND((N263/IF(M263>26,26,M263)/8*(AH263*$AH$5+AI263*$AI$5+AJ263*$AJ$5+AK263*$AK$5+AL263*$AL$5)),0) -> 1731692 | AN263: =ROUND(AG263+AM263,0) -> 11814777 | AO263: 900480 | AP263: 44100 | AQ263: =+VLOOKUP($B263,[1]Sheet1!$C$15:$BW$1300,52,0) -> 0 | AR263: 0 | AS263: 0 | AT263: =+ROUND(SUM(AN263:AN263)-SUM(AO263:AS263),0) -> 10870197 | AW263: NGUYEN THI LIEN | AX263: 050040965057 | AY263: SK1 Box | AZ263: 627 | BA263: =+IF(AY263="SK1 Box","Box",IF(AY263="Seaman","Seaman","Bag")) -> Box
A264: =SUBTOTAL(3,B$6:B264) -> 0 | B264: C5841 | C264: Trần Văn Nhân | D264: 41491 | E264: FACTORY A | F264: P6 - Production Office | G264: Factory manager | H264: 15240000 | I264: 9200000 | J264: 0 | K264: 0 | L264: =SUM(H264:K264) -> 24440000 | M264: 23.7 | N264: =ROUND((H264+I264+J264+K264)/IF($M$2>26,26,$M$2)*M264,0) -> 22278000 | O264: 2 | P264: =ROUND((H264+I264+J264+K264)/IF($M$2>26,26,$M$2)*O264,0) -> 1880000 | Q264: 0 | R264: =IF(M264>0,ROUND(N264/IF(M264>26,26,M264)/8*Q264*30%,0),0) -> 0 | S264: =N264+P264+R264 -> 24158000 | T264: 691923 | U264: 0 | V264: 0 | W264: 0 | X264: 0 | Y264: 0 | Z264: 0 | AC264: 0 | AD264: 0 | AE264: 0 | AG264: =ROUND(SUM(S264:AF264)-AA264,0) -> 24849923 | AH264: 0 | AI264: 0 | AJ264: 0 | AK264: 0 | AL264: 0 | AM264: =ROUND((N264/IF(M264>26,26,M264)/8*(AH264*$AH$5+AI264*$AI$5+AJ264*$AJ$5+AK264*$AK$5+AL264*$AL$5)),0) -> 0 | AN264: =ROUND(AG264+AM264,0) -> 24849923 | AO264: 2566200 | AP264: 44100 | AQ264: =+VLOOKUP($B264,[1]Sheet1!$C$15:$BW$1300,52,0) -> 94590 | AR264: 0 | AS264: 0 | AT264: =+ROUND(SUM(AN264:AN264)-SUM(AO264:AS264),0) -> 22145033 | AW264: TRAN VAN NHAN | AX264: 050040817023 | AY264: SK1 Box | AZ264: 627 | BA264: Manager
A265: =SUBTOTAL(3,B$6:B265) -> 0 | B265: C6063 | C265: Đồng Thị Thu Hiền | D265: 41621 | E265: FACTORY A | F265: P6 - Production Office | G265: Factory vice manager | H265: 6876000 | I265: 6600000 | J265: 0 | K265: 0 | L265: =SUM(H265:K265) -> 13476000 | M265: 24 | N265: =ROUND((H265+I265+J265+K265)/IF($M$2>26,26,$M$2)*M265,0) -> 12439385 | O265: 2 | P265: =ROUND((H265+I265+J265+K265)/IF($M$2>26,26,$M$2)*O265,0) -> 1036615 | Q265: 0 | R265: =IF(M265>0,ROUND(N265/IF(M265>26,26,M265)/8*Q265*30%,0),0) -> 0 | S265: =N265+P265+R265 -> 13476000 | T265: 0 | U265: 0 | V265: 200000 | W265: 500000 | X265: 0 | Y265: 400000 | Z265: 0 | AC265: 0 | AD265: 0 | AE265: 97182.695 | AG265: =ROUND(SUM(S265:AF265)-AA265,0) -> 14673183 | AH265: 28 | AI265: 0 | AJ265: 0 | AK265: 0 | AL265: 0 | AM265: =ROUND((N265/IF(M265>26,26,M265)/8*(AH265*$AH$5+AI265*$AI$5+AJ265*$AJ$5+AK265*$AK$5+AL265*$AL$5)),0) -> 2721115 | AN265: =ROUND(AG265+AM265,0) -> 17394298 | AO265: 1414980 | AP265: 44100 | AQ265: =+VLOOKUP($B265,[1]Sheet1!$C$15:$BW$1300,52,0) -> 0 | AR265: 0 | AS265: 0 | AT265: =+ROUND(SUM(AN265:AN265)-SUM(AO265:AS265),0) -> 15935218 | AW265: DONG THI THU HIEN | AX265: 050040958301 | AY265: SK1 Box | AZ265: 627 | BA265: =+IF(AY265="SK1 Box","Box",IF(AY265="Seaman","Seaman","Bag")) -> Box
A266: =SUBTOTAL(3,B$6:B266) -> 0 | B266: C13547 | C266: Nguyễn Thị Cẩm Tiên | D266: 44270 | E266: FACTORY A | F266: P6 - QC | G266: QC Worker | H266: 5931000 | I266: 1100000 | J266: 0 | K266: 0 | L266: =SUM(H266:K266) -> 7031000 | M266: 24 | N266: =ROUND((H266+I266+J266+K266)/IF($M$2>26,26,$M$2)*M266,0) -> 6490154 | O266: 2 | P266: =ROUND((H266+I266+J266+K266)/IF($M$2>26,26,$M$2)*O266,0) -> 540846 | Q266: 0 | R266: =IF(M266>0,ROUND(N266/IF(M266>26,26,M266)/8*Q266*30%,0),0) -> 0 | S266: =N266+P266+R266 -> 7031000 | T266: 0 | U266: 0 | V266: 200000 | W266: 500000 | X266: 0 | Y266: 400000 | Z266: 400000 | AC266: 100000 | AD266: 0 | AE266: 50704.328 | AG266: =ROUND(SUM(S266:AF266)-AA266,0) -> 8681704 | AH266: 0 | AI266: 0 | AJ266: 0 | AK266: 0 | AL266: 0 | AM266: =ROUND((N266/IF(M266>26,26,M266)/8*(AH266*$AH$5+AI266*$AI$5+AJ266*$AJ$5+AK266*$AK$5+AL266*$AL$5)),0) -> 0 | AN266: =ROUND(AG266+AM266,0) -> 8681704 | AO266: 738255 | AP266: 44100 | AQ266: =+VLOOKUP($B266,[1]Sheet1!$C$15:$BW$1300,52,0) -> 0 | AR266: 0 | AS266: 0 | AT266: =+ROUND(SUM(AN266:AN266)-SUM(AO266:AS266),0) -> 7899349 | AW266: NGUYEN THI CAM TIEN | AX266: 050040965758 | AY266: SK1 Box | AZ266: 622 | BA266: =+IF(AY266="SK1 Box","Box",IF(AY266="Seaman","Seaman","Bag")) -> Box
A267: =SUBTOTAL(3,B$6:B267) -> 0 | B267: C13762 | C267: Nguyễn Thị Tuyết Ngân | D267: 44287 | E267: FACTORY A | F267: P6 - QC | G267: QC worker | H267: 5931000 | I267: 1100000 | J267: 0 | K267: 0 | L267: =SUM(H267:K267) -> 7031000 | M267: 24 | N267: =ROUND((H267+I267+J267+K267)/IF($M$2>26,26,$M$2)*M267,0) -> 6490154 | O267: 2 | P267: =ROUND((H267+I267+J267+K267)/IF($M$2>26,26,$M$2)*O267,0) -> 540846 | Q267: 0 | R267: =IF(M267>0,ROUND(N267/IF(M267>26,26,M267)/8*Q267*30%,0),0) -> 0 | S267: =N267+P267+R267 -> 7031000 | T267: 0 | U267: 0 | V267: 200000 | W267: 500000 | X267: 0 | Y267: 400000 | Z267: 500000 | AC267: 100000 | AD267: 0 | AE267: 50704.328 | AG267: =ROUND(SUM(S267:AF267)-AA267,0) -> 8781704 | AH267: 21.5 | AI267: 0 | AJ267: 0 | AK267: 0 | AL267: 0 | AM267: =ROUND((N267/IF(M267>26,26,M267)/8*(AH267*$AH$5+AI267*$AI$5+AJ267*$AJ$5+AK267*$AK$5+AL267*$AL$5)),0) -> 1090143 | AN267: =ROUND(AG267+AM267,0) -> 9871847 | AO267: 738255 | AP267: 44100 | AQ267: =+VLOOKUP($B267,[1]Sheet1!$C$15:$BW$1300,52,0) -> 0 | AR267: 0 | AS267: 0 | AT267: =+ROUND(SUM(AN267:AN267)-SUM(AO267:AS267),0) -> 9089492 | AW267: NGUYEN THI TUYET NGAN | AX267: 050127345462 | AY267: SK1 Box | AZ267: 622 | BA267: =+IF(AY267="SK1 Box","Box",IF(AY267="Seaman","Seaman","Bag")) -> Box
A268: =SUBTOTAL(3,B$6:B268) -> 0 | B268: C15453 | C268: Đặng Vũ Thảo Huyền | D268: 45164 | E268: FACTORY A | F268: P6 - QC | G268: QC worker | H268: 5538000 | I268: 500000 | J268: 0 | K268: 0 | L268: =SUM(H268:K268) -> 6038000 | M268: 23.5 | N268: =ROUND((H268+I268+J268+K268)/IF($M$2>26,26,$M$2)*M268,0) -> 5457423 | O268: 2 | P268: =ROUND((H268+I268+J268+K268)/IF($M$2>26,26,$M$2)*O268,0) -> 464462 | Q268: 0 | R268: =IF(M268>0,ROUND(N268/IF(M268>26,26,M268)/8*Q268*30%,0),0) -> 0 | S268: =N268+P268+R268 -> 5921885 | T268: 0 | U268: 0 | V268: 200000 | W268: 500000 | X268: 0 | Y268: 400000 | Z268: 391700 | AC268: 0 | AD268: 0 | AE268: 43543.269 | AG268: =ROUND(SUM(S268:AF268)-AA268,0) -> 7457128 | AH268: 28 | AI268: 0 | AJ268: 0 | AK268: 0 | AL268: 0 | AM268: =ROUND((N268/IF(M268>26,26,M268)/8*(AH268*$AH$5+AI268*$AI$5+AJ268*$AJ$5+AK268*$AK$5+AL268*$AL$5)),0) -> 1219212 | AN268: =ROUND(AG268+AM268,0) -> 8676340 | AO268: 633990 | AP268: 44100 | AQ268: =+VLOOKUP($B268,[1]Sheet1!$C$15:$BW$1300,52,0) -> 0 | AR268: 0 | AS268: 0 | AT268: =+ROUND(SUM(AN268:AN268)-SUM(AO268:AS268),0) -> 7998250 | AW268: DANG VU THAO HUYEN | AX268: 050120705986 | AY268: SK1 Box | AZ268: 622 | BA268: =+IF(AY268="SK1 Box","Box",IF(AY268="Seaman","Seaman","Bag")) -> Box
A269: =SUBTOTAL(3,B$6:B269) -> 0 | B269: C15906 | C269: Phạm Thị Thu Thương | D269: 45419 | E269: FACTORY A | F269: P6 - QC | G269: QC worker | H269: 5274000 | I269: 500000 | J269: 0 | K269: 0 | L269: =SUM(H269:K269) -> 5774000 | M269: 22.8 | N269: =ROUND((H269+I269+J269+K269)/IF($M$2>26,26,$M$2)*M269,0) -> 5063354 | O269: 3 | P269: =ROUND((H269+I269+J269+K269)/IF($M$2>26,26,$M$2)*O269,0) -> 666231 | Q269: 0 | R269: =IF(M269>0,ROUND(N269/IF(M269>26,26,M269)/8*Q269*30%,0),0) -> 0 | S269: =N269+P269+R269 -> 5729585 | T269: 0 | U269: 0 | V269: 200000 | W269: 500000 | X269: 0 | Y269: 400000 | Z269: 380000 | AC269: 0 | AD269: 0 | AE269: 41639.424 | AG269: =ROUND(SUM(S269:AF269)-AA269,0) -> 7251224 | AH269: 24 | AI269: 0 | AJ269: 0 | AK269: 0 | AL269: 0 | AM269: =ROUND((N269/IF(M269>26,26,M269)/8*(AH269*$AH$5+AI269*$AI$5+AJ269*$AJ$5+AK269*$AK$5+AL269*$AL$5)),0) -> 999346 | AN269: =ROUND(AG269+AM269,0) -> 8250570 | AO269: 606270 | AP269: 44100 | AQ269: =+VLOOKUP($B269,[1]Sheet1!$C$15:$BW$1300,52,0) -> 0 | AR269: 0 | AS269: 0 | AT269: =+ROUND(SUM(AN269:AN269)-SUM(AO269:AS269),0) -> 7600200 | AW269: PHAM THI THU THUONG | AX269: 050135011281 | AY269: SK1 Box | AZ269: 622 | BA269: =+IF(AY269="SK1 Box","Box",IF(AY269="Seaman","Seaman","Bag")) -> Box
A270: =SUBTOTAL(3,B$6:B270) -> 0 | B270: C15959 | C270: Khiếu Thị Hoàng Vân | D270: 45444 | E270: FACTORY A | F270: P6 - QC | G270: QC worker | H270: 5274000 | I270: 500000 | J270: 0 | K270: 0 | L270: =SUM(H270:K270) -> 5774000 | M270: 23.8 | N270: =ROUND((H270+I270+J270+K270)/IF($M$2>26,26,$M$2)*M270,0) -> 5285431 | O270: 2 | P270: =ROUND((H270+I270+J270+K270)/IF($M$2>26,26,$M$2)*O270,0) -> 444154 | Q270: 0 | R270: =IF(M270>0,ROUND(N270/IF(M270>26,26,M270)/8*Q270*30%,0),0) -> 0 | S270: =N270+P270+R270 -> 5729585 | T270: 0 | U270: 0 | V270: 200000 | W270: 500000 | X270: 0 | Y270: 400000 | Z270: 396700 | AC270: 0 | AD270: 0 | AE270: 41639.425 | AG270: =ROUND(SUM(S270:AF270)-AA270,0) -> 7267924 | AH270: 28 | AI270: 0 | AJ270: 0 | AK270: 0 | AL270: 0 | AM270: =ROUND((N270/IF(M270>26,26,M270)/8*(AH270*$AH$5+AI270*$AI$5+AJ270*$AJ$5+AK270*$AK$5+AL270*$AL$5)),0) -> 1165904 | AN270: =ROUND(AG270+AM270,0) -> 8433828 | AO270: 606270 | AP270: 44100 | AQ270: =+VLOOKUP($B270,[1]Sheet1!$C$15:$BW$1300,52,0) -> 0 | AR270: 0 | AS270: 0 | AT270: =+ROUND(SUM(AN270:AN270)-SUM(AO270:AS270),0) -> 7783458 | AW270: KHIEU THI HOANG VAN | AX270: 050074107580 | AY270: SK1 Box | AZ270: 622 | BA270: =+IF(AY270="SK1 Box","Box",IF(AY270="Seaman","Seaman","Bag")) -> Box
A271: =SUBTOTAL(3,B$6:B271) -> 0 | B271: C16460 | C271: Hà Nguyễn Tấn Trung | D271: 45710 | E271: FACTORY A | F271: P6 - QC | G271: QC worker | H271: 5023000 | I271: 500000 | J271: 0 | K271: 0 | L271: =SUM(H271:K271) -> 5523000 | M271: 23 | N271: =ROUND((H271+I271+J271+K271)/IF($M$2>26,26,$M$2)*M271,0) -> 4885731 | O271: 3 | P271: =ROUND((H271+I271+J271+K271)/IF($M$2>26,26,$M$2)*O271,0) -> 637269 | Q271: 0 | R271: =IF(M271>0,ROUND(N271/IF(M271>26,26,M271)/8*Q271*30%,0),0) -> 0 | S271: =N271+P271+R271 -> 5523000 | T271: 0 | U271: 0 | V271: 200000 | W271: 500000 | X271: 0 | Y271: 400000 | Z271: 383300 | AC271: 0 | AD271: 0 | AE271: 0 | AG271: =ROUND(SUM(S271:AF271)-AA271,0) -> 7006300 | AH271: 20 | AI271: 0 | AJ271: 0 | AK271: 0 | AL271: 0 | AM271: =ROUND((N271/IF(M271>26,26,M271)/8*(AH271*$AH$5+AI271*$AI$5+AJ271*$AJ$5+AK271*$AK$5+AL271*$AL$5)),0) -> 796587 | AN271: =ROUND(AG271+AM271,0) -> 7802887 | AO271: 579915 | AP271: 0 | AQ271: =+VLOOKUP($B271,[1]Sheet1!$C$15:$BW$1300,52,0) -> 0 | AR271: 0 | AS271: 0 | AT271: =+ROUND(SUM(AN271:AN271)-SUM(AO271:AS271),0) -> 7222972 | AW271: HA NGUYEN TAN TRUNG | AX271: 050968075690 | AY271: SK1 Box | AZ271: 622 | BA271: =+IF(AY271="SK1 Box","Box",IF(AY271="Seaman","Seaman","Bag")) -> Box
A272: =SUBTOTAL(3,B$6:B272) -> 0 | B272: C2982 | C272: Đỗ Thị Nga | D272: 40369 | E272: FACTORY A | F272: P6 - QC | G272: QC worker | H272: 5931000 | I272: 1100000 | J272: 0 | K272: 0 | L272: =SUM(H272:K272) -> 7031000 | M272: 23.9 | N272: =ROUND((H272+I272+J272+K272)/IF($M$2>26,26,$M$2)*M272,0) -> 6463112 | O272: 2 | P272: =ROUND((H272+I272+J272+K272)/IF($M$2>26,26,$M$2)*O272,0) -> 540846 | Q272: 0 | R272: =IF(M272>0,ROUND(N272/IF(M272>26,26,M272)/8*Q272*30%,0),0) -> 0 | S272: =N272+P272+R272 -> 7003958 | T272: 0 | U272: 0 | V272: 200000 | W272: 500000 | X272: 0 | Y272: 400000 | Z272: 398300 | AC272: 100000 | AD272: 0 | AE272: 50704.331 | AG272: =ROUND(SUM(S272:AF272)-AA272,0) -> 8652962 | AH272: 28 | AI272: 0 | AJ272: 0 | AK272: 0 | AL272: 0 | AM272: =ROUND((N272/IF(M272>26,26,M272)/8*(AH272*$AH$5+AI272*$AI$5+AJ272*$AJ$5+AK272*$AK$5+AL272*$AL$5)),0) -> 1419721 | AN272: =ROUND(AG272+AM272,0) -> 10072683 | AO272: 738255 | AP272: 44100 | AQ272: =+VLOOKUP($B272,[1]Sheet1!$C$15:$BW$1300,52,0) -> 0 | AR272: 0 | AS272: 0 | AT272: =+ROUND(SUM(AN272:AN272)-SUM(AO272:AS272),0) -> 9290328 | AW272: DO THI NGA | AX272: 050040966088 | AY272: SK1 Box | AZ272: 622 | BA272: =+IF(AY272="SK1 Box","Box",IF(AY272="Seaman","Seaman","Bag")) -> Box
A273: =SUBTOTAL(3,B$6:B273) -> 0 | B273: C6248 | C273: Huỳnh Văn Mẫu Tám | D273: 41764 | E273: FACTORY A | F273: P6 - QC | G273: Box QC leader | H273: 8176000 | I273: 3200000 | J273: 0 | K273: 5200000 | L273: =SUM(H273:K273) -> 16576000 | M273: 23.9 | N273: =ROUND((H273+I273+J273+K273)/IF($M$2>26,26,$M$2)*M273,0) -> 15237169 | O273: 2 | P273: =ROUND((H273+I273+J273+K273)/IF($M$2>26,26,$M$2)*O273,0) -> 1275077 | Q273: 0 | R273: =IF(M273>0,ROUND(N273/IF(M273>26,26,M273)/8*Q273*30%,0),0) -> 0 | S273: =N273+P273+R273 -> 16512246 | T273: 0 | U273: 0 | V273: 200000 | W273: 500000 | X273: 0 | Y273: 400000 | Z273: 697100 | AC273: 100000 | AD273: 0 | AE273: 0 | AG273: =ROUND(SUM(S273:AF273)-AA273,0) -> 18409346 | AH273: 28 | AI273: 0 | AJ273: 0 | AK273: 0 | AL273: 0 | AM273: =ROUND((N273/IF(M273>26,26,M273)/8*(AH273*$AH$5+AI273*$AI$5+AJ273*$AJ$5+AK273*$AK$5+AL273*$AL$5)),0) -> 3347077 | AN273: =ROUND(AG273+AM273,0) -> 21756423 | AO273: 1740480 | AP273: 44100 | AQ273: =+VLOOKUP($B273,[1]Sheet1!$C$15:$BW$1300,52,0) -> 0 | AR273: 0 | AS273: 0 | AT273: =+ROUND(SUM(AN273:AN273)-SUM(AO273:AS273),0) -> 19971843 | AW273: HUYNH VAN MAU TAM | AX273: 050042516527 | AY273: SK1 Box | AZ273: 622 | BA273: =+IF(AY273="SK1 Box","Box",IF(AY273="Seaman","Seaman","Bag")) -> Box
A274: =SUBTOTAL(3,B$6:B274) -> 0 | B274: C14461 | C274: Nguyễn Ngọc Tùng | D274: 44604 | E274: FACTORY A | F274: P6 - WIP | G274: WIP worker | H274: 5931000 | I274: 500000 | J274: 0 | K274: 0 | L274: =SUM(H274:K274) -> 6431000 | M274: 23.9 | N274: =ROUND((H274+I274+J274+K274)/IF($M$2>26,26,$M$2)*M274,0) -> 5911573 | O274: 2 | P274: =ROUND((H274+I274+J274+K274)/IF($M$2>26,26,$M$2)*O274,0) -> 494692 | Q274: 0 | R274: =IF(M274>0,ROUND(N274/IF(M274>26,26,M274)/8*Q274*30%,0),0) -> 0 | S274: =N274+P274+R274 -> 6406265 | T274: 0 | U274: 0 | V274: 200000 | W274: 500000 | X274: 0 | Y274: 400000 | Z274: 590813 | AC274: 0 | AD274: 0 | AE274: 0 | AG274: =ROUND(SUM(S274:AF274)-AA274,0) -> 8097078 | AH274: 28 | AI274: 0 | AJ274: 0 | AK274: 0 | AL274: 0 | AM274: =ROUND((N274/IF(M274>26,26,M274)/8*(AH274*$AH$5+AI274*$AI$5+AJ274*$AJ$5+AK274*$AK$5+AL274*$AL$5)),0) -> 1298567 | AN274: =ROUND(AG274+AM274,0) -> 9395645 | AO274: 675255 | AP274: 44100 | AQ274: =+VLOOKUP($B274,[1]Sheet1!$C$15:$BW$1300,52,0) -> 0 | AR274: 0 | AS274: 0 | AT274: =+ROUND(SUM(AN274:AN274)-SUM(AO274:AS274),0) -> 8676290 | AW274: NGUYEN NGOC TUNG | AX274: 050131181482 | AY274: SK1 Box | AZ274: 622 | BA274: =+IF(AY274="SK1 Box","Box",IF(AY274="Seaman","Seaman","Bag")) -> Box
