Workbook

Sheet Sheet1
A1: 1
A2: 2
A3: 3 | B3: 2 | C3: 2 | D3: 2 | E3: 2 | F3: 2 | G3: 1 | H3: 1 | I3: 1 | J3: 1 | K3: 1 | L3: 1 | M3: 1 | N3: 1 | O3: 1 | P3: 1 | Q3: 1 | R3: 1 | S3: 1 | T3: 1 | U3: 1 | V3: 1 | W3: 1 | X3: 1 | Y3: 1 | Z3: 1 | AA3: 1 | AB3: 1 | AC3: 1 | AD3: 1 | AE3: 1 | AF3: 1 | AG3: 1 | AH3: 1 | AI3: 1 | AJ3: 1 | AK3: 1 | AL3: 1 | AM3: 1 | AN3: 1 | AO3: 1 | AP3: 1 | AQ3: 1 | AR3: 1 | AS3: 1 | AT3: 1 | AU3: 1 | AV3: 1 | AW3: 1 | AX3: 1 | AY3: 1 | AZ3: 1 | BA3: 1 | BB3: 1 | BC3: 1 | BD3: 1 | BE3: 1 | BF3: 1 | BG3: 1 | BH3: 1 | BI3: 1 | BJ3: 1 | BK3: 1 | BL3: 1 | BM3: 1 | BN3: 1 | BO3: 1 | BP3: 1 | BQ3: 1 | BR3: 1 | BS3: 1 | BT3: 1 | BU3: 1 | BV3: 1 | BW3: 1 | BX3: 1 | BY3: 1 | BZ3: 1 | CA3: 1 | CB3: 1 | CC3: 1 | CD3: 1 | CE3: 1 | CF3: 1 | CG3: 1 | CH3: 1 | CI3: 1 | CJ3: 1 | CK3: 1 | CL3: 1 | CM3: 1 | CN3: 1 | CO3: 1 | CP3: 1
A4: 4 | B4: No | C4: NameEN | D4: NameKR | E4: MaCongViecAll | F4: GroupbyChucDanhAll | G4: SoLuongNVAll | H4: BasicSalaryAll | I4: PhuCapAll | J4: TienTangCaAll | K4: Luong1GioAll | L4: GioLamViecKhongCoNghiAll | M4: GioTangCa150All | N4: GioTangCaCN200All | O4: GioTangCaDem210All | P4: GioTangCaDemCN270All | Q4: GioTangCaLe300All | R4: GioTangCaDemLe390All | S4: TongTangCaAll | T4: TongTangCaVaHCDaChuyenAll | U4: GioLamDem130All | V4: TienCaDem130All | W4: TongLuongAll | X4: CongDoanCtyTraAll | Y4: BHCtyTraAll | Z4: TongChiPhiAll | AA4: BHNVDongAll | AB4: TTCNAll | AC4: CongDoanNVDongAll | AD4: TroCapConNhoAll | AE4: TroCapPhuNuAll | AF4: HoTroKhacAll | AG4: ThucNhanAll | AH4: LuongChoViecAll | AI4: MaCongViecD1 | AJ4: GroupbyChucDanhD1 | AK4: SoLuongNVD1 | AL4: BasicSalaryD1 | AM4: PhuCapD1 | AN4: TienTangCaD1 | AO4: Luong1GioD1 | AP4: GioLamViecKhongCoNghiD1 | AQ4: GioTangCa150D1 | AR4: GioTangCaCN200D1 | AS4: GioTangCaDem210D1 | AT4: GioTangCaDemCN270D1 | AU4: GioTangCaLe300D1 | AV4: GioTangCaDemLe390D1 | AW4: TongTangCaD1 | AX4: TongTangCaVaHCDaChuyenD1 | AY4: GioLamDem130D1 | AZ4: TienCaDem130D1 | BA4: TongLuongD1 | BB4: CongDoanCtyTraD1 | BC4: BHCtyTraD1 | BD4: TongChiPhiD1 | BE4: BHNVDongD1 | BF4: TTCND1 | BG4: CongDoanNVDongD1 | BH4: TroCapConNhoD1 | BI4: TroCapPhuNuD1 | BJ4: HoTroKhacD1 | BK4: ThucNhanD1 | BL4: LuongChoViecD1 | BM4: MaCongViecD2 | BN4: GroupbyChucDanhD2 | BO4: SoLuongNVD2 | BP4: BasicSalaryD2 | BQ4: PhuCapD2 | BR4: TienTangCaD2 | BS4: Luong1GioD2 | BT4: GioLamViecKhongCoNghiD2 | BU4: GioTangCa150D2 | BV4: GioTangCaCN200D2 | BW4: GioTangCaDem210D2 | BX4: GioTangCaDemCN270D2 | BY4: GioTangCaLe300D2 | BZ4: GioTangCaDemLe390D2 | CA4: TongTangCaD2 | CB4: TongTangCaVaHCDaChuyenD2 | CC4: GioLamDem130D2 | CD4: TienCaDem130D2 | CE4: TongLuongD2 | CF4: CongDoanCtyTraD2 | CG4: BHCtyTraD2 | CH4: TongChiPhiD2 | CI4: BHNVDongD2 | CJ4: TTCND2 | CK4: CongDoanNVDongD2 | CL4: TroCapConNhoD2 | CM4: TroCapPhuNuD2 | CN4: HoTroKhacD2 | CO4: ThucNhanD2 | CP4: LuongChoViecD2 | CQ4: MaCongViecAllVT | CR4: GroupbyViTriAllVT | CS4: SoLuongNVAllVT | CT4: BasicSalaryAllVT | CU4: PhuCapAllVT | CV4: TienTangCaAllVT | CW4: Luong1GioAllVT | CX4: GioLamViecKhongCoNghiAllVT | CY4: GioTangCa150AllVT | CZ4: GioTangCaCN200AllVT | DA4: GioTangCaDem210AllVT | DB4: GioTangCaDemCN270AllVT | DC4: GioTangCaLe300AllVT | DD4: GioTangCaDemLe390AllVT | DE4: TongTangCaAllVT | DF4: TongTangCaVaHCDaChuyenAllVT | DG4: GioLamDem130AllVT | DH4: TienCaDem130AllVT | DI4: TongLuongAllVT | DJ4: CongDoanCtyTraAllVT | DK4: BHCtyTraAllVT | DL4: TongChiPhiAllVT | DM4: BHNVDongAllVT | DN4: TTCNAllVT | DO4: CongDoanNVDongAllVT | DP4: TroCapConNhoAllVT | DQ4: TroCapPhuNuAllVT | DR4: HoTroKhacAllVT | DS4: ThucNhanAllVT | DT4: LuongChoViecAllVT | DU4: MaCongViecD1VT | DV4: GroupbyViTriD1VT | DW4: SoLuongNVD1VT | DX4: BasicSalaryD1VT | DY4: PhuCapD1VT | DZ4: TienTangCaD1VT | EA4: Luong1GioD1VT | EB4: GioLamViecKhongCoNghiD1VT | EC4: GioTangCa150D1VT | ED4: GioTangCaCN200D1VT | EE4: GioTangCaDem210D1VT | EF4: GioTangCaDemCN270D1VT | EG4: GioTangCaLe300D1VT | EH4: GioTangCaDemLe390D1VT | EI4: TongTangCaD1VT | EJ4: TongTangCaVaHCDaChuyenD1VT | EK4: GioLamDem130D1VT | EL4: TienCaDem130D1VT | EM4: TongLuongD1VT | EN4: CongDoanCtyTraD1VT | EO4: BHCtyTraD1VT | EP4: TongChiPhiD1VT | EQ4: BHNVDongD1VT | ER4: TTCND1VT | ES4: CongDoanNVDongD1VT | ET4: TroCapConNhoD1VT | EU4: TroCapPhuNuD1VT | EV4: HoTroKhacD1VT | EW4: ThucNhanD1VT | EX4: LuongChoViecD1VT | EY4: MaCongViecD2VT | EZ4: GroupbyViTriD2VT | FA4: SoLuongNVD2VT | FB4: BasicSalaryD2VT | FC4: PhuCapD2VT | FD4: TienTangCaD2VT | FE4: Luong1GioD2VT | FF4: GioLamViecKhongCoNghiD2VT | FG4: GioTangCa150D2VT | FH4: GioTangCaCN200D2VT | FI4: GioTangCaDem210D2VT | FJ4: GioTangCaDemCN270D2VT | FK4: GioTangCaLe300D2VT | FL4: GioTangCaDemLe390D2VT | FM4: TongTangCaD2VT | FN4: TongTangCaVaHCDaChuyenD2VT | FO4: GioLamDem130D2VT | FP4: TienCaDem130D2VT | FQ4: TongLuongD2VT | FR4: CongDoanCtyTraD2VT | FS4: BHCtyTraD2VT | FT4: TongChiPhiD2VT | FU4: BHNVDongD2VT | FV4: TTCND2VT | FW4: CongDoanNVDongD2VT | FX4: TroCapConNhoD2VT | FY4: TroCapPhuNuD2VT | FZ4: HoTroKhacD2VT | GA4: ThucNhanD2VT | GB4: LuongChoViecD2VT | GC4: ActualWorkingDay | GD4: PublicHoliday | GE4: WorkingSaturday | GF4: SaturdayOT
B6: 1

Sheet Sum
A1: =TEXT(Sheet1!A1*28,"MMM") & " " & Sheet1!A2 & " SALARY" -> Jan 2 SALARY
A2: TOTAL
A3: Classification | E3: Manpower | F3: Basic salary (A) | G3: Allowance (B) | H3: OT amount '© | I3: OVERTIME | S3: All 30% | U3: Total salary (A+B+C + D) | V3: Union paid by company | W3: Insurance paied by company | X3: Total amount | Y3: Insurance paied by employee (10.5%) (E) | Z3: PIT | AA3: Union fee paid by employee | AB3: Child allowance | AC3: Women allowance | AD3: Resignation support | AE3: Net income | AF3: Bonus
I4: Unit price/hour | J4: Working hour excluded Annual leave | K4: (150%) Số giờ tăng ca ngày thường / Normal working day OT No. | L4: (200%) Tăng ca ngày nghỉ | M4: 210% tăng ca đêm ngày thường | N4: 270% tăng ca đêm ngày nghỉ | O4: 300% tăng ca ngày lễ, tết | P4: 390% tăng ca đêm ngày lễ, tết | Q4: Total OT hour | R4: Total working & OT converted | S4: Hour | T4: Amount (D)
A5: Office | B5: Office 1 | C5: 1st floor | D5: Indirect | E5: =Sheet1!G6 -> 0 | F5: =Sheet1!H6 -> 0 | G5: =Sheet1!I6 -> 0 | H5: =Sheet1!J6 -> 0 | I5: =Sheet1!K6 -> 0 | J5: =Sheet1!L6 -> 0 | K5: =Sheet1!M6 -> 0 | L5: =Sheet1!N6 -> 0 | ... AF5: =Sheet1!AH6 -> 0
B6: Office 2 | C6: 2nd floor | D6: Admin | E6: =Sheet1!G7 -> 0 | F6: =Sheet1!H7 -> 0 | G6: =Sheet1!I7 -> 0 | H6: =Sheet1!J7 -> 0 | I6: =Sheet1!K7 -> 0 | J6: =Sheet1!L7 -> 0 | K6: =Sheet1!M7 -> 0 | L6: =Sheet1!N7 -> 0 | ... AF6: =Sheet1!AH7 -> 0
B7: Subtotal | E7: =SUBTOTAL(9,E5:E6) -> 0 | F7: =SUBTOTAL(9,F5:F6) -> 0 | G7: =SUBTOTAL(9,G5:G6) -> 0 | H7: =SUBTOTAL(9,H5:H6) -> 0 | I7: =U7/R7 -> #DIV/0! | J7: =SUBTOTAL(9,J5:J6) -> 0 | K7: =SUBTOTAL(9,K5:K6) -> 0 | L7: =SUBTOTAL(9,L5:L6) -> 0 | M7: =SUBTOTAL(9,M5:M6) -> 0 | N7: =SUBTOTAL(9,N5:N6) -> 0 | O7: =SUBTOTAL(9,O5:O6) -> 0 | P7: =SUBTOTAL(9,P5:P6) -> 0 | Q7: =SUBTOTAL(9,Q5:Q6) -> 0 | ... AE7: =SUBTOTAL(9,AE5:AE6) -> 0
A8: Worker | B8: Warehouse | C8: Delivery | D8: Indirect | E8: =Sheet1!G8 -> 0 | F8: =Sheet1!H8 -> 0 | G8: =Sheet1!I8 -> 0 | H8: =Sheet1!J8 -> 0 | I8: =Sheet1!K8 -> 0 | J8: =Sheet1!L8 -> 0 | K8: =Sheet1!M8 -> 0 | L8: =Sheet1!N8 -> 0 | ... AF8: =Sheet1!AH8 -> 0
C9: MCT worker | D9: Indirect | E9: =Sheet1!G9 -> 0 | F9: =Sheet1!H9 -> 0 | G9: =Sheet1!I9 -> 0 | H9: =Sheet1!J9 -> 0 | I9: =Sheet1!K9 -> 0 | J9: =Sheet1!L9 -> 0 | K9: =Sheet1!M9 -> 0 | L9: =Sheet1!N9 -> 0 | ... AF9: =Sheet1!AH9 -> 0
C10: Subtotal | E10: =SUBTOTAL(9,E8:E9) -> 0 | F10: =SUBTOTAL(9,F8:F9) -> 0 | G10: =SUBTOTAL(9,G8:G9) -> 0 | H10: =SUBTOTAL(9,H8:H9) -> 0 | I10: =U10/R10 -> #DIV/0! | J10: =SUBTOTAL(9,J8:J9) -> 0 | K10: =SUBTOTAL(9,K8:K9) -> 0 | L10: =SUBTOTAL(9,L8:L9) -> 0 | M10: =SUBTOTAL(9,M8:M9) -> 0 | N10: =SUBTOTAL(9,N8:N9) -> 0 | O10: =SUBTOTAL(9,O8:O9) -> 0 | P10: =SUBTOTAL(9,P8:P9) -> 0 | Q10: =SUBTOTAL(9,Q8:Q9) -> 0 | ... AE10: =SUBTOTAL(9,AE8:AE9) -> 0
B11: Manufacture | C11: FM/DF Production | D11: Direct | E11: =Sheet1!G10 -> 0 | F11: =Sheet1!H10 -> 0 | G11: =Sheet1!I10 -> 0 | H11: =Sheet1!J10 -> 0 | I11: =Sheet1!K10 -> 0 | J11: =Sheet1!L10 -> 0 | K11: =Sheet1!M10 -> 0 | L11: =Sheet1!N10 -> 0 | ... AF11: =Sheet1!AH10 -> 0 | AG11: =+((L11+N11)/11.5)/E11 -> #DIV/0!
C12: MET/MMT | D12: Indirect | E12: =Sheet1!G11 -> 0 | F12: =Sheet1!H11 -> 0 | G12: =Sheet1!I11 -> 0 | H12: =Sheet1!J11 -> 0 | I12: =Sheet1!K11 -> 0 | J12: =Sheet1!L11 -> 0 | K12: =Sheet1!M11 -> 0 | L12: =Sheet1!N11 -> 0 | ... AF12: =Sheet1!AH11 -> 0 | AG12: =+((L12+N12)/11.5)/E12 -> #DIV/0!
C13: MAT worker | D13: Direct | E13: =Sheet1!G13 -> 0 | F13: =Sheet1!H13 -> 0 | G13: =Sheet1!I13 -> 0 | H13: =Sheet1!J13 -> 0 | I13: =Sheet1!K13 -> 0 | J13: =Sheet1!L13 -> 0 | K13: =Sheet1!M13 -> 0 | L13: =Sheet1!N13 -> 0 | ... AF13: =Sheet1!AH13 -> 0 | AG13: =+((L13+N13)/11.5)/E13 -> #DIV/0!
C14: MAT_Seasonal worker | D14: Direct | E14: 0 | F14: 0 | G14: 0 | H14: 0 | I14: 0 | J14: 0 | K14: 0 | L14: 0 | M14: 0 | N14: 0 | O14: 0 | P14: 0 | Q14: 0 | R14: 0 | S14: 0 | T14: 0 | U14: 0 | V14: 0 | W14: 0 | X14: 0 | Y14: 0 | Z14: 0 | AA14: 0 | AB14: 0 | AC14: 0 | AD14: 0 | AE14: 0 | AF14: 0 | AG14: =+((L14+N14)/11.5)/E14 -> #DIV/0!
C15: Subtotal | E15: =SUBTOTAL(9,E11:E14) -> 0 | F15: =SUBTOTAL(9,F11:F14) -> 0 | G15: =SUBTOTAL(9,G11:G14) -> 0 | H15: =SUBTOTAL(9,H11:H14) -> 0 | I15: =U15/R15 -> #DIV/0! | J15: =SUBTOTAL(9,J11:J14) -> 0 | K15: =SUBTOTAL(9,K11:K14) -> 0 | L15: =SUBTOTAL(9,L11:L14) -> 0 | M15: =SUBTOTAL(9,M11:M14) -> 0 | N15: =SUBTOTAL(9,N11:N14) -> 0 | O15: =SUBTOTAL(9,O11:O14) -> 0 | P15: =SUBTOTAL(9,P11:P14) -> 0 | Q15: =SUBTOTAL(9,Q11:Q14) -> 0 | ... AE15: =SUBTOTAL(9,AE11:AE14) -> 0 | AG15: =+((L15+N15)/11.5)/E15 -> #DIV/0!
B16: Quality | C16: FM/DF QC | D16: Direct | E16: =Sheet1!G14 -> 0 | F16: =Sheet1!H14 -> 0 | G16: =Sheet1!I14 -> 0 | H16: =Sheet1!J14 -> 0 | I16: =Sheet1!K14 -> 0 | J16: =Sheet1!L14 -> 0 | K16: =Sheet1!M14 -> 0 | L16: =Sheet1!N14 -> 0 | ... AF16: =Sheet1!AH14 -> 0 | AG16: =+((L16+N16)/11)/E16 -> #DIV/0!
C17: V/I | D17: Direct | E17: =Sheet1!G15 -> 0 | F17: =Sheet1!H15 -> 0 | G17: =Sheet1!I15 -> 0 | H17: =Sheet1!J15 -> 0 | I17: =Sheet1!K15 -> 0 | J17: =Sheet1!L15 -> 0 | K17: =Sheet1!M15 -> 0 | L17: =Sheet1!N15 -> 0 | ... AF17: =Sheet1!AH15 -> 0 | AG17: =+((L17+N17)/11)/E17 -> #DIV/0!
C18: Auto, Brushing, deburring | D18: Direct | E18: =Sheet1!G16 -> 0 | F18: =Sheet1!H16 -> 0 | G18: =Sheet1!I16 -> 0 | H18: =Sheet1!J16 -> 0 | I18: =Sheet1!K16 -> 0 | J18: =Sheet1!L16 -> 0 | K18: =Sheet1!M16 -> 0 | L18: =Sheet1!N16 -> 0 | ... AF18: =Sheet1!AH16 -> 0 | AG18: =+((L18+N18)/11)/E18 -> #DIV/0!
C19: Other indirect (PQC) | D19: Indirect | E19: =Sheet1!G19 -> 0 | F19: =Sheet1!H19 -> 0 | G19: =Sheet1!I19 -> 0 | H19: =Sheet1!J19 -> 0 | I19: =Sheet1!K19 -> 0 | J19: =Sheet1!L19 -> 0 | K19: =Sheet1!M19 -> 0 | L19: =Sheet1!N19 -> 0 | ... AF19: =Sheet1!AH19 -> 0 | AG19: =+((L19+N19)/11)/E19 -> #DIV/0!
C20: Packing | D20: Indirect | E20: =Sheet1!G20 -> 0 | F20: =Sheet1!H20 -> 0 | G20: =Sheet1!I20 -> 0 | H20: =Sheet1!J20 -> 0 | I20: =Sheet1!K20 -> 0 | J20: =Sheet1!L20 -> 0 | K20: =Sheet1!M20 -> 0 | L20: =Sheet1!N20 -> 0 | ... AF20: =Sheet1!AH20 -> 0 | AG20: =+((L20+N20)/11)/E20 -> #DIV/0!
C21: Seasonal worker | D21: Direct | E21: 0 | F21: 0 | G21: 0 | H21: 0 | I21: 0 | J21: 0 | K21: 0 | L21: 0 | M21: 0 | N21: 0 | O21: 0 | P21: 0 | Q21: 0 | R21: 0 | S21: 0 | T21: 0 | U21: 0 | V21: 0 | W21: 0 | X21: 0 | Y21: 0 | Z21: 0 | AA21: 0 | AB21: 0 | AC21: 0 | AD21: 0 | AE21: 0 | AF21: 0 | AG21: =+((L21+N21)/11)/E21 -> #DIV/0!
C22: Subtotal | E22: =SUBTOTAL(9,E16:E21) -> 0 | F22: =SUBTOTAL(9,F16:F21) -> 0 | G22: =SUBTOTAL(9,G16:G21) -> 0 | H22: =SUBTOTAL(9,H16:H21) -> 0 | I22: =U22/R22 -> #DIV/0! | J22: =SUBTOTAL(9,J16:J21) -> 0 | K22: =SUBTOTAL(9,K16:K21) -> 0 | L22: =SUBTOTAL(9,L16:L21) -> 0 | M22: =SUBTOTAL(9,M16:M21) -> 0 | N22: =SUBTOTAL(9,N16:N21) -> 0 | O22: =SUBTOTAL(9,O16:O21) -> 0 | P22: =SUBTOTAL(9,P16:P21) -> 0 | Q22: =SUBTOTAL(9,Q16:Q21) -> 0 | ... AE22: =SUBTOTAL(9,AE16:AE21) -> 0 | AG22: =+((L22+N22)/11)/E22 -> #DIV/0!
A23: Other | B23: Service | C23: Service | D23: Indirect | E23: =Sheet1!G21 -> 0 | F23: =Sheet1!H21 -> 0 | G23: =Sheet1!I21 -> 0 | H23: =Sheet1!J21 -> 0 | I23: =Sheet1!K21 -> 0 | J23: =Sheet1!L21 -> 0 | K23: =Sheet1!M21 -> 0 | L23: =Sheet1!N21 -> 0 | ... AF23: =Sheet1!AH21 -> 0
B24: Cleaner | C24: Cleaner | D24: Indirect | E24: =Sheet1!G22 -> 0 | F24: =Sheet1!H22 -> 0 | G24: =Sheet1!I22 -> 0 | H24: =Sheet1!J22 -> 0 | I24: =Sheet1!K22 -> 0 | J24: =Sheet1!L22 -> 0 | K24: =Sheet1!M22 -> 0 | L24: =Sheet1!N22 -> 0 | ... AF24: =Sheet1!AH22 -> 0
B25: Subtotal | E25: =SUBTOTAL(9,E23:E24) -> 0 | F25: =SUBTOTAL(9,F23:F24) -> 0 | G25: =SUBTOTAL(9,G23:G24) -> 0 | H25: =SUBTOTAL(9,H23:H24) -> 0 | I25: =U25/R25 -> #DIV/0! | J25: =SUBTOTAL(9,J23:J24) -> 0 | K25: =SUBTOTAL(9,K23:K24) -> 0 | L25: =SUBTOTAL(9,L23:L24) -> 0 | M25: =SUBTOTAL(9,M23:M24) -> 0 | N25: =SUBTOTAL(9,N23:N24) -> 0 | O25: =SUBTOTAL(9,O23:O24) -> 0 | P25: =SUBTOTAL(9,P23:P24) -> 0 | Q25: =SUBTOTAL(9,Q23:Q24) -> 0 | ... AE25: =SUBTOTAL(9,AE23:AE24) -> 0
A26: Sub-Total | E26: =SUBTOTAL(9,E5:E25) -> 0 | F26: =SUBTOTAL(9,F5:F25) -> 0 | G26: =SUBTOTAL(9,G5:G25) -> 0 | H26: =SUBTOTAL(9,H5:H25) -> 0 | I26: =U26/R26 -> #DIV/0! | J26: =SUBTOTAL(9,J5:J25) -> 0 | K26: =SUBTOTAL(9,K5:K25) -> 0 | L26: =SUBTOTAL(9,L5:L25) -> 0 | M26: =SUBTOTAL(9,M5:M25) -> 0 | N26: =SUBTOTAL(9,N5:N25) -> 0 | O26: =SUBTOTAL(9,O5:O25) -> 0 | P26: =SUBTOTAL(9,P5:P25) -> 0 | Q26: =SUBTOTAL(9,Q5:Q25) -> 0 | ... W26: =SUBTOTAL(9,W5:W25) -> 0 | X26: =U26+V26+W26 -> 0 | Y26: =SUBTOTAL(9,Y5:Y25) -> 0 | Z26: =SUBTOTAL(9,Z5:Z25) -> 0 | AA26: =SUBTOTAL(9,AA5:AA25) -> 0 | AB26: =SUBTOTAL(9,AB5:AB25) -> 0 | AC26: =SUBTOTAL(9,AC5:AC25) -> 0 | AD26: =SUBTOTAL(9,AD5:AD25) -> 0 | AE26: =SUBTOTAL(9,AE5:AE25) -> 0 | AG26: =+(AG22+AG15)/2 -> #DIV/0!
A28: Classification | E28: M/P | F28: Basic salary (A) | G28: Allowance (B) | H28: OT amount '© | I28: OVERTIME | S28: All 30% | U28: Total salary (A+B+C + D) | V28: Union paid by company | W28: Insurance paied by company | X28: Total amount | Y28: Insurance paied by employee (10.5%) (E) | Z28: PIT | AA28: Union fee paid by employee | AB28: CV allowance | AC28: Pay tax | AD28: Resignation support | AE28: Net income | AF28: Net income
I29: Unit price/hour | J29: Working day | K29: (150%) Số giờ tăng ca ngày thường / Normal working day OT No. | L29: (200%) Tăng ca ngày nghỉ | M29: 210% tăng ca đêm ngày thường | N29: 270% tăng ca đêm ngày nghỉ | O29: 300% tăng ca ngày lễ, tết | P29: 390% tăng ca đêm ngày lễ, tết | Q29: Total OT hour | R29: Total working and OT hour converted | S29: Hour | T29: Amount (D)
A30: =+D30 -> Direct | D30: Direct | E30: =Sheet1!CS6 -> 0 | F30: =Sheet1!CT6 -> 0 | G30: =Sheet1!CU6 -> 0 | H30: =Sheet1!CV6 -> 0 | I30: =Sheet1!CW6 -> 0 | J30: =Sheet1!CX6 -> 0 | K30: =Sheet1!CY6 -> 0 | L30: =Sheet1!CZ6 -> 0 | ... AF30: =Sheet1!DT6 -> 0
A31: =+D31 -> Indirect | D31: Indirect | E31: =Sheet1!CS7 -> 0 | F31: =Sheet1!CT7 -> 0 | G31: =Sheet1!CU7 -> 0 | H31: =Sheet1!CV7 -> 0 | I31: =Sheet1!CW7 -> 0 | J31: =Sheet1!CX7 -> 0 | K31: =Sheet1!CY7 -> 0 | L31: =Sheet1!CZ7 -> 0 | ... AF31: =Sheet1!DT7 -> 0
A32: =+D32 -> Admin | D32: Admin | E32: =Sheet1!CS8 -> 0 | F32: =Sheet1!CT8 -> 0 | G32: =Sheet1!CU8 -> 0 | H32: =Sheet1!CV8 -> 0 | I32: =Sheet1!CW8 -> 0 | J32: =Sheet1!CX8 -> 0 | K32: =Sheet1!CY8 -> 0 | L32: =Sheet1!CZ8 -> 0 | ... AF32: =Sheet1!DT8 -> 0
A33: Seasonal worker | D33: =+A33 -> Seasonal worker | E33: =Sheet1!CS9 -> 0 | F33: =Sheet1!CT9 -> 0 | G33: =Sheet1!CU9 -> 0 | H33: =Sheet1!CV9 -> 0 | I33: =Sheet1!CW9 -> 0 | J33: =Sheet1!CX9 -> 0 | K33: =Sheet1!CY9 -> 0 | L33: =Sheet1!CZ9 -> 0 | ... AF33: =Sheet1!DT9 -> 0
A34: Total | E34: =SUBTOTAL(9,E30:E33) -> 0 | F34: =SUBTOTAL(9,F30:F33) -> 0 | G34: =SUBTOTAL(9,G30:G33) -> 0 | H34: =SUBTOTAL(9,H30:H33) -> 0 | I34: =U34/R34 -> #DIV/0! | J34: =SUBTOTAL(9,J30:J33) -> 0 | K34: =SUBTOTAL(9,K30:K33) -> 0 | L34: =SUBTOTAL(9,L30:L33) -> 0 | M34: =SUBTOTAL(9,M30:M33) -> 0 | N34: =SUBTOTAL(9,N30:N33) -> 0 | O34: =SUBTOTAL(9,O30:O33) -> 0 | P34: =SUBTOTAL(9,P30:P33) -> 0 | Q34: =SUBTOTAL(9,Q30:Q33) -> 0 | ... W34: =SUBTOTAL(9,W30:W33) -> 0 | X34: =U34+V34+W34 -> 0 | Y34: =SUBTOTAL(9,Y30:Y33) -> 0 | Z34: =SUBTOTAL(9,Z30:Z33) -> 0 | AA34: =SUBTOTAL(9,AA30:AA33) -> 0 | AB34: =SUBTOTAL(9,AB30:AB33) -> 0 | AC34: =SUBTOTAL(9,AC30:AC33) -> 0 | AD34: =SUBTOTAL(9,AD30:AD33) -> 0 | AE34: =SUBTOTAL(9,AE30:AE33) -> 0 | AF34: =SUBTOTAL(9,AF30:AF33) -> 0
E35: =+E34-E26 -> 0 | F35: =+F34-F26 -> 0 | G35: =+G34-G26 -> 0 | H35: =+H34-H26 -> 0 | I35: =+I34-I26 -> #DIV/0! | J35: =+J34-J26 -> 0 | K35: =+K34-K26 -> 0 | L35: =+L34-L26 -> 0 | ... AF35: =+AF34-AF26 -> 0
A36: Month | B36: Working day | H36: OT day | J36: Total actual working day | M36: =+T26+H26 -> 0 | O36: Class | P36: Working hour | Q36: OT | R36: Total OT+ working hour | S36: 0.3 | T36: TOTAL MANHOUR | U36: Attendance rate Included AL
B37: Actual working day | C37: Public holiday | D37: Summer holiday | E37: Working Saturday | F37: Calendar | G37: Calculate salary working day | H37: Saturday | I37: Sunday | O37: Pro | P37: =+J15 -> 0 | Q37: =R37-P37 -> 0 | R37: =+R15 -> 0 | S37: =+S15 -> 0 | T37: =+R37+S37 -> 0 | U37: =+(U34-T34-H34-AB34-AC34-AD34)/(G34+F34) -> #DIV/0! | AE37: =+AE26-AE65-AE99 -> 0 | AF37: =+AF26-AF65-AF99 -> 0
A38: =TEXT(Sheet1!A1*28,"MMM") -> Jan | B38: =Sheet1!GC6 -> 0 | C38: =Sheet1!GD6 -> 0 | D38: 0 | E38: =Sheet1!GE6 -> 0 | F38: =B38+E38 -> 0 | G38: =D38+F38+C38 -> 0 | H38: =Sheet1!GF6 -> 0 | I38: =AG26-H38 -> #DIV/0! | J38: =F38+H38+I38 -> #DIV/0! | O38: QCT | P38: =+J22 -> 0 | Q38: =R38-P38 -> 0 | R38: =+R22 -> 0 | S38: =+S22 -> 0 | T38: =+R38+S38 -> 0
A41: D1
A42: Classification | E42: Manpower | F42: Basic salary (A) | G42: Allowance (B) | H42: OT amount '© | I42: OVERTIME | S42: All 30% | U42: Total salary (A+B+C + D) | V42: Union paid by company | W42: Insurance paied by company | X42: Total amount | Y42: Insurance paied by employee (10.5%) (E) | Z42: PIT | AA42: Union fee paid by employee | AB42: CV allowance | AC42: Pay tax | AD42: Resignation support | AE42: Net income | AF42: Bonus
I43: Unit price/hour | J43: Working hour excluded Annual leave | K43: (150%) Số giờ tăng ca ngày thường / Normal working day OT No. | L43: (200%) Tăng ca ngày nghỉ | M43: 210% tăng ca đêm ngày thường | N43: 270% tăng ca đêm ngày nghỉ | O43: 300% tăng ca ngày lễ, tết | P43: 390% tăng ca đêm ngày lễ, tết | Q43: Total OT hour | R43: Total working & OT converted | S43: Hour | T43: Amount (D)
...

Sheet 보고서
A1: 2023 년 01월 Actual 대비 현지인 노무비 차이분석
A3: 23.02.07 | M3: 단위:명,일,시간,$
A4: Classtication | D4: OP | G4: Actual | J4: Diff (증감) | M4: Remark
D5: Total | E5: D1 | F5: D2 | G5: Total | H5: D1 | I5: D2 | J5: Total | K5: D1 | L5: D2
A6: 매출액 | C6: KVP | J6: =G6-D6 -> 0 | K6: =H6-E6 -> 0 | L6: =I6-F6 -> 0
C7: DY | J7: =G7-D7 -> 0 | K7: =H7-E7 -> 0 | L7: =I7-F7 -> 0
C8: 바이백 | J8: =G8-D8 -> 0 | K8: =H8-E8 -> 0 | L8: =I8-F8 -> 0
C9: 계 | J9: =J8+J7+J6 -> 0 | K9: =K8+K7+K6 -> 0 | L9: =I9-F9 -> 0
C10: 증가율 | J10: =J9/D9 -> #DIV/0! | K10: =K9/E9 -> #DIV/0! | L10: =L9/F9 -> #DIV/0!
A11: Working day (작업일수/월) | C11: 정취 | D11: 18 | E11: =+D11 -> 18 | F11: =+E11 -> 18 | G11: =Sum!F38 -> 0 | H11: =+G11 -> 0 | I11: =+H11 -> 0 | J11: =+G11-D11 -> -18 | K11: =+H11-E11 -> -18 | L11: =+I11-F11 -> -18
C12: 특근 | D12: =+'[1]Compare D1'!$I$30+'[1]Compare D1'!$J$30 -> 4.9484177 | E12: =+D12 -> 4.9484177 | F12: =+E12 -> 4.9484177 | G12: =Sum!H38+Sum!I38 -> #DIV/0! | H12: =+G12 -> #DIV/0! | I12: =+H12 -> #DIV/0! | J12: =+G12-D12 -> #DIV/0! | K12: =+H12-E12 -> #DIV/0! | L12: =+I12-F12 -> #DIV/0!
C13: 계 | D13: =+D12+D11 -> 22.948418 | E13: =+D13 -> 22.948418 | F13: =+E13 -> 22.948418 | G13: =+G12+G11 -> #DIV/0! | H13: =+G13 -> #DIV/0! | I13: =+H13 -> #DIV/0! | J13: =+G13-D13 -> #DIV/0! | K13: =+H13-E13 -> #DIV/0! | L13: =+I13-F13 -> #DIV/0!
A14: MP (소요인원/월) | B14: MCT | C14: 직접 | F14: =+D14-E14 -> 0 | I14: =+G14-H14 -> 0 | J14: =+G14-D14 -> 0 | K14: =+H14-E14 -> 0 | L14: =+I14-F14 -> 0
C15: 간접 | D15: =+'[2]OP 01.2023 Total'!E10 -> 7 | E15: =+[2]D1_B1!E10 -> 7 | F15: =+D15-E15 -> 0 | G15: =Sum!E10 -> 0 | H15: =Sum!E10 -> 0 | I15: =+G15-H15 -> 0 | J15: =+G15-D15 -> -7 | K15: =+H15-E15 -> -7 | L15: =+I15-F15 -> 0
C16: 계 | D16: =+D15 -> 7 | E16: =+E15 -> 7 | F16: =+D16-E16 -> 0 | G16: =+G15 -> 0 | H16: =+H15 -> 0 | I16: =+G16-H16 -> 0 | J16: =+G16-D16 -> -7 | K16: =+H16-E16 -> -7 | L16: =+I16-F16 -> 0
B17: MAT/MMT/MET | C17: 직접 | D17: =+'[2]OP 01.2023 Total'!E11+'[2]OP 01.2023 Total'!E13+'[2]OP 01.2023 Total'!E14 -> 148 | E17: =+[2]D1_B1!E11+[2]D1_B1!E13+[2]D1_B1!E14 -> 124 | F17: =+D17-E17 -> 24 | G17: =Sum!E11+Sum!E13+Sum!E14 -> 0 | H17: =Sum!E11+Sum!E13+Sum!E14 -> 0 | I17: =+G17-H17 -> 0 | J17: =+G17-D17 -> -148 | K17: =+H17-E17 -> -124 | L17: =+I17-F17 -> -24
C18: 간접 | D18: =+'[2]OP 01.2023 Total'!E12 -> 10 | E18: =+[2]D1_B1!E12 -> 10 | F18: =+D18-E18 -> 0 | G18: =Sum!E12 -> 0 | H18: =Sum!E12 -> 0 | I18: =+G18-H18 -> 0 | J18: =+G18-D18 -> -10 | K18: =+H18-E18 -> -10 | L18: =+I18-F18 -> 0
C19: 계 | D19: =+D17+D18 -> 158 | E19: =+E17+E18 -> 134 | F19: =+D19-E19 -> 24 | G19: =+G18+G17 -> 0 | H19: =+H18+H17 -> 0 | I19: =+G19-H19 -> 0 | J19: =+G19-D19 -> -158 | K19: =+H19-E19 -> -134 | L19: =+I19-F19 -> -24
B20: QCT | C20: 직접 | D20: =+'[2]OP 01.2023 Total'!E16+'[2]OP 01.2023 Total'!E17+'[2]OP 01.2023 Total'!E18+'[2]OP 01.2023 Total'!E21 -> 153 | E20: =+[2]D1_B1!E16+[2]D1_B1!E17+[2]D1_B1!E18+[2]D1_B1!E21 -> 135 | F20: =+D20-E20 -> 18 | G20: =Sum!E16+Sum!E17+Sum!E18 -> 0 | H20: =Sum!E17+Sum!E17+Sum!E21 -> 0 | I20: =+G20-H20 -> 0 | J20: =+G20-D20 -> -153 | K20: =+H20-E20 -> -135 | L20: =+I20-F20 -> -18
C21: 간접 | D21: =+'[2]OP 01.2023 Total'!E19+'[2]OP 01.2023 Total'!E20 -> 24 | E21: =+[2]D1_B1!E19+[2]D1_B1!E20 -> 16 | F21: =+D21-E21 -> 8 | G21: =Sum!E19+Sum!E20 -> 0 | H21: =Sum!E19+Sum!E20 -> 0 | I21: =+G21-H21 -> 0 | J21: =+G21-D21 -> -24 | K21: =+H21-E21 -> -16 | L21: =+I21-F21 -> -8
C22: 계 | D22: =+D21+D20 -> 177 | E22: =+E21+E20 -> 151 | F22: =+D22-E22 -> 26 | G22: =+G21+G20 -> 0 | H22: =+H21+H20 -> 0 | I22: =+G22-H22 -> 0 | J22: =+G22-D22 -> -177 | K22: =+H22-E22 -> -151 | L22: =+I22-F22 -> -26
B23: Admin | C23: 일반 | D23: =+'[2]OP 01.2023 Total'!E6 -> 11 | E23: =+[2]D1_B1!E6 -> 10 | F23: =+D23-E23 -> 1 | G23: =Sum!E6 -> 0 | H23: =Sum!E6 -> 0 | I23: =+G23-H23 -> 0 | J23: =+G23-D23 -> -11 | K23: =+H23-E23 -> -10 | L23: =+I23-F23 -> -1
C24: 간접 | D24: =+'[2]OP 01.2023 Total'!E5 -> 17 | E24: =+[2]D1_B1!E5 -> 16 | F24: =+D24-E24 -> 1 | G24: =Sum!E5 -> 0 | H24: =Sum!E5 -> 0 | I24: =+G24-H24 -> 0 | J24: =+G24-D24 -> -17 | K24: =+H24-E24 -> -16 | L24: =+I24-F24 -> -1
C25: 계 | D25: =+D24+D23 -> 28 | E25: =+E24+E23 -> 26 | F25: =+D25-E25 -> 2 | G25: =+G24+G23 -> 0 | H25: =+H24+H23 -> 0 | I25: =+G25-H25 -> 0 | J25: =+G25-D25 -> -28 | K25: =+H25-E25 -> -26 | L25: =+I25-F25 -> -2
B26: Other | C26: 직접 | F26: =+D26-E26 -> 0 | I26: =+G26-H26 -> 0 | J26: =+G26-D26 -> 0 | K26: =+H26-E26 -> 0 | L26: =+I26-F26 -> 0
C27: 간접 | D27: =+'[2]OP 01.2023 Total'!E25 -> 3 | E27: =+[2]D1_B1!E25 -> 3 | F27: =+D27-E27 -> 0 | G27: =Sum!E25 -> 0 | H27: =Sum!E25 -> 0 | I27: =+G27-H27 -> 0 | J27: =+G27-D27 -> -3 | K27: =+H27-E27 -> -3 | L27: =+I27-F27 -> 0
C28: 계 | D28: =+D27 -> 3 | E28: =+E27 -> 3 | F28: =+D28-E28 -> 0 | G28: =+G27+G26 -> 0 | H28: =+H27+H26 -> 0 | I28: =+G28-H28 -> 0 | J28: =+G28-D28 -> -3 | K28: =+H28-E28 -> -3 | L28: =+I28-F28 -> 0
B29: Total | C29: 일반 | D29: =+D23 -> 11 | E29: =+E23 -> 10 | F29: =+D29-E29 -> 1 | G29: =+G23 -> 0 | H29: =+H23 -> 0 | I29: =+G29-H29 -> 0 | J29: =+G29-D29 -> -11 | K29: =+H29-E29 -> -10 | L29: =+I29-F29 -> -1
C30: 직접 | D30: =+D14+D17+D20+D26 -> 301 | E30: =+E14+E17+E20+E26 -> 259 | F30: =+D30-E30 -> 42 | G30: =+G14+G17+G20+G26 -> 0 | H30: =+H14+H17+H20+H26 -> 0 | I30: =+G30-H30 -> 0 | J30: =+G30-D30 -> -301 | K30: =+H30-E30 -> -259 | L30: =+I30-F30 -> -42
C31: 간접 | D31: =+D15+D18+D21+D24+D27 -> 61 | E31: =+E15+E18+E21+E24+E27 -> 52 | F31: =+D31-E31 -> 9 | G31: =+G15+G18+G21+G24+G27 -> 0 | H31: =+H15+H18+H21+H24+H27 -> 0 | I31: =+G31-H31 -> 0 | J31: =+G31-D31 -> -61 | K31: =+H31-E31 -> -52 | L31: =+I31-F31 -> -9
C32: 계 | D32: =+D29+D30+D31 -> 373 | E32: =+E29+E30+E31 -> 321 | F32: =+D32-E32 -> 52 | G32: =+G29+G30+G31 -> 0 | H32: =+H29+H30+H31 -> 0 | I32: =+G32-H32 -> 0 | J32: =+G32-D32 -> -373 | K32: =+H32-E32 -> -321 | L32: =+I32-F32 -> -52
A33: MH Manhour (환산작업시간/월) | B33: MCT | C33: 직접 | F33: =+D33-E33 -> 0 | J33: =+G33-D33 -> 0 | K33: =+H33-E33 -> 0 | L33: =+I33-F33 -> 0
C34: 간접 | D34: =+'[2]OP 01.2023 Total'!R10+'[2]OP 01.2023 Total'!S10 -> 2367.115 | E34: =+[2]D1_B1!R10+[2]D1_B1!S10 -> 2367.115 | F34: =+D34-E34 -> 0 | G34: =Sum!R10+Sum!S10 -> 0 | H34: =Sum!R10+Sum!S10 -> 0 | I34: =+G34-H34 -> 0 | J34: =+G34-D34 -> -2367.115 | K34: =+H34-E34 -> -2367.115 | L34: =+I34-F34 -> 0
C35: 계 | D35: =+D34 -> 2367.115 | E35: =+E34 -> 2367.115 | F35: =+D35-E35 -> 0 | G35: =+G34 -> 0 | H35: =+H34 -> 0 | I35: =+G35-H35 -> 0 | J35: =+G35-D35 -> -2367.115 | K35: =+H35-E35 -> -2367.115 | L35: =+I35-F35 -> 0
B36: MAT/MMT/MET | C36: 직접 | D36: =+'[2]OP 01.2023 Total'!R11+'[2]OP 01.2023 Total'!S11+'[2]OP 01.2023 Total'!R13+'[2]OP 01.2023 Total'!S13+'[2]OP 01.2023 Total'!R14+'[2]OP 01.2023 Total'!S14 -> 57022.04 | E36: =+[2]D1_B1!R11+[2]D1_B1!S11+[2]D1_B1!R13+[2]D1_B1!S13 -> 47150.305 | F36: =+D36-E36 -> 9871.735 | G36: =Sum!R11+Sum!S10+Sum!R12+Sum!S12+Sum!R13+Sum!S13 -> 0 | H36: =Sum!R11+Sum!S10+Sum!R12+Sum!S12+Sum!R13+Sum!S13 -> 0 | I36: =+G36-H36 -> 0 | J36: =+G36-D36 -> -57022.04 | K36: =+H36-E36 -> -47150.305 | L36: =+I36-F36 -> -9871.735
C37: 간접 | D37: =+'[2]OP 01.2023 Total'!R12+'[2]OP 01.2023 Total'!S12 -> 3900.32 | E37: =+[2]D1_B1!R12+[2]D1_B1!S12 -> 3900.32 | F37: =+D37-E37 -> 0 | G37: =Sum!R12+Sum!S12 -> 0 | H37: =Sum!R12+Sum!S12 -> 0 | I37: =+G37-H37 -> 0 | J37: =+G37-D37 -> -3900.32 | K37: =+H37-E37 -> -3900.32 | L37: =+I37-F37 -> 0
C38: 계 | D38: =+D37+D36 -> 60922.36 | E38: =+E37+E36 -> 51050.625 | F38: =+D38-E38 -> 9871.735 | G38: =+G37+G36 -> 0 | H38: =+H37+H36 -> 0 | I38: =+G38-H38 -> 0 | J38: =+G38-D38 -> -60922.36 | K38: =+H38-E38 -> -51050.625 | L38: =+I38-F38 -> -9871.735 | M38: =J38/D38 -> -1
B39: QCT | C39: 직접 | D39: =+'[2]OP 01.2023 Total'!R16+'[2]OP 01.2023 Total'!S16+'[2]OP 01.2023 Total'!R17+'[2]OP 01.2023 Total'!S17+'[2]OP 01.2023 Total'!R18+'[2]OP 01.2023 Total'!S18 -> 51004.075 | E39: =+[2]D1_B1!R16+[2]D1_B1!S16+[2]D1_B1!R17+[2]D1_B1!S17+[2]D1_B1!R18+[2]D1_B1!S18+[2]D1_B1!R21+[2]D1_B1!S21 -> 44156.95 | F39: =+D39-E39 -> 6847.125 | G39: =Sum!R16+Sum!S16+Sum!R17+Sum!S17+Sum!R18+Sum!S18+Sum!R21+Sum!S21 -> 0 | H39: =Sum!R16+Sum!S16+Sum!R17+Sum!S17+Sum!R18+Sum!S18+Sum!R21+Sum!S21 -> 0 | I39: =+G39-H39 -> 0 | J39: =+G39-D39 -> -51004.075 | K39: =+H39-E39 -> -44156.95 | L39: =+I39-F39 -> -6847.125
C40: 간접 | D40: =+'[2]OP 01.2023 Total'!R19+'[2]OP 01.2023 Total'!S19+'[2]OP 01.2023 Total'!R20+'[2]OP 01.2023 Total'!S20 -> 8085.45 | E40: =+[2]D1_B1!R19+[2]D1_B1!S19+[2]D1_B1!R20+[2]D1_B1!S20 -> 5241.15 | F40: =+D40-E40 -> 2844.3 | G40: =Sum!R19+Sum!S19+Sum!R20+Sum!S20 -> 0 | H40: =Sum!R19+Sum!S19+Sum!R20+Sum!S20 -> 0 | I40: =+G40-H40 -> 0 | J40: =+G40-D40 -> -8085.45 | K40: =+H40-E40 -> -5241.15 | L40: =+I40-F40 -> -2844.3
C41: 계 | D41: =+D40+D39 -> 59089.525 | E41: =+E40+E39 -> 49398.1 | F41: =+D41-E41 -> 9691.425 | G41: =+G40+G39 -> 0 | H41: =+H40+H39 -> 0 | I41: =+G41-H41 -> 0 | J41: =+G41-D41 -> -59089.525 | K41: =+H41-E41 -> -49398.1 | L41: =+I41-F41 -> -9691.425 | M41: =J41/D41 -> -1
...
