Workbook

Sheet Sheet1
A1: 1
A2: 2
A3: 3 | B3: 2 | C3: 2 | D3: 2 | E3: 2 | F3: 2 | G3: 1 | H3: 1 | I3: 1 | J3: 1 | K3: 1 | L3: 1 | M3: 1 | N3: 1 | O3: 1 | P3: 1 | Q3: 1 | R3: 1 | S3: 1 | T3: 1 | U3: 1 | V3: 1 | W3: 1 | X3: 1 | Y3: 1 | Z3: 1 | AA3: 1 | AB3: 1 | AC3: 1 | AD3: 1 | AE3: 1 | AF3: 1 | AG3: 1 | AH3: 1 | AI3: 1 | AJ3: 1 | AK3: 1 | AL3: 1 | AM3: 1 | AN3: 1 | AO3: 1 | AP3: 1 | AQ3: 1 | AR3: 1 | AS3: 1 | AT3: 1 | AU3: 1 | AV3: 1 | AW3: 1 | AX3: 1 | AY3: 1 | AZ3: 1 | BA3: 1 | BB3: 1 | BC3: 1 | BD3: 1 | BE3: 1 | BF3: 1 | BG3: 1 | BH3: 1 | BI3: 1 | BJ3: 1 | BK3: 1 | BL3: 1 | BM3: 1 | BN3: 1 | BO3: 1 | BP3: 1 | BQ3: 1 | BR3: 1 | BS3: 1 | BT3: 1 | BU3: 1 | BV3: 1 | BW3: 1 | BX3: 1 | BY3: 1 | BZ3: 1 | CA3: 1 | CB3: 1 | CC3: 1 | CD3: 1 | CE3: 1 | CF3: 1 | CG3: 1 | CH3: 1 | CI3: 1 | CJ3: 1 | CK3: 1 | CL3: 1 | CM3: 1 | CN3: 1 | CO3: 1 | CP3: 1
A4: 4 | B4: No | C4: NameEN | D4: NameKR | E4: MaCongViecAll | F4: GroupbyChucDanhAll | G4: SoLuongNVAll | H4: BasicSalaryAll | I4: PhuCapAll | J4: TienTangCaAll | K4: Luong1GioAll | L4: GioLamViecKhongCoNghiAll | M4: GioTangCa150All | N4: GioTangCaCN200All | O4: GioTangCaDem210All | P4: GioTangCaDemCN270All | Q4: GioTangCaLe300All | R4: GioTangCaDemLe390All | S4: TongTangCaAll | T4: TongTangCaVaHCDaChuyenAll | U4: GioLamDem130All | V4: TienCaDem130All | W4: TongLuongAll | X4: CongDoanCtyTraAll | Y4: BHCtyTraAll | Z4: TongChiPhiAll | AA4: BHNVDongAll | AB4: TTCNAll | AC4: CongDoanNVDongAll | AD4: TroCapConNhoAll | AE4: TroCapPhuNuAll | AF4: HoTroKhacAll | AG4: ThucNhanAll | AH4: LuongChoViecAll | AI4: MaCongViecD1 | AJ4: GroupbyChucDanhD1 | AK4: SoLuongNVD1 | AL4: BasicSalaryD1 | AM4: PhuCapD1 | AN4: TienTangCaD1 | AO4: Luong1GioD1 | AP4: GioLamViecKhongCoNghiD1 | AQ4: GioTangCa150D1 | AR4: GioTangCaCN200D1 | AS4: GioTangCaDem210D1 | AT4: GioTangCaDemCN270D1 | AU4: GioTangCaLe300D1 | AV4: GioTangCaDemLe390D1 | AW4: TongTangCaD1 | AX4: TongTangCaVaHCDaChuyenD1 | AY4: GioLamDem130D1 | AZ4: TienCaDem130D1 | BA4: TongLuongD1 | BB4: CongDoanCtyTraD1 | BC4: BHCtyTraD1 | BD4: TongChiPhiD1 | BE4: BHNVDongD1 | BF4: TTCND1 | BG4: CongDoanNVDongD1 | BH4: TroCapConNhoD1 | BI4: TroCapPhuNuD1 | BJ4: HoTroKhacD1 | BK4: ThucNhanD1 | BL4: LuongChoViecD1 | BM4: MaCongViecD2 | BN4: GroupbyChucDanhD2 | BO4: SoLuongNVD2 | BP4: BasicSalaryD2 | BQ4: PhuCapD2 | BR4: TienTangCaD2 | BS4: Luong1GioD2 | BT4: GioLamViecKhongCoNghiD2 | BU4: GioTangCa150D2 | BV4: GioTangCaCN200D2 | BW4: GioTangCaDem210D2 | BX4: GioTangCaDemCN270D2 | BY4: GioTangCaLe300D2 | BZ4: GioTangCaDemLe390D2 | CA4: TongTangCaD2 | CB4: TongTangCaVaHCDaChuyenD2 | CC4: GioLamDem130D2 | CD4: TienCaDem130D2 | CE4: TongLuongD2 | CF4: CongDoanCtyTraD2 | CG4: BHCtyTraD2 | CH4: TongChiPhiD2 | CI4: BHNVDongD2 | CJ4: TTCND2 | CK4: CongDoanNVDongD2 | CL4: TroCapConNhoD2 | CM4: TroCapPhuNuD2 | CN4: HoTroKhacD2 | CO4: ThucNhanD2 | CP4: LuongChoViecD2 | CQ4: MaCongViecAllVT | CR4: GroupbyViTriAllVT | CS4: SoLuongNVAllVT | CT4: BasicSalaryAllVT | CU4: PhuCapAllVT | CV4: TienTangCaAllVT | CW4: Luong1GioAllVT | CX4: GioLamViecKhongCoNghiAllVT | CY4: GioTangCa150AllVT | CZ4: GioTangCaCN200AllVT | DA4: GioTangCaDem210AllVT | DB4: GioTangCaDemCN270AllVT | DC4: GioTangCaLe300AllVT | DD4: GioTangCaDemLe390AllVT | DE4: TongTangCaAllVT | DF4: TongTangCaVaHCDaChuyenAllVT | DG4: GioLamDem130AllVT | DH4: TienCaDem130AllVT | DI4: TongLuongAllVT | DJ4: CongDoanCtyTraAllVT | DK4: BHCtyTraAllVT | DL4: TongChiPhiAllVT | DM4: BHNVDongAllVT | DN4: TTCNAllVT | DO4: CongDoanNVDongAllVT | DP4: TroCapConNhoAllVT | DQ4: TroCapPhuNuAllVT | DR4: HoTroKhacAllVT | DS4: ThucNhanAllVT | DT4: LuongChoViecAllVT | DU4: MaCongViecD1VT | DV4: GroupbyViTriD1VT | DW4: SoLuongNVD1VT | DX4: BasicSalaryD1VT | DY4: PhuCapD1VT | DZ4: TienTangCaD1VT | EA4: Luong1GioD1VT | EB4: GioLamViecKhongCoNghiD1VT | EC4: GioTangCa150D1VT | ED4: GioTangCaCN200D1VT | EE4: GioTangCaDem210D1VT | EF4: GioTangCaDemCN270D1VT | EG4: GioTangCaLe300D1VT | EH4: GioTangCaDemLe390D1VT | EI4: TongTangCaD1VT | EJ4: TongTangCaVaHCDaChuyenD1VT | EK4: GioLamDem130D1VT | EL4: TienCaDem130D1VT | EM4: TongLuongD1VT | EN4: CongDoanCtyTraD1VT | EO4: BHCtyTraD1VT | EP4: TongChiPhiD1VT | EQ4: BHNVDongD1VT | ER4: TTCND1VT | ES4: CongDoanNVDongD1VT | ET4: TroCapConNhoD1VT | EU4: TroCapPhuNuD1VT | EV4: HoTroKhacD1VT | EW4: ThucNhanD1VT | EX4: LuongChoViecD1VT | EY4: MaCongViecD2VT | EZ4: GroupbyViTriD2VT | FA4: SoLuongNVD2VT | FB4: BasicSalaryD2VT | FC4: PhuCapD2VT | FD4: TienTangCaD2VT | FE4: Luong1GioD2VT | FF4: GioLamViecKhongCoNghiD2VT | FG4: GioTangCa150D2VT | FH4: GioTangCaCN200D2VT | FI4: GioTangCaDem210D2VT | FJ4: GioTangCaDemCN270D2VT | FK4: GioTangCaLe300D2VT | FL4: GioTangCaDemLe390D2VT | FM4: TongTangCaD2VT | FN4: TongTangCaVaHCDaChuyenD2VT | FO4: GioLamDem130D2VT | FP4: TienCaDem130D2VT | FQ4: TongLuongD2VT | FR4: CongDoanCtyTraD2VT | FS4: BHCtyTraD2VT | FT4: TongChiPhiD2VT | FU4: BHNVDongD2VT | FV4: TTCND2VT | FW4: CongDoanNVDongD2VT | FX4: TroCapConNhoD2VT | FY4: TroCapPhuNuD2VT | FZ4: HoTroKhacD2VT | GA4: ThucNhanD2VT | GB4: LuongChoViecD2VT | GC4: ActualWorkingDay | GD4: PublicHoliday | GE4: WorkingSaturday | GF4: SaturdayOT
B6: 1

Sheet Sum
B1: =TEXT(Sheet1!A1*28,"MMM") & " " & Sheet1!A2 & " SALARY" -> Jan 2 SALARY
B2: Plan
B3: Classification | F3: Manpower | G3: Basic salary (A) | H3: Allowance (B) | I3: OT amount '© | J3: OVERTIME | T3: All 30% | V3: Total salary (A+B+C + D) | W3: Union paid by company | X3: Insurance paied by company | Y3: Total amount | Z3: Insurance paied by employee (10.5%) (E) | AA3: PIT | AB3: Union fee paid by employee | AC3: Others | AD3: Quited job | AE3: Resignation support | AF3: Net income
J4: Unit price/hour | K4: Working hour excluded Annual leave | L4: (150%) Số giờ tăng ca ngày thường / Normal working day OT No. | M4: (200%) Tăng ca ngày nghỉ | N4: 210% tăng ca đêm ngày thường | O4: 270% tăng ca đêm ngày nghỉ | P4: 300% tăng ca ngày lễ, tết | Q4: 390% tăng ca đêm ngày lễ, tết | R4: Total OT hour | S4: Total working & OT converted | T4: Hour | U4: Amount (D)
B5: Office | C5: Office 1 | D5: 1st floor | E5: Indirect
C6: Office 2 | D6: 2nd floor | E6: Admin
C7: Subtotal | F7: =SUBTOTAL(9,F5:F6) -> 0 | G7: =SUBTOTAL(9,G5:G6) -> 0 | H7: =SUBTOTAL(9,H5:H6) -> 0 | I7: =SUBTOTAL(9,I5:I6) -> 0 | J7: =SUBTOTAL(9,J5:J6) -> 0 | K7: =SUBTOTAL(9,K5:K6) -> 0 | L7: =SUBTOTAL(9,L5:L6) -> 0 | M7: =SUBTOTAL(9,M5:M6) -> 0 | ... AF7: =SUBTOTAL(9,AF5:AF6) -> 0
B8: Worker | C8: Warehouse | D8: Delivery | E8: Indirect
D9: MCT worker | E9: Indirect
D10: Subtotal | F10: =SUBTOTAL(9,F8:F9) -> 0 | G10: =SUBTOTAL(9,G8:G9) -> 0 | H10: =SUBTOTAL(9,H8:H9) -> 0 | I10: =SUBTOTAL(9,I8:I9) -> 0 | J10: =SUBTOTAL(9,J8:J9) -> 0 | K10: =SUBTOTAL(9,K8:K9) -> 0 | L10: =SUBTOTAL(9,L8:L9) -> 0 | M10: =SUBTOTAL(9,M8:M9) -> 0 | ... AF10: =SUBTOTAL(9,AF8:AF9) -> 0
C11: Manufacture | D11: FM/DF Production | E11: Direct | AG11: =+((L11+N11)/11.5)/E11 -> #VALUE!
D12: MET/MMT | E12: Indirect | AG12: =+((L12+N12)/11.5)/E12 -> #VALUE!
D13: MAT worker | E13: Direct | AG13: =+((L13+N13)/11.5)/E13 -> #VALUE!
D14: MAT_Seasonal worker | E14: Direct | AG14: =+((L14+N14)/11.5)/E14 -> #VALUE!
D15: Subtotal | F15: =SUBTOTAL(9,F11:F14) -> 0 | G15: =SUBTOTAL(9,G11:G14) -> 0 | H15: =SUBTOTAL(9,H11:H14) -> 0 | I15: =SUBTOTAL(9,I11:I14) -> 0 | J15: =SUBTOTAL(9,J11:J14) -> 0 | K15: =SUBTOTAL(9,K11:K14) -> 0 | L15: =SUBTOTAL(9,L11:L14) -> 0 | M15: =SUBTOTAL(9,M11:M14) -> 0 | ... AF15: =SUBTOTAL(9,AF11:AF14) -> 0 | AG15: =+((L15+N15)/11.5)/E15 -> #DIV/0!
C16: Quality | D16: FM/DF QC | E16: Direct | AG16: =+((L16+N16)/11)/E16 -> #VALUE!
D17: V/I | E17: Direct | AG17: =+((L17+N17)/11)/E17 -> #VALUE!
D18: Auto, Brushing, deburring | E18: Direct | AG18: =+((L18+N18)/11)/E18 -> #VALUE!
D19: Other indirect (PQC) | E19: Indirect | AG19: =+((L19+N19)/11)/E19 -> #VALUE!
D20: Packing | E20: Indirect | AG20: =+((L20+N20)/11)/E20 -> #VALUE!
D21: QCT_Seasonal worker | E21: Direct | AG21: =+((L21+N21)/11)/E21 -> #VALUE!
D22: Subtotal | F22: =SUBTOTAL(9,F16:F21) -> 0 | G22: =SUBTOTAL(9,G16:G21) -> 0 | H22: =SUBTOTAL(9,H16:H21) -> 0 | I22: =SUBTOTAL(9,I16:I21) -> 0 | J22: =SUBTOTAL(9,J16:J21) -> 0 | K22: =SUBTOTAL(9,K16:K21) -> 0 | L22: =SUBTOTAL(9,L16:L21) -> 0 | M22: =SUBTOTAL(9,M16:M21) -> 0 | ... AF22: =SUBTOTAL(9,AF16:AF21) -> 0 | AG22: =+((L22+N22)/11)/E22 -> #DIV/0!
B23: Other | C23: Service | D23: Service | E23: Indirect
C24: Cleaner | D24: Cleaner | E24: Indirect
C25: Subtotal | F25: =SUBTOTAL(9,F23:F24) -> 0 | G25: =SUBTOTAL(9,G23:G24) -> 0 | H25: =SUBTOTAL(9,H23:H24) -> 0 | I25: =SUBTOTAL(9,I23:I24) -> 0 | J25: =SUBTOTAL(9,J23:J24) -> 0 | K25: =SUBTOTAL(9,K23:K24) -> 0 | L25: =SUBTOTAL(9,L23:L24) -> 0 | M25: =SUBTOTAL(9,M23:M24) -> 0 | ... AF25: =SUBTOTAL(9,AF23:AF24) -> 0
B26: Sub-Total | F26: =SUBTOTAL(9,F5:F25) -> 0 | G26: =SUBTOTAL(9,G5:G25) -> 0 | H26: =SUBTOTAL(9,H5:H25) -> 0 | I26: =SUBTOTAL(9,I5:I25) -> 0 | J26: =SUBTOTAL(9,J5:J25) -> 0 | K26: =SUBTOTAL(9,K5:K25) -> 0 | L26: =SUBTOTAL(9,L5:L25) -> 0 | M26: =SUBTOTAL(9,M5:M25) -> 0 | ... AF26: =SUBTOTAL(9,AF5:AF25) -> 0 | AG26: =+(AG22+AG15)/2 -> #DIV/0!
P27: Class | Q27: Working hour | R27: OT | S27: Total OT+ working hour | T27: 0.3 | U27: TOTAL MANHOUR | V27: Attendance rate
B28: Month | C28: Working day | I28: OT day | K28: Total actual working day
C29: Actual working day | D29: Annual leave | E29: Summer holiday | F29: Working Saturday | G29: Calendar | H29: Calculate salary working day | I29: Saturday | J29: Sunday | P29: Pro | Q29: =+K15 -> 0 | R29: =S29-Q29 -> 0 | S29: =+S15 -> 0 | T29: =+T15 -> 0 | U29: =+S29+T29 -> 0 | V29: =+(V26-U26-I26-AC26-AD26-AE26)/(G26+H26) -> #DIV/0!
B30: JAN | C30: =Sheet1!GC6 -> 0 | D30: =Sheet1!GD6 -> 0 | E30: 0 | F30: =Sheet1!GE6 -> 0 | G30: =C30+F30 -> 0 | H30: =E30+G30+D30 -> 0 | I30: =Sheet1!GF6 -> 0 | J30: =AH56-I30 -> #DIV/0! | K30: =G30+I30+J30 -> #DIV/0! | P30: QCT | Q30: =+K22 -> 0 | R30: =S30-Q30 -> 0 | S30: =+S22 -> 0 | T30: =+T22 -> 0 | U30: =+S30+T30 -> 0
B32: Actual
B33: Classification | F33: Manpower | G33: Basic salary (A) | H33: Allowance (B) | I33: OT amount '© | J33: OVERTIME | T33: All 30% | V33: Total salary (A+B+C + D) | W33: Union paid by company | X33: Insurance paied by company | Y33: Total amount | Z33: Insurance paied by employee (10.5%) (E) | AA33: PIT | AB33: Union fee paid by employee | AC33: Child allowance | AD33: Women allowance | AE33: Resignation support | AF33: Net income | AG33: Bonus
J34: Unit price/hour | K34: Working hour excluded Annual leave | L34: (150%) Số giờ tăng ca ngày thường / Normal working day OT No. | M34: (200%) Tăng ca ngày nghỉ | N34: 210% tăng ca đêm ngày thường | O34: 270% tăng ca đêm ngày nghỉ | P34: 300% tăng ca ngày lễ, tết | Q34: 390% tăng ca đêm ngày lễ, tết | R34: Total OT hour | S34: Total working & OT converted | T34: Hour | U34: Amount (D)
B35: Office | C35: Office 1 | D35: 1st floor | E35: Indirect | F35: =Sheet1!G6 -> 0 | G35: =Sheet1!H6 -> 0 | H35: =Sheet1!I6 -> 0 | I35: =Sheet1!J6 -> 0 | J35: =Sheet1!K6 -> 0 | K35: =Sheet1!L6 -> 0 | L35: =Sheet1!M6 -> 0 | M35: =Sheet1!N6 -> 0 | ... AG35: =Sheet1!AH6 -> 0
C36: Office 2 | D36: 2nd floor | E36: Admin | F36: =Sheet1!G7 -> 0 | G36: =Sheet1!H7 -> 0 | H36: =Sheet1!I7 -> 0 | I36: =Sheet1!J7 -> 0 | J36: =Sheet1!K7 -> 0 | K36: =Sheet1!L7 -> 0 | L36: =Sheet1!M7 -> 0 | M36: =Sheet1!N7 -> 0 | ... AG36: =Sheet1!AH7 -> 0
C37: Subtotal | F37: =SUBTOTAL(9,F35:F36) -> 0 | G37: =SUBTOTAL(9,G35:G36) -> 0 | H37: =SUBTOTAL(9,H35:H36) -> 0 | I37: =SUBTOTAL(9,I35:I36) -> 0 | J37: =SUBTOTAL(9,J35:J36) -> 0 | K37: =SUBTOTAL(9,K35:K36) -> 0 | L37: =SUBTOTAL(9,L35:L36) -> 0 | M37: =SUBTOTAL(9,M35:M36) -> 0 | ... AF37: =SUBTOTAL(9,AF35:AF36) -> 0
B38: Worker | C38: Warehouse | D38: Delivery | E38: Indirect | F38: =Sheet1!G8 -> 0 | G38: =Sheet1!H8 -> 0 | H38: =Sheet1!I8 -> 0 | I38: =Sheet1!J8 -> 0 | J38: =Sheet1!K8 -> 0 | K38: =Sheet1!L8 -> 0 | L38: =Sheet1!M8 -> 0 | M38: =Sheet1!N8 -> 0 | ... AG38: =Sheet1!AH8 -> 0
D39: MCT worker | E39: Indirect | F39: =Sheet1!G9 -> 0 | G39: =Sheet1!H9 -> 0 | H39: =Sheet1!I9 -> 0 | I39: =Sheet1!J9 -> 0 | J39: =Sheet1!K9 -> 0 | K39: =Sheet1!L9 -> 0 | L39: =Sheet1!M9 -> 0 | M39: =Sheet1!N9 -> 0 | ... AG39: =Sheet1!AH9 -> 0
D40: Subtotal | F40: =SUBTOTAL(9,F38:F39) -> 0 | G40: =SUBTOTAL(9,G38:G39) -> 0 | H40: =SUBTOTAL(9,H38:H39) -> 0 | I40: =SUBTOTAL(9,I38:I39) -> 0 | J40: =SUBTOTAL(9,J38:J39) -> 0 | K40: =SUBTOTAL(9,K38:K39) -> 0 | L40: =SUBTOTAL(9,L38:L39) -> 0 | M40: =SUBTOTAL(9,M38:M39) -> 0 | ... AF40: =SUBTOTAL(9,AF38:AF39) -> 0
C41: Manufacture | D41: FM/DF Production | E41: Direct | F41: =Sheet1!G10 -> 0 | G41: =Sheet1!H10 -> 0 | H41: =Sheet1!I10 -> 0 | I41: =Sheet1!J10 -> 0 | J41: =Sheet1!K10 -> 0 | K41: =Sheet1!L10 -> 0 | L41: =Sheet1!M10 -> 0 | M41: =Sheet1!N10 -> 0 | ... AG41: =Sheet1!AH10 -> 0 | AH41: =+((M41+O41)/11.5)/F41 -> #DIV/0!
...

Sheet 급여 요약
A1: MAN HOUR ANALYSIS ON JAN, 2023
F2: OT | O2: 환산후 | P2: Remarks | T2: Working day | V2: Night shift | W2: OT | X2: CV | Y2: Support 200k OT, & 450k | Z2: Lucky money | AA2: Gross | AB2: Support
B3: DEPT | C3: M/P | D3: NORMAL | E3: 0.3 | F3: 1.5 | G3: 2 | H3: 2.1 | I3: 2.7 | J3: 3 | K3: 3.9 | L3: OT TOTAL | M3: 환산 (Convert) | N3: TOTAL | S3: B/S+A/L | T3: 기본급/수당 | U3: AT rate | V3: 야간조 | W3: 연장 | AA3: 계
B4: 1st floor | C4: =Sum!F5 -> 0 | D4: =Sum!K5 -> 0 | E4: =Sum!T5 -> 0 | F4: =Sum!L5 -> 0 | G4: =Sum!M5 -> 0 | H4: =Sum!N5 -> 0 | I4: =Sum!O5 -> 0 | J4: =Sum!P7 -> 0 | K4: =Sum!Q7 -> 0 | L4: =SUM(F4:K4) -> 0 | M4: =+F4*$F$21+G4*$G$21+H4*$H$21+I4*$I$21+J4*$J$21+K4*$K$21 -> 0 | N4: =L4+D4 -> 0 | O4: =M4+D4+E4 -> 0 | P4: =Sum!AC5 -> 0 | Q4: =+SUM(D4:K4) -> 0 | R4: =Sum!F35 -> 0 | S4: =+SUM(Sum!G5:H5) -> 0 | T4: =+AA4-V4-W4-AB4 -> 0 | U4: =IFERROR(T4/S4,0) -> 0 | V4: =Sum!U5 -> 0 | W4: =Sum!I5 -> 0 | X4: =Sum!AC5 -> 0 | Y4: =Sum!AD5 -> 0 | Z4: =Sum!AD5 -> 0 | AA4: =Sum!V5 -> 0 | AB4: =Sum!AC5+Sum!AD5+Sum!AE5 -> 0
B5: 2nd floor | C5: =Sum!F6 -> 0 | D5: =Sum!K6 -> 0 | E5: =Sum!T6 -> 0 | F5: =Sum!L6 -> 0 | G5: =Sum!M6 -> 0 | H5: =Sum!N6 -> 0 | I5: =Sum!O6 -> 0 | J5: =Sum!P6 -> 0 | K5: =Sum!Q8 -> 0 | L5: =SUM(F5:K5) -> 0 | M5: =+F5*$F$21+G5*$G$21+H5*$H$21+I5*$I$21+J5*$J$21+K5*$K$21 -> 0 | N5: =L5+D5 -> 0 | O5: =M5+D5+E5 -> 0 | P5: =Sum!AC6 -> 0 | Q5: =+SUM(D5:K5) -> 0 | S5: =SUM(Sum!G6:H6) -> 0 | T5: =+AA5-V5-W5-AB5 -> 0 | U5: =IFERROR(T5/S5,0) -> 0 | V5: =Sum!U6 -> 0 | W5: =Sum!I6 -> 0 | X5: =Sum!AC6 -> 0 | Y5: =Sum!AD6 -> 0 | Z5: =Sum!AD6 -> 0 | AA5: =Sum!V6 -> 0 | AB5: =Sum!AC6+Sum!AD6+Sum!AE6 -> 0
B6: MCT | C6: =Sum!F11 -> 0 | D6: =Sum!K9 -> 0 | E6: =Sum!T9 -> 0 | F6: =Sum!L10-Sum!L8 -> 0 | G6: =Sum!M10-Sum!M8 -> 0 | H6: =Sum!N10-Sum!N8 -> 0 | I6: =Sum!O11 -> 0 | J6: =Sum!P11 -> 0 | K6: =Sum!Q11 -> 0 | L6: =SUM(F6:K6) -> 0 | M6: =+F6*$F$21+G6*$G$21+H6*$H$21+I6*$I$21+J6*$J$21+K6*$K$21 -> 0 | N6: =L6+D6 -> 0 | O6: =M6+D6+E6 -> 0 | P6: =Sum!AC11 -> 0 | Q6: =+SUM(D6:K6) -> 0 | S6: =+Sum!G9+Sum!H9 -> 0 | T6: =+AA6-V6-W6-AB6 -> 0 | U6: =IFERROR(T6/S6,0) -> 0 | V6: =+Sum!U9 -> 0 | W6: =+Sum!I9 -> 0 | X6: =+Sum!AC9 -> 0 | Y6: =+Sum!AD9 -> 0 | Z6: =+Sum!AD9 -> 0 | AA6: =+Sum!V9 -> 0 | AB6: =Sum!AC10+Sum!AD10+Sum!AE10 -> 0
A7: PLAN | B7: PRODUCTION | C7: =+Sum!F15-Sum!F14 -> 0 | D7: =+Sum!K15-Sum!K14 -> 0 | E7: =+Sum!T15-Sum!T14 -> 0 | F7: =+Sum!L15-Sum!L14 -> 0 | G7: =+Sum!M15-Sum!M14 -> 0 | H7: =+Sum!N15-Sum!N14 -> 0 | I7: =+Sum!O15-Sum!O14 -> 0 | J7: =+Sum!P15-Sum!P14 -> 0 | K7: =+Sum!Q15-Sum!Q14 -> 0 | L7: =SUM(F7:K7) -> 0 | M7: =+F7*$F$21+G7*$G$21+H7*$H$21+I7*$I$21+J7*$J$21+K7*$K$21 -> 0 | N7: =L7+D7 -> 0 | O7: =M7+D7+E7 -> 0 | P7: =+(Sum!AC9+Sum!AC10+Sum!AC12+Sum!AC13) -> 0 | Q7: =+SUM(D7:K7) -> 0 | R7: =+O7 -> 0 | S7: =+Sum!G15+Sum!H15-Sum!G14-Sum!H14 -> 0 | T7: =+AA7-V7-W7-AB7 -> 0 | U7: =IFERROR(T7/S7,0) -> 0 | V7: =+Sum!U15-Sum!U14 -> 0 | W7: =+Sum!I15-Sum!I14 -> 0 | X7: =+Sum!AC15-Sum!AC14 -> 0 | Y7: =+Sum!AD15-Sum!AD14 -> 0 | Z7: =+Sum!AD15-Sum!AD14 -> 0 | AA7: =+Sum!V15-Sum!V14 -> 0 | AB7: =Sum!AC15+Sum!AD15+Sum!AE15 -> 0
B8: PRO_SEASONAL WORKER | C8: =+Sum!F14 -> 0 | D8: =+Sum!K14 -> 0 | E8: =+Sum!T14 -> 0 | F8: =+Sum!L14 -> 0 | G8: =+Sum!M14 -> 0 | H8: =+Sum!N14 -> 0 | I8: =+Sum!O14 -> 0 | L8: =SUM(F8:K8) -> 0 | M8: =+F8*$F$21+G8*$G$21+H8*$H$21+I8*$I$21+J8*$J$21+K8*$K$21 -> 0 | N8: =L8+D8 -> 0 | O8: =M8+D8+E8 -> 0 | P8: =+(Sum!AC10+Sum!AC11+Sum!AC13+Sum!AC14) -> 0 | Q8: =+SUM(D8:K8) -> 0 | S8: =+Sum!G14+Sum!H14 -> 0 | T8: =+AA8-V8-W8-AB8 -> 0 | U8: =IFERROR(T8/S8,0) -> 0 | V8: =+Sum!U14 -> 0 | W8: =+Sum!I14 -> 0 | X8: =+Sum!AC14 -> 0 | Y8: =+Sum!AD14 -> 0 | Z8: =+Sum!AD14 -> 0 | AA8: =+Sum!V14 -> 0
B9: DRIVER | C9: =+Sum!F8 -> 0 | D9: =+Sum!K8 -> 0 | E9: =+Sum!T8 -> 0 | F9: =+Sum!L8 -> 0 | G9: =+Sum!M8 -> 0 | H9: =+Sum!N8 -> 0 | I9: =+Sum!O8 -> 0 | J9: =Sum!P8 -> 0 | K9: =Sum!Q8 -> 0 | L9: =SUM(F9:K9) -> 0 | M9: =+F9*$F$21+G9*$G$21+H9*$H$21+I9*$I$21+J9*$J$21+K9*$K$21 -> 0 | N9: =L9+D9 -> 0 | O9: =M9+D9+E9 -> 0 | P9: =+Sum!AC8 -> 0 | Q9: =+SUM(D9:K9) -> 0 | S9: =+SUM(Sum!G8:H8) -> 0 | T9: =+AA9-V9-W9-AB9 -> 0 | U9: =IFERROR(T9/S9,0) -> 0 | V9: =Sum!U8 -> 0 | W9: =+Sum!I8 -> 0 | X9: =+Sum!AC8 -> 0 | Y9: =+Sum!AD8 -> 0 | Z9: =+Sum!AD8 -> 0 | AA9: =Sum!V8 -> 0 | AB9: =Sum!AC8+Sum!AD8+Sum!AE8 -> 0
B10: QC | C10: =+Sum!F22-Sum!F21 -> 0 | D10: =+Sum!K22-Sum!K21 -> 0 | E10: =+Sum!T22-Sum!T21 -> 0 | F10: =+Sum!L22-Sum!L21 -> 0 | G10: =+Sum!M22-Sum!M21 -> 0 | H10: =+Sum!N22-Sum!N21 -> 0 | I10: =+Sum!O22-Sum!O21 -> 0 | J10: =+Sum!P22 -> 0 | K10: =+Sum!Q22 -> 0 | L10: =SUM(F10:K10) -> 0 | M10: =+F10*$F$21+G10*$G$21+H10*$H$21+I10*$I$21+J10*$J$21+K10*$K$21 -> 0 | N10: =L10+D10 -> 0 | O10: =M10+D10+E10 -> 0 | P10: =+Sum!AC23 -> 0 | Q10: =+SUM(D10:K10) -> 0 | S10: =+Sum!G22+Sum!H22-Sum!G21-Sum!H21 -> 0 | T10: =+AA10-V10-W10-AB10 -> 0 | U10: =IFERROR(T10/S10,0) -> 0 | V10: =+Sum!U22-Sum!U21 -> 0 | W10: =+Sum!I22-Sum!I21 -> 0 | X10: =+Sum!AC22-Sum!AC21 -> 0 | Y10: =+Sum!AD22-Sum!AD21 -> 0 | Z10: =+Sum!AD22-Sum!AD21 -> 0 | AA10: =+Sum!V22-Sum!V21 -> 0 | AB10: =Sum!AC22+Sum!AD22+Sum!AE22 -> 0
B11: QCT_SEASONAL WORKER | C11: =+Sum!F21 -> 0 | D11: =+Sum!K21 -> 0 | E11: =+Sum!T21 -> 0 | F11: =+Sum!L21 -> 0 | G11: =+Sum!M21 -> 0 | H11: =+Sum!N21 -> 0 | I11: =+Sum!O21 -> 0 | J11: =+Sum!P21 -> 0 | K11: =+Sum!Q21 -> 0 | L11: =SUM(F11:K11) -> 0 | M11: =+F11*$F$21+G11*$G$21+H11*$H$21+I11*$I$21+J11*$J$21+K11*$K$21 -> 0 | N11: =L11+D11 -> 0 | O11: =M11+D11+E11 -> 0 | P11: =+Sum!AC24 -> 0 | Q11: =+SUM(D11:K11) -> 0 | R11: =+O11+O10 -> 0 | S11: =+Sum!G21+Sum!H21 -> 0 | T11: =+AA11-V11-W11-AB11 -> 0 | U11: =IFERROR(T11/S11,0) -> 0 | V11: =+Sum!T21 -> 0 | W11: =+Sum!I21 -> 0 | X11: =+Sum!AC21 -> 0 | Y11: =+Sum!AD21 -> 0 | Z11: =+Sum!AD21 -> 0 | AA11: =+Sum!V21 -> 0
B12: OTHER | C12: =+Sum!F25 -> 0 | D12: =+Sum!K25 -> 0 | E12: =+Sum!T25 -> 0 | F12: =+Sum!L25 -> 0 | G12: =+Sum!M25 -> 0 | H12: =+Sum!N25 -> 0 | I12: =+Sum!O25 -> 0 | J12: =Sum!P26 -> 0 | K12: =Sum!Q26 -> 0 | L12: =SUM(F12:K12) -> 0 | M12: =+F12*$F$21+G12*$G$21+H12*$H$21+I12*$I$21+J12*$J$21+K12*$K$21 -> 0 | N12: =L12+D12 -> 0 | O12: =M12+D12+E12 -> 0 | P12: =+Sum!AC26 -> 0 | Q12: =+SUM(D12:K12) -> 0 | S12: =+Sum!G25+Sum!H25 -> 0 | T12: =+AA12-V12-W12-AB12 -> 0 | U12: =IFERROR(T12/S12,0) -> 0 | W12: =+Sum!I25 -> 0 | X12: =+Sum!AC25 -> 0 | Y12: =+Sum!AD25 -> 0 | Z12: =+Sum!AD25 -> 0 | AA12: =+Sum!V25 -> 0 | AB12: =Sum!AC25+Sum!AD25+Sum!AE25 -> 0
B13: TOTAL | C13: =SUM(C4:C12) -> 0 | D13: =SUM(D4:D12) -> 0 | E13: =SUM(E4:E12) -> 0 | F13: =SUM(F4:F12) -> 0 | G13: =SUM(G4:G12) -> 0 | H13: =SUM(H4:H12) -> 0 | I13: =SUM(I4:I12) -> 0 | J13: =SUM(J4:J12) -> 0 | ... P13: =SUM(P4:P12) -> 0 | Q13: =+SUM(D13:K13) -> 0 | S13: =SUM(S4:S12) -> 0 | T13: =+AA13-V13-W13-AB13 -> 0 | U13: =IFERROR(T13/S13,0) -> 0 | V13: =SUM(V4:V12) -> 0 | W13: =SUM(W4:W12) -> 0 | X13: =SUM(X4:X12) -> 0 | Y13: =SUM(Y4:Y12) -> 0 | Z13: =SUM(Z4:Z12) -> 0 | AA13: =SUM(AA4:AA12) -> 0 | AB13: =SUM(AB4:AB12) -> 0
S14: =+S13-Sum!#REF!-Sum!#REF! -> #REF!
D16: 실제 작업일 (25일): 평일 18일(토요일 1일) 구정연휴:7일
D17: 휴일 : (6일) -요일 (4일), 휴무 토요일 (2일)
D18: 특근 : 1일
F20: OT | O20: 환산후 | P20: Remarks | T20: Working day | V20: Night shift | W20: OT | X20: CV | Y20: Support 200k OT, & 450k | Z20: Lucky money | AA20: Gross | AB20: Support
B21: DEPT | C21: M/P | D21: NORMAL | E21: 0.3 | F21: 1.5 | G21: 2 | H21: 2.1 | I21: 2.7 | J21: 3 | K21: 3.9 | L21: OT TOTAL | M21: 환산 (Convert) | N21: TOTAL | S21: B/S+A/L | T21: 기본급/수당 | U21: AT rate | V21: 야간조 | W21: 연장 | X21: 연장 | Y21: 연장 | Z21: 연장 | AA21: 계
B22: 1st floor | C22: =+Sum!F35 -> 0 | D22: =+Sum!K35 -> 0 | E22: =+Sum!T35 -> 0 | F22: =+Sum!L35 -> 0 | G22: =+Sum!M35 -> 0 | H22: =+Sum!N35 -> 0 | I22: =+Sum!O35 -> 0 | J22: =+Sum!P35 -> 0 | K22: =+Sum!Q35 -> 0 | L22: =SUM(F22:K22) -> 0 | M22: =+F22*$F$21+G22*$G$21+H22*$H$21+I22*$I$21+J22*$J$21+K22*$K$21 -> 0 | N22: =L22+D22 -> 0 | O22: =M22+D22+E22 -> 0 | P22: 0 | S22: =SUM(Sum!G35:H35) -> 0 | T22: =AA22-Z22-V22-W22-Y22-X22-AB22 -> 0 | U22: =IFERROR(T22/S22,0) -> 0 | V22: =+Sum!U35 -> 0 | W22: =+Sum!I35 -> 0 | X22: =+Sum!AC35 -> 0 | Y22: =+Sum!AD35 -> 0 | AA22: =+Sum!V35 -> 0 | AB22: =Sum!AC35+Sum!AD35+Sum!AE35 -> 0
B23: 2nd floor | C23: =+Sum!F36 -> 0 | D23: =+Sum!K36 -> 0 | E23: =+Sum!T36 -> 0 | F23: =+Sum!L36 -> 0 | G23: =+Sum!M36 -> 0 | H23: =+Sum!N36 -> 0 | I23: =+Sum!O36 -> 0 | J23: =+Sum!P36 -> 0 | K23: =+Sum!Q36 -> 0 | L23: =SUM(F23:K23) -> 0 | M23: =+F23*$F$21+G23*$G$21+H23*$H$21+I23*$I$21+J23*$J$21+K23*$K$21 -> 0 | N23: =L23+D23 -> 0 | O23: =M23+D23+E23 -> 0 | P23: 0 | S23: =SUM(Sum!G36:H36) -> 0 | T23: =AA23-Z23-V23-W23-Y23-X23-AB23 -> 0 | U23: =IFERROR(T23/S23,0) -> 0 | V23: =+Sum!U36 -> 0 | W23: =+Sum!I36 -> 0 | X23: =+Sum!AC36 -> 0 | Y23: =+Sum!AD36 -> 0 | AA23: =+Sum!V36 -> 0 | AB23: =Sum!AC36+Sum!AD36+Sum!AE36 -> 0
B24: MCT | C24: =+Sum!F41 -> 0 | D24: =+Sum!K39 -> 0 | E24: =+Sum!T38 -> 0 | F24: =+Sum!L39 -> 0 | G24: =+Sum!M39 -> 0 | H24: =+Sum!N39 -> 0 | I24: =+Sum!O39 -> 0 | J24: =+Sum!P39 -> 0 | K24: =+Sum!Q39 -> 0 | L24: =SUM(F24:K24) -> 0 | M24: =+F24*$F$21+G24*$G$21+H24*$H$21+I24*$I$21+J24*$J$21+K24*$K$21 -> 0 | N24: =L24+D24 -> 0 | O24: =M24+D24+E24 -> 0 | P24: 0 | S24: =+Sum!G39+Sum!H39 -> 0 | T24: =AA24-Z24-V24-W24-Y24-X24-AB24 -> 0 | U24: =IFERROR(T24/S24,0) -> 0 | V24: =+Sum!U39 -> 0 | W24: =+Sum!I39 -> 0 | X24: =+Sum!AC39 -> 0 | Y24: =+Sum!AD39 -> 0 | AA24: =+Sum!V39 -> 0 | AB24: =Sum!AC40+Sum!AD40+Sum!AE40 -> 0
A25: ACTUAL | B25: PRODUCTION | C25: =+Sum!F45-C26 -> 0 | D25: =+Sum!K45-D26 -> 0 | E25: =+Sum!T45-E26 -> 0 | F25: =+Sum!L45-F26 -> 0 | G25: =+Sum!M45-G26 -> 0 | H25: =+Sum!N45-H26 -> 0 | I25: =+Sum!O45-I26 -> 0 | J25: =+Sum!P45 -> 0 | K25: =+Sum!Q45 -> 0 | L25: =SUM(F25:K25) -> 0 | M25: =+F25*$F$21+G25*$G$21+H25*$H$21+I25*$I$21+J25*$J$21+K25*$K$21 -> 0 | N25: =L25+D25 -> 0 | O25: =M25+D25+E25 -> 0 | P25: 0 | R25: =+O25+P25*8+O26 -> 0 | S25: =+Sum!G45+Sum!H45-S26 -> 0 | T25: =AA25-Z25-V25-W25-Y25-X25-AB25 -> 0 | U25: =IFERROR(T25/S25,0) -> 0 | V25: =+Sum!U45-V26 -> 0 | W25: =+Sum!I45-W26 -> 0 | X25: =+Sum!AC45-X26 -> 0 | Y25: =+Sum!AD45-Y26 -> 0 | AA25: =+Sum!V45-AA26 -> 0 | AB25: =Sum!AC45+Sum!AD45+Sum!AE45 -> 0
B26: PRO_SEASONAL WORKER | C26: =+Sum!F44 -> 0 | D26: =+Sum!K44 -> 0 | E26: =+Sum!T44 -> 0 | F26: =+Sum!L44 -> 0 | G26: =+Sum!M44 -> 0 | H26: =+Sum!N44 -> 0 | I26: =+Sum!O44 -> 0 | J26: =+Sum!P44 -> 0 | L26: =SUM(F26:K26) -> 0 | M26: =+F26*$F$21+G26*$G$21+H26*$H$21+I26*$I$21+J26*$J$21+K26*$K$21 -> 0 | N26: =L26+D26 -> 0 | O26: =M26+D26+E26 -> 0 | P26: 0 | S26: =+Sum!G44+Sum!H44 -> 0 | T26: =AA26-Z26-V26-W26-Y26-X26-AB26 -> 0 | U26: =IFERROR(T26/S26,0) -> 0 | V26: =+Sum!U44 -> 0 | W26: =+Sum!I44 -> 0 | X26: =+Sum!AC44 -> 0 | Y26: =+Sum!AD44 -> 0 | AA26: =+Sum!V44 -> 0
B27: DRIVER | C27: =+Sum!F38 -> 0 | D27: =+Sum!K38 -> 0 | E27: =+Sum!T38 -> 0 | F27: =+Sum!L38 -> 0 | G27: =+Sum!M38 -> 0 | H27: =+Sum!N38 -> 0 | I27: =+Sum!O38 -> 0 | J27: =+Sum!P38 -> 0 | K27: =+Sum!Q38 -> 0 | L27: =SUM(F27:K27) -> 0 | M27: =+F27*$F$21+G27*$G$21+H27*$H$21+I27*$I$21+J27*$J$21+K27*$K$21 -> 0 | N27: =L27+D27 -> 0 | O27: =M27+D27+E27 -> 0 | P27: 0 | S27: =+SUM(Sum!G38:H38) -> 0 | T27: =AA27-Z27-V27-W27-Y27-X27-AB27 -> 0 | U27: =IFERROR(T27/S27,0) -> 0 | V27: =+Sum!U38 -> 0 | W27: =+Sum!I38 -> 0 | X27: =+Sum!AC38 -> 0 | Y27: =+Sum!AD38 -> 0 | AA27: =+Sum!V38 -> 0 | AB27: =Sum!AC38+Sum!AD38+Sum!AE38 -> 0
B28: QC | C28: =+Sum!F52-Sum!F51 -> 0 | D28: =+Sum!K52-Sum!K51 -> 0 | E28: =+Sum!T52-Sum!T51 -> 0 | F28: =+Sum!L52-Sum!L51 -> 0 | G28: =+Sum!M52-Sum!M51 -> 0 | H28: =+Sum!N52-Sum!N51 -> 0 | I28: =+Sum!O52-Sum!O51 -> 0 | J28: =+Sum!P52-Sum!P51 -> 0 | K28: =+Sum!Q52-Sum!Q51 -> 0 | L28: =SUM(F28:K28) -> 0 | M28: =+F28*$F$21+G28*$G$21+H28*$H$21+I28*$I$21+J28*$J$21+K28*$K$21 -> 0 | N28: =L28+D28 -> 0 | O28: =M28+D28+E28 -> 0 | P28: 0 | S28: =+Sum!G52+Sum!H52-Sum!G51-Sum!H51 -> 0 | T28: =AA28-Z28-V28-W28-Y28-X28-AB28 -> 0 | U28: =IFERROR(T28/S28,0) -> 0 | V28: =+Sum!U52-Sum!U51 -> 0 | W28: =+Sum!I52-Sum!I51 -> 0 | X28: =+Sum!AC52-Sum!AC51 -> 0 | Y28: =+Sum!AD52-Sum!AD51 -> 0 | AA28: =+Sum!V52-Sum!V51 -> 0 | AB28: =Sum!AC52+Sum!AD52+Sum!AE52 -> 0
B29: QCT_SEASONAL WORKER | C29: =+Sum!F51 -> 0 | D29: =+Sum!K51 -> 0 | E29: =+Sum!T51 -> 0 | F29: =+Sum!L51 -> 0 | G29: =+Sum!M51 -> 0 | H29: =+Sum!N51 -> 0 | I29: =+Sum!O51 -> 0 | J29: =+Sum!P51 -> 0 | K29: =+Sum!Q51 -> 0 | L29: =SUM(F29:K29) -> 0 | M29: =+F29*$F$21+G29*$G$21+H29*$H$21+I29*$I$21+J29*$J$21+K29*$K$21 -> 0 | N29: =L29+D29 -> 0 | O29: =M29+D29+E29 -> 0 | P29: 0 | R29: =+O29+O28+P28*8 -> 0 | S29: =+Sum!G51+Sum!H51 -> 0 | T29: =AA29-Z29-V29-W29-Y29-X29-AB29 -> 0 | U29: =IFERROR(T29/S29,0) -> 0 | V29: =+Sum!U51 -> 0 | W29: =+Sum!I51 -> 0 | X29: =+Sum!AC51 -> 0 | Y29: =+Sum!AD51 -> 0 | AA29: =+Sum!V51 -> 0
B30: OTHER | C30: =+Sum!F55 -> 0 | D30: =+Sum!K55 -> 0 | E30: =+Sum!T55 -> 0 | F30: =+Sum!L55 -> 0 | G30: =+Sum!M55 -> 0 | H30: =+Sum!N55 -> 0 | I30: =+Sum!O55 -> 0 | J30: =+Sum!P55 -> 0 | K30: =+Sum!Q55 -> 0 | L30: =SUM(F30:K30) -> 0 | M30: =+F30*$F$21+G30*$G$21+H30*$H$21+I30*$I$21+J30*$J$21+K30*$K$21 -> 0 | N30: =L30+D30 -> 0 | O30: =M30+D30+E30 -> 0 | P30: 0 | S30: =+Sum!G55+Sum!H55 -> 0 | T30: =AA30-Z30-V30-W30-Y30-X30-AB30 -> 0 | U30: =IFERROR(T30/S30,0) -> 0 | V30: =+Sum!U55 -> 0 | W30: =+Sum!I55 -> 0 | X30: =+Sum!AC55 -> 0 | Y30: =+Sum!AD55 -> 0 | AA30: =+Sum!V55 -> 0 | AB30: =Sum!AC55+Sum!AD55+Sum!AE55 -> 0
B31: TOTAL | C31: =SUM(C22:C30) -> 0 | D31: =SUM(D22:D30) -> 0 | E31: =SUM(E22:E30) -> 0 | F31: =SUM(F22:F30) -> 0 | G31: =SUM(G22:G30) -> 0 | H31: =SUM(H22:H30) -> 0 | I31: =SUM(I22:I30) -> 0 | J31: =SUM(J22:J30) -> 0 | ... N31: =SUM(N22:N30) -> 0 | O31: =M31+D31+E31 -> 0 | P31: =+SUM(P22:P30) -> 0 | S31: =SUM(S22:S30) -> 0 | T31: =+AA31-V31-W31-AB31 -> 0 | U31: =IFERROR(T31/S31,0) -> 0 | V31: =SUM(V22:V30) -> 0 | W31: =SUM(W22:W30) -> 0 | X31: =SUM(X22:X30) -> 0 | Y31: =SUM(Y22:Y30) -> 0 | AA31: =SUM(AA22:AA30) -> 0 | AB31: =SUM(AB22:AB30) -> 0
D33: 실제 작업일 (25일): 평일 18일(토요일 1일) 구정연휴:7일 | O33: ='[1]실적(확정)(W1->5)'!$J$19 -> 33539.85 | P33: ='[1]실적(확정)(W1->5)'!$J$19 -> 33539.85
D34: 휴일 : (6일) -요일 (4일), 휴무 토요일 (2일) | O34: =O33-O28 -> 33539.85 | P34: =P33-P28 -> 33539.85
F35: =+F25*F21 -> 0 | G35: =+G25*G21 -> 0 | H35: =+H25*H21 -> 0 | I35: =+I25*I21 -> 0 | J35: =+J25*J21 -> 0 | K35: =+K25*K21 -> 0
M36: =+F28*1.5+H28*2.1 -> 0
F37: OT | O37: 환산후 | P37: Remarks | T37: 인건비 | V37: 0.3 | X37: CV | Y37: Support 200k OT, & 450k | Z37: Lucky money
B38: DEPT | C38: M/P | D38: NORMAL | E38: 0.3 | F38: 1.5 | G38: 2 | H38: 2.1 | I38: 2.7 | J38: 3 | K38: 3.9 | L38: OT TOTAL | M38: 환산 | N38: TOTAL | S38: 출근율 | T38: 기본급/수당 | U38: AT rate | V38: 야간조 | W38: 연장 | X38: 연장 | Y38: 연장 | Z38: 연장 | AA38: 계 | AB38: =+AB20 -> Support
B39: 1st floor | C39: =+C22-C4 -> 0 | D39: =D22-D4 -> 0 | E39: =E22-E4 -> 0 | F39: =+F22-F4 -> 0 | G39: =+G22-G4 -> 0 | H39: =+H22-H4 -> 0 | I39: =+I22-I4 -> 0 | J39: =+J22-J4 -> 0 | K39: =+K22-K4 -> 0 | L39: =+L22-L4 -> 0 | M39: =+M22-M4 -> 0 | ... P39: =+P22-P4 -> 0 | S39: =+S22-S4 -> 0 | T39: =+T22-T4 -> 0 | U39: =+U22-U4 -> 0 | V39: =+V22-V4 -> 0 | W39: =+W22-W4 -> 0 | X39: =+X22-X4 -> 0 | Y39: =+Y22-Y4 -> 0 | Z39: =+Z22-Z4 -> 0 | ... AB39: =+AB22-AB4 -> 0
B40: 2nd floor | C40: =+C23-C5 -> 0 | D40: =D23-D5 -> 0 | E40: =E23-E5 -> 0 | F40: =+F23-F5 -> 0 | G40: =+G23-G5 -> 0 | H40: =+H23-H5 -> 0 | I40: =+I23-I5 -> 0 | J40: =+J23-J5 -> 0 | K40: =+K23-K5 -> 0 | L40: =+L23-L5 -> 0 | M40: =+M23-M5 -> 0 | ... P40: =+P23-P5 -> 0 | S40: =+S23-S5 -> 0 | T40: =+T23-T5 -> 0 | U40: =+U23-U5 -> 0 | V40: =+V23-V5 -> 0 | W40: =+W23-W5 -> 0 | X40: =+X23-X5 -> 0 | Y40: =+Y23-Y5 -> 0 | Z40: =+Z23-Z5 -> 0 | ... AB40: =+AB23-AB5 -> 0
B41: MCT | C41: =+C24-C6 -> 0 | D41: =D24-D6 -> 0 | E41: =E24-E6 -> 0 | F41: =+F24-F6 -> 0 | G41: =+G24-G6 -> 0 | H41: =+H24-H6 -> 0 | I41: =+I24-I6 -> 0 | J41: =+J24-J6 -> 0 | K41: =+K24-K6 -> 0 | L41: =+L24-L6 -> 0 | M41: =+M24-M6 -> 0 | ... P41: =+P24-P6 -> 0 | S41: =+S24-S6 -> 0 | T41: =+T24-T6 -> 0 | U41: =+U24-U6 -> 0 | V41: =+V24-V6 -> 0 | W41: =+W24-W6 -> 0 | X41: =+X24-X6 -> 0 | Y41: =+Y24-Y6 -> 0 | Z41: =+Z24-Z6 -> 0 | ... AB41: =+AB24-AB6 -> 0
A42: DIFF | B42: PRODUCTION | C42: =+C25-C7 -> 0 | D42: =D25-D7 -> 0 | E42: =E25-E7 -> 0 | F42: =+F25-F7 -> 0 | G42: =+G25-G7 -> 0 | H42: =+H25-H7 -> 0 | I42: =+I25-I7 -> 0 | J42: =+J25-J7 -> 0 | K42: =+K25-K7 -> 0 | L42: =+L25-L7 -> 0 | M42: =+M25-M7 -> 0 | ... P42: =+P25-P7 -> 0 | R42: =+R25-R7 -> 0 | S42: =+S25-S7 -> 0 | T42: =+T25-T7 -> 0 | U42: =+U25-U7 -> 0 | V42: =+V25-V7 -> 0 | W42: =+W25-W7 -> 0 | X42: =+X25-X7 -> 0 | Y42: =+Y25-Y7 -> 0 | ... AB42: =+AB25-AB7 -> 0
B43: PRO_SEASONAL WORKER | C43: =+C26-C8 -> 0 | D43: =D26-D8 -> 0 | E43: =E26-E8 -> 0 | F43: =+F26-F8 -> 0 | G43: =+G26-G8 -> 0 | H43: =+H26-H8 -> 0 | I43: =+I26-I8 -> 0 | J43: =+J26-J8 -> 0 | K43: =+K26-K8 -> 0 | L43: =+L26-L8 -> 0 | M43: =+M26-M8 -> 0 | ... P43: =+P26-P8 -> 0 | S43: =+S26-S8 -> 0 | T43: =+T26-T8 -> 0 | U43: =+U26-U8 -> 0 | V43: =+V26-V8 -> 0 | W43: =+W26-W8 -> 0 | X43: =+X26-X8 -> 0 | Y43: =+Y26-Y8 -> 0 | Z43: =+Z26-Z8 -> 0 | ... AB43: =+AB26-AB8 -> 0
...

Sheet ENGLISH(production)
B1: Man hour/labor cost anaysis (PRODUCTION)
J2: Unit : MH,1,000dong
B3: Classication | E3: =UPPER(TEXT(Sheet1!A1*28,"MMM")) -> JAN | I3: Reason | J3: Remarks
E4: Plan | F4: Actual | G4: Diff. | H4: %
A5: 생산 | B5: Man-power | E5: =+'급여 요약'!C7 -> 0 | F5: =+'급여 요약'!C25+'급여 요약'!C26 -> 0 | G5: =F5-E5 -> 0 | H5: =IFERROR(G5/E5,"")
B6: Working hour (not converted) | C6: Normal | E6: =+'급여 요약'!D7+'급여 요약'!D8 -> 0 | F6: =+'급여 요약'!D25+'급여 요약'!D26 -> 0 | G6: =F6-E6 -> 0 | H6: =IFERROR(G6/E6,"")
C7: Suspension | E7: =+'급여 요약'!P7*8 -> 0 | F7: =+'급여 요약'!P25*8 -> 0 | G7: =F7-E7 -> 0 | H7: =IFERROR(G7/E7,"")
C8: O/T | D8: 1.5 | E8: =+'급여 요약'!F7+'급여 요약'!F8 -> 0 | F8: =+'급여 요약'!F25+'급여 요약'!F26 -> 0 | G8: =F8-E8 -> 0 | H8: =IFERROR(G8/E8,"")
D9: 2 | E9: =+'급여 요약'!G7+'급여 요약'!G8 -> 0 | F9: =+'급여 요약'!G25+'급여 요약'!G26 -> 0 | G9: =F9-E9 -> 0 | H9: =IFERROR(G9/E9,"")
D10: 2.1 | E10: =+'급여 요약'!H7+'급여 요약'!H8 -> 0 | F10: =+'급여 요약'!H25+'급여 요약'!H26 -> 0 | G10: =F10-E10 -> 0 | H10: =IFERROR(G10/E10,"")
D11: 2.7 | E11: =+'급여 요약'!I7+'급여 요약'!I8 -> 0 | F11: =+'급여 요약'!I25+'급여 요약'!I26 -> 0 | G11: =F11-E11 -> 0 | H11: =IFERROR(G11/E11,"")
D12: 3 | E12: =+'급여 요약'!J7 -> 0 | F12: =+'급여 요약'!J25 -> 0 | G12: =F12-E12 -> 0 | H12: =IFERROR(G12/E12,"") | AB12: nan
D13: 3.9 | E13: =+'급여 요약'!K7 -> 0 | F13: =+'급여 요약'!K25 -> 0 | G13: =F13-E13 -> 0 | H13: =IFERROR(G13/E13,"")
D14: Subtotal | E14: =SUM(E8:E11) -> 0 | F14: =SUM(F8:F11) -> 0 | G14: =SUM(G8:G11) -> 0 | H14: =IFERROR(G14/E14,"")
C15: Night shift | D15: 0.3 | E15: =+'급여 요약'!E7+'급여 요약'!E8 -> 0 | F15: =+'급여 요약'!E25+'급여 요약'!E26 -> 0 | G15: =F15-E15 -> 0 | H15: =IFERROR(G15/E15,"")
C16: Total | E16: =+E15+E14+E6+E7 -> 0 | F16: =+F15+F14+F6+F7 -> 0 | G16: =F16-E16 -> 0 | H16: =IFERROR(G16/E16,"")
C17: Attendance | E17: =+'급여 요약'!U7 -> 0 | F17: =+'급여 요약'!U25 -> 0 | G17: =F17-E17 -> 0 | H17: =IFERROR(G17/E17,"")
B18: Working hour (converted) | C18: Normal | E18: =+E6 -> 0 | F18: =+F6 -> 0 | G18: =F18-E18 -> 0 | H18: =IFERROR(G18/E18,"")
C19: Suspension | E19: =+E7 -> 0 | F19: =F7 -> 0 | G19: =F19-E19 -> 0 | H19: =IFERROR(G19/E19,"")
C20: O/T | D20: 1.5 | E20: =+E8*1.5 -> 0 | F20: =+F8*1.5 -> 0 | G20: =F20-E20 -> 0 | H20: =IFERROR(G20/E20,"")
D21: 2 | E21: =+E9*2 -> 0 | F21: =+F9*2 -> 0 | G21: =F21-E21 -> 0 | H21: =IFERROR(G21/E21,"")
D22: 2.1 | E22: =+E10*2.1 -> 0 | F22: =+F10*2.1 -> 0 | G22: =F22-E22 -> 0 | H22: =IFERROR(G22/E22,"")
D23: 2.7 | E23: =+E11*2.7 -> 0 | F23: =+F11*2.7 -> 0 | G23: =F23-E23 -> 0 | H23: =IFERROR(G23/E23,"")
D24: 3 | E24: =+E12*3 -> 0 | F24: =+F12*3 -> 0 | G24: =F24-E24 -> 0 | H24: =IFERROR(G24/E24,"")
D25: 3.9 | E25: =+E13*3.9 -> 0 | F25: =+F13*3.9 -> 0 | G25: =F25-E25 -> 0 | H25: =IFERROR(G25/E25,"")
D26: Subtotal | E26: =SUM(E20:E25) -> 0 | F26: =SUM(F20:F25) -> 0 | G26: =F26-E26 -> 0 | H26: =IFERROR(G26/E26,"")
C27: Night shift | D27: 0.3 | E27: =+E15 -> 0 | F27: =+F15 -> 0 | G27: =F27-E27 -> 0 | H27: =IFERROR(G27/E27,"")
C28: Total | E28: =+E27+E26+E18+E19 -> 0 | F28: =+F27+F26+F18+F19 -> 0 | G28: =F28-E28 -> 0 | H28: =IFERROR(G28/E28,"")
B29: Labor cost | C29: =C18 -> Normal | E29: =+E34-E33-E31-E30 -> 0 | F29: =+F34-F33-F31-F30-F32 -> 0 | G29: =F29-E29 -> 0 | H29: =IFERROR(G29/E29,"")
C30: =C20 -> O/T | E30: =+('급여 요약'!W7+'급여 요약'!W8)/1000 -> 0 | F30: =+('급여 요약'!W25+'급여 요약'!W26)/1000 -> 0 | G30: =F30-E30 -> 0 | H30: =IFERROR(G30/E30,"")
C31: Support | E31: =+('급여 요약'!Y7+'급여 요약'!Y8)/1000 -> 0 | F31: =('급여 요약'!Y25+'급여 요약'!Y26+'급여 요약'!Z25+'급여 요약'!Z26)/1000 -> 0 | G31: =F31-E31 -> 0 | H31: =IFERROR(G31/E31,"")
C32: Suppension amount | E32: 0 | F32: =+'급여 요약'!X25/1000 -> 0 | G32: =F32-E32 -> 0 | H32: =IFERROR(G32/E32,"")
C33: =C27 -> Night shift | E33: =+('급여 요약'!V7+'급여 요약'!V8)/1000 -> 0 | F33: =+('급여 요약'!V26+'급여 요약'!V25)/1000 -> 0 | G33: =F33-E33 -> 0 | H33: =IFERROR(G33/E33,"")
C34: =C28 -> Total | E34: =+('급여 요약'!AA7+'급여 요약'!AA8)/1000 -> 0 | F34: =+('급여 요약'!AA25+'급여 요약'!AA26)/1000 -> 0 | G34: =F34-E34 -> 0 | H34: =IFERROR(G34/E34,"")
E36: =+Sum!V15 -> 0 | F36: =+Sum!V45 -> 0
E38: =+E36/1000-E34 -> 0 | F38: =+F36/1000-F34 -> 0

Sheet ENGLISH(qct)
B1: Man hour/labor cost anaysis (QCT)
J2: Unit : MH,1,000dong
B3: Classication | E3: =UPPER(TEXT(Sheet1!A1*28,"MMM")) -> JAN | I3: Reason | J3: Remarks
E4: Plan | F4: Actual | G4: Diff. | H4: %
A5: 생산 | B5: Man-power | E5: =+Sum!C10+Sum!C11 -> #VALUE! | F5: =+Sum!C28+Sum!C29 -> #VALUE! | G5: =F5-E5 -> #VALUE! | H5: =IFERROR(G5/E5,"")
B6: Working hour (not converted) | C6: Normal | E6: =+Sum!D10+Sum!D11 -> #VALUE! | F6: =+Sum!D28+Sum!D29 -> #VALUE! | G6: =F6-E6 -> #VALUE! | H6: =IFERROR(G6/E6,"")
C7: Suspension | E7: =+Sum!P10*8 -> 0 | F7: =+Sum!P28*8 -> 0 | G7: =F7-E7 -> 0 | H7: =IFERROR(G7/E7,"")
C8: O/T | D8: 1.5 | E8: =+Sum!F10+Sum!F11 -> 0 | F8: =+Sum!F28+Sum!F29 -> #VALUE! | G8: =F8-E8 -> #VALUE! | H8: =IFERROR(G8/E8,"")
D9: 2 | E9: =+Sum!G10+Sum!G11 -> 0 | F9: =+Sum!G28+Sum!G29 -> #VALUE! | G9: =F9-E9 -> #VALUE! | H9: =IFERROR(G9/E9,"")
D10: 2.1 | E10: =+Sum!H10+Sum!H11 -> 0 | F10: =+Sum!H28+Sum!H29 -> #VALUE! | G10: =F10-E10 -> #VALUE! | H10: =IFERROR(G10/E10,"")
D11: 2.7 | E11: =+Sum!I10+Sum!I11 -> 0 | F11: =+Sum!I28+Sum!I29 -> #VALUE! | G11: =F11-E11 -> #VALUE! | H11: =IFERROR(G11/E11,"")
D12: 3 | E12: =+Sum!J10 -> 0 | F12: =+Sum!J28 -> 0 | G12: =F12-E12 -> 0 | H12: =IFERROR(G12/E12,"")
D13: 3.9 | E13: =+Sum!K10 -> 0 | F13: =+Sum!K28 -> Total actual working day | G13: =F13-E13 -> #VALUE! | H13: =IFERROR(G13/E13,"")
D14: Subtotal | E14: =SUM(E8:E13) -> 0 | F14: =SUM(F8:F13) -> #VALUE! | G14: =SUM(G8:G11) -> #VALUE! | H14: =IFERROR(G14/E14,"")
C15: Night shift | D15: 0.3 | E15: =+Sum!E10+Sum!E11 -> #VALUE! | F15: =+Sum!E28+Sum!E29 -> #VALUE! | G15: =F15-E15 -> #VALUE! | H15: =IFERROR(G15/E15,"")
C16: Total | E16: =+E15+E14+E6+E7 -> #VALUE! | F16: =+F15+F14+F6+F7 -> #VALUE! | G16: =F16-E16 -> #VALUE! | H16: =IFERROR(G16/E16,"")
C17: Attendance | E17: =+Sum!U10 -> 0 | F17: =+Sum!U28 -> 0 | G17: =F17-E17 -> 0 | H17: =IFERROR(G17/E17,"")
B18: Working hour (converted) | C18: Normal | E18: =+E6 -> #VALUE! | F18: =+F6 -> #VALUE! | G18: =F18-E18 -> #VALUE! | H18: =IFERROR(G18/E18,"")
C19: Suspension | E19: =+E7 -> 0 | F19: =+F7 -> 0 | G19: =F19-E19 -> 0 | H19: =IFERROR(G19/E19,"")
C20: O/T | D20: 1.5 | E20: =+E8*1.5 -> 0 | F20: =+F8*1.5 -> #VALUE! | G20: =F20-E20 -> #VALUE! | H20: =IFERROR(G20/E20,"")
D21: 2 | E21: =+E9*2 -> 0 | F21: =+F9*2 -> #VALUE! | G21: =F21-E21 -> #VALUE! | H21: =IFERROR(G21/E21,"")
D22: 2.1 | E22: =+E10*2.1 -> 0 | F22: =+F10*2.1 -> #VALUE! | G22: =F22-E22 -> #VALUE! | H22: =IFERROR(G22/E22,"")
D23: 2.7 | E23: =+E11*2.7 -> 0 | F23: =+F11*2.7 -> #VALUE! | G23: =F23-E23 -> #VALUE! | H23: =IFERROR(G23/E23,"")
D24: 3 | E24: =+E12*3 -> 0 | F24: =+F12*3 -> 0 | G24: =F24-E24 -> 0 | H24: =IFERROR(G24/E24,"")
D25: 3.9 | E25: =+E13*3.9 -> 0 | F25: =+F13*3.9 -> #VALUE! | G25: =F25-E25 -> #VALUE! | H25: =IFERROR(G25/E25,"")
D26: Subtotal | E26: =SUM(E20:E25) -> 0 | F26: =SUM(F20:F25) -> #VALUE! | G26: =F26-E26 -> #VALUE! | H26: =IFERROR(G26/E26,"")
C27: Night shift | D27: 0.3 | E27: =+E15 -> #VALUE! | F27: =+F15 -> #VALUE! | G27: =F27-E27 -> #VALUE! | H27: =IFERROR(G27/E27,"")
C28: Total | E28: =+E27+E26+E18+E19 -> #VALUE! | F28: =+F27+F26+F18+F19 -> #VALUE! | G28: =F28-E28 -> #VALUE! | H28: =IFERROR(G28/E28,"")
B29: Labor cost | C29: =C18 -> Normal | E29: =(E34-E31-E33-E30)-E32 -> 0 | F29: =(F34-F31-F33-F30)-F32 -> #DIV/0! | G29: =F29-E29 -> #DIV/0! | H29: =IFERROR(G29/E29,"")
C30: =C20 -> O/T | E30: =+Sum!W10/1000+Sum!W11/1000 -> 0 | F30: =+Sum!W28/1000+Sum!W29/1000 -> 0 | G30: =F30-E30 -> 0 | H30: =IFERROR(G30/E30,"")
C31: Support | E31: =+Sum!Y10+Sum!Y11 -> 0 | F31: =+(Sum!Y28+Sum!Z28)/1000 -> 0 | G31: =F31-E31 -> 0 | H31: =IFERROR(G31/E31,"")
C32: Suppension amount | E32: =(Sum!X10+Sum!Y10+Sum!Z10)/1000 -> 0 | F32: =+Sum!X28/1000 -> 0 | G32: =F32-E32 -> 0 | H32: =IFERROR(G32/E32,"")
C33: =C27 -> Night shift | E33: =+Sum!V10/1000+Sum!V11/1000 -> 0 | F33: =+Sum!V28/1000+Sum!V29/1000 -> #DIV/0! | G33: =F33-E33 -> #DIV/0! | H33: =IFERROR(G33/E33,"")
C34: =C28 -> Total | E34: =+Sum!AA10/1000+Sum!AA11/1000 -> 0 | F34: =+Sum!AA28/1000+Sum!AA29/1000 -> 0 | G34: =F34-E34 -> 0 | H34: =IFERROR(G34/E34,"")
A35: 품질 | B35: Man-power | D35: 115 | E35: =[4]Summary!E18 -> 103 | F35: =[4]Summary!E51 -> 105 | G35: =F35-E35 -> 2 | H35: =G35/E35 -> 0.019417476 | I35: 121person (T/O)
B36: Working hour (converted) | C36: Normal | D36: 18881 | E36: =[4]Summary!J18*8 -> 18787.2 | F36: =[4]Summary!J51*8 -> 19300 | G36: =F36-E36 -> 512.8 | H36: =G36/E36 -> 0.02729518
C37: O/T | D37: =15394-527 -> 14867 | E37: =E39-E36-E38 -> 4110.84 | F37: =F39-F36-F38 -> 9389.3 | G37: =F37-E37 -> 5278.46 | H37: =G37/E37 -> 1.2840344
C38: Night shift | D38: 527 | E38: =[4]Summary!S18*0.3 -> 601.92 | F38: =[4]Summary!S51*0.3 -> 511.2 | G38: =F38-E38 -> -90.72 | H38: =G38/E38 -> -0.1507177
C39: Total | D39: =D38+D37+D36 -> 34275 | E39: =[4]Summary!R18+E38 -> 23499.96 | F39: =[4]Summary!R51+F38 -> 29200.5 | G39: =F39-E39 -> 5700.54 | H39: =G39/E39 -> 0.24257658
B40: Labor cost | C40: =C36 -> Normal | E40: =E43-E41-E42 -> 511693.75 | F40: =F43-F41-F42 -> 525633.25 | G40: =F40-E40 -> 13939.502 | H40: =G40/E40 -> 0.027241884 | I40: 급여인원 감소(5명) | L40: =[4]Summary!F81+[4]Summary!G81 -> 10528000
...
