Workbook

Sheet Sheet1
B4: 1 | C4: 2 | D4: 2 | E4: 2 | F4: 2 | G4: 2 | H4: 2 | I4: 2 | J4: 2 | K4: 2 | L4: 2 | M4: 2 | N4: 2 | O4: 2 | P4: 2 | Q4: 2 | R4: 2 | S4: 2 | T4: 2 | U4: 2 | V4: 2 | W4: 2 | X4: 2 | Y4: 2 | Z4: 2 | AA4: 2 | AB4: 2 | AC4: 2 | AD4: 2 | AE4: 2 | AF4: 2 | AG4: 2 | AI4: 2 | AK4: 2 | AL4: 2 | AM4: 2
B5: Month | C5: HD1NAM | D5: HD3NAM | E5: HDHOCVIEC | F5: HDVTH | G5: THUVIEC | H5: MAN_ | I5: GA_Office | J5: GA_Other | K5: GA_ | M5: MA_Office | N5: MA_Other | O5: MA_ | Q5: PL_Office | R5: PL_WH | S5: PL_ | U5: Pr_Direct | V5: Pr_Indirect | W5: Pr_ | X5: PM_ | Z5: QD_ | AA5: tgMAN | AB5: tgGA | AC5: tgMA | AD5: tgPL | AE5: tgPr | AF5: tgQD | AG5: tgPM | AH5: Vietnamese_Direct | AI5: Vietnamese_Indirect | AJ5: NonVietnamese_Travel | AK5: NonVietnamese_Resident | AL5: TerminationCode | AM5: ReasonTernimated | AN5: CountEmployeeTerminated
B6: Tháng | C6: HĐ 1 năm | D6: HDĐ 3 năm | E6: HĐ học việc | F6: HĐ vô thời hạn | G6: Thử việc | H6: Quản lý | I6: Văn phòng | J6: Văn phòng khác | K6: Hành chính tổng hợp | M6: Bảo trì văn phòng | N6: Bảo trì khác | O6: Bảo trì | Q6: Mua hàng và Logictics - VP | R6: Mua hàng và Logictics - Nhà kho | S6: Mua hàng và Logictics | U6: Sản xuất - Trực tiếp | V6: Sản xuất - Gián tiếp | W6: Sản xuất | X6: Quản lý sản xuất | Z6: Chất lượng | AA6: Tăng quản lý | AB6: Tăng hành chính | AC6: Tăng bảo trì | AD6: Tăng mua hàng | AE6: Tăng sản xuất | AF6: Tăng chất lượng | AG6: Tăng quản lý sản xuất | AH6: Việt nam TT Sản xuất | AI6: Việt nam GT Sản xuất | AJ6: Người nước ngoài k cư trú | AK6: Người nước ngoài cư trú | AL6: Mã nghỉ | AM6: Lý do | AN6: Số lượng
L7: =I7+J7 -> 0 | P7: =M7+N7 -> 0 | T7: =Q7+R7 -> 0 | Y7: =U7+V7+X7 -> 0
L8: =I8+J8 -> 0 | P8: =M8+N8 -> 0 | T8: =Q8+R8 -> 0 | Y8: =U8+V8+X8 -> 0
L9: =I9+J9 -> 0 | P9: =M9+N9 -> 0 | T9: =Q9+R9 -> 0 | Y9: =U9+V9+X9 -> 0
L10: =I10+J10 -> 0 | P10: =M10+N10 -> 0 | T10: =Q10+R10 -> 0 | Y10: =U10+V10+X10 -> 0
L11: =I11+J11 -> 0 | P11: =M11+N11 -> 0 | T11: =Q11+R11 -> 0 | Y11: =U11+V11+X11 -> 0
L12: =I12+J12 -> 0 | P12: =M12+N12 -> 0 | T12: =Q12+R12 -> 0 | Y12: =U12+V12+X12 -> 0
L13: =I13+J13 -> 0 | P13: =M13+N13 -> 0 | T13: =Q13+R13 -> 0 | Y13: =U13+V13+X13 -> 0
L14: =I14+J14 -> 0 | P14: =M14+N14 -> 0 | T14: =Q14+R14 -> 0 | Y14: =U14+V14+X14 -> 0
L15: =I15+J15 -> 0 | P15: =M15+N15 -> 0 | T15: =Q15+R15 -> 0 | Y15: =U15+V15+X15 -> 0
L16: =I16+J16 -> 0 | P16: =M16+N16 -> 0 | T16: =Q16+R16 -> 0 | Y16: =U16+V16+X16 -> 0
L17: =I17+J17 -> 0 | P17: =M17+N17 -> 0 | T17: =Q17+R17 -> 0 | Y17: =U17+V17+X17 -> 0
L18: =I18+J18 -> 0 | P18: =M18+N18 -> 0 | T18: =Q18+R18 -> 0 | Y18: =U18+V18+X18 -> 0
L19: =I19+J19 -> 0 | P19: =M19+N19 -> 0 | T19: =Q19+R19 -> 0 | Y19: =U19+V19+X19 -> 0

Sheet Sheet2
B2: 1. Employees Status ( 근무인원 현황)
B4: Korean-Vietnames ( 주재원-현지)
B14: No | C14: Nationality | D14: Type | G14: Jan | H14: Feb | I14: Mar | J14: Apr | K14: May | L14: Jun | M14: Jul | N14: Aug | O14: Sep | P14: Oct | Q14: Nov | R14: Dec
B15: 1 | C15: Korea | D15: Resident | G15: =Sheet1!AK7 -> 0 | H15: =Sheet1!AK8 -> 0 | I15: =Sheet1!AK9 -> 0 | J15: =Sheet1!AK10 -> 0 | K15: =Sheet1!AK11 -> 0 | L15: =Sheet1!AK12 -> 0 | M15: =Sheet1!AK13 -> 0 | N15: =Sheet1!AK14 -> 0 | O15: =Sheet1!AK15 -> 0 | P15: =Sheet1!AK16 -> 0 | Q15: =Sheet1!AK17 -> 0 | R15: =Sheet1!AK18 -> 0
D16: Travel | G16: =Sheet1!AJ7 -> 0 | H16: =Sheet1!AJ8 -> 0 | I16: =Sheet1!AJ9 -> 0 | J16: =Sheet1!AJ10 -> 0 | K16: =Sheet1!AJ11 -> 0 | L16: =Sheet1!AJ12 -> 0 | M16: =Sheet1!AJ13 -> 0 | N16: =Sheet1!AJ14 -> 0 | O16: =Sheet1!AJ15 -> 0 | P16: =Sheet1!AJ16 -> 0 | Q16: =Sheet1!AJ17 -> 0 | R16: =Sheet1!AJ18 -> 0
B17: 2 | C17: Vietnamese | D17: Indirect | G17: =Sheet1!AI7 -> 0 | H17: =Sheet1!AI8 -> 0 | I17: =Sheet1!AI9 -> 0 | J17: =Sheet1!AI10 -> 0 | K17: =Sheet1!AI11 -> 0 | L17: =Sheet1!AI12 -> 0 | M17: =Sheet1!AI13 -> 0 | N17: =Sheet1!AI14 -> 0 | O17: =Sheet1!AI15 -> 0 | P17: =Sheet1!AI16 -> 0 | Q17: =Sheet1!AI17 -> 0 | R17: =Sheet1!AI18 -> 0
D18: Direct | G18: =Sheet1!AH7 -> 0 | H18: =Sheet1!AH8 -> 0 | I18: =Sheet1!AH9 -> 0 | J18: =Sheet1!AH10 -> 0 | K18: =Sheet1!AH11 -> 0 | L18: =Sheet1!AH12 -> 0 | M18: =Sheet1!AH13 -> 0 | N18: =Sheet1!AH14 -> 0 | O18: =Sheet1!AH15 -> 0 | P18: =Sheet1!AH16 -> 0 | Q18: =Sheet1!AH17 -> 0 | R18: =Sheet1!AH18 -> 0
B20: Employees status ( 직원 현황)
B30: No | C30: Employees status(현황) | G30: Jan | H30: Feb | I30: Mar | J30: Apr | K30: May | L30: Jun | M30: Jul | N30: Aug | O30: Sep | P30: Oct | Q30: Nov | R30: Dec
B31: 1 | C31: Intern | G31: =Sheet1!E7 -> 0 | H31: =Sheet1!E8 -> 0 | I31: =Sheet1!E9 -> 0 | J31: =Sheet1!E10 -> 0 | K31: =Sheet1!E11 -> 0 | L31: =Sheet1!E12 -> 0 | M31: =Sheet1!E13 -> 0 | N31: =Sheet1!E14 -> 0 | O31: =Sheet1!E15 -> 0 | P31: =Sheet1!E16 -> 0 | Q31: =Sheet1!E17 -> 0 | R31: =Sheet1!E18 -> 0
B32: 2 | C32: Probation | G32: =Sheet1!G7 -> 0 | H32: =Sheet1!G8 -> 0 | I32: =Sheet1!G9 -> 0 | J32: =Sheet1!G10 -> 0 | K32: =Sheet1!G11 -> 0 | L32: =Sheet1!G12 -> 0 | M32: =Sheet1!G13 -> 0 | N32: =Sheet1!G14 -> 0 | O32: =Sheet1!G15 -> 0 | P32: =Sheet1!G16 -> 0 | Q32: =Sheet1!G17 -> 0 | R32: =Sheet1!G18 -> 0
B33: 3 | C33: 1Year contract | G33: =Sheet1!C7 -> 0 | H33: =Sheet1!C8 -> 0 | I33: =Sheet1!C9 -> 0 | J33: =Sheet1!C10 -> 0 | K33: =Sheet1!C11 -> 0 | L33: =Sheet1!C12 -> 0 | M33: =Sheet1!C13 -> 0 | N33: =Sheet1!C14 -> 0 | O33: =Sheet1!C15 -> 0 | P33: =Sheet1!C16 -> 0 | Q33: =Sheet1!C17 -> 0 | R33: =Sheet1!C18 -> 0
B34: 4 | C34: 3Year contract | G34: =Sheet1!D7 -> 0 | H34: =Sheet1!D8 -> 0 | I34: =Sheet1!D9 -> 0 | J34: =Sheet1!D10 -> 0 | K34: =Sheet1!D11 -> 0 | L34: =Sheet1!D12 -> 0 | M34: =Sheet1!D13 -> 0 | N34: =Sheet1!D14 -> 0 | O34: =Sheet1!D15 -> 0 | P34: =Sheet1!D16 -> 0 | Q34: =Sheet1!D17 -> 0 | R34: =Sheet1!D18 -> 0
B35: 5 | C35: Permanent | G35: =Sheet1!F7 -> 0 | H35: =Sheet1!F8 -> 0 | I35: =Sheet1!F9 -> 0 | J35: =Sheet1!F10 -> 0 | K35: =Sheet1!F11 -> 0 | L35: =Sheet1!F12 -> 0 | M35: =Sheet1!F13 -> 0 | N35: =Sheet1!F14 -> 0 | O35: =Sheet1!F15 -> 0 | P35: =Sheet1!F16 -> 0 | Q35: =Sheet1!F17 -> 0 | R35: =Sheet1!F18 -> 0
B36: Total | G36: =SUM(G31:G35) -> 0 | H36: =SUM(H31:H35) -> 0 | I36: =SUM(I31:I35) -> 0 | J36: =SUM(J31:J35) -> 0 | K36: =SUM(K31:K35) -> 0 | L36: =SUM(L31:L35) -> 0 | M36: =SUM(M31:M35) -> 0 | N36: =SUM(N31:N35) -> 0 | ... R36: =SUM(R31:R35) -> 0
B38: By Department ( 부서별 인원 현황)
B48: No | C48: Department | E48: Approved H/C | F48: Over/Less | G48: Jan | H48: Feb | I48: Mar | J48: Apr | K48: May | L48: Jun | M48: Jul | N48: Aug | O48: Sep | P48: Oct | Q48: Nov | R48: Dec
B49: 1 | C49: Managerment | G49: =Sheet1!H7 -> 0 | H49: =Sheet1!H8 -> 0 | I49: =Sheet1!H9 -> 0 | J49: =Sheet1!H10 -> 0 | K49: =Sheet1!H11 -> 0 | L49: =Sheet1!H12 -> 0 | M49: =Sheet1!H13 -> 0 | N49: =Sheet1!H14 -> 0 | O49: =Sheet1!H15 -> 0 | P49: =Sheet1!H16 -> 0 | Q49: =Sheet1!H17 -> 0 | R49: =Sheet1!H18 -> 0
B50: 2 | C50: General administration | D50: Office | G50: =Sheet1!I7 -> 0 | H50: =Sheet1!I8 -> 0 | I50: =Sheet1!I9 -> 0 | J50: =Sheet1!I10 -> 0 | K50: =Sheet1!I11 -> 0 | L50: =Sheet1!I12 -> 0 | M50: =Sheet1!I13 -> 0 | N50: =Sheet1!I14 -> 0 | O50: =Sheet1!I15 -> 0 | P50: =Sheet1!I16 -> 0 | Q50: =Sheet1!I17 -> 0 | R50: =Sheet1!I18 -> 0
D51: Other | G51: =Sheet1!J7 -> 0 | H51: =Sheet1!J8 -> 0 | I51: =Sheet1!J9 -> 0 | J51: =Sheet1!J10 -> 0 | K51: =Sheet1!J11 -> 0 | L51: =Sheet1!J12 -> 0 | M51: =Sheet1!J13 -> 0 | N51: =Sheet1!J14 -> 0 | O51: =Sheet1!J15 -> 0 | P51: =Sheet1!J16 -> 0 | Q51: =Sheet1!J17 -> 0 | R51: =Sheet1!J18 -> 0
B52: 3 | C52: Production | D52: Direct | G52: =Sheet1!U7 -> 0 | H52: =Sheet1!U8 -> 0 | I52: =Sheet1!U9 -> 0 | J52: =Sheet1!U10 -> 0 | K52: =Sheet1!U11 -> 0 | L52: =Sheet1!U12 -> 0 | M52: =Sheet1!U13 -> 0 | N52: =Sheet1!U14 -> 0 | O52: =Sheet1!U15 -> 0 | P52: =Sheet1!U16 -> 0 | Q52: =Sheet1!U17 -> 0 | R52: =Sheet1!U18 -> 0
D53: Indirect | G53: =Sheet1!V7 + Sheet1!X7 -> 0 | H53: =Sheet1!V8 + Sheet1!X8 -> 0 | I53: =Sheet1!V9 + Sheet1!X9 -> 0 | J53: =Sheet1!V10 + Sheet1!X10 -> 0 | K53: =Sheet1!V11 + Sheet1!X11 -> 0 | L53: =Sheet1!V12 + Sheet1!X12 -> 0 | M53: =Sheet1!V13 + Sheet1!X13 -> 0 | N53: =Sheet1!V14 + Sheet1!X14 -> 0 | O53: =Sheet1!V15 + Sheet1!X15 -> 0 | P53: =Sheet1!V16 + Sheet1!X16 -> 0 | Q53: =Sheet1!V17 + Sheet1!X17 -> 0 | R53: =Sheet1!V18 + Sheet1!X18 -> 0
B54: 4 | C54: Industrial Engineer | D54: Office | G54: =Sheet1!M7 -> 0 | H54: =Sheet1!M8 -> 0 | I54: =Sheet1!M9 -> 0 | J54: =Sheet1!M10 -> 0 | K54: =Sheet1!M11 -> 0 | L54: =Sheet1!M12 -> 0 | M54: =Sheet1!M13 -> 0 | N54: =Sheet1!M14 -> 0 | O54: =Sheet1!M15 -> 0 | P54: =Sheet1!M16 -> 0 | Q54: =Sheet1!M17 -> 0 | R54: =Sheet1!M18 -> 0
D55: Other | G55: =Sheet1!N7 -> 0 | H55: =Sheet1!N8 -> 0 | I55: =Sheet1!N9 -> 0 | J55: =Sheet1!N10 -> 0 | K55: =Sheet1!N11 -> 0 | L55: =Sheet1!N12 -> 0 | M55: =Sheet1!N13 -> 0 | N55: =Sheet1!N14 -> 0 | O55: =Sheet1!N15 -> 0 | P55: =Sheet1!N16 -> 0 | Q55: =Sheet1!N17 -> 0 | R55: =Sheet1!N18 -> 0
B56: 5 | C56: Quality | G56: =Sheet1!Z7 -> 0 | H56: =Sheet1!Z8 -> 0 | I56: =Sheet1!Z9 -> 0 | J56: =Sheet1!Z10 -> 0 | K56: =Sheet1!Z11 -> 0 | L56: =Sheet1!Z12 -> 0 | M56: =Sheet1!Z13 -> 0 | N56: =Sheet1!Z14 -> 0 | O56: =Sheet1!Z15 -> 0 | P56: =Sheet1!Z16 -> 0 | Q56: =Sheet1!Z17 -> 0 | R56: =Sheet1!Z18 -> 0
B57: 6 | C57: Purchasing & Logistics | D57: Office | G57: =Sheet1!Q7 -> 0 | H57: =Sheet1!Q8 -> 0 | I57: =Sheet1!Q9 -> 0 | J57: =Sheet1!Q10 -> 0 | K57: =Sheet1!Q11 -> 0 | L57: =Sheet1!Q12 -> 0 | M57: =Sheet1!Q13 -> 0 | N57: =Sheet1!Q14 -> 0 | O57: =Sheet1!Q15 -> 0 | P57: =Sheet1!Q16 -> 0 | Q57: =Sheet1!Q17 -> 0 | R57: =Sheet1!Q18 -> 0
D58: W/H | G58: =Sheet1!R7 -> 0 | H58: =Sheet1!R8 -> 0 | I58: =Sheet1!R9 -> 0 | J58: =Sheet1!R10 -> 0 | K58: =Sheet1!R11 -> 0 | L58: =Sheet1!R12 -> 0 | M58: =Sheet1!R13 -> 0 | N58: =Sheet1!R14 -> 0 | O58: =Sheet1!R15 -> 0 | P58: =Sheet1!R16 -> 0 | Q58: =Sheet1!R17 -> 0 | R58: =Sheet1!R18 -> 0
B59: Total | G59: =SUM(G49:G58) -> 0 | H59: =SUM(H49:H58) -> 0 | I59: =SUM(I49:I58) -> 0 | J59: =SUM(J49:J58) -> 0 | K59: =SUM(K49:K58) -> 0 | L59: =SUM(L49:L58) -> 0 | M59: =SUM(M49:M58) -> 0 | N59: =SUM(N49:N58) -> 0 | ... R59: =SUM(R49:R58) -> 0
B61: Employees turnover ( 부서별 인원 변동 현황)
B75: No | C75: Department | G75: Jan | H75: Feb | I75: Mar | J75: Apr | K75: May | L75: Jun | M75: Jul | N75: Aug | O75: Sep | P75: Oct | Q75: Nov | R75: Dec
B76: 1 | C76: Management + | G76: =Sheet1!AA7 -> 0 | H76: =Sheet1!AA8 -> 0 | I76: =Sheet1!AA9 -> 0 | J76: =Sheet1!AA10 -> 0 | K76: =Sheet1!AA11 -> 0 | L76: =Sheet1!AA12 -> 0 | M76: =Sheet1!AA13 -> 0 | N76: =Sheet1!AA14 -> 0 | O76: =Sheet1!AA15 -> 0 | P76: =Sheet1!AA16 -> 0 | Q76: =Sheet1!AA17 -> 0 | R76: =Sheet1!AA18 -> 0
C77: Managenent - | G77: =Sheet1!H7 - (Sheet1!H19 + Sheet1!AA7) -> 0 | H77: =Sheet1!H8 - (Sheet1!H7 + Sheet1!AA8) -> 0 | I77: =Sheet1!H9 - (Sheet1!H8 + Sheet1!AA9) -> 0 | J77: =Sheet1!H10 - (Sheet1!H9 + Sheet1!AA10) -> 0 | K77: =Sheet1!H11 - (Sheet1!H10 + Sheet1!AA11) -> 0 | L77: =Sheet1!H12 - (Sheet1!H11 + Sheet1!AA12) -> 0 | M77: =Sheet1!H13 - (Sheet1!H12 + Sheet1!AA13) -> 0 | N77: =Sheet1!H14 - (Sheet1!H13 + Sheet1!AA14) -> 0 | O77: =Sheet1!H15 - (Sheet1!H14 + Sheet1!AA15) -> 0 | P77: =Sheet1!H16 - (Sheet1!H15 + Sheet1!AA16) -> 0 | Q77: =Sheet1!H17 - (Sheet1!H16 + Sheet1!AA17) -> 0 | R77: =Sheet1!H18 - (Sheet1!H17 + Sheet1!AA18) -> 0
B78: 2 | C78: Industrial Eng + | G78: =Sheet1!AC7 -> 0 | H78: =Sheet1!AC8 -> 0 | I78: =Sheet1!AC9 -> 0 | J78: =Sheet1!AC10 -> 0 | K78: =Sheet1!AC11 -> 0 | L78: =Sheet1!AC12 -> 0 | M78: =Sheet1!AC13 -> 0 | N78: =Sheet1!AC14 -> 0 | O78: =Sheet1!AC15 -> 0 | P78: =Sheet1!AC16 -> 0 | Q78: =Sheet1!AC17 -> 0 | R78: =Sheet1!AC18 -> 0
C79: Industrial Eng - | G79: =Sheet1!P7 - (Sheet1!P19 + Sheet1!AC7) -> 0 | H79: =Sheet1!P8 - (Sheet1!P7 + Sheet1!AC8) -> 0 | I79: =Sheet1!P9 - (Sheet1!P8 + Sheet1!AC9) -> 0 | J79: =Sheet1!P10 - (Sheet1!P9 + Sheet1!AC10) -> 0 | K79: =Sheet1!P11 - (Sheet1!P10 + Sheet1!AC11) -> 0 | L79: =Sheet1!P12 - (Sheet1!P11 + Sheet1!AC12) -> 0 | M79: =Sheet1!P13 - (Sheet1!P12 + Sheet1!AC13) -> 0 | N79: =Sheet1!P14 - (Sheet1!P13 + Sheet1!AC14) -> 0 | O79: =Sheet1!P15 - (Sheet1!P14 + Sheet1!AC15) -> 0 | P79: =Sheet1!P16 - (Sheet1!P15 + Sheet1!AC16) -> 0 | Q79: =Sheet1!P17 - (Sheet1!P16 + Sheet1!AC17) -> 0 | R79: =Sheet1!P18 - (Sheet1!P17 + Sheet1!AC18) -> 0
B80: 3 | C80: General adm + | G80: =Sheet1!AB7 -> 0 | H80: =Sheet1!AB8 -> 0 | I80: =Sheet1!AB9 -> 0 | J80: =Sheet1!AB10 -> 0 | K80: =Sheet1!AB11 -> 0 | L80: =Sheet1!AB12 -> 0 | M80: =Sheet1!AB13 -> 0 | N80: =Sheet1!AB14 -> 0 | O80: =Sheet1!AB15 -> 0 | P80: =Sheet1!AB16 -> 0 | Q80: =Sheet1!AB17 -> 0 | R80: =Sheet1!AB18 -> 0
C81: General adm - | G81: =Sheet1!L7 - (Sheet1!L19 + Sheet1!AB7) -> 0 | H81: =Sheet1!L8 - (Sheet1!L7 + Sheet1!AB8) -> 0 | I81: =Sheet1!L9 - (Sheet1!L8 + Sheet1!AB9) -> 0 | J81: =Sheet1!L10 - (Sheet1!L9 + Sheet1!AB10) -> 0 | K81: =Sheet1!L11 - (Sheet1!L10 + Sheet1!AB11) -> 0 | L81: =Sheet1!L12 - (Sheet1!L11 + Sheet1!AB12) -> 0 | M81: =Sheet1!L13 - (Sheet1!L12 + Sheet1!AB13) -> 0 | N81: =Sheet1!L14 - (Sheet1!L13 + Sheet1!AB14) -> 0 | O81: =Sheet1!L15 - (Sheet1!L14 + Sheet1!AB15) -> 0 | P81: =Sheet1!L16 - (Sheet1!L15 + Sheet1!AB16) -> 0 | Q81: =Sheet1!L17 - (Sheet1!L16 + Sheet1!AB17) -> 0 | R81: =Sheet1!L18 - (Sheet1!L17 + Sheet1!AB18) -> 0
B82: 4 | C82: Production + | G82: =Sheet1!AE7+Sheet1!AG7 -> 0 | H82: =Sheet1!AE8+Sheet1!AG8 -> 0 | I82: =Sheet1!AE9+Sheet1!AG9 -> 0 | J82: =Sheet1!AE10+Sheet1!AG10 -> 0 | K82: =Sheet1!AE11+Sheet1!AG11 -> 0 | L82: =Sheet1!AE12+Sheet1!AG12 -> 0 | M82: =Sheet1!AE13+Sheet1!AG13 -> 0 | N82: =Sheet1!AE14+Sheet1!AG14 -> 0 | O82: =Sheet1!AE15+Sheet1!AG15 -> 0 | P82: =Sheet1!AE16+Sheet1!AG16 -> 0 | Q82: =Sheet1!AE17+Sheet1!AG17 -> 0 | R82: =Sheet1!AE18+Sheet1!AG18 -> 0
C83: Production - | G83: =Sheet1!Y7-(Sheet1!Y19+Sheet1!AE7+Sheet1!AG7) -> 0 | H83: =Sheet1!Y8-(Sheet1!Y7+Sheet1!AE8+Sheet1!AG8) -> 0 | I83: =Sheet1!Y9-(Sheet1!Y8+Sheet1!AE9+Sheet1!AG9) -> 0 | J83: =Sheet1!Y10-(Sheet1!Y9+Sheet1!AE10+Sheet1!AG10) -> 0 | K83: =Sheet1!Y11-(Sheet1!Y10+Sheet1!AE11+Sheet1!AG11) -> 0 | L83: =Sheet1!Y12-(Sheet1!Y11+Sheet1!AE12+Sheet1!AG12) -> 0 | M83: =Sheet1!Y13-(Sheet1!Y12+Sheet1!AE13+Sheet1!AG13) -> 0 | N83: =Sheet1!Y14-(Sheet1!Y13+Sheet1!AE14+Sheet1!AG14) -> 0 | O83: =Sheet1!Y15-(Sheet1!Y14+Sheet1!AE15+Sheet1!AG15) -> 0 | P83: =Sheet1!Y16-(Sheet1!Y15+Sheet1!AE16+Sheet1!AG16) -> 0 | Q83: =Sheet1!Y17-(Sheet1!Y16+Sheet1!AE17+Sheet1!AG17) -> 0 | R83: =Sheet1!Y18-(Sheet1!Y17+Sheet1!AE18+Sheet1!AG18) -> 0
B84: 5 | C84: Quality + | G84: =Sheet1!AF7 -> 0 | H84: =Sheet1!AF8 -> 0 | I84: =Sheet1!AF9 -> 0 | J84: =Sheet1!AF10 -> 0 | K84: =Sheet1!AF11 -> 0 | L84: =Sheet1!AF12 -> 0 | M84: =Sheet1!AF13 -> 0 | N84: =Sheet1!AF14 -> 0 | O84: =Sheet1!AF15 -> 0 | P84: =Sheet1!AF16 -> 0 | Q84: =Sheet1!AF17 -> 0 | R84: =Sheet1!AF18 -> 0
C85: Quality - | G85: =Sheet1!Z7-(Sheet1!Z19+Sheet1!AF7) -> 0 | H85: =Sheet1!Z8-(Sheet1!Z7+Sheet1!AF8) -> 0 | I85: =Sheet1!Z9-(Sheet1!Z8+Sheet1!AF9) -> 0 | J85: =Sheet1!Z10-(Sheet1!Z9+Sheet1!AF10) -> 0 | K85: =Sheet1!Z11-(Sheet1!Z10+Sheet1!AF11) -> 0 | L85: =Sheet1!Z12-(Sheet1!Z11+Sheet1!AF12) -> 0 | M85: =Sheet1!Z13-(Sheet1!Z12+Sheet1!AF13) -> 0 | N85: =Sheet1!Z14-(Sheet1!Z13+Sheet1!AF14) -> 0 | O85: =Sheet1!Z15-(Sheet1!Z14+Sheet1!AF15) -> 0 | P85: =Sheet1!Z16-(Sheet1!Z15+Sheet1!AF16) -> 0 | Q85: =Sheet1!Z17-(Sheet1!Z16+Sheet1!AF17) -> 0 | R85: =Sheet1!Z18-(Sheet1!Z17+Sheet1!AF18) -> 0
...
