Workbook

Sheet Sheet1
A1: 1
B4: 1 | C4: 1 | D4: 1 | F4: 1 | G4: 1 | H4: 1 | I4: 1 | J4: 2 | K4: 2 | L4: 2 | M4: 2 | N4: 2 | O4: 2 | P4: 2 | Q4: 2 | R4: 2 | S4: 2 | T4: 2 | U4: 2 | V4: 2 | W4: 2
B5: Orderby | C5: Month | D5: Position | E5: Year | H5: NameEN | I5: Position_NameEN | J5: WeekdayNormal | K5: WeekdayOT | L5: NightSunday | M5: NightShift | N5: SundayWorking | O5: AnnualLeave | P5: AbsentLeave | Q5: NotWorkingHr | R5: LateIn | S5: EarlyOut | T5: GoOut | U5: Sales | V5: Vietnamese | W5: TotalEmployeePaySalary
B6: Order by | C6: Month | D6: Position | E6: Year | F6: Find total | G6: Find Position | H6: Position Name | I6: Position Name Pr | J6: Weekday Nornal | K6: Weekday OT | L6: Night Sunday | M6: Night Shift | N6: Sunday Working | O6: Annual Leave | P6: Absent Leave | Q6: Not Working Hr | R6: Late In | S6: Early Out | T6: Go Out | U6: Sales | V6: Vietnamese | W6: Total Employee Pay Salary | X6: Total Working | Y6: Weekday working | Z6: LOSS
F7: =C7&"-"&E7 -> - | G7: =C7&"-"&E7&"-"&D7 -> -- | X7: =J7+K7+N7 -> 0 | Y7: =J7+K7 -> 0 | Z7: =R7+S7+T7+O7+P7 -> 0

Sheet Sales per employees
B2: 2. Sales per employees
B4: Sales turnover as Employees/ hour ( 인당 및 시간당 매출액)
B17: Year (년도) | D17: Sales turnover (매출액) | E17: # of Employees (평균 인원) | F17: Sales/Person ( 인당 매출액) | G17: Sales/Hour (시간당매출 ) | H17: Sales/Weekday (평일시간당매출) | I17: Weekday rate(평일시간매출율) | J17: Sales/Sunday (특근시간당매출) | K17: Sales/Sunday (특근매출율)
B18: ="Y" & C18 -> Y0 | C18: =VALUE(Sheet1!$A$1-1) -> 0 | D18: =SUM(D45:D52) -> 0 | E18: 65 | F18: =IFERROR(D18/E18,0) -> 0 | G18: =IFERROR(D18/SUMIF(Sheet1!$E$7:$E$4000,C18,Sheet1!$X$7:$X$4000),0) -> 0 | H18: =IFERROR(G18*(SUMIF(Sheet1!$E$7:$E$4000,C18,Sheet1!$Y$7:$Y$4000)/SUMIF(Sheet1!$E$7:$E$4000,C18,Sheet1!$X$7:$X$4000)),0) -> 0 | I18: =IFERROR(H18/G18, "") | J18: =IFERROR(G18*(SUMIF(Sheet1!$E$7:$E$4000,C18,Sheet1!$N$7:$N$4000)/SUMIF(Sheet1!$E$7:$E$4000,C18,Sheet1!$X$7:$X$4000)),0) -> 0 | K18: =IFERROR(J18/G18, "")
B19: ="Y" & C19 -> Y1 | C19: =VALUE(Sheet1!$A$1) -> 1 | D19: =SUM(D53:D64) -> 0 | E19: =IFERROR(VLOOKUP('Sales per employees'!C19,Sheet1!$E$7:$W$4000,19,0),0) -> 0 | F19: =IFERROR(D19/E19,0) -> 0 | G19: =IFERROR(D19/SUMIF(Sheet1!$E$7:$E$4000,C19,Sheet1!$X$7:$X$4000),0) -> 0 | H19: =IFERROR(G19*(SUMIF(Sheet1!$E$7:$E$4000,C19,Sheet1!$Y$7:$Y$4000)/SUMIF(Sheet1!$E$7:$E$4000,C19,Sheet1!$X$7:$X$4000)),0) -> 0 | I19: =IFERROR(H19/G19, "") | J19: =IFERROR(G19*(SUMIF(Sheet1!$E$7:$E$4000,C19,Sheet1!$N$7:$N$4000)/SUMIF(Sheet1!$E$7:$E$4000,C19,Sheet1!$X$7:$X$4000)),0) -> 0 | K19: =IFERROR(J19/G19, "")
B20: ="Y" & C20 -> Y2 | C20: =VALUE(Sheet1!$A$1+1) -> 2 | D20: =SUM(D65:D76) -> 0 | E20: =IFERROR(VLOOKUP('Sales per employees'!C20,Sheet1!$E$7:$W$4000,19,0),0) -> 0 | F20: =IFERROR(D20/E20,0) -> 0 | G20: =IFERROR(D20/SUMIF(Sheet1!$E$7:$E$4000,C20,Sheet1!$X$7:$X$4000),0) -> 0 | H20: =IFERROR(G20*(SUMIF(Sheet1!$E$7:$E$4000,C20,Sheet1!$Y$7:$Y$4000)/SUMIF(Sheet1!$E$7:$E$4000,C20,Sheet1!$X$7:$X$4000)),0) -> 0 | I20: =IFERROR(H20/G20, "") | J20: =IFERROR(G20*(SUMIF(Sheet1!$E$7:$E$4000,C20,Sheet1!$N$7:$N$4000)/SUMIF(Sheet1!$E$7:$E$4000,C20,Sheet1!$X$7:$X$4000)),0) -> 0 | K20: =IFERROR(J20/G20, "")
B26: Monthly Sales per Employees/ hour ( 월별 인당 및 시간당 매출액)
B44: Month (월) | D44: Sales (매출) | E44: # of Employees (인원) | F44: Sales/Person ( 인당 매출액) | G44: Sales/Hour (시간당매출 ) | H44: Sales/Weekday (평일시간당매출) | I44: Weekday rate(평일시간매출율) | J44: Sales/Sunday (특근시간당매출) | K44: Sales/Sunday (특근매출율)
B45: =DATE(N45,M45,1) -> 122 | C45: =TEXT(M45*29,"mmm")& "-" &N45 -> May-0 | D45: =IFERROR(VLOOKUP(C45,Sheet1!$F$7:$U$4000,16,0),0) -> 0 | E45: =IFERROR(VLOOKUP(C45,Sheet1!$F$7:$V$4000,17,0),0) -> 0 | F45: =IFERROR(D45/E45,0) -> 0 | G45: =IFERROR(D45/SUMIF(Sheet1!$F$7:$F$4000,C45,Sheet1!$X$7:$X$4000),0) -> 0 | H45: =IFERROR(G45*(SUMIF(Sheet1!$F$7:$F$4000,C45,Sheet1!$Y$7:$Y$4000)/SUMIF(Sheet1!$F$7:$F$4000,C45,Sheet1!$X$7:$X$4000)),0) -> 0 | I45: =IFERROR(H45/G45, "") | J45: =IFERROR(G45*(SUMIF(Sheet1!$F$7:$F$4000,C45,Sheet1!$N$7:$N$4000)/SUMIF(Sheet1!$F$7:$F$4000,C45,Sheet1!$X$7:$X$4000)),0) -> 0 | K45: =IFERROR(J45/G45, "") | M45: 5 | N45: =Sheet1!$A$1-1 -> 0
B46: =DATE(N46,M46,1) -> 153 | C46: =TEXT(M46*29,"mmm")& "-" &N46 -> Jun-0 | D46: =IFERROR(VLOOKUP(C46,Sheet1!$F$7:$U$4000,16,0),0) -> 0 | E46: =IFERROR(VLOOKUP(C46,Sheet1!$F$7:$V$4000,17,0),0) -> 0 | F46: =IFERROR(D46/E46,0) -> 0 | G46: =IFERROR(D46/SUMIF(Sheet1!$F$7:$F$4000,C46,Sheet1!$X$7:$X$4000),0) -> 0 | H46: =IFERROR(G46*(SUMIF(Sheet1!$F$7:$F$4000,C46,Sheet1!$Y$7:$Y$4000)/SUMIF(Sheet1!$F$7:$F$4000,C46,Sheet1!$X$7:$X$4000)),0) -> 0 | I46: =IFERROR(H46/G46, "") | J46: =IFERROR(G46*(SUMIF(Sheet1!$F$7:$F$4000,C46,Sheet1!$N$7:$N$4000)/SUMIF(Sheet1!$F$7:$F$4000,C46,Sheet1!$X$7:$X$4000)),0) -> 0 | K46: =IFERROR(J46/G46, "") | M46: 6 | N46: =Sheet1!$A$1-1 -> 0
B47: =DATE(N47,M47,1) -> 183 | C47: =TEXT(M47*29,"mmm")& "-" &N47 -> Jul-0 | D47: =IFERROR(VLOOKUP(C47,Sheet1!$F$7:$U$4000,16,0),0) -> 0 | E47: =IFERROR(VLOOKUP(C47,Sheet1!$F$7:$V$4000,17,0),0) -> 0 | F47: =IFERROR(D47/E47,0) -> 0 | G47: =IFERROR(D47/SUMIF(Sheet1!$F$7:$F$4000,C47,Sheet1!$X$7:$X$4000),0) -> 0 | H47: =IFERROR(G47*(SUMIF(Sheet1!$F$7:$F$4000,C47,Sheet1!$Y$7:$Y$4000)/SUMIF(Sheet1!$F$7:$F$4000,C47,Sheet1!$X$7:$X$4000)),0) -> 0 | I47: =IFERROR(H47/G47, "") | J47: =IFERROR(G47*(SUMIF(Sheet1!$F$7:$F$4000,C47,Sheet1!$N$7:$N$4000)/SUMIF(Sheet1!$F$7:$F$4000,C47,Sheet1!$X$7:$X$4000)),0) -> 0 | K47: =IFERROR(J47/G47, "") | M47: 7 | N47: =Sheet1!$A$1-1 -> 0
B48: =DATE(N48,M48,1) -> 214 | C48: =TEXT(M48*29,"mmm")& "-" &N48 -> Aug-0 | D48: =IFERROR(VLOOKUP(C48,Sheet1!$F$7:$U$4000,16,0),0) -> 0 | E48: =IFERROR(VLOOKUP(C48,Sheet1!$F$7:$V$4000,17,0),0) -> 0 | F48: =IFERROR(D48/E48,0) -> 0 | G48: =IFERROR(D48/SUMIF(Sheet1!$F$7:$F$4000,C48,Sheet1!$X$7:$X$4000),0) -> 0 | H48: =IFERROR(G48*(SUMIF(Sheet1!$F$7:$F$4000,C48,Sheet1!$Y$7:$Y$4000)/SUMIF(Sheet1!$F$7:$F$4000,C48,Sheet1!$X$7:$X$4000)),0) -> 0 | I48: =IFERROR(H48/G48, "") | J48: =IFERROR(G48*(SUMIF(Sheet1!$F$7:$F$4000,C48,Sheet1!$N$7:$N$4000)/SUMIF(Sheet1!$F$7:$F$4000,C48,Sheet1!$X$7:$X$4000)),0) -> 0 | K48: =IFERROR(J48/G48, "") | M48: 8 | N48: =Sheet1!$A$1-1 -> 0
B49: =DATE(N49,M49,1) -> 245 | C49: =TEXT(M49*29,"mmm")& "-" &N49 -> Sep-0 | D49: =IFERROR(VLOOKUP(C49,Sheet1!$F$7:$U$4000,16,0),0) -> 0 | E49: =IFERROR(VLOOKUP(C49,Sheet1!$F$7:$V$4000,17,0),0) -> 0 | F49: =IFERROR(D49/E49,0) -> 0 | G49: =IFERROR(D49/SUMIF(Sheet1!$F$7:$F$4000,C49,Sheet1!$X$7:$X$4000),0) -> 0 | H49: =IFERROR(G49*(SUMIF(Sheet1!$F$7:$F$4000,C49,Sheet1!$Y$7:$Y$4000)/SUMIF(Sheet1!$F$7:$F$4000,C49,Sheet1!$X$7:$X$4000)),0) -> 0 | I49: =IFERROR(H49/G49, "") | J49: =IFERROR(G49*(SUMIF(Sheet1!$F$7:$F$4000,C49,Sheet1!$N$7:$N$4000)/SUMIF(Sheet1!$F$7:$F$4000,C49,Sheet1!$X$7:$X$4000)),0) -> 0 | K49: =IFERROR(J49/G49, "") | M49: 9 | N49: =Sheet1!$A$1-1 -> 0
B50: =DATE(N50,M50,1) -> 275 | C50: =TEXT(M50*29,"mmm")& "-" &N50 -> Oct-0 | D50: =IFERROR(VLOOKUP(C50,Sheet1!$F$7:$U$4000,16,0),0) -> 0 | E50: =IFERROR(VLOOKUP(C50,Sheet1!$F$7:$V$4000,17,0),0) -> 0 | F50: =IFERROR(D50/E50,0) -> 0 | G50: =IFERROR(D50/SUMIF(Sheet1!$F$7:$F$4000,C50,Sheet1!$X$7:$X$4000),0) -> 0 | H50: =IFERROR(G50*(SUMIF(Sheet1!$F$7:$F$4000,C50,Sheet1!$Y$7:$Y$4000)/SUMIF(Sheet1!$F$7:$F$4000,C50,Sheet1!$X$7:$X$4000)),0) -> 0 | I50: =IFERROR(H50/G50, "") | J50: =IFERROR(G50*(SUMIF(Sheet1!$F$7:$F$4000,C50,Sheet1!$N$7:$N$4000)/SUMIF(Sheet1!$F$7:$F$4000,C50,Sheet1!$X$7:$X$4000)),0) -> 0 | K50: =IFERROR(J50/G50, "") | M50: 10 | N50: =Sheet1!$A$1-1 -> 0
B51: =DATE(N51,M51,1) -> 306 | C51: =TEXT(M51*29,"mmm")& "-" &N51 -> Nov-0 | D51: =IFERROR(VLOOKUP(C51,Sheet1!$F$7:$U$4000,16,0),0) -> 0 | E51: =IFERROR(VLOOKUP(C51,Sheet1!$F$7:$V$4000,17,0),0) -> 0 | F51: =IFERROR(D51/E51,0) -> 0 | G51: =IFERROR(D51/SUMIF(Sheet1!$F$7:$F$4000,C51,Sheet1!$X$7:$X$4000),0) -> 0 | H51: =IFERROR(G51*(SUMIF(Sheet1!$F$7:$F$4000,C51,Sheet1!$Y$7:$Y$4000)/SUMIF(Sheet1!$F$7:$F$4000,C51,Sheet1!$X$7:$X$4000)),0) -> 0 | I51: =IFERROR(H51/G51, "") | J51: =IFERROR(G51*(SUMIF(Sheet1!$F$7:$F$4000,C51,Sheet1!$N$7:$N$4000)/SUMIF(Sheet1!$F$7:$F$4000,C51,Sheet1!$X$7:$X$4000)),0) -> 0 | K51: =IFERROR(J51/G51, "") | M51: 11 | N51: =Sheet1!$A$1-1 -> 0
B52: =DATE(N52,M52,1) -> 336 | C52: =TEXT(M52*29,"mmm")& "-" &N52 -> Dec-0 | D52: =IFERROR(VLOOKUP(C52,Sheet1!$F$7:$U$4000,16,0),0) -> 0 | E52: =IFERROR(VLOOKUP(C52,Sheet1!$F$7:$V$4000,17,0),0) -> 0 | F52: =IFERROR(D52/E52,0) -> 0 | G52: =IFERROR(D52/SUMIF(Sheet1!$F$7:$F$4000,C52,Sheet1!$X$7:$X$4000),0) -> 0 | H52: =IFERROR(G52*(SUMIF(Sheet1!$F$7:$F$4000,C52,Sheet1!$Y$7:$Y$4000)/SUMIF(Sheet1!$F$7:$F$4000,C52,Sheet1!$X$7:$X$4000)),0) -> 0 | I52: =IFERROR(H52/G52, "") | J52: =IFERROR(G52*(SUMIF(Sheet1!$F$7:$F$4000,C52,Sheet1!$N$7:$N$4000)/SUMIF(Sheet1!$F$7:$F$4000,C52,Sheet1!$X$7:$X$4000)),0) -> 0 | K52: =IFERROR(J52/G52, "") | M52: 12 | N52: =Sheet1!$A$1-1 -> 0
B53: =DATE(N53,M53,1) -> 367 | C53: =TEXT(M53*29,"mmm")& "-" &N53 -> Jan-1 | D53: =IFERROR(VLOOKUP(C53,Sheet1!$F$7:$U$4000,16,0),0) -> 0 | E53: =IFERROR(VLOOKUP(C53,Sheet1!$F$7:$V$4000,17,0),0) -> 0 | F53: =IFERROR(D53/E53,0) -> 0 | G53: =IFERROR(D53/SUMIF(Sheet1!$F$7:$F$4000,C53,Sheet1!$X$7:$X$4000),0) -> 0 | H53: =IFERROR(G53*(SUMIF(Sheet1!$F$7:$F$4000,C53,Sheet1!$Y$7:$Y$4000)/SUMIF(Sheet1!$F$7:$F$4000,C53,Sheet1!$X$7:$X$4000)),0) -> 0 | I53: =IFERROR(H53/G53, "") | J53: =IFERROR(G53*(SUMIF(Sheet1!$F$7:$F$4000,C53,Sheet1!$N$7:$N$4000)/SUMIF(Sheet1!$F$7:$F$4000,C53,Sheet1!$X$7:$X$4000)),0) -> 0 | K53: =IFERROR(J53/G53, "") | M53: 1 | N53: =Sheet1!$A$1 -> 1
B54: =DATE(N54,M54,1) -> 398 | C54: =TEXT(M54*29,"mmm")& "-" &N54 -> Feb-1 | D54: =IFERROR(VLOOKUP(C54,Sheet1!$F$7:$U$4000,16,0),0) -> 0 | E54: =IFERROR(VLOOKUP(C54,Sheet1!$F$7:$V$4000,17,0),0) -> 0 | F54: =IFERROR(D54/E54,0) -> 0 | G54: =IFERROR(D54/SUMIF(Sheet1!$F$7:$F$4000,C54,Sheet1!$X$7:$X$4000),0) -> 0 | H54: =IFERROR(G54*(SUMIF(Sheet1!$F$7:$F$4000,C54,Sheet1!$Y$7:$Y$4000)/SUMIF(Sheet1!$F$7:$F$4000,C54,Sheet1!$X$7:$X$4000)),0) -> 0 | I54: =IFERROR(H54/G54, "") | J54: =IFERROR(G54*(SUMIF(Sheet1!$F$7:$F$4000,C54,Sheet1!$N$7:$N$4000)/SUMIF(Sheet1!$F$7:$F$4000,C54,Sheet1!$X$7:$X$4000)),0) -> 0 | K54: =IFERROR(J54/G54, "") | M54: 2 | N54: =Sheet1!$A$1 -> 1
B55: =DATE(N55,M55,1) -> 426 | C55: =TEXT(M55*29,"mmm")& "-" &N55 -> Mar-1 | D55: =IFERROR(VLOOKUP(C55,Sheet1!$F$7:$U$4000,16,0),0) -> 0 | E55: =IFERROR(VLOOKUP(C55,Sheet1!$F$7:$V$4000,17,0),0) -> 0 | F55: =IFERROR(D55/E55,0) -> 0 | G55: =IFERROR(D55/SUMIF(Sheet1!$F$7:$F$4000,C55,Sheet1!$X$7:$X$4000),0) -> 0 | H55: =IFERROR(G55*(SUMIF(Sheet1!$F$7:$F$4000,C55,Sheet1!$Y$7:$Y$4000)/SUMIF(Sheet1!$F$7:$F$4000,C55,Sheet1!$X$7:$X$4000)),0) -> 0 | I55: =IFERROR(H55/G55, "") | J55: =IFERROR(G55*(SUMIF(Sheet1!$F$7:$F$4000,C55,Sheet1!$N$7:$N$4000)/SUMIF(Sheet1!$F$7:$F$4000,C55,Sheet1!$X$7:$X$4000)),0) -> 0 | K55: =IFERROR(J55/G55, "") | M55: 3 | N55: =Sheet1!$A$1 -> 1
B56: =DATE(N56,M56,1) -> 457 | C56: =TEXT(M56*29,"mmm")& "-" &N56 -> Apr-1 | D56: =IFERROR(VLOOKUP(C56,Sheet1!$F$7:$U$4000,16,0),0) -> 0 | E56: =IFERROR(VLOOKUP(C56,Sheet1!$F$7:$V$4000,17,0),0) -> 0 | F56: =IFERROR(D56/E56,0) -> 0 | G56: =IFERROR(D56/SUMIF(Sheet1!$F$7:$F$4000,C56,Sheet1!$X$7:$X$4000),0) -> 0 | H56: =IFERROR(G56*(SUMIF(Sheet1!$F$7:$F$4000,C56,Sheet1!$Y$7:$Y$4000)/SUMIF(Sheet1!$F$7:$F$4000,C56,Sheet1!$X$7:$X$4000)),0) -> 0 | I56: =IFERROR(H56/G56, "") | J56: =IFERROR(G56*(SUMIF(Sheet1!$F$7:$F$4000,C56,Sheet1!$N$7:$N$4000)/SUMIF(Sheet1!$F$7:$F$4000,C56,Sheet1!$X$7:$X$4000)),0) -> 0 | K56: =IFERROR(J56/G56, "") | M56: 4 | N56: =Sheet1!$A$1 -> 1
B57: =DATE(N57,M57,1) -> 487 | C57: =TEXT(M57*29,"mmm")& "-" &N57 -> May-1 | D57: =IFERROR(VLOOKUP(C57,Sheet1!$F$7:$U$4000,16,0),0) -> 0 | E57: =IFERROR(VLOOKUP(C57,Sheet1!$F$7:$V$4000,17,0),0) -> 0 | F57: =IFERROR(D57/E57,0) -> 0 | G57: =IFERROR(D57/SUMIF(Sheet1!$F$7:$F$4000,C57,Sheet1!$X$7:$X$4000),0) -> 0 | H57: =IFERROR(G57*(SUMIF(Sheet1!$F$7:$F$4000,C57,Sheet1!$Y$7:$Y$4000)/SUMIF(Sheet1!$F$7:$F$4000,C57,Sheet1!$X$7:$X$4000)),0) -> 0 | I57: =IFERROR(H57/G57, "") | J57: =IFERROR(G57*(SUMIF(Sheet1!$F$7:$F$4000,C57,Sheet1!$N$7:$N$4000)/SUMIF(Sheet1!$F$7:$F$4000,C57,Sheet1!$X$7:$X$4000)),0) -> 0 | K57: =IFERROR(J57/G57, "") | M57: 5 | N57: =Sheet1!$A$1 -> 1
B58: =DATE(N58,M58,1) -> 518 | C58: =TEXT(M58*29,"mmm")& "-" &N58 -> Jun-1 | D58: =IFERROR(VLOOKUP(C58,Sheet1!$F$7:$U$4000,16,0),0) -> 0 | E58: =IFERROR(VLOOKUP(C58,Sheet1!$F$7:$V$4000,17,0),0) -> 0 | F58: =IFERROR(D58/E58,0) -> 0 | G58: =IFERROR(D58/SUMIF(Sheet1!$F$7:$F$4000,C58,Sheet1!$X$7:$X$4000),0) -> 0 | H58: =IFERROR(G58*(SUMIF(Sheet1!$F$7:$F$4000,C58,Sheet1!$Y$7:$Y$4000)/SUMIF(Sheet1!$F$7:$F$4000,C58,Sheet1!$X$7:$X$4000)),0) -> 0 | I58: =IFERROR(H58/G58, "") | J58: =IFERROR(G58*(SUMIF(Sheet1!$F$7:$F$4000,C58,Sheet1!$N$7:$N$4000)/SUMIF(Sheet1!$F$7:$F$4000,C58,Sheet1!$X$7:$X$4000)),0) -> 0 | K58: =IFERROR(J58/G58, "") | M58: 6 | N58: =Sheet1!$A$1 -> 1
B59: =DATE(N59,M59,1) -> 548 | C59: =TEXT(M59*29,"mmm")& "-" &N59 -> Jul-1 | D59: =IFERROR(VLOOKUP(C59,Sheet1!$F$7:$U$4000,16,0),0) -> 0 | E59: =IFERROR(VLOOKUP(C59,Sheet1!$F$7:$V$4000,17,0),0) -> 0 | F59: =IFERROR(D59/E59,0) -> 0 | G59: =IFERROR(D59/SUMIF(Sheet1!$F$7:$F$4000,C59,Sheet1!$X$7:$X$4000),0) -> 0 | H59: =IFERROR(G59*(SUMIF(Sheet1!$F$7:$F$4000,C59,Sheet1!$Y$7:$Y$4000)/SUMIF(Sheet1!$F$7:$F$4000,C59,Sheet1!$X$7:$X$4000)),0) -> 0 | I59: =IFERROR(H59/G59, "") | J59: =IFERROR(G59*(SUMIF(Sheet1!$F$7:$F$4000,C59,Sheet1!$N$7:$N$4000)/SUMIF(Sheet1!$F$7:$F$4000,C59,Sheet1!$X$7:$X$4000)),0) -> 0 | K59: =IFERROR(J59/G59, "") | M59: 7 | N59: =Sheet1!$A$1 -> 1
B60: =DATE(N60,M60,1) -> 579 | C60: =TEXT(M60*29,"mmm")& "-" &N60 -> Aug-1 | D60: =IFERROR(VLOOKUP(C60,Sheet1!$F$7:$U$4000,16,0),0) -> 0 | E60: =IFERROR(VLOOKUP(C60,Sheet1!$F$7:$V$4000,17,0),0) -> 0 | F60: =IFERROR(D60/E60,0) -> 0 | G60: =IFERROR(D60/SUMIF(Sheet1!$F$7:$F$4000,C60,Sheet1!$X$7:$X$4000),0) -> 0 | H60: =IFERROR(G60*(SUMIF(Sheet1!$F$7:$F$4000,C60,Sheet1!$Y$7:$Y$4000)/SUMIF(Sheet1!$F$7:$F$4000,C60,Sheet1!$X$7:$X$4000)),0) -> 0 | I60: =IFERROR(H60/G60, "") | J60: =IFERROR(G60*(SUMIF(Sheet1!$F$7:$F$4000,C60,Sheet1!$N$7:$N$4000)/SUMIF(Sheet1!$F$7:$F$4000,C60,Sheet1!$X$7:$X$4000)),0) -> 0 | K60: =IFERROR(J60/G60, "") | M60: 8 | N60: =Sheet1!$A$1 -> 1
B61: =DATE(N61,M61,1) -> 610 | C61: =TEXT(M61*29,"mmm")& "-" &N61 -> Sep-1 | D61: =IFERROR(VLOOKUP(C61,Sheet1!$F$7:$U$4000,16,0),0) -> 0 | E61: =IFERROR(VLOOKUP(C61,Sheet1!$F$7:$V$4000,17,0),0) -> 0 | F61: =IFERROR(D61/E61,0) -> 0 | G61: =IFERROR(D61/SUMIF(Sheet1!$F$7:$F$4000,C61,Sheet1!$X$7:$X$4000),0) -> 0 | H61: =IFERROR(G61*(SUMIF(Sheet1!$F$7:$F$4000,C61,Sheet1!$Y$7:$Y$4000)/SUMIF(Sheet1!$F$7:$F$4000,C61,Sheet1!$X$7:$X$4000)),0) -> 0 | I61: =IFERROR(H61/G61, "") | J61: =IFERROR(G61*(SUMIF(Sheet1!$F$7:$F$4000,C61,Sheet1!$N$7:$N$4000)/SUMIF(Sheet1!$F$7:$F$4000,C61,Sheet1!$X$7:$X$4000)),0) -> 0 | K61: =IFERROR(J61/G61, "") | M61: 9 | N61: =Sheet1!$A$1 -> 1
B62: =DATE(N62,M62,1) -> 640 | C62: =TEXT(M62*29,"mmm")& "-" &N62 -> Oct-1 | D62: =IFERROR(VLOOKUP(C62,Sheet1!$F$7:$U$4000,16,0),0) -> 0 | E62: =IFERROR(VLOOKUP(C62,Sheet1!$F$7:$V$4000,17,0),0) -> 0 | F62: =IFERROR(D62/E62,0) -> 0 | G62: =IFERROR(D62/SUMIF(Sheet1!$F$7:$F$4000,C62,Sheet1!$X$7:$X$4000),0) -> 0 | H62: =IFERROR(G62*(SUMIF(Sheet1!$F$7:$F$4000,C62,Sheet1!$Y$7:$Y$4000)/SUMIF(Sheet1!$F$7:$F$4000,C62,Sheet1!$X$7:$X$4000)),0) -> 0 | I62: =IFERROR(H62/G62, "") | J62: =IFERROR(G62*(SUMIF(Sheet1!$F$7:$F$4000,C62,Sheet1!$N$7:$N$4000)/SUMIF(Sheet1!$F$7:$F$4000,C62,Sheet1!$X$7:$X$4000)),0) -> 0 | K62: =IFERROR(J62/G62, "") | M62: 10 | N62: =Sheet1!$A$1 -> 1
B63: =DATE(N63,M63,1) -> 671 | C63: =TEXT(M63*29,"mmm")& "-" &N63 -> Nov-1 | D63: =IFERROR(VLOOKUP(C63,Sheet1!$F$7:$U$4000,16,0),0) -> 0 | E63: =IFERROR(VLOOKUP(C63,Sheet1!$F$7:$V$4000,17,0),0) -> 0 | F63: =IFERROR(D63/E63,0) -> 0 | G63: =IFERROR(D63/SUMIF(Sheet1!$F$7:$F$4000,C63,Sheet1!$X$7:$X$4000),0) -> 0 | H63: =IFERROR(G63*(SUMIF(Sheet1!$F$7:$F$4000,C63,Sheet1!$Y$7:$Y$4000)/SUMIF(Sheet1!$F$7:$F$4000,C63,Sheet1!$X$7:$X$4000)),0) -> 0 | I63: =IFERROR(H63/G63, "") | J63: =IFERROR(G63*(SUMIF(Sheet1!$F$7:$F$4000,C63,Sheet1!$N$7:$N$4000)/SUMIF(Sheet1!$F$7:$F$4000,C63,Sheet1!$X$7:$X$4000)),0) -> 0 | K63: =IFERROR(J63/G63, "") | M63: 11 | N63: =Sheet1!$A$1 -> 1
B64: =DATE(N64,M64,1) -> 701 | C64: =TEXT(M64*29,"mmm")& "-" &N64 -> Dec-1 | D64: =IFERROR(VLOOKUP(C64,Sheet1!$F$7:$U$4000,16,0),0) -> 0 | E64: =IFERROR(VLOOKUP(C64,Sheet1!$F$7:$V$4000,17,0),0) -> 0 | F64: =IFERROR(D64/E64,0) -> 0 | G64: =IFERROR(D64/SUMIF(Sheet1!$F$7:$F$4000,C64,Sheet1!$X$7:$X$4000),0) -> 0 | H64: =IFERROR(G64*(SUMIF(Sheet1!$F$7:$F$4000,C64,Sheet1!$Y$7:$Y$4000)/SUMIF(Sheet1!$F$7:$F$4000,C64,Sheet1!$X$7:$X$4000)),0) -> 0 | I64: =IFERROR(H64/G64, "") | J64: =IFERROR(G64*(SUMIF(Sheet1!$F$7:$F$4000,C64,Sheet1!$N$7:$N$4000)/SUMIF(Sheet1!$F$7:$F$4000,C64,Sheet1!$X$7:$X$4000)),0) -> 0 | K64: =IFERROR(J64/G64, "") | M64: 12 | N64: =Sheet1!$A$1 -> 1
B65: =DATE(N65,M65,1) -> 732 | C65: =TEXT(M65*29,"mmm")& "-" &N65 -> Jan-2 | D65: =IFERROR(VLOOKUP(C65,Sheet1!$F$7:$U$4000,16,0),0) -> 0 | E65: =IFERROR(VLOOKUP(C65,Sheet1!$F$7:$V$4000,17,0),0) -> 0 | F65: =IFERROR(D65/E65,0) -> 0 | G65: =IFERROR(D65/SUMIF(Sheet1!$F$7:$F$4000,C65,Sheet1!$X$7:$X$4000),0) -> 0 | H65: =IFERROR(G65*(SUMIF(Sheet1!$F$7:$F$4000,C65,Sheet1!$Y$7:$Y$4000)/SUMIF(Sheet1!$F$7:$F$4000,C65,Sheet1!$X$7:$X$4000)),0) -> 0 | I65: =IFERROR(H65/G65, "") | J65: =IFERROR(G65*(SUMIF(Sheet1!$F$7:$F$4000,C65,Sheet1!$N$7:$N$4000)/SUMIF(Sheet1!$F$7:$F$4000,C65,Sheet1!$X$7:$X$4000)),0) -> 0 | K65: =IFERROR(J65/G65, "") | M65: 1 | N65: =Sheet1!$A$1+1 -> 2
B66: =DATE(N66,M66,1) -> 763 | C66: =TEXT(M66*29,"mmm")& "-" &N66 -> Feb-2 | D66: =IFERROR(VLOOKUP(C66,Sheet1!$F$7:$U$4000,16,0),0) -> 0 | E66: =IFERROR(VLOOKUP(C66,Sheet1!$F$7:$V$4000,17,0),0) -> 0 | F66: =IFERROR(D66/E66,0) -> 0 | G66: =IFERROR(D66/SUMIF(Sheet1!$F$7:$F$4000,C66,Sheet1!$X$7:$X$4000),0) -> 0 | H66: =IFERROR(G66*(SUMIF(Sheet1!$F$7:$F$4000,C66,Sheet1!$Y$7:$Y$4000)/SUMIF(Sheet1!$F$7:$F$4000,C66,Sheet1!$X$7:$X$4000)),0) -> 0 | I66: =IFERROR(H66/G66, "") | J66: =IFERROR(G66*(SUMIF(Sheet1!$F$7:$F$4000,C66,Sheet1!$N$7:$N$4000)/SUMIF(Sheet1!$F$7:$F$4000,C66,Sheet1!$X$7:$X$4000)),0) -> 0 | K66: =IFERROR(J66/G66, "") | M66: 2 | N66: =Sheet1!$A$1+1 -> 2
B67: =DATE(N67,M67,1) -> 791 | C67: =TEXT(M67*29,"mmm")& "-" &N67 -> Mar-2 | D67: =IFERROR(VLOOKUP(C67,Sheet1!$F$7:$U$4000,16,0),0) -> 0 | E67: =IFERROR(VLOOKUP(C67,Sheet1!$F$7:$V$4000,17,0),0) -> 0 | F67: =IFERROR(D67/E67,0) -> 0 | G67: =IFERROR(D67/SUMIF(Sheet1!$F$7:$F$4000,C67,Sheet1!$X$7:$X$4000),0) -> 0 | H67: =IFERROR(G67*(SUMIF(Sheet1!$F$7:$F$4000,C67,Sheet1!$Y$7:$Y$4000)/SUMIF(Sheet1!$F$7:$F$4000,C67,Sheet1!$X$7:$X$4000)),0) -> 0 | I67: =IFERROR(H67/G67, "") | J67: =IFERROR(G67*(SUMIF(Sheet1!$F$7:$F$4000,C67,Sheet1!$N$7:$N$4000)/SUMIF(Sheet1!$F$7:$F$4000,C67,Sheet1!$X$7:$X$4000)),0) -> 0 | K67: =IFERROR(J67/G67, "") | M67: 3 | N67: =Sheet1!$A$1+1 -> 2
B68: =DATE(N68,M68,1) -> 822 | C68: =TEXT(M68*29,"mmm")& "-" &N68 -> Apr-2 | D68: =IFERROR(VLOOKUP(C68,Sheet1!$F$7:$U$4000,16,0),0) -> 0 | E68: =IFERROR(VLOOKUP(C68,Sheet1!$F$7:$V$4000,17,0),0) -> 0 | F68: =IFERROR(D68/E68,0) -> 0 | G68: =IFERROR(D68/SUMIF(Sheet1!$F$7:$F$4000,C68,Sheet1!$X$7:$X$4000),0) -> 0 | H68: =IFERROR(G68*(SUMIF(Sheet1!$F$7:$F$4000,C68,Sheet1!$Y$7:$Y$4000)/SUMIF(Sheet1!$F$7:$F$4000,C68,Sheet1!$X$7:$X$4000)),0) -> 0 | I68: =IFERROR(H68/G68, "") | J68: =IFERROR(G68*(SUMIF(Sheet1!$F$7:$F$4000,C68,Sheet1!$N$7:$N$4000)/SUMIF(Sheet1!$F$7:$F$4000,C68,Sheet1!$X$7:$X$4000)),0) -> 0 | K68: =IFERROR(J68/G68, "") | M68: 4 | N68: =Sheet1!$A$1+1 -> 2
B69: =DATE(N69,M69,1) -> 852 | C69: =TEXT(M69*29,"mmm")& "-" &N69 -> May-2 | D69: =IFERROR(VLOOKUP(C69,Sheet1!$F$7:$U$4000,16,0),0) -> 0 | E69: =IFERROR(VLOOKUP(C69,Sheet1!$F$7:$V$4000,17,0),0) -> 0 | F69: =IFERROR(D69/E69,0) -> 0 | G69: =IFERROR(D69/SUMIF(Sheet1!$F$7:$F$4000,C69,Sheet1!$X$7:$X$4000),0) -> 0 | H69: =IFERROR(G69*(SUMIF(Sheet1!$F$7:$F$4000,C69,Sheet1!$Y$7:$Y$4000)/SUMIF(Sheet1!$F$7:$F$4000,C69,Sheet1!$X$7:$X$4000)),0) -> 0 | I69: =IFERROR(H69/G69, "") | J69: =IFERROR(G69*(SUMIF(Sheet1!$F$7:$F$4000,C69,Sheet1!$N$7:$N$4000)/SUMIF(Sheet1!$F$7:$F$4000,C69,Sheet1!$X$7:$X$4000)),0) -> 0 | K69: =IFERROR(J69/G69, "") | M69: 5 | N69: =Sheet1!$A$1+1 -> 2
B70: =DATE(N70,M70,1) -> 883 | C70: =TEXT(M70*29,"mmm")& "-" &N70 -> Jun-2 | D70: =IFERROR(VLOOKUP(C70,Sheet1!$F$7:$U$4000,16,0),0) -> 0 | E70: =IFERROR(VLOOKUP(C70,Sheet1!$F$7:$V$4000,17,0),0) -> 0 | F70: =IFERROR(D70/E70,0) -> 0 | G70: =IFERROR(D70/SUMIF(Sheet1!$F$7:$F$4000,C70,Sheet1!$X$7:$X$4000),0) -> 0 | H70: =IFERROR(G70*(SUMIF(Sheet1!$F$7:$F$4000,C70,Sheet1!$Y$7:$Y$4000)/SUMIF(Sheet1!$F$7:$F$4000,C70,Sheet1!$X$7:$X$4000)),0) -> 0 | I70: =IFERROR(H70/G70, "") | J70: =IFERROR(G70*(SUMIF(Sheet1!$F$7:$F$4000,C70,Sheet1!$N$7:$N$4000)/SUMIF(Sheet1!$F$7:$F$4000,C70,Sheet1!$X$7:$X$4000)),0) -> 0 | K70: =IFERROR(J70/G70, "") | M70: 6 | N70: =Sheet1!$A$1+1 -> 2
B71: =DATE(N71,M71,1) -> 913 | C71: =TEXT(M71*29,"mmm")& "-" &N71 -> Jul-2 | D71: =IFERROR(VLOOKUP(C71,Sheet1!$F$7:$U$4000,16,0),0) -> 0 | E71: =IFERROR(VLOOKUP(C71,Sheet1!$F$7:$V$4000,17,0),0) -> 0 | F71: =IFERROR(D71/E71,0) -> 0 | G71: =IFERROR(D71/SUMIF(Sheet1!$F$7:$F$4000,C71,Sheet1!$X$7:$X$4000),0) -> 0 | H71: =IFERROR(G71*(SUMIF(Sheet1!$F$7:$F$4000,C71,Sheet1!$Y$7:$Y$4000)/SUMIF(Sheet1!$F$7:$F$4000,C71,Sheet1!$X$7:$X$4000)),0) -> 0 | I71: =IFERROR(H71/G71, "") | J71: =IFERROR(G71*(SUMIF(Sheet1!$F$7:$F$4000,C71,Sheet1!$N$7:$N$4000)/SUMIF(Sheet1!$F$7:$F$4000,C71,Sheet1!$X$7:$X$4000)),0) -> 0 | K71: =IFERROR(J71/G71, "") | M71: 7 | N71: =Sheet1!$A$1+1 -> 2
B72: =DATE(N72,M72,1) -> 944 | C72: =TEXT(M72*29,"mmm")& "-" &N72 -> Aug-2 | D72: =IFERROR(VLOOKUP(C72,Sheet1!$F$7:$U$4000,16,0),0) -> 0 | E72: =IFERROR(VLOOKUP(C72,Sheet1!$F$7:$V$4000,17,0),0) -> 0 | F72: =IFERROR(D72/E72,0) -> 0 | G72: =IFERROR(D72/SUMIF(Sheet1!$F$7:$F$4000,C72,Sheet1!$X$7:$X$4000),0) -> 0 | H72: =IFERROR(G72*(SUMIF(Sheet1!$F$7:$F$4000,C72,Sheet1!$Y$7:$Y$4000)/SUMIF(Sheet1!$F$7:$F$4000,C72,Sheet1!$X$7:$X$4000)),0) -> 0 | I72: =IFERROR(H72/G72, "") | J72: =IFERROR(G72*(SUMIF(Sheet1!$F$7:$F$4000,C72,Sheet1!$N$7:$N$4000)/SUMIF(Sheet1!$F$7:$F$4000,C72,Sheet1!$X$7:$X$4000)),0) -> 0 | K72: =IFERROR(J72/G72, "") | M72: 8 | N72: =Sheet1!$A$1+1 -> 2
B73: =DATE(N73,M73,1) -> 975 | C73: =TEXT(M73*29,"mmm")& "-" &N73 -> Sep-2 | D73: =IFERROR(VLOOKUP(C73,Sheet1!$F$7:$U$4000,16,0),0) -> 0 | E73: =IFERROR(VLOOKUP(C73,Sheet1!$F$7:$V$4000,17,0),0) -> 0 | F73: =IFERROR(D73/E73,0) -> 0 | G73: =IFERROR(D73/SUMIF(Sheet1!$F$7:$F$4000,C73,Sheet1!$X$7:$X$4000),0) -> 0 | H73: =IFERROR(G73*(SUMIF(Sheet1!$F$7:$F$4000,C73,Sheet1!$Y$7:$Y$4000)/SUMIF(Sheet1!$F$7:$F$4000,C73,Sheet1!$X$7:$X$4000)),0) -> 0 | I73: =IFERROR(H73/G73, "") | J73: =IFERROR(G73*(SUMIF(Sheet1!$F$7:$F$4000,C73,Sheet1!$N$7:$N$4000)/SUMIF(Sheet1!$F$7:$F$4000,C73,Sheet1!$X$7:$X$4000)),0) -> 0 | K73: =IFERROR(J73/G73, "") | M73: 9 | N73: =Sheet1!$A$1+1 -> 2
B74: =DATE(N74,M74,1) -> 1005 | C74: =TEXT(M74*29,"mmm")& "-" &N74 -> Oct-2 | D74: =IFERROR(VLOOKUP(C74,Sheet1!$F$7:$U$4000,16,0),0) -> 0 | E74: =IFERROR(VLOOKUP(C74,Sheet1!$F$7:$V$4000,17,0),0) -> 0 | F74: =IFERROR(D74/E74,0) -> 0 | G74: =IFERROR(D74/SUMIF(Sheet1!$F$7:$F$4000,C74,Sheet1!$X$7:$X$4000),0) -> 0 | H74: =IFERROR(G74*(SUMIF(Sheet1!$F$7:$F$4000,C74,Sheet1!$Y$7:$Y$4000)/SUMIF(Sheet1!$F$7:$F$4000,C74,Sheet1!$X$7:$X$4000)),0) -> 0 | I74: =IFERROR(H74/G74, "") | J74: =IFERROR(G74*(SUMIF(Sheet1!$F$7:$F$4000,C74,Sheet1!$N$7:$N$4000)/SUMIF(Sheet1!$F$7:$F$4000,C74,Sheet1!$X$7:$X$4000)),0) -> 0 | K74: =IFERROR(J74/G74, "") | M74: 10 | N74: =Sheet1!$A$1+1 -> 2
B75: =DATE(N75,M75,1) -> 1036 | C75: =TEXT(M75*29,"mmm")& "-" &N75 -> Nov-2 | D75: =IFERROR(VLOOKUP(C75,Sheet1!$F$7:$U$4000,16,0),0) -> 0 | E75: =IFERROR(VLOOKUP(C75,Sheet1!$F$7:$V$4000,17,0),0) -> 0 | F75: =IFERROR(D75/E75,0) -> 0 | G75: =IFERROR(D75/SUMIF(Sheet1!$F$7:$F$4000,C75,Sheet1!$X$7:$X$4000),0) -> 0 | H75: =IFERROR(G75*(SUMIF(Sheet1!$F$7:$F$4000,C75,Sheet1!$Y$7:$Y$4000)/SUMIF(Sheet1!$F$7:$F$4000,C75,Sheet1!$X$7:$X$4000)),0) -> 0 | I75: =IFERROR(H75/G75, "") | J75: =IFERROR(G75*(SUMIF(Sheet1!$F$7:$F$4000,C75,Sheet1!$N$7:$N$4000)/SUMIF(Sheet1!$F$7:$F$4000,C75,Sheet1!$X$7:$X$4000)),0) -> 0 | K75: =IFERROR(J75/G75, "") | M75: 11 | N75: =Sheet1!$A$1+1 -> 2
B76: =DATE(N76,M76,1) -> 1066 | C76: =TEXT(M76*29,"mmm")& "-" &N76 -> Dec-2 | D76: =IFERROR(VLOOKUP(C76,Sheet1!$F$7:$U$4000,16,0),0) -> 0 | E76: =IFERROR(VLOOKUP(C76,Sheet1!$F$7:$V$4000,17,0),0) -> 0 | F76: =IFERROR(D76/E76,0) -> 0 | G76: =IFERROR(D76/SUMIF(Sheet1!$F$7:$F$4000,C76,Sheet1!$X$7:$X$4000),0) -> 0 | H76: =IFERROR(G76*(SUMIF(Sheet1!$F$7:$F$4000,C76,Sheet1!$Y$7:$Y$4000)/SUMIF(Sheet1!$F$7:$F$4000,C76,Sheet1!$X$7:$X$4000)),0) -> 0 | I76: =IFERROR(H76/G76, "") | J76: =IFERROR(G76*(SUMIF(Sheet1!$F$7:$F$4000,C76,Sheet1!$N$7:$N$4000)/SUMIF(Sheet1!$F$7:$F$4000,C76,Sheet1!$X$7:$X$4000)),0) -> 0 | K76: =IFERROR(J76/G76, "") | M76: 12 | N76: =Sheet1!$A$1+1 -> 2

Sheet 비교 So sánh
A1: 1. 특근시간 비율분석자료 (종합) - Dữ liệu phân tích tỷ lệ giờ làm ngày nghỉ (Tổng hợp)
B2: 대분류 - Phân loại chung | C2: 중분류 - Phân loại vừa | D2: 소분류 - Phân loại nhỏ | E2: =RIGHT(L3,2) & "년" -> 0년 | F2: =RIGHT(M3,2) & "년" -> 1년 | G2: =RIGHT(N3,2) & "년" -> 2년 | H2: 전년대비 증가액 - Lượng gia tăng so với năm trước | I2: 전년대비 증가비율 - Tỷ lệ gia tăng so với năm trước | J2: 비고 - Ghi chú
B3: 합계 - Tổng cộng | D3: 시간당 매출(원) - Doanh thu (chính) trên thời gian | E3: =IFERROR(VLOOKUP($K$3 & L3,'Sales per employees'!$B$18:$F$20,5,0),0) -> 0 | F3: =IFERROR(VLOOKUP($K$3 & M3,'Sales per employees'!$B$18:$F$20,5,0),0) -> 0 | G3: =IFERROR(VLOOKUP($K$3 & N3,'Sales per employees'!$B$18:$F$20,5,0),0) -> 0 | H3: =F3-E3 -> 0 | I3: =IFERROR(H3/F3,0) -> 0 | J3: 근무시간 1시간당 발생하는 매출은 4.6% 증가 - Doanh thu tăng thêm mỗi một giờ làm việc là 4.6% 즉, 총근무시간 대비한 매출 효율은 증가 - Tức là hiệu suất doanh thu tăng so với tổng thời gian làm việc 단, 4.6%의 시간당 매출증가효율이 인건비 상승분을 따라잡기는 어려움 - Tuy nhiên, rất khó để hiệu suất 4,6% doanh số tăng theo giờ theo kịp với sự gia tăng của chi phí nhân công | K3: Y | L3: =M3-1 -> 0 | M3: =Sheet1!A1 -> 1 | N3: =M3+1 -> 2
D4: 합계시간(h) - Tổng thời gian | E4: =IFERROR(E5+E10,0) -> 0 | F4: =IFERROR(F5+F10,0) -> 0 | G4: =IFERROR(G5+G10,0) -> 0 | H4: =F4-E4 -> 0 | I4: =IFERROR(H4/F4,0) -> 0
D5: 총근무시간(h) -Tổng số giờ làm việc | E5: =IFERROR(AVERAGEIFS('월별 기본데이터 합계'!$W$5:$W$28,'월별 기본데이터 합계'!$C$5:$C$28,L3,'월별 기본데이터 합계'!$W$5:$W$28,">0"),0) -> 0 | F5: =IFERROR(AVERAGEIFS('월별 기본데이터 합계'!$W$5:$W$28,'월별 기본데이터 합계'!$C$5:$C$28,M3,'월별 기본데이터 합계'!$W$5:$W$28,">0"),0) -> 0 | G5: =IFERROR(AVERAGEIFS('월별 기본데이터 합계'!$W$5:$W$28,'월별 기본데이터 합계'!$C$5:$C$28,N3,'월별 기본데이터 합계'!$W$5:$W$28,">0"),0) -> 0 | H5: =F5-E5 -> 0 | I5: =IFERROR(H5/F5,0) -> 0
D6: 평일시간(h) Thời gian làm việc ngày thường | E6: =IFERROR(E4-E8-E10,0) -> 0 | F6: =F4-F8-F10 -> 0 | G6: =G4-G8-G10 -> 0 | H6: =F6-E6 -> 0 | I6: =IFERROR(H6/F6,0) -> 0
D7: 평일비율(h) Tỷ lệ ngày thường | E7: =IFERROR(E6/E4,0) -> 0 | F7: =IFERROR(F6/F4,0) -> 0 | G7: =IFERROR(G6/G4,0) -> 0 | H7: =F7-E7 -> 0
D8: 특근시간(h) Thời gian làm ngày nghỉ | E8: =IFERROR(AVERAGEIFS('월별 기본데이터 합계'!$R$5:$R$28,'월별 기본데이터 합계'!$C$5:$C$28,L3,'월별 기본데이터 합계'!$R$5:$R$28,">0"),0) -> 0 | F8: =IFERROR(AVERAGEIFS('월별 기본데이터 합계'!$R$5:$R$28,'월별 기본데이터 합계'!$C$5:$C$28,M3,'월별 기본데이터 합계'!$R$5:$R$28,">0"),0) -> 0 | G8: =IFERROR(AVERAGEIFS('월별 기본데이터 합계'!$R$5:$R$28,'월별 기본데이터 합계'!$C$5:$C$28,N3,'월별 기본데이터 합계'!$R$5:$R$28,">0"),0) -> 0 | H8: =F8-E8 -> 0 | I8: =IFERROR(H8/F8,0) -> 0
D9: 특근비율(%) Tỷ lệ làm ngày nghỉ | E9: =IFERROR(E8/E4,0) -> 0 | F9: =IFERROR(F8/F4,0) -> 0 | G9: =IFERROR(G8/G4,0) -> 0 | H9: =F9-E9 -> 0
D10: 미근무 시간(h) Số giờ không làm việc | E10: =IFERROR(AVERAGEIFS('월별 기본데이터 합계'!$X$5:$X$28,'월별 기본데이터 합계'!$C$5:$C$28,L3,'월별 기본데이터 합계'!$X$5:$X$28,">0"),0) -> 0 | F10: =IFERROR(AVERAGEIFS('월별 기본데이터 합계'!$X$5:$X$28,'월별 기본데이터 합계'!$C$5:$C$28,M3,'월별 기본데이터 합계'!$X$5:$X$28,">0"),0) -> 0 | G10: =IFERROR(AVERAGEIFS('월별 기본데이터 합계'!$X$5:$X$28,'월별 기본데이터 합계'!$C$5:$C$28,N3,'월별 기본데이터 합계'!$X$5:$X$28,">0"),0) -> 0 | H10: =F10-E10 -> 0 | I10: =IFERROR(H10/F10,0) -> 0
D11: 미근무 시간 비율(%) Tỷ lệ thời gian không làm việc | E11: =IFERROR(E10/E4,0) -> 0 | F11: =IFERROR(F10/F4,0) -> 0 | G11: =IFERROR(G10/G4,0) -> 0 | H11: =F11-E11 -> 0
B12: 부서별 - Theo bộ phận | C12: General Admistration | D12: 합계시간(h) - Tổng thời gian | E12: =IFERROR(E13+E18,0) -> 0 | F12: =IFERROR(F13+F18,0) -> 0 | G12: =IFERROR(G13+G18,0) -> 0 | H12: =F12-E12 -> 0 | I12: =IFERROR((F12-E12)/E12,0) -> 0 | K12: GA
D13: 총근무시간(h) -Tổng số giờ làm việc | E13: =IFERROR(AVERAGEIFS('업무월별분석 Phân tích CV theo tháng'!$C$55:$C$78,'업무월별분석 Phân tích CV theo tháng'!$P$55:$P$78,L3,'업무월별분석 Phân tích CV theo tháng'!$C$55:$C$78,">0"),0) -> 0 | F13: =IFERROR(AVERAGEIFS('업무월별분석 Phân tích CV theo tháng'!$C$55:$C$78,'업무월별분석 Phân tích CV theo tháng'!$P$55:$P$78,M3,'업무월별분석 Phân tích CV theo tháng'!$C$55:$C$78,">0"),0) -> 0 | G13: =IFERROR(AVERAGEIFS('업무월별분석 Phân tích CV theo tháng'!$C$55:$C$78,'업무월별분석 Phân tích CV theo tháng'!$P$55:$P$78,N3,'업무월별분석 Phân tích CV theo tháng'!$C$55:$C$78,">0"),0) -> 0 | H13: =F13-E13 -> 0 | I13: =IFERROR((F13-E13)/F13,0) -> 0
D14: 평일시간(h) Thời gian làm việc ngày thường | E14: =IFERROR(E13-E16,0) -> 0 | F14: =IFERROR(F13-F16,0) -> 0 | G14: =IFERROR(G13-G16,0) -> 0 | H14: =F14-E14 -> 0 | I14: =IFERROR((F14-E14)/F14,0) -> 0
D15: 평일비율(h) Tỷ lệ ngày thường | E15: =IFERROR(E14/E12,0) -> 0 | F15: =IFERROR(F14/F12,0) -> 0 | G15: =IFERROR(G14/G12,0) -> 0 | H15: =F15-E15 -> 0
D16: 특근시간(h) Thời gian làm ngày nghỉ | E16: =IFERROR(AVERAGEIFS('업무월별분석 Phân tích CV theo tháng'!$F$55:$F$78,'업무월별분석 Phân tích CV theo tháng'!$P$55:$P$78,L3,'업무월별분석 Phân tích CV theo tháng'!$F$55:$F$78,">0"),0) -> 0 | F16: =IFERROR(AVERAGEIFS('업무월별분석 Phân tích CV theo tháng'!$F$55:$F$78,'업무월별분석 Phân tích CV theo tháng'!$P$55:$P$78,M3,'업무월별분석 Phân tích CV theo tháng'!$F$55:$F$78,">0"),0) -> 0 | G16: =IFERROR(AVERAGEIFS('업무월별분석 Phân tích CV theo tháng'!$F$55:$F$78,'업무월별분석 Phân tích CV theo tháng'!$P$55:$P$78,N3,'업무월별분석 Phân tích CV theo tháng'!$F$55:$F$78,">0"),0) -> 0 | H16: =F16-E16 -> 0 | I16: =IFERROR((F16-E16)/F16,0) -> 0
D17: 특근비율(%) Tỷ lệ làm ngày nghỉ | E17: =IFERROR(E16/E12,0) -> 0 | F17: =IFERROR(F16/F12,0) -> 0 | G17: =IFERROR(G16/G12,0) -> 0 | H17: =F17-E17 -> 0
D18: 미근무 시간(h) Số giờ không làm việc | E18: =IFERROR(AVERAGEIFS('업무월별분석 Phân tích CV theo tháng'!$G$55:$G$78,'업무월별분석 Phân tích CV theo tháng'!$P$55:$P$78,L3,'업무월별분석 Phân tích CV theo tháng'!$G$55:$G$78,">0"),0) -> 0 | F18: =IFERROR(AVERAGEIFS('업무월별분석 Phân tích CV theo tháng'!$G$55:$G$78,'업무월별분석 Phân tích CV theo tháng'!$P$55:$P$78,M3,'업무월별분석 Phân tích CV theo tháng'!$G$55:$G$78,">0"),0) -> 0 | G18: =IFERROR(AVERAGEIFS('업무월별분석 Phân tích CV theo tháng'!$G$55:$G$78,'업무월별분석 Phân tích CV theo tháng'!$P$55:$P$78,N3,'업무월별분석 Phân tích CV theo tháng'!$G$55:$G$78,">0"),0) -> 0 | H18: =F18-E18 -> 0 | I18: =IFERROR((F18-E18)/F18,0) -> 0
D19: 미근무 시간 비율(%) Tỷ lệ thời gian không làm việc | E19: =IFERROR(E18/E12,0) -> 0 | F19: =IFERROR(F18/F12,0) -> 0 | G19: =IFERROR(G18/G12,0) -> 0 | H19: =F19-E19 -> 0
C20: Production Managerment | D20: 합계시간(h) - Tổng thời gian | E20: =IFERROR(E21+E26,0) -> 0 | F20: =IFERROR(F21+F26,0) -> 0 | G20: =IFERROR(G21+G26,0) -> 0 | H20: =F20-E20 -> 0 | I20: =IFERROR((F20-E20)/E20,0) -> 0 | K20: PM
D21: 총근무시간(h) -Tổng số giờ làm việc | E21: =IFERROR(AVERAGEIFS('업무월별분석 Phân tích CV theo tháng'!$C$82:$C$105,'업무월별분석 Phân tích CV theo tháng'!$P$82:$P$105,L3,'업무월별분석 Phân tích CV theo tháng'!$C$82:$C$105,">0"),0) -> 0 | F21: =IFERROR(AVERAGEIFS('업무월별분석 Phân tích CV theo tháng'!$C$82:$C$105,'업무월별분석 Phân tích CV theo tháng'!$P$82:$P$105,M3,'업무월별분석 Phân tích CV theo tháng'!$C$82:$C$105,">0"),0) -> 0 | G21: =IFERROR(AVERAGEIFS('업무월별분석 Phân tích CV theo tháng'!$C$82:$C$105,'업무월별분석 Phân tích CV theo tháng'!$P$82:$P$105,N3,'업무월별분석 Phân tích CV theo tháng'!$C$82:$C$105,">0"),0) -> 0 | H21: =F21-E21 -> 0 | I21: =IFERROR((F21-E21)/F21,0) -> 0
D22: 평일시간(h) Thời gian làm việc ngày thường | E22: =IFERROR(E21-E24,0) -> 0 | F22: =IFERROR(F21-F24,0) -> 0 | G22: =IFERROR(G21-G24,0) -> 0 | H22: =F22-E22 -> 0 | I22: =IFERROR((F22-E22)/F22,0) -> 0
D23: 평일비율(h) Tỷ lệ ngày thường | E23: =IFERROR(E22/E20,0) -> 0 | F23: =IFERROR(F22/F20,0) -> 0 | G23: =IFERROR(G22/G20,0) -> 0 | H23: =F23-E23 -> 0
D24: 특근시간(h) Thời gian làm ngày nghỉ | E24: =IFERROR(AVERAGEIFS('업무월별분석 Phân tích CV theo tháng'!$F$82:$F$105,'업무월별분석 Phân tích CV theo tháng'!$P$82:$P$105,L3,'업무월별분석 Phân tích CV theo tháng'!$F$82:$F$105,">0"),0) -> 0 | F24: =IFERROR(AVERAGEIF('업무월별분석 Phân tích CV theo tháng'!$P$82:$P$105,M3,'업무월별분석 Phân tích CV theo tháng'!$F$82:$F$105),0) -> 0 | G24: =IFERROR(AVERAGEIF('업무월별분석 Phân tích CV theo tháng'!$P$82:$P$105,N3,'업무월별분석 Phân tích CV theo tháng'!$F$82:$F$105),0) -> 0 | H24: =F24-E24 -> 0 | I24: =IFERROR((F24-E24)/F24,0) -> 0
D25: 특근비율(%) Tỷ lệ làm ngày nghỉ | E25: =IFERROR(E24/E20,0) -> 0 | F25: =IFERROR(F24/F20,0) -> 0 | G25: =IFERROR(G24/G20,0) -> 0 | H25: =F25-E25 -> 0
D26: 미근무 시간(h) Số giờ không làm việc | E26: =IFERROR(AVERAGEIFS('업무월별분석 Phân tích CV theo tháng'!$G$82:$G$105,'업무월별분석 Phân tích CV theo tháng'!$P$82:$P$105,L3,'업무월별분석 Phân tích CV theo tháng'!$G$82:$G$105,">0"),0) -> 0 | F26: =IFERROR(AVERAGEIFS('업무월별분석 Phân tích CV theo tháng'!$G$82:$G$105,'업무월별분석 Phân tích CV theo tháng'!$P$82:$P$105,M3,'업무월별분석 Phân tích CV theo tháng'!$G$82:$G$105,">0"),0) -> 0 | G26: =IFERROR(AVERAGEIFS('업무월별분석 Phân tích CV theo tháng'!$G$82:$G$105,'업무월별분석 Phân tích CV theo tháng'!$P$82:$P$105,N3,'업무월별분석 Phân tích CV theo tháng'!$G$82:$G$105,">0"),0) -> 0 | H26: =F26-E26 -> 0 | I26: =IFERROR((F26-E26)/F26,0) -> 0
D27: 미근무 시간 비율(%) Tỷ lệ thời gian không làm việc | E27: =IFERROR(E26/E20,0) -> 0 | F27: =IFERROR(F26/F20,0) -> 0 | G27: =IFERROR(G26/G20,0) -> 0 | H27: =F27-E27 -> 0
C28: Quality Department | D28: 합계시간(h) - Tổng thời gian | E28: =IFERROR(E29+E34,0) -> 0 | F28: =IFERROR(F29+F34,0) -> 0 | G28: =IFERROR(G29+G34,0) -> 0 | H28: =F28-E28 -> 0 | I28: =IFERROR((F28-E28)/E28,0) -> 0 | K28: QD
D29: 총근무시간(h) -Tổng số giờ làm việc | E29: =IFERROR(AVERAGEIF('업무월별분석 Phân tích CV theo tháng'!$P$109:$P$132,L3,'업무월별분석 Phân tích CV theo tháng'!$C$109:$C$132),0) -> 0 | F29: =IFERROR(AVERAGEIF('업무월별분석 Phân tích CV theo tháng'!$P$109:$P$132,M3,'업무월별분석 Phân tích CV theo tháng'!$C$109:$C$132),0) -> 0 | G29: =IFERROR(AVERAGEIF('업무월별분석 Phân tích CV theo tháng'!$P$109:$P$132,N3,'업무월별분석 Phân tích CV theo tháng'!$C$109:$C$132),0) -> 0 | H29: =F29-E29 -> 0 | I29: =IFERROR((F29-E29)/F29,0) -> 0
D30: 평일시간(h) Thời gian làm việc ngày thường | E30: =IFERROR(E29-E32,0) -> 0 | F30: =IFERROR(F29-F32,0) -> 0 | G30: =IFERROR(G29-G32,0) -> 0 | H30: =F30-E30 -> 0 | I30: =IFERROR((F30-E30)/F30,0) -> 0
D31: 평일비율(h) Tỷ lệ ngày thường | E31: =IFERROR(E30/E28,0) -> 0 | F31: =IFERROR(F30/F28,0) -> 0 | G31: =IFERROR(G30/G28,0) -> 0 | H31: =F31-E31 -> 0
D32: 특근시간(h) Thời gian làm ngày nghỉ | E32: =IFERROR(AVERAGEIFS('업무월별분석 Phân tích CV theo tháng'!$F$109:$F$132,'업무월별분석 Phân tích CV theo tháng'!$P$109:$P$132,L3,'업무월별분석 Phân tích CV theo tháng'!$F$109:$F$132,">0"),0) -> 0 | F32: =IFERROR(AVERAGEIFS('업무월별분석 Phân tích CV theo tháng'!$F$109:$F$132,'업무월별분석 Phân tích CV theo tháng'!$P$109:$P$132,M3,'업무월별분석 Phân tích CV theo tháng'!$F$109:$F$132,">0"),0) -> 0 | G32: =IFERROR(AVERAGEIFS('업무월별분석 Phân tích CV theo tháng'!$F$109:$F$132,'업무월별분석 Phân tích CV theo tháng'!$P$109:$P$132,N3,'업무월별분석 Phân tích CV theo tháng'!$F$109:$F$132,">0"),0) -> 0 | H32: =F32-E32 -> 0 | I32: =IFERROR((F32-E32)/F32,0) -> 0
D33: 특근비율(%) Tỷ lệ làm ngày nghỉ | E33: =IFERROR(E32/E28,0) -> 0 | F33: =IFERROR(F32/F28,0) -> 0 | G33: =IFERROR(G32/G28,0) -> 0 | H33: =F33-E33 -> 0
D34: 미근무 시간(h) Số giờ không làm việc | E34: =IFERROR(AVERAGEIFS('업무월별분석 Phân tích CV theo tháng'!$G$109:$G$132,'업무월별분석 Phân tích CV theo tháng'!$P$109:$P$132,L3,'업무월별분석 Phân tích CV theo tháng'!$G$109:$G$132,">0"),0) -> 0 | F34: =IFERROR(AVERAGEIFS('업무월별분석 Phân tích CV theo tháng'!$G$109:$G$132,'업무월별분석 Phân tích CV theo tháng'!$P$109:$P$132,M3,'업무월별분석 Phân tích CV theo tháng'!$G$109:$G$132,">0"),0) -> 0 | G34: =IFERROR(AVERAGEIFS('업무월별분석 Phân tích CV theo tháng'!$G$109:$G$132,'업무월별분석 Phân tích CV theo tháng'!$P$109:$P$132,N3,'업무월별분석 Phân tích CV theo tháng'!$G$109:$G$132,">0"),0) -> 0 | H34: =F34-E34 -> 0 | I34: =IFERROR((F34-E34)/F34,0) -> 0
D35: 미근무 시간 비율(%) Tỷ lệ thời gian không làm việc | E35: =IFERROR(E34/E28,0) -> 0 | F35: =IFERROR(F34/F28,0) -> 0 | G35: =IFERROR(G34/G28,0) -> 0 | H35: =F35-E35 -> 0
C36: PUR & Logistics | D36: 합계시간(h) - Tổng thời gian | E36: =IFERROR(E37+E42,0) -> 0 | F36: =IFERROR(F37+F42,0) -> 0 | G36: =IFERROR(G37+G42,0) -> 0 | H36: =F36-E36 -> 0 | I36: =IFERROR((F36-E36)/E36,0) -> 0 | K36: PL
D37: 총근무시간(h) -Tổng số giờ làm việc | E37: =IFERROR(AVERAGEIFS('업무월별분석 Phân tích CV theo tháng'!$C$136:$C$159,'업무월별분석 Phân tích CV theo tháng'!$P$136:$P$159,L3,'업무월별분석 Phân tích CV theo tháng'!$C$136:$C$159,">0"),0) -> 0 | F37: =IFERROR(AVERAGEIFS('업무월별분석 Phân tích CV theo tháng'!$C$136:$C$159,'업무월별분석 Phân tích CV theo tháng'!$P$136:$P$159,M3,'업무월별분석 Phân tích CV theo tháng'!$C$136:$C$159,">0"),0) -> 0 | G37: =IFERROR(AVERAGEIFS('업무월별분석 Phân tích CV theo tháng'!$C$136:$C$159,'업무월별분석 Phân tích CV theo tháng'!$P$136:$P$159,N3,'업무월별분석 Phân tích CV theo tháng'!$C$136:$C$159,">0"),0) -> 0 | H37: =F37-E37 -> 0 | I37: =IFERROR((F37-E37)/F37,0) -> 0
D38: 평일시간(h) Thời gian làm việc ngày thường | E38: =IFERROR(E37-E40,0) -> 0 | F38: =IFERROR(F37-F40,0) -> 0 | G38: =IFERROR(G37-G40,0) -> 0 | H38: =F38-E38 -> 0 | I38: =IFERROR((F38-E38)/F38,0) -> 0
D39: 평일비율(h) Tỷ lệ ngày thường | E39: =IFERROR(E38/E36,0) -> 0 | F39: =IFERROR(F38/F36,0) -> 0 | G39: =IFERROR(G38/G36,0) -> 0 | H39: =F39-E39 -> 0
D40: 특근시간(h) Thời gian làm ngày nghỉ | E40: =IFERROR(AVERAGEIFS('업무월별분석 Phân tích CV theo tháng'!$F$136:$F$159,'업무월별분석 Phân tích CV theo tháng'!$P$136:$P$159,L3,'업무월별분석 Phân tích CV theo tháng'!$F$136:$F$159,">0"),0) -> 0 | F40: =IFERROR(AVERAGEIFS('업무월별분석 Phân tích CV theo tháng'!$F$136:$F$159,'업무월별분석 Phân tích CV theo tháng'!$P$136:$P$159,M3,'업무월별분석 Phân tích CV theo tháng'!$F$136:$F$159,">0"),0) -> 0 | G40: =IFERROR(AVERAGEIFS('업무월별분석 Phân tích CV theo tháng'!$F$136:$F$159,'업무월별분석 Phân tích CV theo tháng'!$P$136:$P$159,N3,'업무월별분석 Phân tích CV theo tháng'!$F$136:$F$159,">0"),0) -> 0 | H40: =F40-E40 -> 0 | I40: =IFERROR((F40-E40)/F40,0) -> 0
...

Sheet 월별분석 Phân tích theo tháng
A1: 기본정보 - Thông tin cơ bản | B1: 총합계시간 대비 비율 (시간) - Tỷ lệ so sánh thời gian tổng (tiếng)
A2: 월 | B2: 통상근무비율 Tỷ lệ làm việc bình thường | C2: 잔업비율 tỷ lệ tăng ca | D2: 특근비율 Tỷ lệ ngày nghỉ - nghỉ phép | E2: LOSS비율 - Tỷ lệ k đi làm trong giờ Hành chính | F2: 통상+잔업(평일근무) Bình thường + tăng ca(làm việc ngày thường)
A3: =DATE(I3,H3,1) -> 1 | B3: =VLOOKUP(A3,'월별 기본데이터 합계'!$A$5:$AD$28,30,0) -> 0 | C3: =VLOOKUP(A3,'월별 기본데이터 합계'!$A$5:$AE$28,31,0) -> 0 | D3: =VLOOKUP(A3,'월별 기본데이터 합계'!$A$5:$AF$28,32,0) -> 0 | E3: =VLOOKUP(A3,'월별 기본데이터 합계'!$A$5:$AG$28,33,0) -> 0 | F3: =IFERROR(B3+C3,"") -> 0 | H3: 1 | I3: =Sheet1!$A$1-1 -> 0
A4: =DATE(I4,H4,1) -> 32 | B4: =VLOOKUP(A4,'월별 기본데이터 합계'!$A$5:$AD$28,30,0) -> 0 | C4: =VLOOKUP(A4,'월별 기본데이터 합계'!$A$5:$AE$28,31,0) -> 0 | D4: =VLOOKUP(A4,'월별 기본데이터 합계'!$A$5:$AF$28,32,0) -> 0 | E4: =VLOOKUP(A4,'월별 기본데이터 합계'!$A$5:$AG$28,33,0) -> 0 | F4: =IFERROR(B4+C4,"") -> 0 | H4: 2 | I4: =Sheet1!$A$1-1 -> 0
A5: =DATE(I5,H5,1) -> 61 | B5: =VLOOKUP(A5,'월별 기본데이터 합계'!$A$5:$AD$28,30,0) -> 0 | C5: =VLOOKUP(A5,'월별 기본데이터 합계'!$A$5:$AE$28,31,0) -> 0 | D5: =VLOOKUP(A5,'월별 기본데이터 합계'!$A$5:$AF$28,32,0) -> 0 | E5: =VLOOKUP(A5,'월별 기본데이터 합계'!$A$5:$AG$28,33,0) -> 0 | F5: =IFERROR(B5+C5,"") -> 0 | H5: 3 | I5: =Sheet1!$A$1-1 -> 0
A6: =DATE(I6,H6,1) -> 92 | B6: =VLOOKUP(A6,'월별 기본데이터 합계'!$A$5:$AD$28,30,0) -> 0 | C6: =VLOOKUP(A6,'월별 기본데이터 합계'!$A$5:$AE$28,31,0) -> 0 | D6: =VLOOKUP(A6,'월별 기본데이터 합계'!$A$5:$AF$28,32,0) -> 0 | E6: =VLOOKUP(A6,'월별 기본데이터 합계'!$A$5:$AG$28,33,0) -> 0 | F6: =IFERROR(B6+C6,"") -> 0 | H6: 4 | I6: =Sheet1!$A$1-1 -> 0
A7: =DATE(I7,H7,1) -> 122 | B7: =VLOOKUP(A7,'월별 기본데이터 합계'!$A$5:$AD$28,30,0) -> 0 | C7: =VLOOKUP(A7,'월별 기본데이터 합계'!$A$5:$AE$28,31,0) -> 0 | D7: =VLOOKUP(A7,'월별 기본데이터 합계'!$A$5:$AF$28,32,0) -> 0 | E7: =VLOOKUP(A7,'월별 기본데이터 합계'!$A$5:$AG$28,33,0) -> 0 | F7: =IFERROR(B7+C7,"") -> 0 | H7: 5 | I7: =Sheet1!$A$1-1 -> 0
A8: =DATE(I8,H8,1) -> 153 | B8: =VLOOKUP(A8,'월별 기본데이터 합계'!$A$5:$AD$28,30,0) -> 0 | C8: =VLOOKUP(A8,'월별 기본데이터 합계'!$A$5:$AE$28,31,0) -> 0 | D8: =VLOOKUP(A8,'월별 기본데이터 합계'!$A$5:$AF$28,32,0) -> 0 | E8: =VLOOKUP(A8,'월별 기본데이터 합계'!$A$5:$AG$28,33,0) -> 0 | F8: =IFERROR(B8+C8,"") -> 0 | H8: 6 | I8: =Sheet1!$A$1-1 -> 0
A9: =DATE(I9,H9,1) -> 183 | B9: =VLOOKUP(A9,'월별 기본데이터 합계'!$A$5:$AD$28,30,0) -> 0 | C9: =VLOOKUP(A9,'월별 기본데이터 합계'!$A$5:$AE$28,31,0) -> 0 | D9: =VLOOKUP(A9,'월별 기본데이터 합계'!$A$5:$AF$28,32,0) -> 0 | E9: =VLOOKUP(A9,'월별 기본데이터 합계'!$A$5:$AG$28,33,0) -> 0 | F9: =IFERROR(B9+C9,"") -> 0 | H9: 7 | I9: =Sheet1!$A$1-1 -> 0
A10: =DATE(I10,H10,1) -> 214 | B10: =VLOOKUP(A10,'월별 기본데이터 합계'!$A$5:$AD$28,30,0) -> 0 | C10: =VLOOKUP(A10,'월별 기본데이터 합계'!$A$5:$AE$28,31,0) -> 0 | D10: =VLOOKUP(A10,'월별 기본데이터 합계'!$A$5:$AF$28,32,0) -> 0 | E10: =VLOOKUP(A10,'월별 기본데이터 합계'!$A$5:$AG$28,33,0) -> 0 | F10: =IFERROR(B10+C10,"") -> 0 | H10: 8 | I10: =Sheet1!$A$1-1 -> 0
A11: =DATE(I11,H11,1) -> 245 | B11: =VLOOKUP(A11,'월별 기본데이터 합계'!$A$5:$AD$28,30,0) -> 0 | C11: =VLOOKUP(A11,'월별 기본데이터 합계'!$A$5:$AE$28,31,0) -> 0 | D11: =VLOOKUP(A11,'월별 기본데이터 합계'!$A$5:$AF$28,32,0) -> 0 | E11: =VLOOKUP(A11,'월별 기본데이터 합계'!$A$5:$AG$28,33,0) -> 0 | F11: =IFERROR(B11+C11,"") -> 0 | H11: 9 | I11: =Sheet1!$A$1-1 -> 0
A12: =DATE(I12,H12,1) -> 275 | B12: =VLOOKUP(A12,'월별 기본데이터 합계'!$A$5:$AD$28,30,0) -> 0 | C12: =VLOOKUP(A12,'월별 기본데이터 합계'!$A$5:$AE$28,31,0) -> 0 | D12: =VLOOKUP(A12,'월별 기본데이터 합계'!$A$5:$AF$28,32,0) -> 0 | E12: =VLOOKUP(A12,'월별 기본데이터 합계'!$A$5:$AG$28,33,0) -> 0 | F12: =IFERROR(B12+C12,"") -> 0 | H12: 10 | I12: =Sheet1!$A$1-1 -> 0
A13: =DATE(I13,H13,1) -> 306 | B13: =VLOOKUP(A13,'월별 기본데이터 합계'!$A$5:$AD$28,30,0) -> 0 | C13: =VLOOKUP(A13,'월별 기본데이터 합계'!$A$5:$AE$28,31,0) -> 0 | D13: =VLOOKUP(A13,'월별 기본데이터 합계'!$A$5:$AF$28,32,0) -> 0 | E13: =VLOOKUP(A13,'월별 기본데이터 합계'!$A$5:$AG$28,33,0) -> 0 | F13: =IFERROR(B13+C13,"") -> 0 | H13: 11 | I13: =Sheet1!$A$1-1 -> 0
A14: =DATE(I14,H14,1) -> 336 | B14: =VLOOKUP(A14,'월별 기본데이터 합계'!$A$5:$AD$28,30,0) -> 0 | C14: =VLOOKUP(A14,'월별 기본데이터 합계'!$A$5:$AE$28,31,0) -> 0 | D14: =VLOOKUP(A14,'월별 기본데이터 합계'!$A$5:$AF$28,32,0) -> 0 | E14: =VLOOKUP(A14,'월별 기본데이터 합계'!$A$5:$AG$28,33,0) -> 0 | F14: =IFERROR(B14+C14,"") -> 0 | H14: 12 | I14: =Sheet1!$A$1-1 -> 0
A15: =DATE(I15,H15,1) -> 367 | B15: =VLOOKUP(A15,'월별 기본데이터 합계'!$A$5:$AD$28,30,0) -> 0 | C15: =VLOOKUP(A15,'월별 기본데이터 합계'!$A$5:$AE$28,31,0) -> 0 | D15: =VLOOKUP(A15,'월별 기본데이터 합계'!$A$5:$AF$28,32,0) -> 0 | E15: =VLOOKUP(A15,'월별 기본데이터 합계'!$A$5:$AG$28,33,0) -> 0 | F15: =IFERROR(B15+C15,"") -> 0 | H15: 1 | I15: =Sheet1!$A$1 -> 1
A16: =DATE(I16,H16,1) -> 398 | B16: =VLOOKUP(A16,'월별 기본데이터 합계'!$A$5:$AD$28,30,0) -> 0 | C16: =VLOOKUP(A16,'월별 기본데이터 합계'!$A$5:$AE$28,31,0) -> 0 | D16: =VLOOKUP(A16,'월별 기본데이터 합계'!$A$5:$AF$28,32,0) -> 0 | E16: =VLOOKUP(A16,'월별 기본데이터 합계'!$A$5:$AG$28,33,0) -> 0 | F16: =IFERROR(B16+C16,"") -> 0 | H16: 2 | I16: =Sheet1!$A$1 -> 1
A17: =DATE(I17,H17,1) -> 426 | B17: =VLOOKUP(A17,'월별 기본데이터 합계'!$A$5:$AD$28,30,0) -> 0 | C17: =VLOOKUP(A17,'월별 기본데이터 합계'!$A$5:$AE$28,31,0) -> 0 | D17: =VLOOKUP(A17,'월별 기본데이터 합계'!$A$5:$AF$28,32,0) -> 0 | E17: =VLOOKUP(A17,'월별 기본데이터 합계'!$A$5:$AG$28,33,0) -> 0 | F17: =IFERROR(B17+C17,"") -> 0 | H17: 3 | I17: =Sheet1!$A$1 -> 1
A18: =DATE(I18,H18,1) -> 457 | B18: =VLOOKUP(A18,'월별 기본데이터 합계'!$A$5:$AD$28,30,0) -> 0 | C18: =VLOOKUP(A18,'월별 기본데이터 합계'!$A$5:$AE$28,31,0) -> 0 | D18: =VLOOKUP(A18,'월별 기본데이터 합계'!$A$5:$AF$28,32,0) -> 0 | E18: =VLOOKUP(A18,'월별 기본데이터 합계'!$A$5:$AG$28,33,0) -> 0 | F18: =IFERROR(B18+C18,"") -> 0 | H18: 4 | I18: =Sheet1!$A$1 -> 1
A19: =DATE(I19,H19,1) -> 487 | B19: =VLOOKUP(A19,'월별 기본데이터 합계'!$A$5:$AD$28,30,0) -> 0 | C19: =VLOOKUP(A19,'월별 기본데이터 합계'!$A$5:$AE$28,31,0) -> 0 | D19: =VLOOKUP(A19,'월별 기본데이터 합계'!$A$5:$AF$28,32,0) -> 0 | E19: =VLOOKUP(A19,'월별 기본데이터 합계'!$A$5:$AG$28,33,0) -> 0 | F19: =IFERROR(B19+C19,"") -> 0 | H19: 5 | I19: =Sheet1!$A$1 -> 1
A20: =DATE(I20,H20,1) -> 518 | B20: =VLOOKUP(A20,'월별 기본데이터 합계'!$A$5:$AD$28,30,0) -> 0 | C20: =VLOOKUP(A20,'월별 기본데이터 합계'!$A$5:$AE$28,31,0) -> 0 | D20: =VLOOKUP(A20,'월별 기본데이터 합계'!$A$5:$AF$28,32,0) -> 0 | E20: =VLOOKUP(A20,'월별 기본데이터 합계'!$A$5:$AG$28,33,0) -> 0 | F20: =IFERROR(B20+C20,"") -> 0 | H20: 6 | I20: =Sheet1!$A$1 -> 1
A21: =DATE(I21,H21,1) -> 548 | B21: =VLOOKUP(A21,'월별 기본데이터 합계'!$A$5:$AD$28,30,0) -> 0 | C21: =VLOOKUP(A21,'월별 기본데이터 합계'!$A$5:$AE$28,31,0) -> 0 | D21: =VLOOKUP(A21,'월별 기본데이터 합계'!$A$5:$AF$28,32,0) -> 0 | E21: =VLOOKUP(A21,'월별 기본데이터 합계'!$A$5:$AG$28,33,0) -> 0 | F21: =IFERROR(B21+C21,"") -> 0 | H21: 7 | I21: =Sheet1!$A$1 -> 1
A22: =DATE(I22,H22,1) -> 579 | B22: =VLOOKUP(A22,'월별 기본데이터 합계'!$A$5:$AD$28,30,0) -> 0 | C22: =VLOOKUP(A22,'월별 기본데이터 합계'!$A$5:$AE$28,31,0) -> 0 | D22: =VLOOKUP(A22,'월별 기본데이터 합계'!$A$5:$AF$28,32,0) -> 0 | E22: =VLOOKUP(A22,'월별 기본데이터 합계'!$A$5:$AG$28,33,0) -> 0 | F22: =IFERROR(B22+C22,"") -> 0 | H22: 8 | I22: =Sheet1!$A$1 -> 1
A23: =DATE(I23,H23,1) -> 610 | B23: =VLOOKUP(A23,'월별 기본데이터 합계'!$A$5:$AD$28,30,0) -> 0 | C23: =VLOOKUP(A23,'월별 기본데이터 합계'!$A$5:$AE$28,31,0) -> 0 | D23: =VLOOKUP(A23,'월별 기본데이터 합계'!$A$5:$AF$28,32,0) -> 0 | E23: =VLOOKUP(A23,'월별 기본데이터 합계'!$A$5:$AG$28,33,0) -> 0 | F23: =IFERROR(B23+C23,"") -> 0 | H23: 9 | I23: =Sheet1!$A$1 -> 1
A24: =DATE(I24,H24,1) -> 640 | B24: =VLOOKUP(A24,'월별 기본데이터 합계'!$A$5:$AD$28,30,0) -> 0 | C24: =VLOOKUP(A24,'월별 기본데이터 합계'!$A$5:$AE$28,31,0) -> 0 | D24: =VLOOKUP(A24,'월별 기본데이터 합계'!$A$5:$AF$28,32,0) -> 0 | E24: =VLOOKUP(A24,'월별 기본데이터 합계'!$A$5:$AG$28,33,0) -> 0 | F24: =IFERROR(B24+C24,"") -> 0 | H24: 10 | I24: =Sheet1!$A$1 -> 1
A25: =DATE(I25,H25,1) -> 671 | B25: =VLOOKUP(A25,'월별 기본데이터 합계'!$A$5:$AD$28,30,0) -> 0 | C25: =VLOOKUP(A25,'월별 기본데이터 합계'!$A$5:$AE$28,31,0) -> 0 | D25: =VLOOKUP(A25,'월별 기본데이터 합계'!$A$5:$AF$28,32,0) -> 0 | E25: =VLOOKUP(A25,'월별 기본데이터 합계'!$A$5:$AG$28,33,0) -> 0 | F25: =IFERROR(B25+C25,"") -> 0 | H25: 11 | I25: =Sheet1!$A$1 -> 1
A26: =DATE(I26,H26,1) -> 701 | B26: =VLOOKUP(A26,'월별 기본데이터 합계'!$A$5:$AD$28,30,0) -> 0 | C26: =VLOOKUP(A26,'월별 기본데이터 합계'!$A$5:$AE$28,31,0) -> 0 | D26: =VLOOKUP(A26,'월별 기본데이터 합계'!$A$5:$AF$28,32,0) -> 0 | E26: =VLOOKUP(A26,'월별 기본데이터 합계'!$A$5:$AG$28,33,0) -> 0 | F26: =IFERROR(B26+C26,"") -> 0 | H26: 12 | I26: =Sheet1!$A$1 -> 1

Sheet 업무월별분석 Phân tích CV theo tháng
A1: 3. Montly working hour rate ( 월간 월 근무 시간 율)
A3: Total | C3: Working hour (근무시간) | I3: Hour rate /Total working hr (총합계시간 대비 비율 (%)) | O3: 1 | P3: Total
A4: 월 Tháng | C4: 총근무 Tổng đi làm | D4: 통상근무 Đi làm bình thường | E4: 잔업 Tăng ca | F4: 특근 Đi làm ngày nghỉ | G4: LOSS | H4: 통상+잔업(평일근무) Bình thường+Tăng ca (Đi làm ngày thường) | I4: 통상근무 Đi làm bình thường | J4: 잔업 Tăng ca | K4: 특근 Ngày nghỉ | L4: LOSS | M4: 통상+잔업(평일근무) Bình thường + tăng ca (làm việc ngày thường)
A5: =DATE(P5,O5,1) -> 1 | B5: =TEXT(O5*29,"mmm")& "-" &P5 -> Jan-0 | C5: =SUM(D5:G5) -> 0 | D5: =SUMIF(Sheet1!F:F,B5,Sheet1!J:J) -> 0 | E5: =SUMIF(Sheet1!F:F,B5,Sheet1!K:K) -> 0 | F5: =SUMIF(Sheet1!F:F,B5,Sheet1!N:N) -> 0 | G5: =SUMIF(Sheet1!F:F,B5,Sheet1!Z:Z) -> 0 | H5: =D5+E5 -> 0 | I5: =IFERROR(D5/C5*100%,"") | J5: =IFERROR(E5/C5*100%,"") | K5: =IFERROR(F5/C5*100%,"") | L5: =IFERROR(G5/C5*100%,"") | M5: =IFERROR(I5+J5,"") | O5: 1 | P5: =Sheet1!$A$1-1 -> 0
A6: =DATE(P6,O6,1) -> 32 | B6: =TEXT(O6*29,"mmm")& "-" &P6 -> Feb-0 | C6: =SUM(D6:G6) -> 0 | D6: =SUMIF(Sheet1!F:F,B6,Sheet1!J:J) -> 0 | E6: =SUMIF(Sheet1!F:F,B6,Sheet1!K:K) -> 0 | F6: =SUMIF(Sheet1!F:F,B6,Sheet1!N:N) -> 0 | G6: =SUMIF(Sheet1!F:F,B6,Sheet1!Z:Z) -> 0 | H6: =D6+E6 -> 0 | I6: =IFERROR(D6/C6*100%,"") | J6: =IFERROR(E6/C6*100%,"") | K6: =IFERROR(F6/C6*100%,"") | L6: =IFERROR(G6/C6*100%,"") | M6: =IFERROR(I6+J6,"") | O6: 2 | P6: =Sheet1!$A$1-1 -> 0
A7: =DATE(P7,O7,1) -> 61 | B7: =TEXT(O7*29,"mmm")& "-" &P7 -> Mar-0 | C7: =SUM(D7:G7) -> 0 | D7: =SUMIF(Sheet1!F:F,B7,Sheet1!J:J) -> 0 | E7: =SUMIF(Sheet1!F:F,B7,Sheet1!K:K) -> 0 | F7: =SUMIF(Sheet1!F:F,B7,Sheet1!N:N) -> 0 | G7: =SUMIF(Sheet1!F:F,B7,Sheet1!Z:Z) -> 0 | H7: =D7+E7 -> 0 | I7: =IFERROR(D7/C7*100%,"") | J7: =IFERROR(E7/C7*100%,"") | K7: =IFERROR(F7/C7*100%,"") | L7: =IFERROR(G7/C7*100%,"") | M7: =IFERROR(I7+J7,"") | O7: 3 | P7: =Sheet1!$A$1-1 -> 0
A8: =DATE(P8,O8,1) -> 92 | B8: =TEXT(O8*29,"mmm")& "-" &P8 -> Apr-0 | C8: =SUM(D8:G8) -> 0 | D8: =SUMIF(Sheet1!F:F,B8,Sheet1!J:J) -> 0 | E8: =SUMIF(Sheet1!F:F,B8,Sheet1!K:K) -> 0 | F8: =SUMIF(Sheet1!F:F,B8,Sheet1!N:N) -> 0 | G8: =SUMIF(Sheet1!F:F,B8,Sheet1!Z:Z) -> 0 | H8: =D8+E8 -> 0 | I8: =IFERROR(D8/C8*100%,"") | J8: =IFERROR(E8/C8*100%,"") | K8: =IFERROR(F8/C8*100%,"") | L8: =IFERROR(G8/C8*100%,"") | M8: =IFERROR(I8+J8,"") | O8: 4 | P8: =Sheet1!$A$1-1 -> 0
A9: =DATE(P9,O9,1) -> 122 | B9: =TEXT(O9*29,"mmm")& "-" &P9 -> May-0 | C9: =SUM(D9:G9) -> 0 | D9: =SUMIF(Sheet1!F:F,B9,Sheet1!J:J) -> 0 | E9: =SUMIF(Sheet1!F:F,B9,Sheet1!K:K) -> 0 | F9: =SUMIF(Sheet1!F:F,B9,Sheet1!N:N) -> 0 | G9: =SUMIF(Sheet1!F:F,B9,Sheet1!Z:Z) -> 0 | H9: =D9+E9 -> 0 | I9: =IFERROR(D9/C9*100%,"") | J9: =IFERROR(E9/C9*100%,"") | K9: =IFERROR(F9/C9*100%,"") | L9: =IFERROR(G9/C9*100%,"") | M9: =IFERROR(I9+J9,"") | O9: 5 | P9: =Sheet1!$A$1-1 -> 0
A10: =DATE(P10,O10,1) -> 153 | B10: =TEXT(O10*29,"mmm")& "-" &P10 -> Jun-0 | C10: =SUM(D10:G10) -> 0 | D10: =SUMIF(Sheet1!F:F,B10,Sheet1!J:J) -> 0 | E10: =SUMIF(Sheet1!F:F,B10,Sheet1!K:K) -> 0 | F10: =SUMIF(Sheet1!F:F,B10,Sheet1!N:N) -> 0 | G10: =SUMIF(Sheet1!F:F,B10,Sheet1!Z:Z) -> 0 | H10: =D10+E10 -> 0 | I10: =IFERROR(D10/C10*100%,"") | J10: =IFERROR(E10/C10*100%,"") | K10: =IFERROR(F10/C10*100%,"") | L10: =IFERROR(G10/C10*100%,"") | M10: =IFERROR(I10+J10,"") | O10: 6 | P10: =Sheet1!$A$1-1 -> 0
A11: =DATE(P11,O11,1) -> 183 | B11: =TEXT(O11*29,"mmm")& "-" &P11 -> Jul-0 | C11: =SUM(D11:G11) -> 0 | D11: =SUMIF(Sheet1!F:F,B11,Sheet1!J:J) -> 0 | E11: =SUMIF(Sheet1!F:F,B11,Sheet1!K:K) -> 0 | F11: =SUMIF(Sheet1!F:F,B11,Sheet1!N:N) -> 0 | G11: =SUMIF(Sheet1!F:F,B11,Sheet1!Z:Z) -> 0 | H11: =D11+E11 -> 0 | I11: =IFERROR(D11/C11*100%,"") | J11: =IFERROR(E11/C11*100%,"") | K11: =IFERROR(F11/C11*100%,"") | L11: =IFERROR(G11/C11*100%,"") | M11: =IFERROR(I11+J11,"") | O11: 7 | P11: =Sheet1!$A$1-1 -> 0
A12: =DATE(P12,O12,1) -> 214 | B12: =TEXT(O12*29,"mmm")& "-" &P12 -> Aug-0 | C12: =SUM(D12:G12) -> 0 | D12: =SUMIF(Sheet1!F:F,B12,Sheet1!J:J) -> 0 | E12: =SUMIF(Sheet1!F:F,B12,Sheet1!K:K) -> 0 | F12: =SUMIF(Sheet1!F:F,B12,Sheet1!N:N) -> 0 | G12: =SUMIF(Sheet1!F:F,B12,Sheet1!Z:Z) -> 0 | H12: =D12+E12 -> 0 | I12: =IFERROR(D12/C12*100%,"") | J12: =IFERROR(E12/C12*100%,"") | K12: =IFERROR(F12/C12*100%,"") | L12: =IFERROR(G12/C12*100%,"") | M12: =IFERROR(I12+J12,"") | O12: 8 | P12: =Sheet1!$A$1-1 -> 0
A13: =DATE(P13,O13,1) -> 245 | B13: =TEXT(O13*29,"mmm")& "-" &P13 -> Sep-0 | C13: =SUM(D13:G13) -> 0 | D13: =SUMIF(Sheet1!F:F,B13,Sheet1!J:J) -> 0 | E13: =SUMIF(Sheet1!F:F,B13,Sheet1!K:K) -> 0 | F13: =SUMIF(Sheet1!F:F,B13,Sheet1!N:N) -> 0 | G13: =SUMIF(Sheet1!F:F,B13,Sheet1!Z:Z) -> 0 | H13: =D13+E13 -> 0 | I13: =IFERROR(D13/C13*100%,"") | J13: =IFERROR(E13/C13*100%,"") | K13: =IFERROR(F13/C13*100%,"") | L13: =IFERROR(G13/C13*100%,"") | M13: =IFERROR(I13+J13,"") | O13: 9 | P13: =Sheet1!$A$1-1 -> 0
A14: =DATE(P14,O14,1) -> 275 | B14: =TEXT(O14*29,"mmm")& "-" &P14 -> Oct-0 | C14: =SUM(D14:G14) -> 0 | D14: =SUMIF(Sheet1!F:F,B14,Sheet1!J:J) -> 0 | E14: =SUMIF(Sheet1!F:F,B14,Sheet1!K:K) -> 0 | F14: =SUMIF(Sheet1!F:F,B14,Sheet1!N:N) -> 0 | G14: =SUMIF(Sheet1!F:F,B14,Sheet1!Z:Z) -> 0 | H14: =D14+E14 -> 0 | I14: =IFERROR(D14/C14*100%,"") | J14: =IFERROR(E14/C14*100%,"") | K14: =IFERROR(F14/C14*100%,"") | L14: =IFERROR(G14/C14*100%,"") | M14: =IFERROR(I14+J14,"") | O14: 10 | P14: =Sheet1!$A$1-1 -> 0
A15: =DATE(P15,O15,1) -> 306 | B15: =TEXT(O15*29,"mmm")& "-" &P15 -> Nov-0 | C15: =SUM(D15:G15) -> 0 | D15: =SUMIF(Sheet1!F:F,B15,Sheet1!J:J) -> 0 | E15: =SUMIF(Sheet1!F:F,B15,Sheet1!K:K) -> 0 | F15: =SUMIF(Sheet1!F:F,B15,Sheet1!N:N) -> 0 | G15: =SUMIF(Sheet1!F:F,B15,Sheet1!Z:Z) -> 0 | H15: =D15+E15 -> 0 | I15: =IFERROR(D15/C15*100%,"") | J15: =IFERROR(E15/C15*100%,"") | K15: =IFERROR(F15/C15*100%,"") | L15: =IFERROR(G15/C15*100%,"") | M15: =IFERROR(I15+J15,"") | O15: 11 | P15: =Sheet1!$A$1-1 -> 0
A16: =DATE(P16,O16,1) -> 336 | B16: =TEXT(O16*29,"mmm")& "-" &P16 -> Dec-0 | C16: =SUM(D16:G16) -> 0 | D16: =SUMIF(Sheet1!F:F,B16,Sheet1!J:J) -> 0 | E16: =SUMIF(Sheet1!F:F,B16,Sheet1!K:K) -> 0 | F16: =SUMIF(Sheet1!F:F,B16,Sheet1!N:N) -> 0 | G16: =SUMIF(Sheet1!F:F,B16,Sheet1!Z:Z) -> 0 | H16: =D16+E16 -> 0 | I16: =IFERROR(D16/C16*100%,"") | J16: =IFERROR(E16/C16*100%,"") | K16: =IFERROR(F16/C16*100%,"") | L16: =IFERROR(G16/C16*100%,"") | M16: =IFERROR(I16+J16,"") | O16: 12 | P16: =Sheet1!$A$1-1 -> 0
A17: =DATE(P17,O17,1) -> 367 | B17: =TEXT(O17*29,"mmm")& "-" &P17 -> Jan-1 | C17: =SUM(D17:G17) -> 0 | D17: =SUMIF(Sheet1!F:F,B17,Sheet1!J:J) -> 0 | E17: =SUMIF(Sheet1!F:F,B17,Sheet1!K:K) -> 0 | F17: =SUMIF(Sheet1!F:F,B17,Sheet1!N:N) -> 0 | G17: =SUMIF(Sheet1!F:F,B17,Sheet1!Z:Z) -> 0 | H17: =D17+E17 -> 0 | I17: =IFERROR(D17/C17*100%,"") | J17: =IFERROR(E17/C17*100%,"") | K17: =IFERROR(F17/C17*100%,"") | L17: =IFERROR(G17/C17*100%,"") | M17: =IFERROR(I17+J17,"") | O17: 1 | P17: =Sheet1!$A$1 -> 1
A18: =DATE(P18,O18,1) -> 398 | B18: =TEXT(O18*29,"mmm")& "-" &P18 -> Feb-1 | C18: =SUM(D18:G18) -> 0 | D18: =SUMIF(Sheet1!F:F,B18,Sheet1!J:J) -> 0 | E18: =SUMIF(Sheet1!F:F,B18,Sheet1!K:K) -> 0 | F18: =SUMIF(Sheet1!F:F,B18,Sheet1!N:N) -> 0 | G18: =SUMIF(Sheet1!F:F,B18,Sheet1!Z:Z) -> 0 | H18: =D18+E18 -> 0 | I18: =IFERROR(D18/C18*100%,"") | J18: =IFERROR(E18/C18*100%,"") | K18: =IFERROR(F18/C18*100%,"") | L18: =IFERROR(G18/C18*100%,"") | M18: =IFERROR(I18+J18,"") | O18: 2 | P18: =Sheet1!$A$1 -> 1
A19: =DATE(P19,O19,1) -> 426 | B19: =TEXT(O19*29,"mmm")& "-" &P19 -> Mar-1 | C19: =SUM(D19:G19) -> 0 | D19: =SUMIF(Sheet1!F:F,B19,Sheet1!J:J) -> 0 | E19: =SUMIF(Sheet1!F:F,B19,Sheet1!K:K) -> 0 | F19: =SUMIF(Sheet1!F:F,B19,Sheet1!N:N) -> 0 | G19: =SUMIF(Sheet1!F:F,B19,Sheet1!Z:Z) -> 0 | H19: =D19+E19 -> 0 | I19: =IFERROR(D19/C19*100%,"") | J19: =IFERROR(E19/C19*100%,"") | K19: =IFERROR(F19/C19*100%,"") | L19: =IFERROR(G19/C19*100%,"") | M19: =IFERROR(I19+J19,"") | O19: 3 | P19: =Sheet1!$A$1 -> 1
A20: =DATE(P20,O20,1) -> 457 | B20: =TEXT(O20*29,"mmm")& "-" &P20 -> Apr-1 | C20: =SUM(D20:G20) -> 0 | D20: =SUMIF(Sheet1!F:F,B20,Sheet1!J:J) -> 0 | E20: =SUMIF(Sheet1!F:F,B20,Sheet1!K:K) -> 0 | F20: =SUMIF(Sheet1!F:F,B20,Sheet1!N:N) -> 0 | G20: =SUMIF(Sheet1!F:F,B20,Sheet1!Z:Z) -> 0 | H20: =D20+E20 -> 0 | I20: =IFERROR(D20/C20*100%,"") | J20: =IFERROR(E20/C20*100%,"") | K20: =IFERROR(F20/C20*100%,"") | L20: =IFERROR(G20/C20*100%,"") | M20: =IFERROR(I20+J20,"") | O20: 4 | P20: =Sheet1!$A$1 -> 1
A21: =DATE(P21,O21,1) -> 487 | B21: =TEXT(O21*29,"mmm")& "-" &P21 -> May-1 | C21: =SUM(D21:G21) -> 0 | D21: =SUMIF(Sheet1!F:F,B21,Sheet1!J:J) -> 0 | E21: =SUMIF(Sheet1!F:F,B21,Sheet1!K:K) -> 0 | F21: =SUMIF(Sheet1!F:F,B21,Sheet1!N:N) -> 0 | G21: =SUMIF(Sheet1!F:F,B21,Sheet1!Z:Z) -> 0 | H21: =D21+E21 -> 0 | I21: =IFERROR(D21/C21*100%,"") | J21: =IFERROR(E21/C21*100%,"") | K21: =IFERROR(F21/C21*100%,"") | L21: =IFERROR(G21/C21*100%,"") | M21: =IFERROR(I21+J21,"") | O21: 5 | P21: =Sheet1!$A$1 -> 1
A22: =DATE(P22,O22,1) -> 518 | B22: =TEXT(O22*29,"mmm")& "-" &P22 -> Jun-1 | C22: =SUM(D22:G22) -> 0 | D22: =SUMIF(Sheet1!F:F,B22,Sheet1!J:J) -> 0 | E22: =SUMIF(Sheet1!F:F,B22,Sheet1!K:K) -> 0 | F22: =SUMIF(Sheet1!F:F,B22,Sheet1!N:N) -> 0 | G22: =SUMIF(Sheet1!F:F,B22,Sheet1!Z:Z) -> 0 | H22: =D22+E22 -> 0 | I22: =IFERROR(D22/C22*100%,"") | J22: =IFERROR(E22/C22*100%,"") | K22: =IFERROR(F22/C22*100%,"") | L22: =IFERROR(G22/C22*100%,"") | M22: =IFERROR(I22+J22,"") | O22: 6 | P22: =Sheet1!$A$1 -> 1
A23: =DATE(P23,O23,1) -> 548 | B23: =TEXT(O23*29,"mmm")& "-" &P23 -> Jul-1 | C23: =SUM(D23:G23) -> 0 | D23: =SUMIF(Sheet1!F:F,B23,Sheet1!J:J) -> 0 | E23: =SUMIF(Sheet1!F:F,B23,Sheet1!K:K) -> 0 | F23: =SUMIF(Sheet1!F:F,B23,Sheet1!N:N) -> 0 | G23: =SUMIF(Sheet1!F:F,B23,Sheet1!Z:Z) -> 0 | H23: =D23+E23 -> 0 | I23: =IFERROR(D23/C23*100%,"") | J23: =IFERROR(E23/C23*100%,"") | K23: =IFERROR(F23/C23*100%,"") | L23: =IFERROR(G23/C23*100%,"") | M23: =IFERROR(I23+J23,"") | O23: 7 | P23: =Sheet1!$A$1 -> 1
A24: =DATE(P24,O24,1) -> 579 | B24: =TEXT(O24*29,"mmm")& "-" &P24 -> Aug-1 | C24: =SUM(D24:G24) -> 0 | D24: =SUMIF(Sheet1!F:F,B24,Sheet1!J:J) -> 0 | E24: =SUMIF(Sheet1!F:F,B24,Sheet1!K:K) -> 0 | F24: =SUMIF(Sheet1!F:F,B24,Sheet1!N:N) -> 0 | G24: =SUMIF(Sheet1!F:F,B24,Sheet1!Z:Z) -> 0 | H24: =D24+E24 -> 0 | I24: =IFERROR(D24/C24*100%,"") | J24: =IFERROR(E24/C24*100%,"") | K24: =IFERROR(F24/C24*100%,"") | L24: =IFERROR(G24/C24*100%,"") | M24: =IFERROR(I24+J24,"") | O24: 8 | P24: =Sheet1!$A$1 -> 1
A25: =DATE(P25,O25,1) -> 610 | B25: =TEXT(O25*29,"mmm")& "-" &P25 -> Sep-1 | C25: =SUM(D25:G25) -> 0 | D25: =SUMIF(Sheet1!F:F,B25,Sheet1!J:J) -> 0 | E25: =SUMIF(Sheet1!F:F,B25,Sheet1!K:K) -> 0 | F25: =SUMIF(Sheet1!F:F,B25,Sheet1!N:N) -> 0 | G25: =SUMIF(Sheet1!F:F,B25,Sheet1!Z:Z) -> 0 | H25: =D25+E25 -> 0 | I25: =IFERROR(D25/C25*100%,"") | J25: =IFERROR(E25/C25*100%,"") | K25: =IFERROR(F25/C25*100%,"") | L25: =IFERROR(G25/C25*100%,"") | M25: =IFERROR(I25+J25,"") | O25: 9 | P25: =Sheet1!$A$1 -> 1
A26: =DATE(P26,O26,1) -> 640 | B26: =TEXT(O26*29,"mmm")& "-" &P26 -> Oct-1 | C26: =SUM(D26:G26) -> 0 | D26: =SUMIF(Sheet1!F:F,B26,Sheet1!J:J) -> 0 | E26: =SUMIF(Sheet1!F:F,B26,Sheet1!K:K) -> 0 | F26: =SUMIF(Sheet1!F:F,B26,Sheet1!N:N) -> 0 | G26: =SUMIF(Sheet1!F:F,B26,Sheet1!Z:Z) -> 0 | H26: =D26+E26 -> 0 | I26: =IFERROR(D26/C26*100%,"") | J26: =IFERROR(E26/C26*100%,"") | K26: =IFERROR(F26/C26*100%,"") | L26: =IFERROR(G26/C26*100%,"") | M26: =IFERROR(I26+J26,"") | O26: 10 | P26: =Sheet1!$A$1 -> 1
A27: =DATE(P27,O27,1) -> 671 | B27: =TEXT(O27*29,"mmm")& "-" &P27 -> Nov-1 | C27: =SUM(D27:G27) -> 0 | D27: =SUMIF(Sheet1!F:F,B27,Sheet1!J:J) -> 0 | E27: =SUMIF(Sheet1!F:F,B27,Sheet1!K:K) -> 0 | F27: =SUMIF(Sheet1!F:F,B27,Sheet1!N:N) -> 0 | G27: =SUMIF(Sheet1!F:F,B27,Sheet1!Z:Z) -> 0 | H27: =D27+E27 -> 0 | I27: =IFERROR(D27/C27*100%,"") | J27: =IFERROR(E27/C27*100%,"") | K27: =IFERROR(F27/C27*100%,"") | L27: =IFERROR(G27/C27*100%,"") | M27: =IFERROR(I27+J27,"") | O27: 11 | P27: =Sheet1!$A$1 -> 1
A28: =DATE(P28,O28,1) -> 701 | B28: =TEXT(O28*29,"mmm")& "-" &P28 -> Dec-1 | C28: =SUM(D28:G28) -> 0 | D28: =SUMIF(Sheet1!F:F,B28,Sheet1!J:J) -> 0 | E28: =SUMIF(Sheet1!F:F,B28,Sheet1!K:K) -> 0 | F28: =SUMIF(Sheet1!F:F,B28,Sheet1!N:N) -> 0 | G28: =SUMIF(Sheet1!F:F,B28,Sheet1!Z:Z) -> 0 | H28: =D28+E28 -> 0 | I28: =IFERROR(D28/C28*100%,"") | J28: =IFERROR(E28/C28*100%,"") | K28: =IFERROR(F28/C28*100%,"") | L28: =IFERROR(G28/C28*100%,"") | M28: =IFERROR(I28+J28,"") | O28: 12 | P28: =Sheet1!$A$1 -> 1
A53: General Admistration | C53: Working hour (근무시간) | I53: Hour rate /Total working hr (총합계시간 대비 비율 (%)) | O53: 2 | P53: GA
A54: 월 Tháng | C54: 총근무 Tổng đi làm | D54: 통상근무 Đi làm bình thường | E54: 잔업 Tăng ca | F54: 특근 Đi làm ngày nghỉ | G54: LOSS | H54: 통상+잔업(평일근무) Bình thường+Tăng ca (Đi làm ngày thường) | I54: 통상근무 Đi làm bình thường | J54: 잔업 Tăng ca | K54: 특근 Ngày nghỉ | L54: LOSS | M54: 통상+잔업(평일근무) Bình thường + tăng ca (làm việc ngày thường)
A55: =DATE(P55,O55,1) -> 1 | B55: =TEXT(O55*29,"mmm")&"-" & P55&"-"&$P$53 -> Jan-0-GA | C55: =SUM(D55:G55) -> 0 | D55: =IFERROR(VLOOKUP(B55,Sheet1!$G$7:$J$4000,4,0),0) -> 0 | E55: =IFERROR(VLOOKUP(B55,Sheet1!$G$7:$K$4000,5,0),0) -> 0 | F55: =IFERROR(VLOOKUP(B55,Sheet1!$G$7:$N$4000,8,0),0) -> 0 | G55: =IFERROR(VLOOKUP(B55,Sheet1!$G$7:$Q$4000,11,0),0) -> 0 | H55: =IFERROR(D55+E55,0) -> 0 | I55: =IFERROR(D55/C55*100%,"") | J55: =IFERROR(E55/C55*100%,"") | K55: =IFERROR(F55/C55*100%,"") | L55: =IFERROR(G55/C55*100%,"") | M55: =IFERROR(I55+J55,"") | O55: 1 | P55: =Sheet1!$A$1-1 -> 0
