Workbook
Name Giang___S_S: [1]Inzi!#REF!
Name Giang___S_S: [1]Inzi!#REF!
Name Giang___S_S: [1]Inzi!#REF!

Sheet HR-Summarize
A1: HR IMPLEMENTTION SCHEDULE
A2: No STT 순번 | B2: Service Dịch vụ 서비스 | C2: Total Time - Tổng thời gian - 총시간 | D2: Start Date Ngày bắt đầu 시작일 | E2: Golive Chính thức vận hành 가동시작
C3: Hours/Days - H/Ngày - 시간/일
A4: 1 | B4: DEMO & SIGN CONTRACT 회사 서명 | C4: 4 (Hours) / 0.5 (Days) | D4: ='HR-Details of Schedule'!F3 -> 45551 | E4: ='HR-Details of Schedule'!G3 -> 45551
A5: 2 | B5: SET UP SERVER AND DATABASE 서버 및 데이터베이스 설정 | C5: 8 (Hours) / 1 (Days) | D5: ='HR-Details of Schedule'!F8 -> 45561 | E5: ='HR-Details of Schedule'!G8 -> 45561
A6: 3 | B6: SET UP BASIC INFORMATION 기본 정보 설정 | C6: 8 (Hours) / 1 (Days) | D6: ='HR-Details of Schedule'!F11 -> 45562 | E6: ='HR-Details of Schedule'!G11 -> 45562
A7: 4 | B7: EMPLOYEE INFORMATION 직원 정보 | C7: 40 (Hours) / 5 (Days) | D7: ='HR-Details of Schedule'!F28 -> 45565 | E7: ='HR-Details of Schedule'!G28 -> 45569
A8: 5 | B8: TIME ATTENDANCE 시간 출석 | C8: 160 (Hours) / 20 (Days) | D8: ='HR-Details of Schedule'!F32 -> 45569 | E8: ='HR-Details of Schedule'!G32 -> 45586
A9: 6 | B9: PAYROLL 급여명세서 | C9: 152 (Hours) / 19 (Days) | D9: ='HR-Details of Schedule'!F54 -> 45587 | E9: ='HR-Details of Schedule'!G54 -> 45603
A10: 7 | B10: HR & ACCOUNTING INTERFACE 인사 및 회계 인터페이스 | C10: 8 (Hours) / 2 (Days) | D10: ='HR-Details of Schedule'!F66 -> 45575 | E10: ='HR-Details of Schedule'!G66 -> 45577
A11: 9 | B11: HANDLE OT JAN TO SEP 1월부터 9월까지 핸들링 OT | C11: 104 (Hours) / 13 (Days) | D11: ='HR-Details of Schedule'!F73 -> 45604 | E11: ='HR-Details of Schedule'!G73 -> 45618
A12: 8 | B12: REPORTS 보고 | C12: 48 (Hours) / 6 (Days) | D12: ='HR-Details of Schedule'!F75 -> 45619 | E12: ='HR-Details of Schedule'!G75 -> 45626
B13: HR Smartbooks software. Phần mềm HR Smartbooks. HR 스마트북 소프트웨어. | C13: 540 (Hours)/ 67.5 (Days) | D13: ='HR-Details of Schedule'!G75 -> 45626
A14: TESTING ACTUAL DATA for ONE MONTHS 1개월간 실제 데이터 테스트 | C14: ONE MONTH based on Actual Status 실제 상태 기준으로 1 개월 | D14: ='HR-Details of Schedule'!F83 -> 45627 | E14: ='HR-Details of Schedule'!G83 -> 46022

Sheet HR-Details of Schedule
A1: HR IMPLEMENTTION SCHEDULE DETAIL
A2: No/ STT/ 순번 | B2: Description/ Chi Tiết/ 항목 | C2: S&S PIC Phụ trách 담당 | D2: Elensys PIC Phụ trách 담당 | E2: Progress Tiến độ 진도 | F2: Start date Ngày bắt đầu 시작일 | G2: End date Ngày kết thúc 마감일 | H2: Days Ngày 일자 | I2: Note Ghi chú 비고
A3: SIGN CONTRACT 회사 서명 | F3: 45551 | G3: 45551 | H3: 0.5
A4: 1 | B4: Sign contract/ Ký hợp đồng- 계약 체결 | E4: 0
A5: 2 | B5: Test Timekeeping and PayRoll the first month/ Kiểm thử công lương tháng đầu tiên- 첫 번째 달의 근태관리 및 급여지급 테스트 | E5: 0
A6: 3 | B6: Test Timekeeping and Payroll the second month/ Kiểm thử công lương tháng thứ 2- 두 번째 달의 근태관리 및 급여지급 테스트 | E6: 0
A7: 4 | B7: Close/ Nghiệm thu- 마감 | E7: 0
A8: SET UP SERVER AND DATABASE/ 서버 및 데이터베이스 설정 | E8: 0 | F8: 45561 | G8: 45561 | H8: 1
A9: 1 | B9: Create new database to test/ Tạo mới dữ liệu- 테스트를 위한 새 데이터베이스 생성 | C9: Mr. Son/Mr. Ha | E9: 0
A10: 2 | B10: Install the new set up to test/ Cài đặt mới hệ thống- 테스트를 위한 새로 설정 설치 | C10: Mr. Son/Mr. Ha | E10: 0
A11: SET UP BASIS INFORMATION/ CÀI ĐẶT TỔNG QUÁT/ 총괄 설치 | E11: 0 | F11: 45562 | G11: 45562 | H11: 1
A12: 1 | B12: Register working time shift - Đăng ký ca - 근무 시간 교대제 등록 | C12: Mr. Son/Mr. Ha | E12: 0
A13: 2 | B13: Set up timekeeping - Cài đặt công - 출퇴근 기록 설정 | C13: Mr. Son/Mr. Ha | E13: 0
A14: 3 | B14: Create / Edit Factory - Tạo/ Sửa xưởng - 공장 생성/ 편집 | C14: Mr. Son/Mr. Ha | E14: 0
A15: 4 | B15: Create / Edit Department - Tạo/ Sửa bộ phận - 부서 생성/ 편집 | C15: Mr. Son/Mr. Ha | E15: 0
A16: 5 | B16: Create / Edit Team - Tạo/ Sửa nhóm - 팀 생성/ 편집 | C16: Mr. Son/Mr. Ha | E16: 0
A17: 6 | B17: Create / Edit Position - Tạo/ Sửa vị trí - 직위 생성/ 편집 | C17: Mr. Son/Mr. Ha | E17: 0
A18: 7 | B18: Create / Edit type of labour contract - Tạo/ Sửa hợp đồng - 근로계약 생성/ 편집 | C18: Mr. Son/Mr. Ha | E18: 0
A19: 8 | B19: Create / Edit Degrees - Tạo/ Sửa bằng cấp - 학위 생성/ 편집 | C19: Mr. Son/Mr. Ha | E19: 0
A20: 9 | B20: Create / Edit Discipline Type - Tạo/ Sửa loại kỷ luật - 징계 유형 생성/ 편집 | C20: Mr. Son/Mr. Ha | E20: 0
A21: 10 | B21: Create/ Edit Leave type - Tạo/ Sửa loại nghỉ - 휴가 유형 생성/ 편집 | C21: Mr. Son/Mr. Ha | E21: 0
A22: 11 | B22: Create/ Edit Working Time type - Tạo/ Sửa loại công - 근무시간 유형 생성/ 편집 | C22: Mr. Son/Mr. Ha | E22: 0
A23: 12 | B23: Create/Edit Regional - Tạo/ Sửa vùng miền - 지역별 생성/ 편집 | C23: Mr. Son/Mr. Ha | E23: 0
... A27: 16 | B27: Authority user permission - Phân quyền người dùng - 사용자 분권 | C27: Mr. Son/Mr. Ha | E27: 0
A28: EMPLOYEE INFORMATION / THÔNG TIN NHÂN VIÊN/ 직원 정보 | E28: 0 | F28: 45565 | G28: 45569 | H28: 5
A29: 1 | B29: Create/Edit Employee information - Tạo/ Sửa thông tin nhân viên - 직원 정보 생성/ 편집 | C29: Mr. Son/Mr. Ha | E29: 0
A30: 2 | B30: Contract Labour management - Tạo/ Sửa hợp đồng lao động - 근로계약 생성/ 편집 | C30: Mr. Son/Mr. Ha | E30: 0
A31: 3 | B31: Family Information - Tạo/ Sửa thông tin gia đình - 가정 정보 생성/ 편집 | C31: Mr. Son/Mr. Ha | E31: 0
A32: TIME ATTENDANCE/CHẤM CÔNG/ 출퇴근 | E32: 0 | F32: 45569 | G32: 45586 | H32: 20
A33: 1 | B33: Time keeping - Daily - Chấm công - 출퇴근시간 | C33: Mr. Son/Mr. Ha | E33: 0
A34: 2 | B34: Working time of exception - Công ngoại lệ - 예외 근무시간 | C34: Mr. Son/Mr. Ha | E34: 0
A35: 3 | B35: Register Overtime - Đăng ký tăng ca - 초과근무 신청 | C35: Mr. Son/Mr. Ha | E35: 0
A36: 4 | B36: Machine working time data - Dữ liệu máy chấm công - 출퇴근 기록기의 데이터 | C36: Mr. Son/Mr. Ha | E36: 0
A37: 5 | B37: Employee Register Time shift - Đăng ký ca - 교대신청 | C37: Mr. Son/Mr. Ha | E37: 0
A38: 6 | B38: Employee Leave Register - Đăng ký nghỉ - 휴가 신청 | C38: Mr. Son/Mr. Ha | E38: 0
A39: 7 | B39: Pregnancy Registration - Đăng ký thai sản 임신 신청 | C39: Mr. Son/Mr. Ha | E39: 0
A40: 8 | B40: Uniform control - Đăng ký đồng phục - 유니폼 신청 | C40: Mr. Son/Mr. Ha | E40: 0
A41: 9 | B41: The violate employee list - Danh sách nhân viên kỷ luật - 위반 직원 리스트 | C41: Mr. Son/Mr. Ha | E41: 0
A42: 10 | B42: Leave time report - Báo cáo nghỉ - 휴가 보고서 | C42: Mr. Son/Mr. Ha | E42: 0
A43: 11 | B43: Pregnancy report - Báo cáo thai sản - 임신 보고서 | C43: Mr. Son/Mr. Ha | E43: 0
...
